Workbook

Sheet CORNEJO ESTELA
B2: CORNEJO DONATO DE CORDOVA ESTELA PILAR
A4: FECHA | B4: DOCUMENTO | C4: PERIODO | D4: CONCEPTO | E4: POR COBRAR | F4: PAGADO | G4: SALDO POR COBRAR
A5: 42736 | B5: SALDO AL 2016 | G5: 1045.3
A6: 42740 | B6: 12074 | C6: A CUENTA 2016 | F6: 8 | G6: =+G5+E6-F6 -> 1037.3
A7: 42804 | B7: 12414 | C7: A CUENTA 2016 | F7: 66.9 | G7: =+G6+E7-F7 -> 970.4
A8: 42787 | B8: 12339 | C8: A CUENTA 2016 | F8: 50.3 | G8: =+G7+E8-F8 -> 920.1
A9: 42763 | B9: TARJETA | C9: A CUENTA 2016 | F9: 80 | G9: =+G8+E9-F9 -> 840.1
A10: 42794 | B10: TARJETA | C10: A CUENTA 2016 | F10: 197 | G10: =+G9+E10-F10 -> 643.1
A11: 42802 | B11: TARJETA | C11: A CUENTA 2016 | F11: 43.1 | G11: =+G10+E11-F11 -> 600
A12: 42804 | B12: 12413 | C12: A CUENTA 2016 | F12: 600 | G12: =+G11+E12-F12 -> 0
A13: 42766 | B13: POR COBRAR | C13: ENERO | D13: LUZ | E13: 22 | G13: =+G12+E13-F13 -> 22
D14: AGUA | E14: 2.8 | G14: =+G13+E14-F14 -> 24.8
D15: G. ADM | E15: 60 | G15: =+G14+E15-F15 -> 84.8
D16: P. SOCIAL | E16: 2 | G16: =+G15+E16-F16 -> 86.8
D17: DEPOSITO | E17: 55 | G17: =+G16+E17-F17 -> 141.8
D18: P.S. FALLEC. | E18: 10 | G18: =+G17+E18-F18 -> 151.8
A19: 42763 | B19: TARJETA | C19: ENERO | D19: G. ADM | F19: 56 | G19: =+G18+E19-F19 -> 95.8
A20: 42804 | B20: 12413 | C20: ENERO | D20: DEPOSITO | F20: 55 | G20: =+G19+E20-F20 -> 40.8
A21: 42787 | B21: 12339 | C21: ENERO | D21: LUZ | F21: 22 | G21: =+G20+E21-F21 -> 18.8
A22: 42787 | B22: 12339 | C22: ENERO | D22: AGUA | F22: 2.8 | G22: =+G21+E22-F22 -> 16
A23: 42787 | B23: 12339 | C23: ENERO | D23: P.S. FALLEC. | F23: 10 | G23: =+G22+E23-F23 -> 6
A24: 42769 | B24: 12910 | C24: ENERO | D24: P. SOCIAL | F24: 2 | G24: =+G23+E24-F24 -> 4
A25: 42773 | B25: 12926 | C25: ENERO | D25: G. ADM | F25: 4 | G25: =+G24+E25-F25 -> 1.0658141e-14
A26: 42794 | B26: POR COBRAR | C26: FEBRERO | D26: LUZ | E26: 21.8 | G26: =+G25+E26-F26 -> 21.8
D27: AGUA | E27: 2 | G27: =+G26+E27-F27 -> 23.8
D28: G. ADM | E28: 56 | G28: =+G27+E28-F28 -> 79.8
D29: P. SOCIAL | E29: 2 | G29: =+G28+E29-F29 -> 81.8
D30: DEPOSITO | E30: 55 | G30: =+G29+E30-F30 -> 136.8
A31: 42794 | B31: TARJETA | C31: FEBRERO | D31: DEPOSITO | F31: 2 | G31: =+G30+E31-F31 -> 134.8
A32: 42794 | B32: TARJETA | C32: FEBRERO | D32: G. ADM | F32: 56 | G32: =+G31+E32-F32 -> 78.8
A33: 42794 | B33: TARJETA | C33: FEBRERO | D33: P. SOCIAL | F33: 2 | G33: =+G32+E33-F33 -> 76.8
A34: 42825 | B34: TARJETA | C34: FEBRERO | D34: DEPOSITO | F34: 20.9 | G34: =+G33+E34-F34 -> 55.9
A35: 42804 | B35: 12413 | C35: FEBRERO | D35: DEPOSITO | F35: 32.1 | G35: =+G34+E35-F35 -> 23.8
A36: 42818 | B36: 12464 | C36: FEBRERO | D36: LUZ | F36: 21.8 | G36: =+G35+E36-F36 -> 2
A37: 42818 | B37: 12464 | C37: FEBRERO | D37: AGUA | F37: 2 | G37: =+G36+E37-F37 -> 1.0658141e-14
A38: 42825 | B38: POR COBRAR | C38: MARZO | D38: LUZ | E38: 20.5 | G38: =+G37+E38-F38 -> 20.5
D39: AGUA | E39: 2 | G39: =+G38+E39-F39 -> 22.5
D40: G. ADM | E40: 60 | G40: =+G39+E40-F40 -> 82.5
D41: P. SOCIAL | E41: 2 | G41: =+G40+E41-F41 -> 84.5
D42: DEPOSITO | E42: 55 | F42: 0 | G42: =+G41+E42-F42 -> 139.5
...

Sheet CRUZ LUIS
B2: CRUZ JARAMILLO LUIS
A4: FECHA | B4: DOCUMENTO | C4: PERIODO | D4: CONCEPTO | E4: POR COBRAR | F4: PAGADO | G4: SALDO POR COBRAR
A5: 42736 | B5: SALDO AL 2016 | G5: 152.2
A6: 42739 | B6: 12061 | C6: A CUENTA 2016 | F6: 73.5 | G6: =+G5+E6-F6 -> 78.7
A7: 42763 | B7: 12173 | C7: A CUENTA 2016 | F7: 78.7 | G7: =+G6+E7-F7 -> 0
A8: 42766 | B8: POR COBRAR | C8: ENERO | D8: LUZ | E8: 79.2 | G8: =+G7+E8-F8 -> 79.2
D9: AGUA | E9: 2.8 | G9: =+G8+E9-F9 -> 82
D10: G. ADM | E10: 60 | G10: =+G9+E10-F10 -> 142
D11: P. SOCIAL | E11: 2 | G11: =+G10+E11-F11 -> 144
A12: 42765 | B12: TARJETA | C12: ENERO | D12: G. ADM | F12: 60 | G12: =+G11+E12-F12 -> 84
A13: 42765 | B13: TARJETA | C13: ENERO | D13: P. SOCIAL | F13: 2 | G13: =+G12+E13-F13 -> 82
A14: 42784 | B14: 12990 | C14: ENERO | D14: LUZ | F14: 79.2 | G14: =+G13+E14-F14 -> 2.8
A15: 42784 | B15: 12990 | C15: ENERO | D15: AGUA | F15: 2.8 | G15: =+G14+E15-F15 -> 0
A16: 42794 | B16: POR COBRAR | C16: FEBRERO | D16: LUZ | E16: 76 | G16: =+G15+E16-F16 -> 76
D17: AGUA | E17: 2 | G17: =+G16+E17-F17 -> 78
D18: G. ADM | E18: 56 | G18: =+G17+E18-F18 -> 134
D19: P. SOCIAL | E19: 2 | G19: =+G18+E19-F19 -> 136
D20: P.S. FALLEC. | E20: 10 | G20: =+G19+E20-F20 -> 146
A21: 42783 | B21: 12974 | C21: FEBRERO | D21: P.S. FALLEC. | F21: 10 | G21: =+G20+E21-F21 -> 136
A22: 42794 | B22: TARJETA | C22: FEBRERO | D22: G. ADM | F22: 56 | G22: =+G21+E22-F22 -> 80
A23: 42794 | B23: TARJETA | C23: FEBRERO | D23: P. SOCIAL | F23: 2 | G23: =+G22+E23-F23 -> 78
A24: 42818 | B24: 12456 | C24: FEBRERO | D24: LUZ | F24: 76 | G24: =+G23+E24-F24 -> 2
A25: 42818 | B25: 12456 | C25: FEBRERO | D25: AGUA | F25: 2 | G25: =+G24+E25-F25 -> 0
A26: 42825 | B26: POR COBRAR | C26: MARZO | D26: LUZ | E26: 72.7 | G26: =+G25+E26-F26 -> 72.7
D27: AGUA | E27: 2 | G27: =+G26+E27-F27 -> 74.7
D28: G. ADM | E28: 60 | G28: =+G27+E28-F28 -> 134.7
D29: P. SOCIAL | E29: 2 | G29: =+G28+E29-F29 -> 136.7
A30: 42824 | B30: TARJETA | C30: MARZO | D30: G. ADM | F30: 60 | G30: =+G29+E30-F30 -> 76.7
A31: 42824 | B31: TARJETA | C31: MARZO | D31: P. SOCIAL | F31: 2 | G31: =+G30+E31-F31 -> 74.7
A32: 42845 | B32: 12664 | C32: MARZO | D32: AGUA | F32: 2 | G32: =+G31+E32-F32 -> 72.7
A33: 42845 | B33: 12664 | C33: MARZO | D33: LUZ | F33: 72.7 | G33: =+G32+E33-F33 -> 0
A34: 42855 | B34: POR COBRAR | C34: ABRIL | D34: LUZ | E34: 74.3 | G34: =+G33+E34-F34 -> 74.3
D35: AGUA | E35: 2 | G35: =+G34+E35-F35 -> 76.3
D36: G. ADM | E36: 60 | G36: =+G35+E36-F36 -> 136.3
D37: P. SOCIAL | E37: 2 | G37: =+G36+E37-F37 -> 138.3
A38: 42855 | B38: TARJETA | C38: ABRIL | D38: G. ADM | F38: 60 | G38: =+G37+E38-F38 -> 78.3
A39: 42855 | B39: TARJETA | C39: ABRIL | D39: P. SOCIAL | F39: 2 | G39: =+G38+E39-F39 -> 76.3
A40: 42878 | B40: 12803 | C40: ABRIL | D40: LUZ | F40: 74.3 | G40: =+G39+E40-F40 -> 2
A41: 42878 | B41: 12803 | C41: ABRIL | D41: AGUA | F41: 2 | G41: =+G40+E41-F41 -> 1.4210855e-14
A42: 42886 | B42: POR COBRAR | C42: MAYO | D42: LUZ | E42: 69.4 | G42: =+G41+E42-F42 -> 69.4
...

Sheet CUCHO SAUL
B2: CUCHO DE LA CRUZ SAUL
A4: FECHA | B4: DOCUMENTO | C4: PERIODO | D4: CONCEPTO | E4: POR COBRAR | F4: PAGADO | G4: SALDO POR COBRAR
A5: 42736 | B5: SALDO AL 2016 | G5: 217
A6: 42786 | B6: 12241 | C6: A CUENTA 2016 | F6: 217 | G6: =+G5+E6-F6 -> 0
A7: 42766 | B7: POR COBRAR | C7: ENERO | D7: LUZ | E7: 107.1 | G7: =+G6+E7-F7 -> 107.1
D8: AGUA | E8: 2.8 | G8: =+G7+E8-F8 -> 109.9
D9: G. ADM | E9: 60 | G9: =+G8+E9-F9 -> 169.9
D10: P. SOCIAL | E10: 2 | G10: =+G9+E10-F10 -> 171.9
A11: 42765 | B11: TARJETA | C11: ENERO | D11: G. ADM | F11: 60 | G11: =+G10+E11-F11 -> 111.9
A12: 42765 | B12: TARJETA | C12: ENERO | D12: P. SOCIAL | F12: 2 | G12: =+G11+E12-F12 -> 109.9
A13: 42786 | B13: 12241 | C13: ENERO | D13: AGUA | F13: 2.8 | G13: =+G12+E13-F13 -> 107.1
A14: 42786 | B14: 12241 | C14: ENERO | D14: LUZ | F14: 107.1 | G14: =+G13+E14-F14 -> 0
A15: 42794 | B15: POR COBRAR | C15: FEBRERO | D15: LUZ | E15: 110.2 | G15: =+G14+E15-F15 -> 110.2
D16: AGUA | E16: 2 | G16: =+G15+E16-F16 -> 112.2
D17: G. ADM | E17: 56 | G17: =+G16+E17-F17 -> 168.2
D18: P. SOCIAL | E18: 2 | G18: =+G17+E18-F18 -> 170.2
A19: 42794 | B19: TARJETA | C19: ENERO | D19: G. ADM | F19: 56 | G19: =+G18+E19-F19 -> 114.2
A20: 42794 | B20: TARJETA | C20: ENERO | D20: P. SOCIAL | F20: 2 | G20: =+G19+E20-F20 -> 112.2
A21: 42828 | B21: 12626 | C21: FEBRERO | D21: AGUA | F21: 2 | G21: =+G20+E21-F21 -> 110.2
A22: 42828 | B22: 12626 | C22: FEBRERO | D22: LUZ | F22: 110.2 | G22: =+G21+E22-F22 -> 0
A23: 42825 | B23: POR COBRAR | C23: MARZO | D23: LUZ | E23: 105.7 | G23: =+G22+E23-F23 -> 105.7
D24: AGUA | E24: 2 | G24: =+G23+E24-F24 -> 107.7
D25: G. ADM | E25: 60 | G25: =+G24+E25-F25 -> 167.7
D26: P. SOCIAL | E26: 2 | G26: =+G25+E26-F26 -> 169.7
D27: MULTA | E27: 85 | G27: =+G26+E27-F27 -> 254.7
A28: 42824 | B28: TARJETA | C28: MARZO | D28: G. ADM | F28: 105.7 | G28: =+G27+E28-F28 -> 149
A29: 42885 | B29: 12885 | C29: MARZO | D29: LUZ | F29: 50 | G29: =+G28+E29-F29 -> 99
A30: 42885 | B30: 12885 | C30: MARZO | D30: AGUA | F30: 2 | G30: =+G29+E30-F30 -> 97
A31: 42948 | B31: 13298 | C31: MARZO | D31: G. ADM | F31: 10 | G31: =+G30+E31-F31 -> 87
A32: 42948 | B32: 13298 | C32: MARZO | D32: P. SOCIAL | F32: 2 | G32: =+G31+E32-F32 -> 85
A33: 42948 | B33: 13298 | C33: MARZO | D33: MULTA | F33: 85 | G33: =+G32+E33-F33 -> 0
A34: 42855 | B34: POR COBRAR | C34: ABRIL | D34: LUZ | E34: 107.6 | G34: =+G33+E34-F34 -> 107.6
D35: AGUA | E35: 2 | G35: =+G34+E35-F35 -> 109.6
D36: G. ADM | E36: 60 | G36: =+G35+E36-F36 -> 169.6
D37: P. SOCIAL | E37: 2 | G37: =+G36+E37-F37 -> 171.6
A38: 42855 | B38: TARJETA | C38: ABRIL | D38: G. ADM | F38: 60 | G38: =+G37+E38-F38 -> 111.6
A39: 42855 | B39: TARJETA | C39: ABRIL | D39: P. SOCIAL | F39: 2 | G39: =+G38+E39-F39 -> 109.6
A40: 42885 | B40: 12885 | C40: ABRIL | D40: LUZ | F40: 107.6 | G40: =+G39+E40-F40 -> 2
A41: 42885 | B41: 12885 | C41: ABRIL | D41: AGUA | F41: 2 | G41: =+G40+E41-F41 -> 0
A42: 42886 | B42: POR COBRAR | C42: MAYO | D42: LUZ | E42: 100.1 | G42: =+G41+E42-F42 -> 100.1
...

Sheet CUEVAS ENRIQUE
B2: CUEVAS MAYO ENRIQUE
A4: FECHA | B4: DOCUMENTO | C4: PERIODO | D4: CONCEPTO | E4: POR COBRAR | F4: PAGADO | G4: SALDO POR COBRAR
A5: 42736 | B5: SALDO AL 2016 | G5: 288.7
A6: 42768 | B6: 12193 | C6: A CUENTA 2016 | F6: 282.7 | G6: =+G5+E6-F6 -> 6
A7: 42768 | B7: 12194 | C7: A CUENTA 2016 | F7: 6 | G7: =+G6+E7-F7 -> 0
A8: 42766 | B8: POR COBRAR | C8: ENERO | D8: LUZ | E8: 120.6 | G8: =+G7+E8-F8 -> 120.6
D9: AGUA | E9: 2.8 | G9: =+G8+E9-F9 -> 123.4
D10: G. ADM | E10: 60 | G10: =+G9+E10-F10 -> 183.4
D11: P. SOCIAL | E11: 2 | G11: =+G10+E11-F11 -> 185.4
A12: 42768 | B12: 12193 | C12: ENERO | D12: G. ADM | F12: 60 | G12: =+G11+E12-F12 -> 125.4
A13: 42768 | B13: 12193 | C13: ENERO | D13: P. SOCIAL | F13: 2 | G13: =+G12+E13-F13 -> 123.4
A14: 42822 | B14: 12584 | C14: ENERO | D14: AGUA | F14: 2.8 | G14: =+G13+E14-F14 -> 120.6
A15: 42822 | B15: 12584 | C15: ENERO | D15: LUZ | F15: 120.6 | G15: =+G14+E15-F15 -> 0
A16: 42794 | B16: POR COBRAR | C16: FEBRERO | D16: LUZ | E16: 123.2 | G16: =+G15+E16-F16 -> 123.2
D17: AGUA | E17: 2 | G17: =+G16+E17-F17 -> 125.2
D18: G. ADM | E18: 56 | G18: =+G17+E18-F18 -> 181.2
D19: P. SOCIAL | E19: 2 | G19: =+G18+E19-F19 -> 183.2
A20: 42822 | B20: 12579 | C20: FEBRERO | D20: G. ADM | F20: 56 | G20: =+G19+E20-F20 -> 127.2
A21: 42822 | B21: 12579 | C21: FEBRERO | D21: P. SOCIAL | F21: 2 | G21: =+G20+E21-F21 -> 125.2
A22: 42822 | B22: 12579 | C22: FEBRERO | D22: AGUA | F22: 2 | G22: =+G21+E22-F22 -> 123.2
A23: 42822 | B23: 12579 | C23: FEBRERO | D23: LUZ | F23: 123.2 | G23: =+G22+E23-F23 -> 0
A24: 42825 | B24: POR COBRAR | C24: MARZO | D24: LUZ | E24: 117.7 | G24: =+G23+E24-F24 -> 117.7
D25: AGUA | E25: 2 | G25: =+G24+E25-F25 -> 119.7
D26: G. ADM | E26: 60 | G26: =+G25+E26-F26 -> 179.7
D27: P. SOCIAL | E27: 2 | G27: =+G26+E27-F27 -> 181.7
A28: 42854 | B28: 12708 | C28: MARZO | D28: LUZ | F28: 2 | G28: =+G27+E28-F28 -> 179.7
A29: 42854 | B29: 12708 | C29: MARZO | D29: AGUA | F29: 117.7 | G29: =+G28+E29-F29 -> 62
A30: 42854 | B30: 12708 | C30: MARZO | D30: P. SOCIAL | F30: 2 | G30: =+G29+E30-F30 -> 60
A31: 42854 | B31: 12708 | C31: MARZO | D31: G. ADM | F31: 60 | G31: =+G30+E31-F31 -> 0
A32: 42855 | B32: POR COBRAR | C32: ABRIL | D32: LUZ | E32: 120.6 | G32: =+G31+E32-F32 -> 120.6
D33: AGUA | E33: 2 | G33: =+G32+E33-F33 -> 122.6
D34: G. ADM | E34: 60 | G34: =+G33+E34-F34 -> 182.6
D35: P. SOCIAL | E35: 2 | G35: =+G34+E35-F35 -> 184.6
A36: 42885 | B36: 12867 | C36: ABRIL | D36: G. ADM | F36: 60 | G36: =+G35+E36-F36 -> 124.6
A37: 42885 | B37: 12867 | C37: ABRIL | D37: P. SOCIAL | F37: 2 | G37: =+G36+E37-F37 -> 122.6
A38: 42885 | B38: 12867 | C38: ABRIL | D38: LUZ | F38: 120.6 | G38: =+G37+E38-F38 -> 2
A39: 42885 | B39: 12867 | C39: ABRIL | D39: AGUA | F39: 2 | G39: =+G38+E39-F39 -> 0
A40: 42886 | B40: POR COBRAR | C40: MAYO | D40: LUZ | E40: 109.2 | G40: =+G39+E40-F40 -> 109.2
D41: AGUA | E41: 2 | G41: =+G40+E41-F41 -> 111.2
D42: G. ADM | E42: 60 | G42: =+G41+E42-F42 -> 171.2
...

Sheet CULE HAYDEE
B2: CULE CARRASCO HAYDEE MONICA
A4: FECHA | B4: DOCUMENTO | C4: PERIODO | D4: CONCEPTO | E4: POR COBRAR | F4: PAGADO | G4: SALDO POR COBRAR
A5: 42736 | B5: SALDO AL 2016 | G5: 495.1
A6: 42736 | B6: AGUA R. | E6: 9 | G6: =+G5+E6-F6 -> 504.1
A7: 42763 | B7: TARJETA | C7: A CUENTA DEL 2016 | F7: 60 | G7: =+G6+E7-F7 -> 444.1
A8: 42794 | B8: TARJETA | C8: A CUENTA DEL 2016 | F8: 445 | G8: =+G7+E8-F8 -> -0.9
A9: 42766 | B9: POR COBRAR | C9: ENERO | D9: LUZ | E9: 113.5 | G9: =+G8+E9-F9 -> 112.6
D10: AGUA | E10: 50 | G10: =+G9+E10-F10 -> 162.6
D11: G. ADM | E11: 60 | G11: =+G10+E11-F11 -> 222.6
D12: P. SOCIAL | E12: 2 | G12: =+G11+E12-F12 -> 224.6
D13: PS X FALLEC | E13: 10 | G13: =+G12+E13-F13 -> 234.6
A14: 42763 | B14: TARJETA | C14: ENERO | D14: G. ADM | F14: 24 | G14: =+G13+E14-F14 -> 210.6
A15: 42763 | B15: TARJETA | C15: ENERO | D15: LUZ | F15: 36 | G15: =+G14+E15-F15 -> 174.6
A16: 42809 | B16: 12421 | C16: ENERO | D16: G. ADM | F16: 35.1 | G16: =+G15+E16-F16 -> 139.5
A17: 42809 | B17: 12421 | C17: ENERO | D17: P. SOCIAL | F17: 2 | G17: =+G16+E17-F17 -> 137.5
A18: 42809 | B18: 12421 | C18: ENERO | D18: LUZ | F18: 77.5 | G18: =+G17+E18-F18 -> 60
A19: 42809 | B19: 12421 | C19: ENERO | D19: AGUA | F19: 50 | G19: =+G18+E19-F19 -> 10
A20: 42809 | B20: 12421 | C20: ENERO | D20: PS X FALLEC | F20: 10 | G20: =+G19+E20-F20 -> 2.8421709e-14
A21: 42794 | B21: POR COBRAR | C21: FEBRERO | D21: LUZ | E21: 118 | G21: =+G20+E21-F21 -> 118
D22: AGUA | E22: 35 | G22: =+G21+E22-F22 -> 153
D23: G. ADM | E23: 56 | G23: =+G22+E23-F23 -> 209
D24: P. SOCIAL | E24: 2 | G24: =+G23+E24-F24 -> 211
A25: 42794 | B25: TARJETA | C25: FEBRERO | D25: G. ADM | F25: 18 | G25: =+G24+E25-F25 -> 193
A26: 42794 | B26: TARJETA | C26: FEBRERO | D26: LUZ | F26: 27 | G26: =+G25+E26-F26 -> 166
A27: 42809 | B27: 12421 | C27: FEBRERO | D27: G. ADM | F27: 38 | G27: =+G26+E27-F27 -> 128
A28: 42809 | B28: 12421 | C28: FEBRERO | D28: P. SOCIAL | F28: 2 | G28: =+G27+E28-F28 -> 126
A29: 42822 | B29: 12600 | C29: FEBRERO | D29: LUZ | F29: 91 | G29: =+G28+E29-F29 -> 35
A30: 42822 | B30: 12600 | C30: FEBRERO | D30: AGUA | F30: 35 | G30: =+G29+E30-F30 -> 0
A31: 42825 | B31: POR COBRAR | C31: MARZO | D31: LUZ | E31: 116.2 | G31: =+G30+E31-F31 -> 116.2
D32: AGUA | E32: 36 | G32: =+G31+E32-F32 -> 152.2
D33: G. ADM | E33: 60 | G33: =+G32+E33-F33 -> 212.2
D34: P. SOCIAL | E34: 2 | G34: =+G33+E34-F34 -> 214.2
A35: 42823 | B35: TARJETA | C35: MARZO | D35: G. ADM | F35: 26 | G35: =+G34+E35-F35 -> 188.2
A36: 42823 | B36: TARJETA | C36: MARZO | D36: LUZ | F36: 104 | G36: =+G35+E36-F36 -> 84.2
A37: 42898 | B37: 13094 | C37: MARZO | D37: LUZ | F37: 12.2 | G37: =+G36+E37-F37 -> 72
A38: 42898 | B38: 13094 | C38: MARZO | D38: AGUA | F38: 36 | G38: =+G37+E38-F38 -> 36
A39: 42950 | B39: 13410 | C39: MARZO | D39: G. ADM | F39: 2 | G39: =+G38+E39-F39 -> 34
A40: 42950 | B40: 13410 | C40: MARZO | D40: P. SOCIAL | F40: 34 | G40: =+G39+E40-F40 -> 0
A41: 42855 | B41: POR COBRAR | C41: ABRIL | D41: LUZ | E41: 115 | G41: =+G40+E41-F41 -> 115
D42: AGUA | E42: 36.8 | G42: =+G41+E42-F42 -> 151.8
...

Sheet CUSI SONIA
B2: CUSI LAURA SONIA
A4: FECHA | B4: DOCUMENTO | C4: PERIODO | D4: CONCEPTO | E4: POR COBRAR | F4: PAGADO | G4: SALDO POR COBRAR
A5: 42736 | B5: SALDO AL 2016 | G5: 31.9
A6: 42762 | B6: 12170 | C6: A CUENTA 2016 | F6: 31.9 | G6: =+G5+E6-F6 -> 0
A7: 42766 | B7: POR COBRAR | C7: ENERO | D7: LUZ | E7: 28.5 | G7: =+G6+E7-F7 -> 28.5
D8: AGUA | E8: 3 | G8: =+G7+E8-F8 -> 31.5
D9: G. ADM | E9: 60 | G9: =+G8+E9-F9 -> 91.5
D10: P. SOCIAL | E10: 2 | G10: =+G9+E10-F10 -> 93.5
A11: 42765 | B11: TARJETA | C11: ENERO | D11: G. ADM | F11: 60 | G11: =+G10+E11-F11 -> 33.5
A12: 42765 | B12: TARJETA | C12: ENERO | D12: P. SOCIAL | F12: 2 | G12: =+G11+E12-F12 -> 31.5
A13: 42783 | B13: 12981 | C13: ENERO | D13: LUZ | F13: 28.5 | G13: =+G12+E13-F13 -> 3
A14: 42783 | B14: 12981 | C14: ENERO | D14: AGUA | F14: 3 | G14: =+G13+E14-F14 -> 0
A15: 42794 | B15: POR COBRAR | C15: FEBRERO | D15: LUZ | E15: 28.5 | G15: =+G14+E15-F15 -> 28.5
D16: AGUA | E16: 2 | G16: =+G15+E16-F16 -> 30.5
D17: G. ADM | E17: 56 | G17: =+G16+E17-F17 -> 86.5
D18: P. SOCIAL | E18: 2 | G18: =+G17+E18-F18 -> 88.5
D19: MULTA | E19: 85 | G19: =+G18+E19-F19 -> 173.5
A20: 42789 | B20: 12361 | C20: FEBRERO | D20: MULTA | F20: 85 | G20: =+G19+E20-F20 -> 88.5
A21: 42794 | B21: TARJETA | C21: FEBRERO | D21: G. ADM | F21: 56 | G21: =+G20+E21-F21 -> 32.5
A22: 42794 | B22: TARJETA | C22: FEBRERO | D22: P. SOCIAL | F22: 2 | G22: =+G21+E22-F22 -> 30.5
A23: 42821 | B23: 12522 | C23: FEBRERO | D23: LUZ | F23: 28.5 | G23: =+G22+E23-F23 -> 2
A24: 42821 | B24: 12522 | C24: FEBRERO | D24: AGUA | F24: 2 | G24: =+G23+E24-F24 -> 0
A25: 42825 | B25: POR COBRAR | C25: MARZO | D25: LUZ | E25: 26.9 | G25: =+G24+E25-F25 -> 26.9
D26: AGUA | E26: 2 | G26: =+G25+E26-F26 -> 28.9
D27: G. ADM | E27: 60 | G27: =+G26+E27-F27 -> 88.9
D28: P. SOCIAL | E28: 2 | G28: =+G27+E28-F28 -> 90.9
A29: 42824 | B29: TARJETA | C29: MARZO | D29: G. ADM | F29: 60 | G29: =+G28+E29-F29 -> 30.9
A30: 42824 | B30: TARJETA | C30: MARZO | D30: P. SOCIAL | F30: 2 | G30: =+G29+E30-F30 -> 28.9
A31: 42845 | B31: 12665 | C31: MARZO | D31: LUZ | F31: 26.9 | G31: =+G30+E31-F31 -> 2
A32: 42845 | B32: 12665 | C32: MARZO | D32: AGUA | F32: 2 | G32: =+G31+E32-F32 -> 7.1054274e-15
A33: 42855 | B33: POR COBRAR | C33: ABRIL | D33: LUZ | E33: 28.1 | G33: =+G32+E33-F33 -> 28.1
D34: AGUA | E34: 2 | G34: =+G33+E34-F34 -> 30.1
D35: G. ADM | E35: 60 | G35: =+G34+E35-F35 -> 90.1
D36: P. SOCIAL | E36: 2 | G36: =+G35+E36-F36 -> 92.1
A37: 42854 | B37: TARJETA | C37: ABRIL | D37: G. ADM | F37: 60 | G37: =+G36+E37-F37 -> 32.1
A38: 42854 | B38: TARJETA | C38: ABRIL | D38: P. SOCIAL | F38: 2 | G38: =+G37+E38-F38 -> 30.1
A39: 42874 | B39: 12777 | C39: ABRIL | D39: LUZ | F39: 28.1 | G39: =+G38+E39-F39 -> 2
A40: 42874 | B40: 12777 | C40: ABRIL | D40: AGUA | F40: 2 | G40: =+G39+E40-F40 -> 7.1054274e-15
A41: 42886 | B41: POR COBRAR | C41: MAYO | D41: LUZ | E41: 26.9 | G41: =+G40+E41-F41 -> 26.9
D42: AGUA | E42: 2 | G42: =+G41+E42-F42 -> 28.9
...

Sheet CUYA ALBERTO
B2: CUYA SANCHEZ ALBERTO
A4: FECHA | B4: DOCUMENTO | C4: PERIODO | D4: CONCEPTO | E4: POR COBRAR | F4: PAGADO | G4: SALDO POR COBRAR
A5: 42736 | B5: SALDO AL 2016 | G5: 376.1
A6: 42786 | B6: 12277 | C6: A CUENTA 2016 | F6: 65.1 | G6: =+G5+E6-F6 -> 311
A7: 42786 | B7: 12311 | C7: A CUENTA 2016 | F7: 311 | G7: =+G6+E7-F7 -> 0
A8: 42766 | B8: POR COBRAR | C8: ENERO | D8: LUZ | E8: 61 | G8: =+G7+E8-F8 -> 61
D9: AGUA | E9: 2.8 | G9: =+G8+E9-F9 -> 63.8
D10: G. ADM | E10: 60 | G10: =+G9+E10-F10 -> 123.8
D11: P. SOCIAL | E11: 2 | G11: =+G10+E11-F11 -> 125.8
A12: 42786 | B12: 12277 | C12: ENERO | D12: LUZ | F12: 61 | G12: =+G11+E12-F12 -> 64.8
A13: 42786 | B13: 12277 | C13: ENERO | D13: AGUA | F13: 2.8 | G13: =+G12+E13-F13 -> 62
A14: 42786 | B14: 12311 | C14: ENERO | D14: G. ADM | F14: 60 | G14: =+G13+E14-F14 -> 2
A15: 42786 | B15: 12311 | C15: ENERO | D15: P. SOCIAL | F15: 2 | G15: =+G14+E15-F15 -> 0
A16: 42794 | B16: POR COBRAR | C16: FEBRERO | D16: LUZ | E16: 61.4 | G16: =+G15+E16-F16 -> 61.4
D17: AGUA | E17: 2 | G17: =+G16+E17-F17 -> 63.4
D18: G. ADM | E18: 56 | G18: =+G17+E18-F18 -> 119.4
D19: P. SOCIAL | E19: 2 | G19: =+G18+E19-F19 -> 121.4
A20: 42822 | B20: 12605 | C20: FEBRERO | D20: G. ADM | F20: 56 | G20: =+G19+E20-F20 -> 65.4
A21: 42822 | B21: 12605 | C21: FEBRERO | D21: P. SOCIAL | F21: 2 | G21: =+G20+E21-F21 -> 63.4
A22: 42822 | B22: 12605 | C22: FEBRERO | D22: LUZ | F22: 61.4 | G22: =+G21+E22-F22 -> 2
A23: 42822 | B23: 12605 | C23: FEBRERO | D23: AGUA | F23: 2 | G23: =+G22+E23-F23 -> 7.1054274e-15
A24: 42825 | B24: POR COBRAR | C24: MARZO | D24: LUZ | E24: 58.1 | G24: =+G23+E24-F24 -> 58.1
D25: AGUA | E25: 2 | G25: =+G24+E25-F25 -> 60.1
D26: G. ADM | E26: 60 | G26: =+G25+E26-F26 -> 120.1
D27: P. SOCIAL | E27: 2 | G27: =+G26+E27-F27 -> 122.1
D28: MULTA | E28: 85 | G28: =+G27+E28-F28 -> 207.1
A29: 42885 | B29: 12878 | C29: MARZO | D29: LUZ | F29: 58.1 | G29: =+G28+E29-F29 -> 149
A30: 42885 | B30: 12878 | C30: MARZO | D30: AGUA | F30: 2 | G30: =+G29+E30-F30 -> 147
A31: 42893 | B31: 13082 | C31: MARZO | D31: G. ADM | F31: 60 | G31: =+G30+E31-F31 -> 87
A32: 42893 | B32: 13082 | C32: MARZO | D32: P. SOCIAL | F32: 2 | G32: =+G31+E32-F32 -> 85
A33: 42949 | B33: 13370 | C33: MARZO | D33: MULTA | F33: 85 | G33: =+G32+E33-F33 -> 0
A34: 42855 | B34: POR COBRAR | C34: ABRIL | D34: LUZ | E34: 60.4 | G34: =+G33+E34-F34 -> 60.4
D35: AGUA | E35: 2 | G35: =+G34+E35-F35 -> 62.4
D36: G. ADM | E36: 60 | G36: =+G35+E36-F36 -> 122.4
D37: P. SOCIAL | E37: 2 | G37: =+G36+E37-F37 -> 124.4
A38: 42885 | B38: 12878 | C38: ABRIL | D38: LUZ | F38: 60.4 | G38: =+G37+E38-F38 -> 64
A39: 42885 | B39: 12878 | C39: ABRIL | D39: AGUA | F39: 2 | G39: =+G38+E39-F39 -> 62
A40: 42893 | B40: 13082 | C40: ABRIL | D40: G. ADM | F40: 60 | G40: =+G39+E40-F40 -> 2
A41: 42893 | B41: 13082 | C41: ABRIL | D41: P. SOCIAL | F41: 2 | G41: =+G40+E41-F41 -> 0
A42: 42886 | B42: POR COBRAR | C42: MAYO | D42: LUZ | E42: 57.7 | G42: =+G41+E42-F42 -> 57.7
...

Sheet DAVILA MARISOL
B2: DAVILA CAHUANA MARISOL
A4: FECHA | B4: DOCUMENTO | C4: PERIODO | D4: CONCEPTO | E4: POR COBRAR | F4: PAGADO
A5: 42736 | B5: SALDO AL 2016 | G5: 1069.6
A6: 42753 | B6: 12116 | C6: A CUENTA 2016 | F6: 124 | G6: =+G5+E6-F6 -> 945.6
A7: 42753 | B7: 12117 | C7: A CUENTA 2016 | F7: 59 | G7: =+G6+E7-F7 -> 886.6
A8: 42786 | B8: 12257 | C8: A CUENTA 2016 | F8: 607 | G8: =+G7+E8-F8 -> 279.6
A9: 42823 | B9: 12622 | C9: CANCELACION DEL 2016 | F9: 279.6 | G9: =+G8+E9-F9 -> 0
A10: 42766 | B10: POR COBRAR | C10: ENERO | D10: LUZ | E10: 261.9 | G10: =+G9+E10-F10 -> 261.9
D11: AGUA | E11: 2.8 | G11: =+G10+E11-F11 -> 264.7
D12: G. ADM | E12: 60 | G12: =+G11+E12-F12 -> 324.7
D13: P. SOCIAL | E13: 2 | G13: =+G12+E13-F13 -> 326.7
A14: 42786 | B14: 12263 | C14: ENERO | D14: LUZ | F14: 261.9 | G14: =+G13+E14-F14 -> 64.8
A15: 42786 | B15: 12263 | C15: ENERO | D15: AGUA | F15: 2.8 | G15: =+G14+E15-F15 -> 62
A16: 42787 | B16: 12338 | C16: ENERO | D16: G. ADM | F16: 60 | G16: =+G15+E16-F16 -> 2
A17: 42787 | B17: 12338 | C17: ENERO | D17: P. SOCIAL | F17: 2 | G17: =+G16+E17-F17 -> 1.4210855e-14
A18: 42794 | B18: POR COBRAR | C18: FEBRERO | D18: LUZ | E18: 270.2 | G18: =+G17+E18-F18 -> 270.2
D19: AGUA | E19: 2 | G19: =+G18+E19-F19 -> 272.2
D20: G. ADM | E20: 56 | G20: =+G19+E20-F20 -> 328.2
D21: P. SOCIAL | E21: 2 | G21: =+G20+E21-F21 -> 330.2
A22: 42821 | B22: 12514 | C22: FEBRERO | D22: LUZ | F22: 270.2 | G22: =+G21+E22-F22 -> 60
A23: 42821 | B23: 12514 | C23: FEBRERO | D23: AGUA | F23: 2 | G23: =+G22+E23-F23 -> 58
A24: 42822 | B24: 12612 | C24: FEBRERO | D24: G. ADM | F24: 56 | G24: =+G23+E24-F24 -> 2
A25: 42822 | B25: 12612 | C25: FEBRERO | D25: P. SOCIAL | F25: 2 | G25: =+G24+E25-F25 -> 0
A26: 42825 | B26: POR COBRAR | C26: MARZO | D26: LUZ | E26: 259.4 | G26: =+G25+E26-F26 -> 259.4
D27: AGUA | E27: 2 | G27: =+G26+E27-F27 -> 261.4
D28: G. ADM | E28: 60 | G28: =+G27+E28-F28 -> 321.4
D29: P. SOCIAL | E29: 2 | G29: =+G28+E29-F29 -> 323.4
A30: 42842 | B30: 12647 | C30: MARZO | D30: G. ADM | F30: 60 | G30: =+G29+E30-F30 -> 263.4
A31: 42842 | B31: 12647 | C31: MARZO | D31: P. SOCIAL | F31: 2 | G31: =+G30+E31-F31 -> 261.4
A32: 42885 | B32: 12896 | C32: MARZO | D32: LUZ | F32: 259.4 | G32: =+G31+E32-F32 -> 2
A33: 42885 | B33: 12896 | C33: MARZO | D33: AGUA | F33: 2 | G33: =+G32+E33-F33 -> 0
A34: 42855 | B34: POR COBRAR | C34: ABRIL | D34: LUZ | E34: 263.6 | G34: =+G33+E34-F34 -> 263.6
D35: AGUA | E35: 2 | G35: =+G34+E35-F35 -> 265.6
D36: G. ADM | E36: 60 | G36: =+G35+E36-F36 -> 325.6
D37: P. SOCIAL | E37: 2 | G37: =+G36+E37-F37 -> 327.6
A38: 42885 | B38: 12896 | C38: ABRIL | D38: LUZ | F38: 263.6 | G38: =+G37+E38-F38 -> 64
A39: 42885 | B39: 12896 | C39: ABRIL | D39: AGUA | F39: 2 | G39: =+G38+E39-F39 -> 62
A40: 42935 | B40: 13220 | C40: ABRIL | D40: G. ADM | F40: 60 | G40: =+G39+E40-F40 -> 2
A41: 42935 | B41: 13220 | C41: ABRIL | D41: P. SOCIAL | F41: 2 | G41: =+G40+E41-F41 -> 0
A42: 42886 | B42: POR COBRAR | C42: MAYO | D42: LUZ | E42: 244.8 | G42: =+G41+E42-F42 -> 244.8
...

Sheet DELA CRUZ JOSE
B2: DELA CRUZ ESTEBAN JOSE
A4: FECHA | B4: DOCUMENTO | C4: PERIODO | D4: CONCEPTO | E4: POR COBRAR | F4: PAGADO | G4: SALDO POR COBRAR
A5: 42736 | B5: SALDO AL 2016 | G5: 5499.5
A6: 42777 | B6: 12941 | C6: A CUENTA 2016 | F6: 96.6 | G6: =+G5+E6-F6 -> 5402.9
A7: 42763 | B7: TARJETA | C7: A CUENTA 2016 | F7: 190 | G7: =+G6+E7-F7 -> 5212.9
A8: 42793 | B8: TARJETA | C8: A CUENTA 2016 | F8: 180 | G8: =+G7+E8-F8 -> 5032.9
A9: 42825 | B9: TARJETA | C9: A CUENTA 2016 | F9: 210 | G9: =+G8+E9-F9 -> 4822.9
A10: 42854 | B10: TARJETA | C10: A CUENTA 2016 | F10: 220 | G10: =+G9+E10-F10 -> 4602.9
A11: 42885 | B11: TARJETA | C11: A CUENTA 2016 | F11: 300 | G11: =+G10+E11-F11 -> 4302.9
A12: 42914 | B12: TARJETA | C12: A CUENTA 2016 | F12: 180 | G12: =+G11+E12-F12 -> 4122.9
A13: 42947 | B13: TARJETA | C13: A CUENTA 2016 | F13: 300 | G13: =+G12+E13-F13 -> 3822.9
A14: 42978 | B14: TARJETA | C14: A CUENTA 2016 | F14: 110 | G14: =+G13+E14-F14 -> 3712.9
A15: 43008 | B15: TARJETA | C15: A CUENTA 2016 | F15: 160 | G15: =+G14+E15-F15 -> 3552.9
A16: 43039 | B16: TARJETA | C16: A CUENTA 2016 | F16: 300 | G16: =+G15+E16-F16 -> 3252.9
A17: 43067 | B17: 14135 | C17: A CUENTA 2016 | F17: 210 | G17: =+G16+E17-F17 -> 3042.9
A18: 43069 | B18: TARJETA | C18: A CUENTA 2016 | F18: 114 | G18: =+G17+E18-F18 -> 2928.9
A19: 43099 | B19: TARJETA | C19: A CUENTA 2016 | F19: 290 | G19: =+G18+E19-F19 -> 2638.9
A20: 43131 | B20: TARJETA | C20: A CUENTA 2016 | F20: 190 | G20: =+G19+E20-F20 -> 2448.9
A21: 43159 | B21: TARJETA | C21: A CUENTA 2016 | F21: 90 | G21: =+G20+E21-F21 -> 2358.9
A22: 43190 | B22: TARJETA | C22: A CUENTA 2016 | F22: 60 | G22: =+G21+E22-F22 -> 2298.9
A23: 43220 | B23: TARJETA | C23: A CUENTA 2016 | F23: 70 | G23: =+G22+E23-F23 -> 2228.9
A24: 43251 | B24: TARJETA | C24: A CUENTA 2016 | F24: 30 | G24: =+G23+E24-F24 -> 2198.9
A25: 44139 | B25: 20607 | C25: A CUENTA 2016 | F25: 110.7 | G25: =+G24+E25-F25 -> 2088.2
A26: 44161 | B26: CARTA -124-2020 | C26: EXONERACION | F26: 1517.2 | G26: =+G25+E26-F26 -> 571
A27: 44233 | B27: 21528 | C27: CANCELACION | F27: 571 | G27: =+G26+E27-F27 -> 0
A28: 42766 | B28: POR COBRAR | C28: ENERO | D28: LUZ | E28: 60.3 | G28: =+G27+E28-F28 -> 60.3
D29: AGUA | E29: 31.9 | G29: =+G28+E29-F29 -> 92.2
D30: G. ADM | E30: 60 | G30: =+G29+E30-F30 -> 152.2
D31: P. SOCIAL | E31: 2 | G31: =+G30+E31-F31 -> 154.2
A32: 42765 | B32: TARJETA | C32: ENERO | D32: G. ADM | F32: 60 | G32: =+G31+E32-F32 -> 94.2
A33: 42765 | B33: TARJETA | C33: ENERO | D33: P. SOCIAL | F33: 2 | G33: =+G32+E33-F33 -> 92.2
A34: 42816 | B34: 12441 | C34: ENERO | D34: LUZ | F34: 60.3 | G34: =+G33+E34-F34 -> 31.9
A35: 42816 | B35: 12441 | C35: ENERO | D35: AGUA | F35: 31.9 | G35: =+G34+E35-F35 -> 0
A36: 42794 | B36: POR COBRAR | C36: FEBRERO | D36: LUZ | E36: 61.6 | G36: =+G35+E36-F36 -> 61.6
D37: AGUA | E37: 22 | G37: =+G36+E37-F37 -> 83.6
D38: G. ADM | E38: 56 | G38: =+G37+E38-F38 -> 139.6
D39: P. SOCIAL | E39: 2 | G39: =+G38+E39-F39 -> 141.6
A40: 42793 | B40: TARJETA | C40: FEBRERO | D40: G. ADM | F40: 36 | G40: =+G39+E40-F40 -> 105.6
A41: 42846 | B41: 12681 | C41: FEBRERO | D41: LUZ | F41: 61.6 | G41: =+G40+E41-F41 -> 44
A42: 42846 | B42: 12681 | C42: FEBRERO | D42: AGUA | F42: 22 | G42: =+G41+E42-F42 -> 22
...

Sheet ESPEJO ROSA
B2: ESPEJO URBANO ROSA FLORENCIA
A4: FECHA | B4: DOCUMENTO | C4: PERIODO | D4: CONCEPTO | E4: POR COBRAR | F4: PAGADO | G4: SALDO POR COBRAR
A5: 42736 | B5: SALDO AL 2016 | G5: 123.6
G6: =+G5+E6-F6 -> 123.6
A7: 42822 | B7: 12588 | C7: CANCELACION | F7: 123.6 | G7: =+G6+E7-F7 -> 0
A8: 42766 | B8: POR COBRAR | C8: ENERO | D8: LUZ | E8: 50.4 | G8: =+G7+E8-F8 -> 50.4
D9: AGUA | E9: 2.8 | G9: =+G8+E9-F9 -> 53.2
D10: G. ADM | E10: 60 | G10: =+G9+E10-F10 -> 113.2
D11: P. SOCIAL | E11: 2 | G11: =+G10+E11-F11 -> 115.2
A12: 42765 | B12: TARJETA | C12: ENERO | D12: G. ADM | F12: 60 | G12: =+G11+E12-F12 -> 55.2
A13: 42765 | B13: TARJETA | C13: ENERO | D13: P. SOCIAL | F13: 2 | G13: =+G12+E13-F13 -> 53.2
A14: 42822 | B14: 12588 | C14: ENERO | D14: AGUA | F14: 2.8 | G14: =+G13+E14-F14 -> 50.4
A15: 42822 | B15: 12588 | C15: ENERO | D15: LUZ | F15: 50.4 | G15: =+G14+E15-F15 -> 0
A16: 42794 | B16: POR COBRAR | C16: FEBRERO | D16: LUZ | E16: 50.3 | G16: =+G15+E16-F16 -> 50.3
D17: AGUA | E17: 2 | G17: =+G16+E17-F17 -> 52.3
D18: G. ADM | E18: 56 | G18: =+G17+E18-F18 -> 108.3
D19: P. SOCIAL | E19: 2 | G19: =+G18+E19-F19 -> 110.3
A20: 42794 | B20: TARJETA | C20: FEBRERO | D20: G. ADM | F20: 56 | G20: =+G19+E20-F20 -> 54.3
A21: 42794 | B21: TARJETA | C21: FEBRERO | D21: P. SOCIAL | F21: 2 | G21: =+G20+E21-F21 -> 52.3
A22: 42822 | B22: 12588 | C22: FEBRERO | D22: LUZ | F22: 50.3 | G22: =+G21+E22-F22 -> 2
A23: 42822 | B23: 12588 | C23: FEBRERO | D23: AGUA | F23: 2 | G23: =+G22+E23-F23 -> 0
A24: 42825 | B24: POR COBRAR | C24: MARZO | D24: LUZ | E24: 47.4 | G24: =+G23+E24-F24 -> 47.4
D25: AGUA | E25: 2 | G25: =+G24+E25-F25 -> 49.4
D26: G. ADM | E26: 60 | G26: =+G25+E26-F26 -> 109.4
D27: P. SOCIAL | E27: 2 | G27: =+G26+E27-F27 -> 111.4
A28: 42824 | B28: TARJETA | C28: MARZO | D28: G. ADM | F28: 60 | G28: =+G27+E28-F28 -> 51.4
A29: 42824 | B29: TARJETA | C29: MARZO | D29: P. SOCIAL | F29: 2 | G29: =+G28+E29-F29 -> 49.4
A30: 42885 | B30: 12872 | C30: MARZO | D30: LUZ | F30: 47.4 | G30: =+G29+E30-F30 -> 2
A31: 42885 | B31: 12872 | C31: MARZO | D31: AGUA | F31: 2 | G31: =+G30+E31-F31 -> 7.1054274e-15
A32: 42855 | B32: POR COBRAR | C32: ABRIL | D32: LUZ | E32: 49.7 | G32: =+G31+E32-F32 -> 49.7
D33: AGUA | E33: 2 | G33: =+G32+E33-F33 -> 51.7
D34: G. ADM | E34: 60 | G34: =+G33+E34-F34 -> 111.7
D35: P. SOCIAL | E35: 2 | G35: =+G34+E35-F35 -> 113.7
A36: 42855 | B36: TARJETA | C36: ABRIL | D36: G. ADM | F36: 60 | G36: =+G35+E36-F36 -> 53.7
A37: 42855 | B37: TARJETA | C37: ABRIL | D37: P. SOCIAL | F37: 2 | G37: =+G36+E37-F37 -> 51.7
A38: 42885 | B38: 12872 | C38: ABRIL | D38: LUZ | F38: 49.7 | G38: =+G37+E38-F38 -> 2
A39: 42885 | B39: 12872 | C39: ABRIL | D39: AGUA | F39: 2 | G39: =+G38+E39-F39 -> 1.4210855e-14
A40: 42886 | B40: POR COBRAR | C40: MAYO | D40: LUZ | E40: 47.8 | G40: =+G39+E40-F40 -> 47.8
D41: AGUA | E41: 2 | G41: =+G40+E41-F41 -> 49.8
D42: G. ADM | E42: 60 | G42: =+G41+E42-F42 -> 109.8
...

Sheet ESTELA ELVIA
B2: ESTELA SUAREZ ELVIA
A4: FECHA | B4: DOCUMENTO | C4: PERIODO | D4: CONCEPTO | E4: POR COBRAR | F4: PAGADO | G4: SALDO POR COBRAR
A5: 42736 | B5: SALDO AL 2016 | G5: 253.8
A6: 42752 | B6: 12115 | C6: A CUENTA 2016 | F6: 181.8 | G6: =+G5+E6-F6 -> 72
A7: 42786 | B7: 12268 | C7: A CUENTA 2016 | F7: 10.8 | G7: =+G6+E7-F7 -> 61.2
A8: 42817 | B8: 12451 | C8: A CUENTA 2016 | F8: 8 | G8: =+G7+E8-F8 -> 53.2
A9: 42845 | B9: 12669 | C9: A CUENTA 2016 | F9: 8 | G9: =+G8+E9-F9 -> 45.2
A10: 42871 | B10: 12759 | C10: A CUENTA 2016 | F10: 8 | G10: =+G9+E10-F10 -> 37.2
A11: 42906 | B11: 13117 | C11: A CUENTA 2016 | F11: 8 | G11: =+G10+E11-F11 -> 29.2
A12: 42941 | B12: 13254 | C12: A CUENTA 2016 | F12: 8 | G12: =+G11+E12-F12 -> 21.2
A13: 42969 | B13: 13450 | C13: A CUENTA 2016 | F13: 8 | G13: =+G12+E13-F13 -> 13.2
A14: 42997 | B14: 13620 | C14: CANCELACION 2016 | F14: 13.2 | G14: =+G13+E14-F14 -> 0
A15: 42766 | B15: POR COBRAR | C15: ENERO | D15: LUZ | E15: 75.2 | G15: =+G14+E15-F15 -> 75.2
D16: AGUA | E16: 32.2 | G16: =+G15+E16-F16 -> 107.4
D17: G. ADM | E17: 60 | G17: =+G16+E17-F17 -> 167.4
D18: P. SOCIAL | E18: 2 | G18: =+G17+E18-F18 -> 169.4
A19: 42786 | B19: 12268 | C19: ENERO | D19: LUZ | F19: 75.2 | G19: =+G18+E19-F19 -> 94.2
A20: 42787 | B20: 12342 | C20: ENERO | D20: AGUA | F20: 32.2 | G20: =+G19+E20-F20 -> 62
A21: 42787 | B21: 12342 | C21: ENERO | D21: G. ADM | F21: 60 | G21: =+G20+E21-F21 -> 2
A22: 42787 | B22: 12342 | C22: ENERO | D22: P. SOCIAL | F22: 2 | G22: =+G21+E22-F22 -> 0
A23: 42794 | B23: POR COBRAR | C23: FEBRERO | D23: LUZ | E23: 77.1 | G23: =+G22+E23-F23 -> 77.1
D24: AGUA | E24: 24.5 | G24: =+G23+E24-F24 -> 101.6
D25: G. ADM | E25: 56 | G25: =+G24+E25-F25 -> 157.6
D26: P. SOCIAL | E26: 2 | G26: =+G25+E26-F26 -> 159.6
A27: 42817 | B27: 12451 | C27: FEBRERO | D27: G. ADM | F27: 56 | G27: =+G26+E27-F27 -> 103.6
A28: 42817 | B28: 12451 | C28: FEBRERO | D28: P. SOCIAL | F28: 2 | G28: =+G27+E28-F28 -> 101.6
A29: 42817 | B29: 12451 | C29: FEBRERO | D29: LUZ | F29: 77.1 | G29: =+G28+E29-F29 -> 24.5
A30: 42807 | B30: 12451 | C30: FEBRERO | D30: AGUA | F30: 24.5 | G30: =+G29+E30-F30 -> 0
A31: 42825 | B31: POR COBRAR | C31: MARZO | D31: LUZ | E31: 73.8 | G31: =+G30+E31-F31 -> 73.8
D32: AGUA | E32: 25.5 | G32: =+G31+E32-F32 -> 99.3
D33: G. ADM | E33: 60 | G33: =+G32+E33-F33 -> 159.3
D34: P. SOCIAL | E34: 2 | G34: =+G33+E34-F34 -> 161.3
A35: 42845 | B35: 12669 | C35: MARZO | D35: G. ADM | F35: 60 | G35: =+G34+E35-F35 -> 101.3
A36: 42845 | B36: 12669 | C36: MARZO | D36: P. SOCIAL | F36: 2 | G36: =+G35+E36-F36 -> 99.3
A37: 42845 | B37: 12669 | C37: MARZO | D37: LUZ | F37: 73.8 | G37: =+G36+E37-F37 -> 25.5
A38: 42845 | B38: 12669 | C38: MARZO | D38: AGUA | F38: 25.5 | G38: =+G37+E38-F38 -> 0
A39: 42855 | B39: POR COBRAR | C39: ABRIL | D39: LUZ | E39: 75.4 | G39: =+G38+E39-F39 -> 75.4
D40: AGUA | E40: 22.8 | G40: =+G39+E40-F40 -> 98.2
D41: G. ADM | E41: 60 | G41: =+G40+E41-F41 -> 158.2
D42: P. SOCIAL | E42: 2 | G42: =+G41+E42-F42 -> 160.2
...

Sheet ESTRADA  OSCAR
I1: ESTRADA OSORIO DONATO
B2: ESTRADA CHACON OSCAR ALFREDO
A4: FECHA | B4: DOCUMENTO | C4: PERIODO | D4: CONCEPTO | E4: POR COBRAR | F4: PAGADO | G4: SALDO POR COBRAR
A5: 42736 | B5: SALDO AL 2016 | G5: 1186.4
A6: 42736 | B6: MULTA POZO | E6: 100 | G6: =+G5+E6-F6 -> 1286.4
A7: 42756 | B7: 12131 | C7: A CUENTA2016 | F7: 101.9 | G7: =+G6+E7-F7 -> 1184.5
A8: 42781 | B8: 12955 | C8: A CUENTA2016 | F8: 100.5 | G8: =+G7+E8-F8 -> 1084
A9: 43176 | B9: 14832 | C9: A CUENTA2016 | F9: 600 | G9: =+G8+E9-F9 -> 484
A10: 43193 | B10: 15078 | C10: A CUENTA2016 | F10: 281 | G10: =+G9+E10-F10 -> 203
A11: 43220 | B11: 15279 | C11: CANCELACION TOTAL 2016 | F11: 203 | G11: =+G10+E11-F11 -> 0
A12: 42766 | B12: POR COBRAR | C12: ENERO | D12: LUZ | E12: 39.1 | G12: =+G11+E12-F12 -> 39.1
D13: AGUA | E13: 66.5 | G13: =+G12+E13-F13 -> 105.6
D14: G. ADM | E14: 60 | G14: =+G13+E14-F14 -> 165.6
D15: P. SOCIAL | E15: 2 | G15: =+G14+E15-F15 -> 167.6
A16: 42765 | B16: TARJETA | C16: ENERO | D16: G. ADM | F16: 60 | G16: =+G15+E16-F16 -> 107.6
A17: 42765 | B17: TARJETA | C17: ENERO | D17: P. SOCIAL | F17: 2 | G17: =+G16+E17-F17 -> 105.6
A18: 42817 | B18: 12454 | C18: ENERO | D18: LUZ | F18: 39.1 | G18: =+G17+E18-F18 -> 66.5
A19: 42817 | B19: 12454 | C19: ENERO | D19: AGUA | F19: 66.5 | G19: =+G18+E19-F19 -> 0
A20: 42794 | B20: POR COBRAR | C20: FEBRERO | D20: LUZ | E20: 61.6 | G20: =+G19+E20-F20 -> 61.6
D21: AGUA | E21: 60 | G21: =+G20+E21-F21 -> 121.6
D22: G. ADM | E22: 56 | G22: =+G21+E22-F22 -> 177.6
D23: P. SOCIAL | E23: 2 | G23: =+G22+E23-F23 -> 179.6
A24: 42791 | B24: TARJETA | C24: FEBRERO | D24: G. ADM | F24: 50 | G24: =+G23+E24-F24 -> 129.6
A25: 42795 | B25: 12385 | C25: FEBRERO | D25: G. ADM | F25: 6 | G25: =+G24+E25-F25 -> 123.6
A26: 42767 | B26: 12385 | C26: FEBRERO | D26: P. SOCIAL | F26: 2 | G26: =+G25+E26-F26 -> 121.6
A27: 42817 | B27: 12454 | C27: FEBRERO | D27: LUZ | F27: 61.6 | G27: =+G26+E27-F27 -> 60
A28: 42817 | B28: 12454 | C28: FEBRERO | D28: AGUA | F28: 60 | G28: =+G27+E28-F28 -> 0
A29: 42825 | B29: POR COBRAR | C29: MARZO | D29: LUZ | E29: 58.9 | G29: =+G28+E29-F29 -> 58.9
D30: AGUA | E30: 48.9 | G30: =+G29+E30-F30 -> 107.8
D31: G. ADM | E31: 60 | G31: =+G30+E31-F31 -> 167.8
D32: P. SOCIAL | E32: 2 | G32: =+G31+E32-F32 -> 169.8
A33: 42825 | B33: TARJETA | C33: MARZO | D33: G. ADM | F33: 60 | G33: =+G32+E33-F33 -> 109.8
A34: 42825 | B34: TARJETA | C34: MARZO | D34: P. SOCIAL | F34: 2 | G34: =+G33+E34-F34 -> 107.8
A35: 42885 | B35: 12861 | C35: MARZO | D35: LUZ | F35: 58.9 | G35: =+G34+E35-F35 -> 48.9
A36: 42885 | B36: 12861 | C36: MARZO | D36: AGUA | F36: 48.9 | G36: =+G35+E36-F36 -> 0
A37: 42855 | B37: POR COBRAR | C37: ABRIL | D37: LUZ | E37: 60.3 | G37: =+G36+E37-F37 -> 60.3
D38: AGUA | E38: 48 | G38: =+G37+E38-F38 -> 108.3
D39: G. ADM | E39: 60 | G39: =+G38+E39-F39 -> 168.3
D40: P. SOCIAL | E40: 2 | G40: =+G39+E40-F40 -> 170.3
A41: 42855 | B41: TARJETA | C41: ABRIL | D41: G. ADM | F41: 60 | G41: =+G40+E41-F41 -> 110.3
...

Sheet FALCON HECTOR 
B2: FALCON CHIARA HECTOR
A4: FECHA | B4: DOCUMENTO | C4: PERIODO | D4: CONCEPTO | E4: POR COBRAR | F4: PAGADO | G4: SALDO POR COBRAR
A5: 42736 | B5: SALDO AL 2016 | G5: 80.3
A6: 42786 | B6: 12286 | C6: A CUENTA 2016 | F6: 80.3 | G6: =+G5+E6-F6 -> 0
A7: 42766 | B7: POR COBRAR | C7: ENERO | D7: LUZ | E7: 99.3 | G7: =+G6+E7-F7 -> 99.3
D8: AGUA | E8: 2.8 | G8: =+G7+E8-F8 -> 102.1
D9: G. ADM | E9: 60 | G9: =+G8+E9-F9 -> 162.1
D10: P. SOCIAL | E10: 2 | G10: =+G9+E10-F10 -> 164.1
D11: DEPOSITO | E11: 70 | G11: =+G10+E11-F11 -> 234.1
A12: 42756 | B12: 12132 | C12: ENERO | D12: G. ADM | F12: 60 | G12: =+G11+E12-F12 -> 174.1
A13: 42756 | B13: 12132 | C13: ENERO | D13: P. SOCIAL | F13: 2 | G13: =+G12+E13-F13 -> 172.1
A14: 42786 | B14: 12286 | C14: ENERO | D14: LUZ | F14: 99.3 | G14: =+G13+E14-F14 -> 72.8
A15: 42786 | B15: 12286 | C15: ENERO | D15: AGUA | F15: 2.8 | G15: =+G14+E15-F15 -> 70
A16: 42822 | B16: 12602 | C16: ENERO | D16: DEPOSITO | F16: 70 | G16: =+G15+E16-F16 -> 0
A17: 42794 | B17: POR COBRAR | C17: FEBRERO | D17: LUZ | E17: 101.1 | G17: =+G16+E17-F17 -> 101.1
D18: AGUA | E18: 2 | G18: =+G17+E18-F18 -> 103.1
D19: G. ADM | E19: 60 | G19: =+G18+E19-F19 -> 163.1
D20: P. SOCIAL | E20: 2 | G20: =+G19+E20-F20 -> 165.1
D21: DEPOSITO | E21: 70 | G21: =+G20+E21-F21 -> 235.1
A22: 42782 | B22: 12959 | C22: FEBRERO | D22: G. ADM | F22: 60 | G22: =+G21+E22-F22 -> 175.1
A23: 42782 | B23: 12959 | C23: FEBRERO | D23: P. SOCIAL | F23: 2 | G23: =+G22+E23-F23 -> 173.1
A24: 42822 | B24: 12602 | C24: FEBRERO | D24: LUZ | F24: 101.1 | G24: =+G23+E24-F24 -> 72
A25: 42822 | B25: 12602 | C25: FEBRERO | D25: AGUA | F25: 2 | G25: =+G24+E25-F25 -> 70
A26: 42822 | B26: 12602 | C26: FEBRERO | D26: DEPOSITO | F26: 70 | G26: =+G25+E26-F26 -> 0
A27: 42825 | B27: POR COBRAR | C27: MARZO | D27: LUZ | E27: 86.8 | G27: =+G26+E27-F27 -> 86.8
D28: AGUA | E28: 2 | G28: =+G27+E28-F28 -> 88.8
D29: G. ADM | E29: 60 | G29: =+G28+E29-F29 -> 148.8
D30: P. SOCIAL | E30: 2 | G30: =+G29+E30-F30 -> 150.8
D31: CAMBIO DE GIRO | E31: 300 | G31: =+G30+E31-F31 -> 450.8
D32: DEPOSITO | E32: 70 | G32: =+G31+E32-F32 -> 520.8
A33: 42804 | B33: 12412 | C33: MARZO | D33: CAMBIO DE GIRO | F33: 300 | G33: =+G32+E33-F33 -> 220.8
A34: 42821 | B34: 12491 | C34: MARZO | D34: G. ADM | F34: 60 | G34: =+G33+E34-F34 -> 160.8
A35: 42821 | B35: 12491 | C35: MARZO | D35: P. SOCIAL | F35: 2 | G35: =+G34+E35-F35 -> 158.8
A36: 42885 | B36: 12868 | C36: MARZO | D36: LUZ | F36: 86.8 | G36: =+G35+E36-F36 -> 72
A37: 42885 | B37: 12868 | C37: MARZO | D37: AGUA | F37: 2 | G37: =+G36+E37-F37 -> 70
A38: 42885 | B38: 12868 | C38: MARZO | D38: DEPOSITO | F38: 70 | G38: =+G37+E38-F38 -> 0
A39: 42855 | B39: POR COBRAR | C39: ABRIL | D39: LUZ | E39: 89.4 | G39: =+G38+E39-F39 -> 89.4
D40: AGUA | E40: 2 | G40: =+G39+E40-F40 -> 91.4
D41: G. ADM | E41: 60 | G41: =+G40+E41-F41 -> 151.4
D42: P. SOCIAL | E42: 2 | G42: =+G41+E42-F42 -> 153.4
...

Sheet FLORES FLORES IRENE
B2: FLORES FLORES IRENE BERTILIA
A4: FECHA | B4: DOCUMENTO | C4: PERIODO | D4: CONCEPTO | E4: POR COBRAR | F4: PAGADO | G4: SALDO POR COBRAR
A5: 42736 | B5: SALDO AL 2016 | G5: 99.5
A6: 42765 | B6: 12179 | C6: A CUENTA 2016 | F6: 99.5 | G6: =+G5+E6-F6 -> 0
A7: 42766 | B7: POR COBRAR | C7: ENERO | D7: LUZ | E7: 180 | G7: =+G6+E7-F7 -> 180
D8: AGUA | E8: 39 | G8: =+G7+E8-F8 -> 219
D9: G. ADM | E9: 60 | G9: =+G8+E9-F9 -> 279
D10: P. SOCIAL | E10: 2 | G10: =+G9+E10-F10 -> 281
A11: 42765 | B11: TARJETA | C11: ENERO | D11: LUZ | F11: 169 | G11: =+G10+E11-F11 -> 112
A12: 42765 | B12: TARJETA | C12: ENERO | D12: G. ADM | F12: 60 | G12: =+G11+E12-F12 -> 52
A13: 42765 | B13: TARJETA | C13: ENERO | D13: P. SOCIAL | F13: 2 | G13: =+G12+E13-F13 -> 50
A14: 42786 | B14: 12235 | C14: ENERO | D14: LUZ | F14: 11 | G14: =+G13+E14-F14 -> 39
A15: 42786 | B15: 12235 | C15: ENERO | D15: AGUA | F15: 39 | G15: =+G14+E15-F15 -> 0
A16: 42794 | B16: POR COBRAR | C16: FEBRERO | D16: LUZ | E16: 197.5 | G16: =+G15+E16-F16 -> 197.5
D17: AGUA | E17: 25 | G17: =+G16+E17-F17 -> 222.5
D18: G. ADM | E18: 56 | G18: =+G17+E18-F18 -> 278.5
D19: P. SOCIAL | E19: 2 | G19: =+G18+E19-F19 -> 280.5
A20: 42794 | B20: TARJETA | C20: FEBRERO | D20: G. ADM | F20: 56 | G20: =+G19+E20-F20 -> 224.5
A21: 42794 | B21: TARJETA | C21: FEBRERO | D21: P. SOCIAL | F21: 2 | G21: =+G20+E21-F21 -> 222.5
A22: 42794 | B22: TARJETA | C22: FEBRERO | D22: LUZ | F22: 168 | G22: =+G21+E22-F22 -> 54.5
A23: 42821 | B23: 12529 | C23: FEBRERO | D23: LUZ | F23: 29.5 | G23: =+G22+E23-F23 -> 25
A24: 42821 | B24: 12529 | C24: FEBRERO | D24: AGUA | F24: 25 | G24: =+G23+E24-F24 -> 0
A25: 42825 | B25: POR COBRAR | C25: MARZO | D25: LUZ | E25: 169.6 | G25: =+G24+E25-F25 -> 169.6
D26: AGUA | E26: 27 | G26: =+G25+E26-F26 -> 196.6
D27: G. ADM | E27: 60 | G27: =+G26+E27-F27 -> 256.6
D28: P. SOCIAL | E28: 2 | G28: =+G27+E28-F28 -> 258.6
A29: 42824 | B29: TARJETA | C29: MARZO | D29: G. ADM | F29: 60 | G29: =+G28+E29-F29 -> 198.6
A30: 42824 | B30: TARJETA | C30: MARZO | D30: P. SOCIAL | F30: 2 | G30: =+G29+E30-F30 -> 196.6
A31: 42824 | B31: TARJETA | C31: MARZO | D31: LUZ | F31: 169.6 | G31: =+G30+E31-F31 -> 27
A32: 42824 | B32: TARJETA | C32: MARZO | D32: AGUA | F32: 10.4 | G32: =+G31+E32-F32 -> 16.6
A33: 42886 | B33: 13006 | C33: MARZO | D33: AGUA | F33: 16.6 | G33: =+G32+E33-F33 -> 2.8421709e-14
A34: 42855 | B34: POR COBRAR | C34: ABRIL | D34: LUZ | E34: 156 | G34: =+G33+E34-F34 -> 156
D35: AGUA | E35: 25.5 | G35: =+G34+E35-F35 -> 181.5
D36: G. ADM | E36: 60 | G36: =+G35+E36-F36 -> 241.5
D37: P. SOCIAL | E37: 2 | G37: =+G36+E37-F37 -> 243.5
A38: 42854 | B38: TARJETA | C38: ABRIL | D38: G. ADM | F38: 60 | G38: =+G37+E38-F38 -> 183.5
A39: 42854 | B39: TARJETA | C39: ABRIL | D39: P. SOCIAL | F39: 2 | G39: =+G38+E39-F39 -> 181.5
A40: 42854 | B40: TARJETA | C40: ABRIL | D40: LUZ | F40: 156 | G40: =+G39+E40-F40 -> 25.5
A41: 42854 | B41: TARJETA | C41: ABRIL | D41: AGUA | F41: 1.5 | G41: =+G40+E41-F41 -> 24
A42: 42886 | B42: 13006 | C42: ABRIL | D42: AGUA | F42: 24 | G42: =+G41+E42-F42 -> 2.8421709e-14
...

Sheet FLORES FLORES UMBELINA
B2: FLORES FLORES UMBELINA DORA
A4: FECHA | B4: DOCUMENTO | C4: PERIODO | D4: CONCEPTO | E4: POR COBRAR | F4: PAGADO | G4: SALDO POR COBRAR
A5: 42736 | B5: SALDO AL 2016 | G5: 680.2
A6: 42781 | B6: 12957 | C6: A CUENTA 2016 | F6: 291.7 | G6: =+G5+E6-F6 -> 388.5
A7: 43227 | B7: 15305 | C7: CANCELACION TOTAL 2016 | F7: 388.5 | G7: =+G6+E7-F7 -> 0
A8: 42766 | B8: POR COBRAR | C8: ENERO | D8: LUZ | E8: 91.4 | G8: =+G7+E8-F8 -> 91.4
D9: AGUA | E9: 39 | G9: =+G8+E9-F9 -> 130.4
D10: G. ADM | E10: 60 | G10: =+G9+E10-F10 -> 190.4
D11: P. SOCIAL | E11: 2 | G11: =+G10+E11-F11 -> 192.4
A12: 42765 | B12: TARJETA | C12: ENERO | D12: G. ADM | F12: 60 | G12: =+G11+E12-F12 -> 132.4
A13: 42765 | B13: TARJETA | C13: ENERO | D13: P. SOCIAL | F13: 2 | G13: =+G12+E13-F13 -> 130.4
A14: 42787 | B14: 12341 | C14: ENERO | D14: LUZ | F14: 91.4 | G14: =+G13+E14-F14 -> 39
A15: 42787 | B15: 12341 | C15: ENERO | D15: AGUA | F15: 39 | G15: =+G14+E15-F15 -> 0
A16: 42794 | B16: POR COBRAR | C16: FEBRERO | D16: LUZ | E16: 87 | G16: =+G15+E16-F16 -> 87
D17: AGUA | E17: 27.3 | G17: =+G16+E17-F17 -> 114.3
D18: G. ADM | E18: 56 | G18: =+G17+E18-F18 -> 170.3
D19: P. SOCIAL | E19: 2 | G19: =+G18+E19-F19 -> 172.3
A20: 42791 | B20: TARJETA | C20: FEBRERO | D20: G. ADM | F20: 50 | G20: =+G19+E20-F20 -> 122.3
A21: 42795 | B21: 12386 | C21: FEBRERO | D21: G. ADM | F21: 6 | G21: =+G20+E21-F21 -> 116.3
A22: 42795 | B22: 12386 | C22: FEBRERO | D22: P. SOCIAL | F22: 2 | G22: =+G21+E22-F22 -> 114.3
A23: 42884 | B23: 12850 | C23: FEBRERO | D23: LUZ | F23: 87 | G23: =+G22+E23-F23 -> 27.3
A24: 42884 | B24: 12850 | C24: FEBRERO | D24: AGUA | F24: 27.3 | G24: =+G23+E24-F24 -> 0
A25: 42825 | B25: POR COBRAR | C25: MARZO | D25: LUZ | E25: 83.4 | G25: =+G24+E25-F25 -> 83.4
D26: AGUA | E26: 28.4 | G26: =+G25+E26-F26 -> 111.8
D27: G. ADM | E27: 60 | G27: =+G26+E27-F27 -> 171.8
D28: P. SOCIAL | E28: 2 | G28: =+G27+E28-F28 -> 173.8
A29: 42825 | B29: TARJETA | C29: MARZO | D29: G. ADM | F29: 60 | G29: =+G28+E29-F29 -> 113.8
A30: 42884 | B30: 12850 | C30: MARZO | D30: LUZ | F30: 83.4 | G30: =+G29+E30-F30 -> 30.4
A31: 42884 | B31: 12850 | C31: MARZO | D31: AGUA | F31: 28.4 | G31: =+G30+E31-F31 -> 2
A32: 42949 | B32: 13335 | C32: MARZO | D32: P. SOCIAL | F32: 2 | G32: =+G31+E32-F32 -> 7.1054274e-15
A33: 42855 | B33: POR COBRAR | C33: ABRIL | D33: LUZ | E33: 85 | G33: =+G32+E33-F33 -> 85
D34: AGUA | E34: 27.9 | G34: =+G33+E34-F34 -> 112.9
D35: G. ADM | E35: 60 | G35: =+G34+E35-F35 -> 172.9
D36: P. SOCIAL | E36: 2 | G36: =+G35+E36-F36 -> 174.9
A37: 42854 | B37: TARJETA | C37: ABRIL | D37: G. ADM | F37: 60 | G37: =+G36+E37-F37 -> 114.9
A38: 42854 | B38: TARJETA | C38: ABRIL | D38: P. SOCIAL | F38: 2 | G38: =+G37+E38-F38 -> 112.9
A39: 42949 | B39: 13335 | C39: ABRIL | D39: LUZ | F39: 85 | G39: =+G38+E39-F39 -> 27.9
A40: 42949 | B40: 13335 | C40: ABRIL | D40: AGUA | F40: 27.9 | G40: =+G39+E40-F40 -> 0
A41: 42886 | B41: POR COBRAR | C41: MAYO | D41: LUZ | E41: 79.3 | G41: =+G40+E41-F41 -> 79.3
D42: AGUA | E42: 27.3 | G42: =+G41+E42-F42 -> 106.6
...

Sheet FLORES FRANCISCA
B2: FLORES YATO FRANCISCA DOLORES
A4: FECHA | B4: DOCUMENTO | C4: PERIODO | D4: CONCEPTO | E4: POR COBRAR | F4: PAGADO | G4: SALDO POR COBRAR
A5: 42736 | B5: SALDO AL 2016 | G5: 594.3
A6: 42747 | B6: 12102 | C6: A CUENTA 2016 | F6: 59 | G6: =+G5+E6-F6 -> 535.3
A7: 42776 | B7: 12940 | C7: A CUENTA 2016 | F7: 535.3 | G7: =+G6+E7-F7 -> 0
A8: 42766 | B8: POR COBRAR | C8: ENERO | D8: LUZ | E8: 204.6 | G8: =+G7+E8-F8 -> 204.6
D9: AGUA | E9: 2.8 | G9: =+G8+E9-F9 -> 207.4
D10: G. ADM | E10: 60 | G10: =+G9+E10-F10 -> 267.4
D11: P. SOCIAL | E11: 2 | G11: =+G10+E11-F11 -> 269.4
D12: POZO SEPTICO | E12: 50 | G12: =+G11+E12-F12 -> 319.4
A13: 42776 | B13: 12940 | C13: ENERO | D13: G. ADM | F13: 60 | G13: =+G12+E13-F13 -> 259.4
A14: 42776 | B14: 12940 | C14: ENERO | D14: P. SOCIAL | F14: 2 | G14: =+G13+E14-F14 -> 257.4
A15: 42779 | B15: 12942 | C15: ENERO | D15: POZO SEPTICO | F15: 50 | G15: =+G14+E15-F15 -> 207.4
A16: 42787 | B16: 12329 | C16: ENERO | D16: AGUA | F16: 2.8 | G16: =+G15+E16-F16 -> 204.6
A17: 42787 | B17: 12329 | C17: ENERO | D17: LUZ | F17: 204.6 | G17: =+G16+E17-F17 -> 0
A18: 42794 | B18: POR COBRAR | C18: FEBRERO | D18: LUZ | E18: 196.2 | G18: =+G17+E18-F18 -> 196.2
D19: AGUA | E19: 2 | G19: =+G18+E19-F19 -> 198.2
D20: G. ADM | E20: 56 | G20: =+G19+E20-F20 -> 254.2
D21: P. SOCIAL | E21: 2 | G21: =+G20+E21-F21 -> 256.2
A22: 42821 | B22: 12513 | C22: FEBRERO | D22: G. ADM | F22: 56 | G22: =+G21+E22-F22 -> 200.2
A23: 42821 | B23: 12513 | C23: FEBRERO | D23: P. SOCIAL | F23: 2 | G23: =+G22+E23-F23 -> 198.2
A24: 42821 | B24: 12513 | C24: FEBRERO | D24: LUZ | F24: 196.2 | G24: =+G23+E24-F24 -> 2
A25: 42821 | B25: 12513 | C25: FEBRERO | D25: AGUA | F25: 2 | G25: =+G24+E25-F25 -> 0
A26: 42825 | B26: POR COBRAR | C26: MARZO | D26: LUZ | E26: 188 | G26: =+G25+E26-F26 -> 188
D27: AGUA | E27: 2 | G27: =+G26+E27-F27 -> 190
D28: G. ADM | E28: 60 | G28: =+G27+E28-F28 -> 250
D29: P. SOCIAL | E29: 2 | G29: =+G28+E29-F29 -> 252
A30: 42891 | B30: 13048 | C30: MARZO | D30: LUZ | F30: 188 | G30: =+G29+E30-F30 -> 64
A31: 42891 | B31: 13048 | C31: MARZO | D31: AGUA | F31: 2 | G31: =+G30+E31-F31 -> 62
A32: 42949 | B32: 13357 | C32: MARZO | D32: G. ADM | F32: 60 | G32: =+G31+E32-F32 -> 2
A33: 42949 | B33: 13357 | C33: MARZO | D33: P. SOCIAL | F33: 2 | G33: =+G32+E33-F33 -> 0
A34: 42855 | B34: POR COBRAR | C34: ABRIL | D34: LUZ | E34: 191.6 | G34: =+G33+E34-F34 -> 191.6
D35: AGUA | E35: 2 | G35: =+G34+E35-F35 -> 193.6
D36: G. ADM | E36: 60 | G36: =+G35+E36-F36 -> 253.6
D37: P. SOCIAL | E37: 2 | G37: =+G36+E37-F37 -> 255.6
A38: 42891 | B38: 13048 | C38: ABRIL | D38: LUZ | F38: 191.6 | G38: =+G37+E38-F38 -> 64
A39: 42891 | B39: 13048 | C39: ABRIL | D39: AGUA | F39: 2 | G39: =+G38+E39-F39 -> 62
A40: 42949 | B40: 13357 | C40: ABRIL | D40: P. SOCIAL | F40: 2 | G40: =+G39+E40-F40 -> 60
A41: 42949 | B41: 13357 | C41: ABRIL | D41: G. ADM | F41: 60 | G41: =+G40+E41-F41 -> 0
A42: 42886 | B42: POR COBRAR | C42: MAYO | D42: LUZ | E42: 158.7 | G42: =+G41+E42-F42 -> 158.7
...

Sheet GAVILAN NORMA
B2: GAVILAN MOSQUERA NORMA
A4: FECHA | B4: DOCUMENTO | C4: PERIODO | D4: CONCEPTO | E4: POR COBRAR | F4: PAGADO | G4: SALDO POR COBRAR
A5: 42736 | B5: SALDO AL 2016 | G5: 12814.9
A6: 42766 | B6: 12185 | C6: A CUENTA 2016 | F6: 80 | G6: =+G5+E6-F6 -> 12734.9
A7: 42766 | B7: 12181 | C7: A CUENTA 2016 | F7: 353.8 | G7: =+G6+E7-F7 -> 12381.1
A8: 43031 | B8: 13870 | C8: A CUENTA 2016 | F8: 130 | G8: =+G7+E8-F8 -> 12251.1
A9: 43045 | B9: 13935 | C9: A CUENTA 2016 | F9: 130 | G9: =+G8+E9-F9 -> 12121.1
A10: 43815 | B10: 19316 | C10: A CUENTA 2016 | F10: 4624.5 | G10: =+G9+E10-F10 -> 7496.6
A11: 44761 | B11: R 25100 | C11: A CUENTA 2016 | F11: 4000 | G11: =+G10+E11-F11 -> 3496.6
A12: 44761 | B12: R 25101 | C12: A CUENTA 2016 | F12: 1900 | G12: =+G11+E12-F12 -> 1596.6
A13: 44820 | B13: R 25517 | C13: A CUENTA 2016 | F13: 1500 | G13: =+G12+E13-F13 -> 96.6
A14: 45162 | B14: R 27368 | C14: A CUENTA 2016 | F14: 94.5 | G14: =+G13+E14-F14 -> 2.1
A15: 45419 | B15: 28803 | C15: A CUENTA 2016 | F15: 2.1 | G15: =+G14+E15-F15 -> 3.6370906e-13
A16: 42766 | B16: POR COBRAR | C16: ENERO | D16: LUZ | E16: 204.6 | G16: =+G15+E16-F16 -> 204.6
D17: AGUA | E17: 35.6 | G17: =+G16+E17-F17 -> 240.2
D18: G. ADM | E18: 60 | G18: =+G17+E18-F18 -> 300.2
D19: P. SOCIAL | E19: 2 | G19: =+G18+E19-F19 -> 302.2
A20: 42766 | B20: 12185 | C20: ENERO | D20: G. ADM | F20: 60 | G20: =+G19+E20-F20 -> 242.2
A21: 42766 | B21: 12185 | C21: ENERO | D21: P. SOCIAL | F21: 2 | G21: =+G20+E21-F21 -> 240.2
A22: 42819 | B22: 12483 | C22: ENERO | D22: LUZ | F22: 204.6 | G22: =+G21+E22-F22 -> 35.6
A23: 42819 | B23: 12483 | C23: ENERO | D23: AGUA | F23: 35.6 | G23: =+G22+E23-F23 -> 3.907985e-13
A24: 42794 | B24: POR COBRAR | C24: FEBRERO | D24: LUZ | E24: 174.3 | G24: =+G23+E24-F24 -> 174.3
D25: AGUA | E25: 25 | G25: =+G24+E25-F25 -> 199.3
D26: G. ADM | E26: 56 | G26: =+G25+E26-F26 -> 255.3
D27: P. SOCIAL | E27: 2 | G27: =+G26+E27-F27 -> 257.3
A28: 42819 | B28: 12483 | C28: FEBRERO | D28: LUZ | F28: 174.3 | G28: =+G27+E28-F28 -> 83
A29: 42819 | B29: 12483 | C29: FEBRERO | D29: AGUA | F29: 25 | G29: =+G28+E29-F29 -> 58
A30: 42819 | B30: 12483 | C30: FEBRERO | D30: G. ADM | F30: 56 | G30: =+G29+E30-F30 -> 2
A31: 42819 | B31: 12483 | C31: FEBRERO | D31: P. SOCIAL | F31: 2 | G31: =+G30+E31-F31 -> 3.9790393e-13
A32: 42825 | B32: POR COBRAR | C32: MARZO | D32: LUZ | E32: 149.4 | G32: =+G31+E32-F32 -> 149.4
D33: AGUA | E33: 25.7 | G33: =+G32+E33-F33 -> 175.1
D34: G. ADM | E34: 60 | G34: =+G33+E34-F34 -> 235.1
D35: P. SOCIAL | E35: 2 | G35: =+G34+E35-F35 -> 237.1
A36: 42846 | B36: 12674 | C36: MARZO | D36: G. ADM | F36: 60 | G36: =+G35+E36-F36 -> 177.1
A37: 42846 | B37: 12674 | C37: MARZO | D37: P. SOCIAL | F37: 2 | G37: =+G36+E37-F37 -> 175.1
A38: 42846 | B38: 12674 | C38: MARZO | D38: LUZ | F38: 149.4 | G38: =+G37+E38-F38 -> 25.7
A39: 42846 | B39: 12674 | C39: MARZO | D39: AGUA | F39: 25.7 | G39: =+G38+E39-F39 -> 3.8724579e-13
A40: 42855 | B40: POR COBRAR | C40: ABRIL | D40: LUZ | E40: 170 | G40: =+G39+E40-F40 -> 170
D41: AGUA | E41: 25.4 | G41: =+G40+E41-F41 -> 195.4
D42: G. ADM | E42: 60 | G42: =+G41+E42-F42 -> 255.4
...

Sheet GELDRES MIGUEL
B2: GELDRES REVILLA MIGUEL
A4: FECHA | B4: DOCUMENTO | C4: PERIODO | D4: CONCEPTO | E4: POR COBRAR | F4: PAGADO | G4: SALDO POR COBRAR
A5: 42736 | B5: SALDO AL 2016 | G5: 270.2
A6: 42753 | B6: 12119 | C6: A CUENTA 2016 | F6: 175.2 | G6: =+G5+E6-F6 -> 95
A7: 42786 | B7: 12301 | C7: A CUENTA 2016 | F7: 15 | G7: =+G6+E7-F7 -> 80
A8: 42845 | B8: 12668 | C8: A CUENTA 2016 | F8: 80 | G8: =+G7+E8-F8 -> 0
A9: 42766 | B9: POR COBRAR | C9: ENERO | D9: LUZ | E9: 116 | G9: =+G8+E9-F9 -> 116
D10: AGUA | E10: 57 | G10: =+G9+E10-F10 -> 173
D11: G. ADM | E11: 60 | G11: =+G10+E11-F11 -> 233
D12: P. SOCIAL | E12: 2 | G12: =+G11+E12-F12 -> 235
A13: 42765 | B13: TARJETA | C13: ENERO | D13: G. ADM | F13: 60 | G13: =+G12+E13-F13 -> 175
A14: 42765 | B14: TARJETA | C14: ENERO | D14: P. SOCIAL | F14: 2 | G14: =+G13+E14-F14 -> 173
A15: 42786 | B15: 12301 | C15: ENERO | D15: LUZ | F15: 116 | G15: =+G14+E15-F15 -> 57
A16: 42786 | B16: 12301 | C16: ENERO | D16: AGUA | F16: 57 | G16: =+G15+E16-F16 -> 0
A17: 42794 | B17: POR COBRAR | C17: FEBRERO | D17: LUZ | E17: 119.1 | G17: =+G16+E17-F17 -> 119.1
D18: AGUA | E18: 36 | G18: =+G17+E18-F18 -> 155.1
D19: G. ADM | E19: 56 | G19: =+G18+E19-F19 -> 211.1
D20: P. SOCIAL | E20: 2 | G20: =+G19+E20-F20 -> 213.1
A21: 42793 | B21: TARJETA | C21: FEBRERO | D21: G. ADM | F21: 56 | G21: =+G20+E21-F21 -> 157.1
A22: 42793 | B22: TARJETA | C22: FEBRERO | D22: P. SOCIAL | F22: 2 | G22: =+G21+E22-F22 -> 155.1
A23: 42821 | B23: 12572 | C23: FEBRERO | D23: LUZ | F23: 119.1 | G23: =+G22+E23-F23 -> 36
A24: 42821 | B24: 12572 | C24: FEBRERO | D24: AGUA | F24: 36 | G24: =+G23+E24-F24 -> 0
A25: 42825 | B25: POR COBRAR | C25: MARZO | D25: LUZ | E25: 114.2 | G25: =+G24+E25-F25 -> 114.2
D26: AGUA | E26: 37.8 | G26: =+G25+E26-F26 -> 152
D27: G. ADM | E27: 60 | G27: =+G26+E27-F27 -> 212
D28: P. SOCIAL | E28: 2 | G28: =+G27+E28-F28 -> 214
A29: 42824 | B29: TARJETA | C29: MARZO | D29: G. ADM | F29: 60 | G29: =+G28+E29-F29 -> 154
A30: 42824 | B30: TARJETA | C30: MARZO | D30: P. SOCIAL | F30: 2 | G30: =+G29+E30-F30 -> 152
A31: 42845 | B31: 12667 | C31: MARZO | D31: LUZ | F31: 114.2 | G31: =+G30+E31-F31 -> 37.8
A32: 42845 | B32: 12667 | C32: MARZO | D32: AGUA | F32: 37.8 | G32: =+G31+E32-F32 -> 0
A33: 42855 | B33: POR COBRAR | C33: ABRIL | D33: LUZ | E33: 116.2 | G33: =+G32+E33-F33 -> 116.2
D34: AGUA | E34: 37 | G34: =+G33+E34-F34 -> 153.2
D35: G. ADM | E35: 60 | G35: =+G34+E35-F35 -> 213.2
D36: P. SOCIAL | E36: 2 | G36: =+G35+E36-F36 -> 215.2
A37: 42854 | B37: TARJETA | C37: ABRIL | D37: G. ADM | F37: 60 | G37: =+G36+E37-F37 -> 155.2
A38: 42854 | B38: TARJETA | C38: ABRIL | D38: P. SOCIAL | F38: 2 | G38: =+G37+E38-F38 -> 153.2
A39: 42881 | B39: 12822 | C39: ABRIL | D39: LUZ | F39: 116.2 | G39: =+G38+E39-F39 -> 37
A40: 42881 | B40: 12822 | C40: ABRIL | D40: AGUA | F40: 37 | G40: =+G39+E40-F40 -> 0
A41: 42886 | B41: POR COBRAR | C41: MAYO | D41: LUZ | E41: 108 | G41: =+G40+E41-F41 -> 108
D42: AGUA | E42: 36.3 | G42: =+G41+E42-F42 -> 144.3
...

Sheet GUTIERREZ CASTILLO JORGE
B2: GUTIERREZ CASTILLO JORGE
A4: FECHA | B4: DOCUMENTO | C4: PERIODO | D4: CONCEPTO | E4: POR COBRAR | F4: PAGADO | G4: SALDO POR COBRAR
A5: 42736 | B5: SALDO AL 2016 | G5: 162.7
A6: 42786 | B6: 12253 | C6: CANCELACION | F6: 162.7 | G6: =+G5+E6-F6 -> 0
A7: 42766 | B7: POR COBRAR | C7: ENERO | D7: LUZ | E7: 79.4 | G7: =+G6+E7-F7 -> 79.4
D8: AGUA | E8: 2.8 | G8: =+G7+E8-F8 -> 82.2
D9: G. ADM | E9: 60 | G9: =+G8+E9-F9 -> 142.2
D10: P. SOCIAL | E10: 2 | G10: =+G9+E10-F10 -> 144.2
A11: 42765 | B11: TARJETA | C11: ENERO | D11: G. ADM | F11: 58 | G11: =+G10+E11-F11 -> 86.2
A12: 42783 | B12: 12987 | C12: ENERO | D12: G. ADM | F12: 2 | G12: =+G11+E12-F12 -> 84.2
A13: 42783 | B13: 12987 | C13: ENERO | D13: P. SOCIAL | F13: 2 | G13: =+G12+E13-F13 -> 82.2
A14: 42786 | B14: 12253 | C14: ENERO | D14: AGUA | F14: 2.8 | G14: =+G13+E14-F14 -> 79.4
A15: 42786 | B15: 12253 | C15: ENERO | D15: LUZ | F15: 79.4 | G15: =+G14+E15-F15 -> 0
A16: 42794 | B16: POR COBRAR | C16: FEBRERO | D16: LUZ | E16: 81.5 | G16: =+G15+E16-F16 -> 81.5
D17: AGUA | E17: 2 | G17: =+G16+E17-F17 -> 83.5
D18: G. ADM | E18: 56 | G18: =+G17+E18-F18 -> 139.5
D19: P. SOCIAL | E19: 2 | G19: =+G18+E19-F19 -> 141.5
A20: 42794 | B20: TARJETA | C20: FEBRERO | D20: G. ADM | F20: 56 | G20: =+G19+E20-F20 -> 85.5
A21: 42794 | B21: TARJETA | C21: FEBRERO | D21: P. SOCIAL | F21: 2 | G21: =+G20+E21-F21 -> 83.5
A22: 42822 | B22: 12614 | C22: FEBRERO | D22: LUZ | F22: 81.5 | G22: =+G21+E22-F22 -> 2
A23: 42822 | B23: 12614 | C23: FEBRERO | D23: AGUA | F23: 2 | G23: =+G22+E23-F23 -> 0
A24: 42825 | B24: POR COBRAR | C24: MARZO | D24: LUZ | E24: 78 | G24: =+G23+E24-F24 -> 78
D25: AGUA | E25: 2 | G25: =+G24+E25-F25 -> 80
D26: G. ADM | E26: 60 | G26: =+G25+E26-F26 -> 140
D27: P. SOCIAL | E27: 2 | G27: =+G26+E27-F27 -> 142
A28: 42824 | B28: TARJETA | C28: MARZO | D28: G. ADM | F28: 60 | G28: =+G27+E28-F28 -> 82
A29: 42824 | B29: TARJETA | C29: MARZO | D29: P. SOCIAL | F29: 2 | G29: =+G28+E29-F29 -> 80
A30: 42888 | B30: 13038 | C30: MARZO | D30: LUZ | F30: 78 | G30: =+G29+E30-F30 -> 2
A31: 42888 | B31: 13038 | C31: MARZO | D31: AGUA | F31: 2 | G31: =+G30+E31-F31 -> 0
A32: 42855 | B32: POR COBRAR | C32: ABRIL | D32: LUZ | E32: 79.7 | G32: =+G31+E32-F32 -> 79.7
D33: AGUA | E33: 2 | G33: =+G32+E33-F33 -> 81.7
D34: G. ADM | E34: 60 | G34: =+G33+E34-F34 -> 141.7
D35: P. SOCIAL | E35: 2 | G35: =+G34+E35-F35 -> 143.7
A36: 42855 | B36: TARJETA | C36: ABRIL | D36: G. ADM | F36: 60 | G36: =+G35+E36-F36 -> 83.7
A37: 42855 | B37: TARJETA | C37: ABRIL | D37: P. SOCIAL | F37: 2 | G37: =+G36+E37-F37 -> 81.7
A38: 42888 | B38: 13038 | C38: ABRIL | D38: AGUA | F38: 2 | G38: =+G37+E38-F38 -> 79.7
A39: 42888 | B39: 13038 | C39: ABRIL | D39: LUZ | F39: 79.7 | G39: =+G38+E39-F39 -> 0
A40: 42886 | B40: POR COBRAR | C40: MAYO | D40: LUZ | E40: 74.4 | G40: =+G39+E40-F40 -> 74.4
D41: AGUA | E41: 2 | G41: =+G40+E41-F41 -> 76.4
D42: G. ADM | E42: 60 | G42: =+G41+E42-F42 -> 136.4
...

Sheet GUTIERREZ CASTILLO TERESA
B2: GUTIERREZ CASTILLO TERESA JESUS 21/6
A4: FECHA | B4: DOCUMENTO | C4: PERIODO | D4: CONCEPTO | E4: POR COBRAR | F4: PAGADO | G4: SALDO POR COBRAR
A5: 42736 | B5: SALDO AL 2016 | G5: 108.8
A6: 42767 | B6: 12191 | C6: A CUENTA 2016 | F6: 49.8 | G6: =+G5+E6-F6 -> 59
A7: 42786 | B7: 12306 | C7: A CUENTA 2016 | F7: 59 | G7: =+G6+E7-F7 -> 0
A8: 42766 | B8: POR COBRAR | C8: ENERO | D8: LUZ | E8: 24.5 | G8: =+G7+E8-F8 -> 24.5
D9: AGUA | E9: 4 | G9: =+G8+E9-F9 -> 28.5
D10: G. ADM | E10: 60 | G10: =+G9+E10-F10 -> 88.5
D11: P. SOCIAL | E11: 2 | G11: =+G10+E11-F11 -> 90.5
A12: 42765 | B12: TARJETA | C12: ENERO | D12: G. ADM | F12: 60 | G12: =+G11+E12-F12 -> 30.5
A13: 42765 | B13: TARJETA | C13: ENERO | D13: P. SOCIAL | F13: 2 | G13: =+G12+E13-F13 -> 28.5
A14: 42767 | B14: 12191 | C14: ENERO | D14: LUZ | F14: 24.5 | G14: =+G13+E14-F14 -> 4
A15: 42767 | B15: 12191 | C15: ENERO | D15: AGUA | F15: 4 | G15: =+G14+E15-F15 -> 0
A16: 42794 | B16: POR COBRAR | C16: FEBRERO | D16: LUZ | E16: 13 | G16: =+G15+E16-F16 -> 13
D17: AGUA | E17: 2 | G17: =+G16+E17-F17 -> 15
D18: G. ADM | E18: 56 | G18: =+G17+E18-F18 -> 71
D19: P. SOCIAL | E19: 2 | G19: =+G18+E19-F19 -> 73
D20: MULTA | E20: 85 | G20: =+G19+E20-F20 -> 158
A21: 42795 | B21: 12381 | C21: FEBRERO | D21: G. ADM | F21: 56 | G21: =+G20+E21-F21 -> 102
A22: 42795 | B22: 12381 | C22: FEBRERO | D22: P. SOCIAL | F22: 2 | G22: =+G21+E22-F22 -> 100
A23: 42894 | B23: 13985 | C23: FEBRERO | D23: LUZ | F23: 13 | G23: =+G22+E23-F23 -> 87
A24: 42894 | B24: 13086 | C24: FEBRERO | D24: AGUA | F24: 2 | G24: =+G23+E24-F24 -> 85
A25: 43067 | B25: 185-2017 | C25: FEBRERO | D25: MULTA | F25: 85 | G25: =+G24+E25-F25 -> 0
A26: 42825 | B26: POR COBRAR | C26: MARZO | D26: LUZ | E26: 12 | G26: =+G25+E26-F26 -> 12
D27: AGUA | E27: 2 | G27: =+G26+E27-F27 -> 14
D28: G. ADM | E28: 60 | G28: =+G27+E28-F28 -> 74
D29: P. SOCIAL | E29: 2 | G29: =+G28+E29-F29 -> 76
D30: MULTA | E30: 85 | G30: =+G29+E30-F30 -> 161
A31: 42894 | B31: 13985 | C31: MARZO | D31: G. ADM | F31: 60 | G31: =+G30+E31-F31 -> 101
A32: 42894 | B32: 13985 | C32: MARZO | D32: P. SOCIAL | F32: 2 | G32: =+G31+E32-F32 -> 99
A33: 42894 | B33: 13985 | C33: MARZO | D33: LUZ | F33: 12 | G33: =+G32+E33-F33 -> 87
A34: 42894 | B34: 13086 | C34: MARZO | D34: AGUA | F34: 2 | G34: =+G33+E34-F34 -> 85
A35: 43067 | B35: 185-2017 | C35: MARZO | D35: MULTA | F35: 85 | G35: =+G34+E35-F35 -> 0
