Workbook

Sheet Marin Rocha ESTEFANY
B2: MARIN ROCHA ESTEFANY JULISSA - ROCHA JULIIA
A4: FECHA | B4: DOCUMENTO | C4: PERIODO | D4: CONCEPTO | E4: POR COBRAR | F4: PAGADO | G4: SALDO POR COBRAR
A5: 42736 | B5: SALDO AL 2016 | G5: 156.6
A6: 42737 | B6: 12046 | C6: A CUENTA DEL 2016 | F6: 109.5 | G6: =+G5+E6-F6 -> 47.1
A7: 42768 | B7: 12196 | C7: A CUENTA DEL 2016 | F7: 47.1 | G7: =+G6+E7-F7 -> 0
A8: 42766 | B8: POR COBRAR | C8: ENERO | D8: LUZ | E8: 43.3 | G8: =+G7+E8-F8 -> 43.3
D9: AGUA | E9: 2.8 | G9: =+G8+E9-F9 -> 46.1
D10: G. ADM | E10: 60 | G10: =+G9+E10-F10 -> 106.1
D11: P. SOCIAL | E11: 2 | G11: =+G10+E11-F11 -> 108.1
D12: P.S.FALLEC. | E12: 10 | G12: =+G11+E12-F12 -> 118.1
A13: 42774 | B13: 12929 | C13: ENERO | D13: P.S.FALLEC. | F13: 10 | G13: =+G12+E13-F13 -> 108.1
A14: 42768 | B14: 12196 | C14: ENERO | D14: G. ADM | F14: 60 | G14: =+G13+E14-F14 -> 48.1
A15: 42768 | B15: 12196 | C15: ENERO | D15: P. SOCIAL | F15: 2 | G15: =+G14+E15-F15 -> 46.1
A16: 42786 | B16: 12252 | C16: ENERO | D16: LUZ | F16: 43.3 | G16: =+G15+E16-F16 -> 2.8
A17: 42786 | B17: 12252 | C17: ENERO | D17: AGUA | F17: 2.8 | G17: =+G16+E17-F17 -> 0
A18: 42794 | B18: POR COBRAR | C18: FEBRERO | D18: LUZ | E18: 43.9 | G18: =+G17+E18-F18 -> 43.9
D19: AGUA | E19: 2 | G19: =+G18+E19-F19 -> 45.9
D20: G. ADM | E20: 56 | G20: =+G19+E20-F20 -> 101.9
D21: P. SOCIAL | E21: 2 | G21: =+G20+E21-F21 -> 103.9
A22: 42794 | B22: 12378 | C22: FEBRERO | D22: G. ADM | F22: 56 | G22: =+G21+E22-F22 -> 47.9
A23: 42794 | B23: 12378 | C23: FEBRERO | D23: P. SOCIAL | F23: 2 | G23: =+G22+E23-F23 -> 45.9
A24: 42821 | B24: 12543 | C24: FEBRERO | D24: LUZ | F24: 43.9 | G24: =+G23+E24-F24 -> 2
A25: 42821 | B25: 12543 | C25: FEBRERO | D25: AGUA | F25: 2 | G25: =+G24+E25-F25 -> 7.1054274e-15
A26: 42825 | B26: POR COBRAR | C26: MARZO | D26: LUZ | E26: 41.8 | G26: =+G25+E26-F26 -> 41.8
D27: AGUA | E27: 2 | G27: =+G26+E27-F27 -> 43.8
D28: G. ADM | E28: 60 | G28: =+G27+E28-F28 -> 103.8
D29: P. SOCIAL | E29: 2 | G29: =+G28+E29-F29 -> 105.8
A30: 42885 | B30: 12882 | C30: MARZO | D30: LUZ | F30: 41.8 | G30: =+G29+E30-F30 -> 64
A31: 42885 | B31: 12882 | C31: MARZO | D31: AGUA | F31: 2 | G31: =+G30+E31-F31 -> 62
A32: 42885 | B32: 12882 | C32: MARZO | D32: G. ADM | F32: 60 | G32: =+G31+E32-F32 -> 2
A33: 42885 | B33: 12882 | C33: MARZO | D33: P. SOCIAL | F33: 2 | G33: =+G32+E33-F33 -> 1.4210855e-14
A34: 42855 | B34: POR COBRAR | C34: ABRIL | D34: LUZ | E34: 43.1 | G34: =+G33+E34-F34 -> 43.1
D35: AGUA | E35: 2 | G35: =+G34+E35-F35 -> 45.1
D36: G. ADM | E36: 60 | G36: =+G35+E36-F36 -> 105.1
D37: P. SOCIAL | E37: 2 | G37: =+G36+E37-F37 -> 107.1
A38: 42885 | B38: 12882 | C38: ABRIL | D38: LUZ | F38: 43.1 | G38: =+G37+E38-F38 -> 64
A39: 42885 | B39: 12882 | C39: ABRIL | D39: AGUA | F39: 2 | G39: =+G38+E39-F39 -> 62
A40: 42885 | B40: 12882 | C40: ABRIL | D40: G. ADM | F40: 60 | G40: =+G39+E40-F40 -> 2
A41: 42885 | B41: 12882 | C41: ABRIL | D41: P. SOCIAL | F41: 2 | G41: =+G40+E41-F41 -> 2.8421709e-14
A42: 42886 | B42: POR COBRAR | C42: MAYO | D42: LUZ | E42: 40.7 | G42: =+G41+E42-F42 -> 40.7
...

Sheet MAYHUASCA  CLUDY
B2: CLUDY AYDE MAYHUASCA BASTIDAS
A4: FECHA | B4: DOCUMENTO | C4: PERIODO | D4: CONCEPTO | E4: POR COBRAR | F4: PAGADO | G4: SALDO POR COBRAR
A5: 42736 | B5: SALDO AL 2016 | G5: 1494.1
A6: 42754 | B6: 12125 | C6: A CUENTA 2016 | F6: 274.1 | G6: =+G5+E6-F6 -> 1220
A7: 42881 | B7: 12827 | C7: CANCELADO | F7: 1220 | G7: =+G6+E7-F7 -> 0
A8: 42766 | B8: POR COBRAR | C8: ENERO | D8: LUZ | E8: 167.5 | G8: =+G7+E8-F8 -> 167.5
D9: AGUA | E9: 32 | G9: =+G8+E9-F9 -> 199.5
D10: G. ADM | E10: 60 | G10: =+G9+E10-F10 -> 259.5
D11: P. SOCIAL | E11: 2 | G11: =+G10+E11-F11 -> 261.5
A12: 42766 | B12: TARJETA | C12: ENERO | D12: G. ADM | F12: 60 | G12: =+G11+E12-F12 -> 201.5
A13: 42766 | B13: TARJETA | C13: ENERO | D13: P. SOCIAL | F13: 2 | G13: =+G12+E13-F13 -> 199.5
A14: 42787 | B14: 12315 | C14: ENERO | D14: LUZ | F14: 167.5 | G14: =+G13+E14-F14 -> 32
A15: 42787 | B15: 12315 | C15: ENERO | D15: AGUA | F15: 32 | G15: =+G14+E15-F15 -> 0
A16: 42794 | B16: POR COBRAR | C16: FEBRERO | D16: LUZ | E16: 219.6 | G16: =+G15+E16-F16 -> 219.6
D17: AGUA | E17: 22 | G17: =+G16+E17-F17 -> 241.6
D18: G. ADM | E18: 56 | G18: =+G17+E18-F18 -> 297.6
D19: P. SOCIAL | E19: 2 | G19: =+G18+E19-F19 -> 299.6
A20: 42794 | B20: TARJETA | C20: FEBRERO | D20: G. ADM | F20: 56 | G20: =+G19+E20-F20 -> 243.6
A21: 42794 | B21: TARJETA | C21: FEBRERO | D21: P. SOCIAL | F21: 2 | G21: =+G20+E21-F21 -> 241.6
A22: 42821 | B22: 12532 | C22: FEBRERO | D22: LUZ | F22: 219.6 | G22: =+G21+E22-F22 -> 22
A23: 42821 | B23: 12532 | C23: FEBRERO | D23: AGUA | F23: 22 | G23: =+G22+E23-F23 -> 2.8421709e-14
A24: 42825 | B24: POR COBRAR | C24: MARZO | D24: LUZ | E24: 211.2 | G24: =+G23+E24-F24 -> 211.2
D25: AGUA | E25: 23.2 | G25: =+G24+E25-F25 -> 234.4
D26: G. ADM | E26: 60 | G26: =+G25+E26-F26 -> 294.4
D27: P. SOCIAL | E27: 2 | G27: =+G26+E27-F27 -> 296.4
A28: 42824 | B28: TARJETA | C28: MARZO | D28: G. ADM | F28: 60 | G28: =+G27+E28-F28 -> 236.4
A29: 42824 | B29: TARJETA | C29: MARZO | D29: P. SOCIAL | F29: 2 | G29: =+G28+E29-F29 -> 234.4
A30: 42851 | B30: 12702 | C30: MARZO | D30: LUZ | F30: 23.2 | G30: =+G29+E30-F30 -> 211.2
A31: 42851 | B31: 12702 | C31: MARZO | D31: AGUA | F31: 211.2 | G31: =+G30+E31-F31 -> 0
A32: 42855 | B32: POR COBRAR | C32: ABRIL | D32: LUZ | E32: 171 | G32: =+G31+E32-F32 -> 171
D33: AGUA | E33: 22.8 | G33: =+G32+E33-F33 -> 193.8
D34: G. ADM | E34: 60 | G34: =+G33+E34-F34 -> 253.8
D35: P. SOCIAL | E35: 2 | G35: =+G34+E35-F35 -> 255.8
A36: 42854 | B36: TARJETA | C36: ABRIL | D36: G. ADM | F36: 60 | G36: =+G35+E36-F36 -> 195.8
A37: 42854 | B37: TARJETA | C37: ABRIL | D37: P. SOCIAL | F37: 2 | G37: =+G36+E37-F37 -> 193.8
A38: 42872 | B38: 12763 | C38: ABRIL | D38: LUZ | F38: 171 | G38: =+G37+E38-F38 -> 22.8
A39: 42872 | B39: 12763 | C39: ABRIL | D39: AGUA | F39: 22.8 | G39: =+G38+E39-F39 -> 0
A40: 42886 | B40: POR COBRAR | C40: MAYO | D40: LUZ | E40: 148.6 | G40: =+G39+E40-F40 -> 148.6
D41: AGUA | E41: 22.3 | G41: =+G40+E41-F41 -> 170.9
D42: G. ADM | E42: 60 | G42: =+G41+E42-F42 -> 230.9
...

Sheet MAYHUASCA MARILU
B2: MAYHUASCA BASTIDAS MARILU
A4: FECHA | B4: DOCUMENTO | C4: PERIODO | D4: CONCEPTO | E4: POR COBRAR | F4: PAGADO | G4: SALDO POR COBRAR
A5: 42736 | B5: SALDO AL 2016 | G5: 114
A6: 42400 | B6: 12186 | C6: A CUENTA 2016 | F6: 34 | G6: =+G5+E6-F6 -> 80
A7: 42787 | B7: 12355 | C7: A CUENTA 2016 | F7: 80 | G7: =+G6+E7-F7 -> 0
A8: 42766 | B8: POR COBRAR | C8: ENERO | D8: LUZ | E8: 32.1 | G8: =+G7+E8-F8 -> 32.1
D9: AGUA | E9: 2.8 | G9: =+G8+E9-F9 -> 34.9
D10: G. ADM | E10: 60 | G10: =+G9+E10-F10 -> 94.9
D11: P. SOCIAL | E11: 2 | G11: =+G10+E11-F11 -> 96.9
A12: 42765 | B12: TARJETA | C12: ENERO | D12: G. ADM | F12: 60 | G12: =+G11+E12-F12 -> 36.9
A13: 42765 | B13: TARJETA | C13: ENERO | D13: P. SOCIAL | F13: 2 | G13: =+G12+E13-F13 -> 34.9
A14: 42787 | B14: 12355 | C14: ENERO | D14: LUZ | F14: 32.1 | G14: =+G13+E14-F14 -> 2.8
A15: 42787 | B15: 12355 | C15: ENERO | D15: AGUA | F15: 2.8 | G15: =+G14+E15-F15 -> 4.4408921e-15
A16: 42794 | B16: POR COBRAR | C16: FEBRERO | D16: LUZ | E16: 57.2 | G16: =+G15+E16-F16 -> 57.2
D17: AGUA | E17: 2 | G17: =+G16+E17-F17 -> 59.2
D18: G. ADM | E18: 56 | G18: =+G17+E18-F18 -> 115.2
D19: P. SOCIAL | E19: 2 | G19: =+G18+E19-F19 -> 117.2
A20: 42794 | B20: TARJETA | C20: FEBRERO | D20: G. ADM | F20: 56 | G20: =+G19+E20-F20 -> 61.2
A21: 42794 | B21: TARJETA | C21: FEBRERO | D21: P. SOCIAL | F21: 2 | G21: =+G20+E21-F21 -> 59.2
A22: 42817 | B22: 12450 | C22: FEBRERO | D22: LUZ | F22: 57.2 | G22: =+G21+E22-F22 -> 2
A23: 42817 | B23: 12450 | C23: FEBRERO | D23: AGUA | F23: 2 | G23: =+G22+E23-F23 -> 1.4210855e-14
A24: 42825 | B24: POR COBRAR | C24: MARZO | D24: LUZ | E24: 44 | G24: =+G23+E24-F24 -> 44
D25: AGUA | E25: 2 | G25: =+G24+E25-F25 -> 46
D26: G. ADM | E26: 60 | G26: =+G25+E26-F26 -> 106
D27: P. SOCIAL | E27: 2 | G27: =+G26+E27-F27 -> 108
A28: 42824 | B28: TARJETA | C28: MARZO | D28: G. ADM | F28: 60 | G28: =+G27+E28-F28 -> 48
A29: 42824 | B29: TARJETA | C29: MARZO | D29: P. SOCIAL | F29: 2 | G29: =+G28+E29-F29 -> 46
A30: 42886 | B30: 13016 | C30: MARZO | D30: LUZ | F30: 44 | G30: =+G29+E30-F30 -> 2
A31: 42886 | B31: 13016 | C31: MARZO | D31: AGUA | F31: 2 | G31: =+G30+E31-F31 -> 1.4210855e-14
A32: 42855 | B32: POR COBRAR | C32: ABRIL | D32: LUZ | E32: 45.3 | G32: =+G31+E32-F32 -> 45.3
D33: AGUA | E33: 2 | G33: =+G32+E33-F33 -> 47.3
D34: G. ADM | E34: 60 | G34: =+G33+E34-F34 -> 107.3
D35: P. SOCIAL | E35: 2 | G35: =+G34+E35-F35 -> 109.3
A36: 42855 | B36: TARJETA | C36: ABRIL | D36: G. ADM | F36: 60 | G36: =+G35+E36-F36 -> 49.3
A37: 42855 | B37: TARJETA | C37: ABRIL | D37: P. SOCIAL | F37: 2 | G37: =+G36+E37-F37 -> 47.3
A38: 42886 | B38: 13016 | C38: ABRIL | D38: LUZ | F38: 45.3 | G38: =+G37+E38-F38 -> 2
A39: 42886 | B39: 13016 | C39: ABRIL | D39: AGUA | F39: 2 | G39: =+G38+E39-F39 -> 1.4210855e-14
A40: 42886 | B40: POR COBRAR | C40: MAYO | D40: LUZ | E40: 42.7 | G40: =+G39+E40-F40 -> 42.7
D41: AGUA | E41: 2 | G41: =+G40+E41-F41 -> 44.7
D42: G. ADM | E42: 60 | G42: =+G41+E42-F42 -> 104.7
...

Sheet MAYHUASCA ULISES
B2: MAYHUASCA BASTIDAS ULISES
A4: FECHA | B4: DOCUMENTO | C4: PERIODO | D4: CONCEPTO | E4: POR COBRAR | F4: PAGADO | G4: SALDO POR COBRAR
A5: 42736 | B5: SALDO AL 2016 | G5: 7193.5
A6: 42741 | B6: 12076 | C6: A CUENTA 2016 | F6: 118.5 | G6: =+G5+E6-F6 -> 7075
A7: 42783 | B7: 12984 | C7: A CUENTA 2016 | F7: 125.8 | G7: =+G6+E7-F7 -> 6949.2
A8: 42765 | B8: TARJETA | C8: A CUENTA 2016 | F8: 54 | G8: =+G7+E8-F8 -> 6895.2
A9: 42794 | B9: TARJETA | C9: A CUENTA 2016 | F9: 57 | G9: =+G8+E9-F9 -> 6838.2
A10: 42824 | B10: TARJETA | C10: A CUENTA 2016 | F10: 57 | G10: =+G9+E10-F10 -> 6781.2
A11: 42855 | B11: TARJETA | C11: A CUENTA 2016 | F11: 60 | G11: =+G10+E11-F11 -> 6721.2
A12: 42886 | B12: TARJETA | C12: A CUENTA 2016 | F12: 78 | G12: =+G11+E12-F12 -> 6643.2
A13: 42916 | B13: TARJETA | C13: A CUENTA 2016 | F13: 48 | G13: =+G12+E13-F13 -> 6595.2
A14: 42947 | B14: TARJETA | C14: A CUENTA 2016 | F14: 72 | G14: =+G13+E14-F14 -> 6523.2
A15: 42978 | B15: TARJETA | C15: A CUENTA 2016 | F15: 60 | G15: =+G14+E15-F15 -> 6463.2
A16: 43008 | B16: TARJETA | C16: A CUENTA 2016 | F16: 72 | G16: =+G15+E16-F16 -> 6391.2
A17: 43039 | B17: 13908 | C17: A CUENTA 2016 | F17: 922.1 | G17: =+G16+E17-F17 -> 5469.1
A18: 43039 | B18: TARJETA | C18: A CUENTA 2016 | F18: 18 | G18: =+G17+E18-F18 -> 5451.1
A19: 43131 | B19: 14592 | C19: A CUENTA 2016 | F19: 922.1 | G19: =+G18+E19-F19 -> 4529
A20: 43160 | B20: 14758 | C20: A CUENTA 2016 | F20: 922.1 | G20: =+G19+E20-F20 -> 3606.9
A21: 43190 | B21: 15069 | C21: A CUENTA 2016 | F21: 922.1 | G21: =+G20+E21-F21 -> 2684.8
A22: 43202 | B22: 15098 | C22: A CUENTA 2016 | F22: 922.1 | G22: =+G21+E22-F22 -> 1762.7
A23: 43202 | B23: 15099 | C23: A CUENTA 2016 | F23: 922.1 | G23: =+G22+E23-F23 -> 840.6
A24: 43222 | B24: 15284 | C24: A CUENTA 2016 | F24: 840.6 | G24: =+G23+E24-F24 -> 0
A25: 42766 | B25: POR COBRAR | C25: ENERO | D25: LUZ | E25: 109.2 | G25: =+G24+E25-F25 -> 109.2
D26: AGUA | E26: 22.8 | G26: =+G25+E26-F26 -> 132
D27: G. ADM | E27: 60 | G27: =+G26+E27-F27 -> 192
D28: P. SOCIAL | E28: 2 | G28: =+G27+E28-F28 -> 194
A29: 42761 | B29: TARJETA | C29: ENERO | D29: G. ADM | F29: 36 | G29: =+G28+E29-F29 -> 158
A30: 42796 | B30: 12390 | C30: ENERO | D30: LUZ | F30: 109.2 | G30: =+G29+E30-F30 -> 48.8
A31: 42796 | B31: 12390 | C31: ENERO | D31: AGUA | F31: 22.8 | G31: =+G30+E31-F31 -> 26
A32: 43222 | B32: 15284 | C32: ENERO | D32: G. ADM | F32: 24 | G32: =+G31+E32-F32 -> 2
A33: 43222 | B33: 15284 | C33: ENERO | D33: P. SOCIAL | F33: 2 | G33: =+G32+E33-F33 -> -3.5527137e-15
A34: 42794 | B34: POR COBRAR | C34: FEBRERO | D34: LUZ | E34: 134.6 | G34: =+G33+E34-F34 -> 134.6
D35: AGUA | E35: 16 | G35: =+G34+E35-F35 -> 150.6
D36: G. ADM | E36: 56 | G36: =+G35+E36-F36 -> 206.6
D37: P. SOCIAL | E37: 2 | G37: =+G36+E37-F37 -> 208.6
D38: MULTA | E38: 85 | G38: =+G37+E38-F38 -> 293.6
A39: 42794 | B39: TARJETA | C39: FEBRERO | D39: G. ADM | F39: 38 | G39: =+G38+E39-F39 -> 255.6
A40: 42844 | B40: 12658 | C40: FEBRERO | D40: LUZ | F40: 134.6 | G40: =+G39+E40-F40 -> 121
A41: 42844 | B41: 12658 | C41: FEBRERO | D41: AGUA | F41: 16 | G41: =+G40+E41-F41 -> 105
A42: 43222 | B42: 15284 | C42: FEBRERO | D42: G. ADM | F42: 18 | G42: =+G41+E42-F42 -> 87
...

Sheet MAYTA VIOLETA
B2: MAYTA COLQUI VIOLETA
A4: FECHA | B4: DOCUMENTO | C4: PERIODO | D4: CONCEPTO | E4: POR COBRAR | F4: PAGADO | G4: SALDO POR COBRAR
A5: 42736 | B5: SALDO AL 2016 | G5: 362
A6: 42784 | B6: 12989 | C6: A CUENTA 2016 | F6: 362 | G6: =+G5+E6-F6 -> 0
A7: 42766 | B7: POR COBRAR | C7: ENERO | D7: LUZ | E7: 65.6 | G7: =+G6+E7-F7 -> 65.6
D8: AGUA | E8: 22.8 | G8: =+G7+E8-F8 -> 88.4
D9: G. ADM | E9: 60 | G9: =+G8+E9-F9 -> 148.4
D10: P. SOCIAL | E10: 2 | G10: =+G9+E10-F10 -> 150.4
A11: 42759 | B11: TARJETA | C11: ENERO | D11: G. ADM | F11: 48 | G11: =+G10+E11-F11 -> 102.4
A12: 42784 | B12: 12989 | C12: ENERO | D12: G. ADM | F12: 12 | G12: =+G11+E12-F12 -> 90.4
A13: 42784 | B13: 12989 | C13: ENERO | D13: P. SOCIAL | F13: 2 | G13: =+G12+E13-F13 -> 88.4
A14: 42784 | B14: 12989 | C14: ENERO | D14: LUZ | F14: 65.6 | G14: =+G13+E14-F14 -> 22.8
A15: 42784 | B15: 12989 | C15: ENERO | D15: AGUA | F15: 22.8 | G15: =+G14+E15-F15 -> 0
A16: 42794 | B16: POR COBRAR | C16: FEBRERO | D16: LUZ | E16: 122.4 | G16: =+G15+E16-F16 -> 122.4
D17: AGUA | E17: 16 | G17: =+G16+E17-F17 -> 138.4
D18: G. ADM | E18: 56 | G18: =+G17+E18-F18 -> 194.4
D19: P. SOCIAL | E19: 2 | G19: =+G18+E19-F19 -> 196.4
A20: 42821 | B20: 12512 | C20: FEBRERO | D20: LUZ | F20: 122.4 | G20: =+G19+E20-F20 -> 74
A21: 42821 | B21: 12512 | C21: FEBRERO | D21: AGUA | F21: 16 | G21: =+G20+E21-F21 -> 58
A22: 42821 | B22: 12512 | C22: FEBRERO | D22: G. ADM | F22: 56 | G22: =+G21+E22-F22 -> 2
A23: 42821 | B23: 12512 | C23: FEBRERO | D23: P. SOCIAL | F23: 2 | G23: =+G22+E23-F23 -> 0
A24: 42825 | B24: POR COBRAR | C24: MARZO | D24: LUZ | E24: 64.2 | G24: =+G23+E24-F24 -> 64.2
D25: AGUA | E25: 16.6 | G25: =+G24+E25-F25 -> 80.8
D26: G. ADM | E26: 60 | G26: =+G25+E26-F26 -> 140.8
D27: P. SOCIAL | E27: 2 | G27: =+G26+E27-F27 -> 142.8
A28: 42891 | B28: 13051 | C28: MARZO | D28: LUZ | F28: 64.2 | G28: =+G27+E28-F28 -> 78.6
A29: 42891 | B29: 13051 | C29: MARZO | D29: AGUA | F29: 16.6 | G29: =+G28+E29-F29 -> 62
A30: 42891 | B30: 13051 | C30: MARZO | D30: P. SOCIAL | F30: 2 | G30: =+G29+E30-F30 -> 60
A31: 42891 | B31: 13051 | C31: MARZO | D31: G. ADM | F31: 60 | G31: =+G30+E31-F31 -> 0
A32: 42855 | B32: POR COBRAR | C32: ABRIL | D32: LUZ | E32: 65.7 | G32: =+G31+E32-F32 -> 65.7
D33: AGUA | E33: 16.3 | G33: =+G32+E33-F33 -> 82
D34: G. ADM | E34: 60 | G34: =+G33+E34-F34 -> 142
D35: P. SOCIAL | E35: 2 | G35: =+G34+E35-F35 -> 144
A36: 42891 | B36: 13051 | C36: ABRIL | D36: LUZ | F36: 65.7 | G36: =+G35+E36-F36 -> 78.3
A37: 42891 | B37: 13051 | C37: ABRIL | D37: AGUA | F37: 16.3 | G37: =+G36+E37-F37 -> 62
A38: 42891 | B38: 13051 | C38: ABRIL | D38: G. ADM | F38: 60 | G38: =+G37+E38-F38 -> 2
A39: 42891 | B39: 13051 | C39: ABRIL | D39: P. SOCIAL | F39: 2 | G39: =+G38+E39-F39 -> 0
A40: 42886 | B40: POR COBRAR | C40: MAYO | D40: LUZ | E40: 49.6 | G40: =+G39+E40-F40 -> 49.6
D41: AGUA | E41: 16 | G41: =+G40+E41-F41 -> 65.6
D42: G. ADM | E42: 60 | G42: =+G41+E42-F42 -> 125.6
...

Sheet MEDINA VICENTA
B2: MEDINA JOTA DE CACERES VICENTA
A4: FECHA | B4: DOCUMENTO | C4: PERIODO | D4: CONCEPTO | E4: POR COBRAR | F4: PAGADO | G4: SALDO POR COBRAR
A5: 42736 | B5: SALDO AL 2016 | G5: 56.4
A6: 42786 | B6: 12270 | C6: A CUENTA 2016 | F6: 56.4 | G6: =+G5+E6-F6 -> 0
A7: 42766 | B7: POR COBRAR | C7: ENERO | D7: LUZ | E7: 92.9 | G7: =+G6+E7-F7 -> 92.9
D8: AGUA | E8: 2.8 | G8: =+G7+E8-F8 -> 95.7
D9: G. ADM | E9: 60 | G9: =+G8+E9-F9 -> 155.7
D10: P. SOCIAL | E10: 2 | G10: =+G9+E10-F10 -> 157.7
A11: 42786 | B11: 12270 | C11: ENERO | D11: LUZ | F11: 92.9 | G11: =+G10+E11-F11 -> 64.8
A12: 42786 | B12: 12270 | C12: ENERO | D12: AGUA | F12: 2.8 | G12: =+G11+E12-F12 -> 62
A13: 42786 | B13: 12270 | C13: ENERO | D13: G. ADM | F13: 60 | G13: =+G12+E13-F13 -> 2
A14: 42786 | B14: 12270 | C14: ENERO | D14: P. SOCIAL | F14: 2 | G14: =+G13+E14-F14 -> -1.4210855e-14
A15: 42794 | B15: POR COBRAR | C15: FEBRERO | D15: LUZ | E15: 94.5 | G15: =+G14+E15-F15 -> 94.5
D16: AGUA | E16: 2 | G16: =+G15+E16-F16 -> 96.5
D17: G. ADM | E17: 56 | G17: =+G16+E17-F17 -> 152.5
D18: P. SOCIAL | E18: 2 | G18: =+G17+E18-F18 -> 154.5
A19: 42822 | B19: 12604 | C19: FEBRERO | D19: LUZ | F19: 94.5 | G19: =+G18+E19-F19 -> 60
A20: 42822 | B20: 12604 | C20: FEBRERO | D20: AGUA | F20: 2 | G20: =+G19+E20-F20 -> 58
A21: 42822 | B21: 12604 | C21: FEBRERO | D21: G. ADM | F21: 56 | G21: =+G20+E21-F21 -> 2
A22: 42822 | B22: 12604 | C22: FEBRERO | D22: P. SOCIAL | F22: 2 | G22: =+G21+E22-F22 -> 0
A23: 42825 | B23: POR COBRAR | C23: MARZO | D23: LUZ | E23: 81.5 | G23: =+G22+E23-F23 -> 81.5
D24: AGUA | E24: 2 | G24: =+G23+E24-F24 -> 83.5
D25: G. ADM | E25: 60 | G25: =+G24+E25-F25 -> 143.5
D26: P. SOCIAL | E26: 2 | G26: =+G25+E26-F26 -> 145.5
A27: 42885 | B27: 12869 | C27: MARZO | D27: LUZ | F27: 81.5 | G27: =+G26+E27-F27 -> 64
A28: 42885 | B28: 12869 | C28: MARZO | D28: AGUA | F28: 2 | G28: =+G27+E28-F28 -> 62
A29: 42885 | B29: 12869 | C29: MARZO | D29: G. ADM | F29: 60 | G29: =+G28+E29-F29 -> 2
A30: 42885 | B30: 12869 | C30: MARZO | D30: P. SOCIAL | F30: 2 | G30: =+G29+E30-F30 -> 0
A31: 42855 | B31: POR COBRAR | C31: ABRIL | D31: LUZ | E31: 84.1 | G31: =+G30+E31-F31 -> 84.1
D32: AGUA | E32: 2 | G32: =+G31+E32-F32 -> 86.1
D33: G. ADM | E33: 60 | G33: =+G32+E33-F33 -> 146.1
D34: P. SOCIAL | E34: 2 | G34: =+G33+E34-F34 -> 148.1
A35: 42885 | B35: 12869 | C35: ABRIL | D35: LUZ | F35: 84.1 | G35: =+G34+E35-F35 -> 64
A36: 42885 | B36: 12869 | C36: ABRIL | D36: AGUA | F36: 2 | G36: =+G35+E36-F36 -> 62
A37: 42885 | B37: 12869 | C37: ABRIL | D37: G. ADM | F37: 60 | G37: =+G36+E37-F37 -> 2
A38: 42885 | B38: 12869 | C38: ABRIL | D38: P. SOCIAL | F38: 2 | G38: =+G37+E38-F38 -> 0
A39: 42886 | B39: POR COBRAR | C39: MAYO | D39: LUZ | E39: 79.5 | G39: =+G38+E39-F39 -> 79.5
D40: AGUA | E40: 2 | G40: =+G39+E40-F40 -> 81.5
D41: G. ADM | E41: 60 | G41: =+G40+E41-F41 -> 141.5
D42: P. SOCIAL | E42: 2 | G42: =+G41+E42-F42 -> 143.5
...

Sheet MEDINA JUAN CARLOS
B2: MEDINA MEDRANO JUAN CARLOS
A4: FECHA | B4: DOCUMENTO | C4: PERIODO | D4: CONCEPTO | E4: POR COBRAR | F4: PAGADO | G4: SALDO POR COBRAR
A5: 42736 | B5: SALDO AL 2016 | G5: 128.6
A6: 42786 | B6: 12246 | C6: A CUENTA 2016 | F6: 16 | G6: =+G5+E6-F6 -> 112.6
A7: 42782 | B7: 12961 | C7: A CUENTA 2016 | F7: 40.6 | G7: =+G6+E7-F7 -> 72
A8: 42844 | B8: 12653 | C8: A CUENTA 2016 | F8: 8 | G8: =+G7+E8-F8 -> 64
A9: 42884 | B9: 12841 | C9: A CUENTA 2016 | F9: 8 | G9: =+G8+E9-F9 -> 56
A10: 42860 | B10: 12727 | C10: A CUENTA 2016 | F10: 8 | G10: =+G9+E10-F10 -> 48
A11: 42933 | B11: 13212 | C11: A CUENTA 2016 | F11: 8 | G11: =+G10+E11-F11 -> 40
A12: 42949 | B12: 13326 | C12: A CUENTA 2016 | F12: 8 | G12: =+G11+E12-F12 -> 32
A13: 42986 | B13: 13556 | C13: A CUENTA 2016 | F13: 8 | G13: =+G12+E13-F13 -> 24
A14: 42999 | B14: 13642 | C14: A CUENTA 2016 | F14: 8 | G14: =+G13+E14-F14 -> 16
A15: 43046 | B15: 13941 | C15: A CUENTA 2016 | F15: 8 | G15: =+G14+E15-F15 -> 8
A16: 43066 | B16: 14112 | C16: CANCELACION 2016 | F16: 8 | G16: =+G15+E16-F16 -> 0
A17: 42766 | B17: POR COBRAR | C17: ENERO | D17: LUZ | E17: 36.9 | G17: =+G16+E17-F17 -> 36.9
D18: AGUA | E18: 2.8 | G18: =+G17+E18-F18 -> 39.7
D19: G. ADM | E19: 60 | G19: =+G18+E19-F19 -> 99.7
D20: P. SOCIAL | E20: 2 | G20: =+G19+E20-F20 -> 101.7
A21: 42765 | B21: TARJETA | C21: ENERO | D21: G. ADM | F21: 60 | G21: =+G20+E21-F21 -> 41.7
A22: 42765 | B22: TARJETA | C22: ENERO | D22: P. SOCIAL | F22: 2 | G22: =+G21+E22-F22 -> 39.7
A23: 42786 | B23: 12246 | C23: ENERO | D23: LUZ | F23: 36.9 | G23: =+G22+E23-F23 -> 2.8
A24: 42786 | B24: 12246 | C24: ENERO | D24: AGUA | F24: 2.8 | G24: =+G23+E24-F24 -> -9.7699626e-15
A25: 42794 | B25: POR COBRAR | C25: FEBRERO | D25: LUZ | E25: 37.3 | G25: =+G24+E25-F25 -> 37.3
D26: AGUA | E26: 2 | G26: =+G25+E26-F26 -> 39.3
D27: G. ADM | E27: 56 | G27: =+G26+E27-F27 -> 95.3
D28: P. SOCIAL | E28: 2 | G28: =+G27+E28-F28 -> 97.3
A29: 42794 | B29: TARJETA | C29: FEBRERO | D29: G. ADM | F29: 56 | G29: =+G28+E29-F29 -> 41.3
A30: 42794 | B30: TARJETA | C30: FEBRERO | D30: P. SOCIAL | F30: 2 | G30: =+G29+E30-F30 -> 39.3
A31: 42844 | B31: 12653 | C31: FEBRERO | D31: LUZ | F31: 37.3 | G31: =+G30+E31-F31 -> 2
A32: 42844 | B32: 12653 | C32: FEBRERO | D32: AGUA | F32: 2 | G32: =+G31+E32-F32 -> -1.4210855e-14
A33: 42825 | B33: POR COBRAR | C33: MARZO | D33: LUZ | E33: 35.4 | G33: =+G32+E33-F33 -> 35.4
D34: AGUA | E34: 2 | G34: =+G33+E34-F34 -> 37.4
D35: G. ADM | E35: 60 | G35: =+G34+E35-F35 -> 97.4
D36: P. SOCIAL | E36: 2 | G36: =+G35+E36-F36 -> 99.4
A37: 42824 | B37: TARJETA | C37: MARZO | D37: G. ADM | F37: 60 | G37: =+G36+E37-F37 -> 39.4
A38: 42824 | B38: TARJETA | C38: MARZO | D38: P. SOCIAL | F38: 2 | G38: =+G37+E38-F38 -> 37.4
A39: 42860 | B39: 12727 | C39: MARZO | D39: LUZ | F39: 35.4 | G39: =+G38+E39-F39 -> 2
A40: 42860 | B40: 12727 | C40: MARZO | D40: AGUA | F40: 2 | G40: =+G39+E40-F40 -> -2.1316282e-14
A41: 42855 | B41: POR COBRAR | C41: ABRIL | D41: LUZ | E41: 36.7 | G41: =+G40+E41-F41 -> 36.7
D42: AGUA | E42: 2 | G42: =+G41+E42-F42 -> 38.7
...

Sheet MELO MARINA 
B2: MELO BACA MARINA
A4: FECHA | B4: DOCUMENTO | C4: PERIODO | D4: CONCEPTO | E4: POR COBRAR | F4: PAGADO | G4: SALDO POR COBRAR
A5: 42736 | B5: SALDO AL 2016 | G5: 1931.4
A6: 42745 | B6: 12099 | C6: A CUENTA 2016 | F6: 368.7 | G6: =+G5+E6-F6 -> 1562.7
A7: 43021 | B7: 13825 | C7: CANCELACION 2016 | F7: 1562.7 | G7: =+G6+E7-F7 -> 0
A8: 42766 | B8: POR COBRAR | C8: ENERO | D8: LUZ | E8: 110.4 | G8: =+G7+E8-F8 -> 110.4
D9: AGUA | E9: 40.1 | G9: =+G8+E9-F9 -> 150.5
D10: G. ADM | E10: 60 | G10: =+G9+E10-F10 -> 210.5
D11: P. SOCIAL | E11: 2 | G11: =+G10+E11-F11 -> 212.5
A12: 42765 | B12: TARJETA | D12: G. ADM | F12: 60 | G12: =+G11+E12-F12 -> 152.5
A13: 42765 | B13: TARJETA | D13: P. SOCIAL | F13: 2 | G13: =+G12+E13-F13 -> 150.5
A14: 42787 | B14: 12325 | C14: ENERO | D14: LUZ | F14: 110.4 | G14: =+G13+E14-F14 -> 40.1
A15: 42787 | B15: 12325 | C15: ENERO | D15: AGUA | F15: 40.1 | G15: =+G14+E15-F15 -> 0
A16: 42794 | B16: POR COBRAR | C16: FEBRERO | D16: LUZ | E16: 127.9 | G16: =+G15+E16-F16 -> 127.9
D17: AGUA | E17: 27 | G17: =+G16+E17-F17 -> 154.9
D18: G. ADM | E18: 56 | G18: =+G17+E18-F18 -> 210.9
D19: P. SOCIAL | E19: 2 | G19: =+G18+E19-F19 -> 212.9
D20: MULTA | E20: 85 | G20: =+G19+E20-F20 -> 297.9
A21: 42794 | B21: TARJETA | D21: G. ADM | F21: 56 | G21: =+G20+E21-F21 -> 241.9
A22: 42794 | B22: TARJETA | D22: P. SOCIAL | F22: 2 | G22: =+G21+E22-F22 -> 239.9
A23: 42818 | B23: 12468 | C23: FEBRERO | D23: LUZ | F23: 127.9 | G23: =+G22+E23-F23 -> 112
A24: 42818 | B24: 12468 | C24: FEBRERO | D24: AGUA | F24: 27 | G24: =+G23+E24-F24 -> 85
A25: 43021 | B25: 13825 | C25: FEBRERO | D25: MULTA | F25: 85 | G25: =+G24+E25-F25 -> 0
A26: 42825 | B26: POR COBRAR | C26: MARZO | D26: LUZ | E26: 122.8 | G26: =+G25+E26-F26 -> 122.8
D27: AGUA | E27: 28.5 | G27: =+G26+E27-F27 -> 151.3
D28: G. ADM | E28: 60 | G28: =+G27+E28-F28 -> 211.3
D29: P. SOCIAL | E29: 2 | G29: =+G28+E29-F29 -> 213.3
A30: 42825 | B30: TARJETA | D30: G. ADM | F30: 60 | G30: =+G29+E30-F30 -> 153.3
A31: 42825 | B31: TARJETA | D31: P. SOCIAL | F31: 2 | G31: =+G30+E31-F31 -> 151.3
A32: 42863 | B32: 12731 | C32: MARZO | D32: LUZ | F32: 122.8 | G32: =+G31+E32-F32 -> 28.5
A33: 42863 | B33: 12731 | C33: MARZO | D33: AGUA | F33: 28.2 | G33: =+G32+E33-F33 -> 0.3
A34: 43021 | B34: 13825 | C34: MARZO | D34: AGUA | F34: 0.3 | G34: =+G33+E34-F34 -> 1.49325e-14
A35: 42855 | B35: POR COBRAR | C35: ABRIL | D35: LUZ | E35: 124.8 | G35: =+G34+E35-F35 -> 124.8
D36: AGUA | E36: 28 | G36: =+G35+E36-F36 -> 152.8
D37: G. ADM | E37: 60 | G37: =+G36+E37-F37 -> 212.8
D38: P. SOCIAL | E38: 2 | G38: =+G37+E38-F38 -> 214.8
A39: 42854 | B39: TARJETA | D39: G. ADM | F39: 60 | G39: =+G38+E39-F39 -> 154.8
A40: 42854 | B40: TARJETA | D40: P. SOCIAL | F40: 2 | G40: =+G39+E40-F40 -> 152.8
A41: 42909 | B41: 13148 | C41: ABRIL | D41: LUZ | F41: 124.8 | G41: =+G40+E41-F41 -> 28
A42: 42909 | B42: 13148 | C42: ABRIL | D42: AGUA | F42: 28 | G42: =+G41+E42-F42 -> 0
...

Sheet MESIA GLADYS
B2: MESIA CRUZ GLADYS
A4: FECHA | B4: DOCUMENTO | C4: PERIODO | D4: CONCEPTO | E4: POR COBRAR | F4: PAGADO | G4: SALDO POR COBRAR
A5: 42736 | B5: SALDO AL 2016 | G5: 6205.7
A6: 42388 | B6: 9287 | C6: A CUENTA 2016 | F6: 73.6 | G6: =+G5+E6-F6 -> 6132.1
A7: 42064 | B7: 7368 | C7: A CUENTA 2016 | F7: 7 | G7: =+G6+E7-F7 -> 6125.1
A8: 42780 | B8: 12947 | C8: A CUENTA 2016 | F8: 31.9 | G8: =+G7+E8-F8 -> 6093.2
A9: 42780 | B9: 12949 | C9: A CUENTA 2016 | F9: 80 | G9: =+G8+E9-F9 -> 6013.2
A10: 43033 | B10: 13894 | C10: A CUENTA 2016 | F10: 1860.4 | G10: =+G9+E10-F10 -> 4152.8
A11: 43068 | B11: 14200 | C11: A CUENTA 2016 | F11: 1850.3 | G11: =+G10+E11-F11 -> 2302.5
A12: 43551 | B12: DESCUENO DEL 50% CARTA N° 018 | F12: 1151.2 | G12: =+G11+E12-F12 -> 1151.3
A13: 43552 | B13: 17581 | C13: A CUENTA 2016 | F13: 1151.3 | G13: =+G12+E13-F13 -> 0
A14: 42766 | B14: POR COBRAR | C14: ENERO | D14: LUZ | E14: 28.4 | G14: =+G13+E14-F14 -> 28.4
D15: AGUA | E15: 2.8 | G15: =+G14+E15-F15 -> 31.2
D16: G. ADM | E16: 60 | G16: =+G15+E16-F16 -> 91.2
D17: P. SOCIAL | E17: 2 | G17: =+G16+E17-F17 -> 93.2
A18: 42780 | B18: 12948 | C18: ENERO | D18: G. ADM | F18: 60 | G18: =+G17+E18-F18 -> 33.2
A19: 42780 | B19: 12948 | C19: ENERO | D19: P. SOCIAL | F19: 2 | G19: =+G18+E19-F19 -> 31.2 | I19: MULTAS | J19: 2009 | K19: 220
A20: 42816 | B20: 12438 | C20: ENERO | D20: LUZ | F20: 28.4 | G20: =+G19+E20-F20 -> 2.8 | J20: 2010 | K20: 330
A21: 42816 | B21: 12438 | C21: ENERO | D21: AGUA | F21: 2.8 | G21: =+G20+E21-F21 -> 4.4408921e-15 | J21: 2011 | K21: 315
A22: 42794 | B22: POR COBRAR | C22: FEBRERO | D22: LUZ | E22: 50.6 | G22: =+G21+E22-F22 -> 50.6 | J22: 2012 | K22: 217.5
D23: AGUA | E23: 2 | G23: =+G22+E23-F23 -> 52.6 | J23: 2014 | K23: 450
D24: G. ADM | E24: 56 | G24: =+G23+E24-F24 -> 108.6 | J24: 2015 | K24: 450
D25: P. SOCIAL | E25: 2 | G25: =+G24+E25-F25 -> 110.6 | J25: 2016 | K25: 320
A26: 42780 | B26: 12948 | C26: FEBRERO | D26: G. ADM | F26: 56 | G26: =+G25+E26-F26 -> 54.6
A27: 42780 | B27: 12948 | C27: FEBRERO | D27: P. SOCIAL | F27: 2 | G27: =+G26+E27-F27 -> 52.6 | K27: =SUM(K19:K26) -> 2302.5
A28: 42816 | B28: 12439 | C28: FEBRERO | D28: LUZ | F28: 50.6 | G28: =+G27+E28-F28 -> 2
A29: 42816 | B29: 12439 | C29: FEBRERO | D29: AGUA | F29: 2 | G29: =+G28+E29-F29 -> 7.1054274e-15
A30: 42825 | B30: POR COBRAR | C30: MARZO | D30: LUZ | E30: 28.2 | G30: =+G29+E30-F30 -> 28.2
D31: AGUA | E31: 2 | G31: =+G30+E31-F31 -> 30.2
D32: G. ADM | E32: 60 | G32: =+G31+E32-F32 -> 90.2
D33: P. SOCIAL | E33: 2 | G33: =+G32+E33-F33 -> 92.2
D34: LUZ 10:00 PM | E34: 20 | G34: =+G33+E34-F34 -> 112.2
A35: 42816 | B35: 12440 | C35: MARZO | D35: G. ADM | F35: 60 | G35: =+G34+E35-F35 -> 52.2
A36: 42816 | B36: 12440 | C36: MARZO | D36: P. SOCIAL | F36: 2 | G36: =+G35+E36-F36 -> 50.2
A37: 42873 | B37: 12769 | C37: MARZO | D37: LUZ | F37: 28.2 | G37: =+G36+E37-F37 -> 22
A38: 42873 | B38: 12769 | C38: MARZO | D38: AGUA | F38: 2 | G38: =+G37+E38-F38 -> 20
A39: 43068 | B39: 14201 | C39: MARZO | D39: LUZ 10:00 PM | F39: 20 | G39: =+G38+E39-F39 -> 0
A40: 42855 | B40: POR COBRAR | C40: ABRIL | D40: LUZ | E40: 29.6 | G40: =+G39+E40-F40 -> 29.6
D41: AGUA | E41: 2 | G41: =+G40+E41-F41 -> 31.6
D42: G. ADM | E42: 60 | G42: =+G41+E42-F42 -> 91.6
...

Sheet NICHO  ESTHEPANY
B2: NICHO LOPEZ ESTHEPANY CARICIA
A4: FECHA | B4: DOCUMENTO | C4: PERIODO | D4: CONCEPTO | E4: POR COBRAR | F4: PAGADO | G4: SALDO POR COBRAR
G5: 0
A6: 45291 | B6: POR COBRAR | C6: DICIEMBRE | D6: LUZ | E6: 228 | G6: =G5+E6-F6 -> 228
D7: AGUA | E7: 59.2 | G7: =G6+E7-F7 -> 287.2
D8: G. ADM | E8: 60 | G8: =G7+E8-F8 -> 347.2
D9: P. SOCIAL | E9: 5 | G9: =G8+E9-F9 -> 352.2
A10: 45348 | B10: RI 28294 | C10: DICIEMBRE | D10: LUZ | F10: 228 | G10: =G9+E10-F10 -> 124.2
A11: 45348 | B11: RI 28294 | C11: DICIEMBRE | D11: AGUA | F11: 59.2 | G11: =G10+E11-F11 -> 65
A12: 45348 | B12: RI 28294 | C12: DICIEMBRE | D12: G. ADM | F12: 60 | G12: =G11+E12-F12 -> 5
A13: 45348 | B13: RI 28294 | C13: DICIEMBRE | D13: P. SOCIAL | F13: 5 | G13: =G12+E13-F13 -> -1.4210855e-14
A14: 45322 | B14: POR COBRAR | C14: ENERO | D14: LUZ | E14: 254.6 | G14: =G13+E14-F14 -> 254.6
D15: AGUA | E15: 70.2 | G15: =G14+E15-F15 -> 324.8
D16: G. ADM | E16: 60 | G16: =G15+E16-F16 -> 384.8
D17: P. SOCIAL | E17: 5 | G17: =G16+E17-F17 -> 389.8
D18: LIMPIEZA DE POZO SEPTICO | E18: 24.2 | G18: =G17+E18-F18 -> 414
A19: 45348 | B19: RI 28294 | C19: ENERO | D19: LUZ | F19: 254.6 | G19: =G18+E19-F19 -> 159.4
A20: 45348 | B20: RI 28294 | C20: ENERO | D20: AGUA | F20: 70.2 | G20: =G19+E20-F20 -> 89.2
A21: 45348 | B21: RI 28294 | C21: ENERO | D21: G. ADM | F21: 60 | G21: =G20+E21-F21 -> 29.2
A22: 45348 | B22: RI 28294 | C22: ENERO | D22: P. SOCIAL | F22: 5 | G22: =G21+E22-F22 -> 24.2
A23: 45358 | B23: RI 28511 | C23: ENERO | D23: LIMPIEZA DE POZO SEPTICO | F23: 24.2 | G23: =G22+E23-F23 -> -5.3290705e-14
A24: 45351 | B24: POR COBRAR | C24: FEBRERO | D24: LUZ | E24: 263.8 | G24: =G23+E24-F24 -> 263.8
D25: AGUA | E25: 59.7 | G25: =G24+E25-F25 -> 323.5
D26: G. ADM | E26: 58 | G26: =G25+E26-F26 -> 381.5
D27: P. SOCIAL | E27: 5 | G27: =G26+E27-F27 -> 386.5
A28: 45358 | B28: RI 28511 | C28: FEBRERO | D28: G. ADM | F28: 58 | G28: =G27+E28-F28 -> 328.5
A29: 45358 | B29: RI 28511 | C29: FEBRERO | D29: P. SOCIAL | F29: 5 | G29: =G28+E29-F29 -> 323.5
A30: 45376 | B30: 28609 | C30: FEBRERO | D30: LUZ | F30: 263.8 | G30: =G29+E30-F30 -> 59.7
A31: 45376 | B31: 28609 | C31: FEBRERO | D31: AGUA | F31: 59.7 | G31: =G30+E31-F31 -> -7.1054274e-14
A32: 45382 | B32: POR COBRAR | C32: MARZO | D32: LUZ | E32: 255.4 | G32: =G31+E32-F32 -> 255.4
D33: AGUA | E33: 41 | G33: =G32+E33-F33 -> 296.4
D34: G. ADM | E34: 60 | G34: =G33+E34-F34 -> 356.4
D35: P. SOCIAL | E35: 5 | G35: =G34+E35-F35 -> 361.4
A36: 45430 | B36: 28883 | C36: MARZO | D36: LUZ | F36: 255.4 | G36: =G35+E36-F36 -> 106
A37: 45430 | B37: 28883 | C37: MARZO | D37: AGUA | F37: 41 | G37: =G36+E37-F37 -> 65
A38: 45430 | B38: 28883 | C38: MARZO | D38: G. ADM | F38: 60 | G38: =G37+E38-F38 -> 5
A39: 45430 | B39: 28883 | C39: MARZO | D39: P. SOCIAL | F39: 5 | G39: =G38+E39-F39 -> -8.5265128e-14
A40: 45412 | B40: POR COBRAR | C40: ABRIL | D40: LUZ | E40: 253.9 | G40: =G39+E40-F40 -> 253.9
D41: AGUA | E41: 44.5 | G41: =G40+E41-F41 -> 298.4
D42: G. ADM | E42: 60 | G42: =G41+E42-F42 -> 358.4
...

Sheet ÑAHUI AURELIO
B2: ÑAHUI RUIZ AURELIO
A4: FECHA | B4: DOCUMENTO | C4: PERIODO | D4: CONCEPTO | E4: POR COBRAR | F4: PAGADO | G4: SALDO POR COBRAR
A5: 42736 | B5: SALDO AL 2016 | G5: 247.3
A6: 42751 | B6: 12110 | C6: CANCELACION DEL 2016 | F6: 247.3 | G6: =+G5+E6-F6 -> 0
A7: 42766 | B7: POR COBRAR | C7: ENERO | D7: LUZ | E7: 63.9 | G7: =+G6+E7-F7 -> 63.9
D8: AGUA | E8: 2.8 | G8: =+G7+E8-F8 -> 66.7
D9: G. ADM | E9: 60 | G9: =+G8+E9-F9 -> 126.7
D10: P. SOCIAL | E10: 2 | G10: =+G9+E10-F10 -> 128.7
A11: 42786 | B11: 12310 | C11: ENERO | D11: G. ADM | F11: 60 | G11: =+G10+E11-F11 -> 68.7
A12: 42786 | B12: 12310 | C12: ENERO | D12: P. SOCIAL | F12: 2 | G12: =+G11+E12-F12 -> 66.7
A13: 42786 | B13: 12310 | C13: ENERO | D13: LUZ | F13: 38 | G13: =+G12+E13-F13 -> 28.7
A14: 42787 | B14: 12346 | C14: ENERO | D14: LUZ | F14: 25.9 | G14: =+G13+E14-F14 -> 2.8
A15: 42787 | B15: 12346 | C15: ENERO | D15: AGUA | F15: 2.8 | G15: =+G14+E15-F15 -> -9.7699626e-15
A16: 42794 | B16: POR COBRAR | C16: FEBRERO | D16: LUZ | E16: 61.4 | G16: =+G15+E16-F16 -> 61.4
D17: AGUA | E17: 2 | G17: =+G16+E17-F17 -> 63.4
D18: G. ADM | E18: 56 | G18: =+G17+E18-F18 -> 119.4
D19: P. SOCIAL | E19: 2 | G19: =+G18+E19-F19 -> 121.4
A20: 42821 | B20: 12487 | C20: FEBRERO | D20: LUZ | F20: 61.4 | G20: =+G19+E20-F20 -> 60
A21: 42821 | B21: 12487 | C21: FEBRERO | D21: AGUA | F21: 2 | G21: =+G20+E21-F21 -> 58
A22: 42821 | B22: 12487 | C22: FEBRERO | D22: G. ADM | F22: 56 | G22: =+G21+E22-F22 -> 2
A23: 42821 | B23: 12487 | C23: FEBRERO | D23: P. SOCIAL | F23: 2 | G23: =+G22+E23-F23 -> -7.1054274e-15
A24: 42825 | B24: POR COBRAR | C24: MARZO | D24: LUZ | E24: 58.1 | G24: =+G23+E24-F24 -> 58.1
D25: AGUA | E25: 2 | G25: =+G24+E25-F25 -> 60.1
D26: G. ADM | E26: 60 | G26: =+G25+E26-F26 -> 120.1
D27: P. SOCIAL | E27: 2 | G27: =+G26+E27-F27 -> 122.1
A28: 42847 | B28: 12687 | C28: MARZO | D28: LUZ | F28: 58.1 | G28: =+G27+E28-F28 -> 64
A29: 42847 | B29: 12687 | C29: MARZO | D29: AGUA | F29: 2 | G29: =+G28+E29-F29 -> 62
A30: 42847 | B30: 12687 | C30: MARZO | D30: G. ADM | F30: 60 | G30: =+G29+E30-F30 -> 2
A31: 42847 | B31: 12687 | C31: MARZO | D31: P. SOCIAL | F31: 2 | G31: =+G30+E31-F31 -> -7.1054274e-15
A32: 42855 | B32: POR COBRAR | C32: ABRIL | D32: LUZ | E32: 60.4 | G32: =+G31+E32-F32 -> 60.4
D33: AGUA | E33: 2 | G33: =+G32+E33-F33 -> 62.4
D34: G. ADM | E34: 60 | G34: =+G33+E34-F34 -> 122.4
D35: P. SOCIAL | E35: 2 | G35: =+G34+E35-F35 -> 124.4
A36: 42887 | B36: 13026 | C36: ABRIL | D36: AGUA | F36: 2 | G36: =+G35+E36-F36 -> 122.4
A37: 42887 | B37: 13026 | C37: ABRIL | D37: LUZ | F37: 60.4 | G37: =+G36+E37-F37 -> 62
A38: 42887 | B38: 13026 | C38: ABRIL | D38: P. SOCIAL | F38: 2 | G38: =+G37+E38-F38 -> 60
A39: 42887 | B39: 13026 | C39: ABRIL | D39: G. ADM | F39: 60 | G39: =+G38+E39-F39 -> 0
A40: 42886 | B40: POR COBRAR | C40: MAYO | D40: LUZ | E40: 57.7 | G40: =+G39+E40-F40 -> 57.7
D41: AGUA | E41: 2 | G41: =+G40+E41-F41 -> 59.7
D42: G. ADM | E42: 60 | G42: =+G41+E42-F42 -> 119.7
...

Sheet OJEDA EDSON
B3: OJEDA CAMPOS EDSON
A5: FECHA | B5: DOCUMENTO | C5: PERIODO | D5: CONCEPTO | E5: POR COBRAR | F5: PAGADO | G5: SALDO POR COBRAR
A6: 42736 | B6: SALDO AL 2016 | G6: 1092.8
A7: 42887 | E7: 10 | G7: =+G6+E7-F7 -> 1102.8
A8: 43068 | B8: 14204 | C8: A CUENTA 2016 | F8: 262.5 | G8: =+G7+E8-F8 -> 840.3
A9: 43530 | B9: 17296 | C9: A CUENTA 2016 | F9: 500 | G9: =+G8+E9-F9 -> 340.3
A10: 43545 | B10: 17366 | C10: A CUENTA 2016 | F10: 134.6 | G10: =+G9+E10-F10 -> 205.7
A11: 43587 | B11: 17716 | C11: CANCELACION 2016 | F11: 205.7 | G11: =+G10+E11-F11 -> 0
A12: 42766 | B12: POR COBRAR | C12: ENERO | D12: LUZ | E12: 192.1 | G12: =+G11+E12-F12 -> 192.1
D13: AGUA | E13: 21 | G13: =+G12+E13-F13 -> 213.1
D14: G. ADM | E14: 60 | G14: =+G13+E14-F14 -> 273.1
D15: P. SOCIAL | E15: 2 | G15: =+G14+E15-F15 -> 275.1
A16: 42765 | B16: TARJETA | C16: ENERO | D16: LUZ | F16: 192.1 | G16: =+G15+E16-F16 -> 83
A17: 42765 | B17: TARJETA | C17: ENERO | D17: AGUA | F17: 17.9 | G17: =+G16+E17-F17 -> 65.1
A18: 42765 | B18: TARJETA | C18: ENERO | D18: G. ADM | F18: 42 | G18: =+G17+E18-F18 -> 23.1
A19: 42855 | B19: TARJETA | C19: ENERO | D19: AGUA | F19: 0.6 | G19: =+G18+E19-F19 -> 22.5
A20: 42886 | B20: TARJETA | C20: ENERO | D20: AGUA | F20: 2.5 | G20: =+G19+E20-F20 -> 20
A21: 42886 | B21: TARJETA | C21: ENERO | D21: P. SOCIAL | F21: 2 | G21: =+G20+E21-F21 -> 18
A22: 43008 | B22: TARJETA | C22: ENERO | D22: G. ADM | F22: 18 | G22: =+G21+E22-F22 -> 0
A23: 42794 | B23: POR COBRAR | C23: FEBRERO | D23: LUZ | E23: 228.5 | G23: =+G22+E23-F23 -> 228.5
D24: AGUA | E24: 13.5 | G24: =+G23+E24-F24 -> 242
D25: G. ADM | E25: 56 | G25: =+G24+E25-F25 -> 298
D26: P. SOCIAL | E26: 2 | G26: =+G25+E26-F26 -> 300
D27: MULTA | E27: 85 | G27: =+G26+E27-F27 -> 385
A28: 42794 | B28: TARJETA | C28: FEBRERO | D28: LUZ | F28: 228.5 | G28: =+G27+E28-F28 -> 156.5
A29: 42794 | B29: TARJETA | C29: FEBRERO | D29: AGUA | F29: 1.5 | G29: =+G28+E29-F29 -> 155
A30: 42794 | B30: TARJETA | C30: FEBRERO | D30: G. ADM | F30: 46 | G30: =+G29+E30-F30 -> 109
A31: 42886 | B31: TARJETA | C31: FEBRERO | D31: AGUA | F31: 12 | G31: =+G30+E31-F31 -> 97
A32: 42886 | B32: TARJETA | C32: FEBRERO | D32: P. SOCIAL | F32: 2 | G32: =+G31+E32-F32 -> 95
A33: 43008 | B33: TARJETA | C33: FEBRERO | D33: G. ADM | F33: 10 | G33: =+G32+E33-F33 -> 85
A34: 43587 | B34: 17716 | C34: FEBRERO | D34: MULTA | F34: 85 | G34: =+G33+E34-F34 -> 0
A35: 42825 | B35: POR COBRAR | C35: MARZO | D35: LUZ | E35: 219.7 | G35: =+G34+E35-F35 -> 219.7
D36: AGUA | E36: 14 | G36: =+G35+E36-F36 -> 233.7
D37: G. ADM | E37: 60 | G37: =+G36+E37-F37 -> 293.7
D38: P. SOCIAL | E38: 2 | G38: =+G37+E38-F38 -> 295.7
A39: 42824 | B39: TARJETA | C39: MARZO | D39: LUZ | F39: 219.7 | G39: =+G38+E39-F39 -> 76
A40: 42824 | B40: TARJETA | C40: MARZO | D40: AGUA | F40: 10.3 | G40: =+G39+E40-F40 -> 65.7
A41: 42824 | B41: TARJETA | C41: MARZO | D41: G. ADM | F41: 46 | G41: =+G40+E41-F41 -> 19.7
A42: 42855 | B42: TARJETA | C42: MARZO | D42: AGUA | F42: 3.7 | G42: =+G41+E42-F42 -> 16
A43: 42886 | B43: TARJETA | C43: MARZO | D43: P. SOCIAL | F43: 2 | G43: =+G42+E43-F43 -> 14
...

Sheet OQUENDO MELESIA
B2: OQUENDO ARISACA MELESIA ROSARIO
A4: FECHA | B4: DOCUMENTO | C4: PERIODO | D4: CONCEPTO | E4: POR COBRAR | F4: PAGADO | G4: SALDO POR COBRAR
A5: 42736 | B5: SALDO AL 2016 | G5: 104.9
A6: 42773 | B6: 12967 | C6: A CUENTA 2016 | F6: 104.9 | G6: =+G5+E6-F6 -> 0
A7: 42766 | B7: POR COBRAR | C7: ENERO | D7: LUZ | E7: 35 | G7: =+G6+E7-F7 -> 35
D8: AGUA | E8: 2.8 | G8: =+G7+E8-F8 -> 37.8
D9: G. ADM | E9: 60 | G9: =+G8+E9-F9 -> 97.8
D10: P. SOCIAL | E10: 2 | G10: =+G9+E10-F10 -> 99.8
A11: 42766 | B11: TARJETA | C11: ENERO | D11: G. ADM | F11: 60 | G11: =+G10+E11-F11 -> 39.8
A12: 42766 | B12: TARJETA | C12: ENERO | D12: P. SOCIAL | F12: 2 | G12: =+G11+E12-F12 -> 37.8
A13: 42786 | B13: 12227 | C13: ENERO | D13: LUZ | F13: 35 | G13: =+G12+E13-F13 -> 2.8
A14: 42786 | B14: 12227 | C14: ENERO | D14: AGUA | F14: 2.8 | G14: =+G13+E14-F14 -> 0
A15: 42794 | B15: POR COBRAR | C15: FEBRERO | D15: LUZ | E15: 13 | G15: =+G14+E15-F15 -> 13
D16: AGUA | E16: 2 | G16: =+G15+E16-F16 -> 15
D17: G. ADM | E17: 56 | G17: =+G16+E17-F17 -> 71
D18: P. SOCIAL | E18: 2 | G18: =+G17+E18-F18 -> 73
A19: 42780 | B19: TARJETA | C19: FEBRERO | D19: G. ADM | F19: 20 | G19: =+G18+E19-F19 -> 53
A20: 42822 | B20: 12576 | C20: FEBRERO | D20: LUZ | F20: 13 | G20: =+G19+E20-F20 -> 40
A21: 42822 | B21: 12576 | C21: FEBRERO | D21: AGUA | F21: 2 | G21: =+G20+E21-F21 -> 38
A22: 42822 | B22: 12576 | C22: FEBRERO | D22: G. ADM | F22: 36 | G22: =+G21+E22-F22 -> 2
A23: 42822 | B23: 12576 | C23: FEBRERO | D23: P. SOCIAL | F23: 2 | G23: =+G22+E23-F23 -> 0
A24: 42825 | B24: POR COBRAR | C24: MARZO | D24: LUZ | E24: 29 | G24: =+G23+E24-F24 -> 29
D25: AGUA | E25: 2 | G25: =+G24+E25-F25 -> 31
D26: G. ADM | E26: 60 | G26: =+G25+E26-F26 -> 91
D27: P. SOCIAL | E27: 2 | G27: =+G26+E27-F27 -> 93
A28: 42823 | B28: TARJETA | C28: MARZO | D28: G. ADM | F28: 63 | G28: =+G27+E28-F28 -> 30
A29: 42823 | B29: TARJETA | C29: MARZO | D29: P. SOCIAL | F29: 2 | G29: =+G28+E29-F29 -> 28
A30: 42885 | B30: 12875 | C30: MARZO | D30: LUZ | F30: 26 | G30: =+G29+E30-F30 -> 2
A31: 42885 | B31: 12875 | C31: MARZO | D31: AGUA | F31: 2 | G31: =+G30+E31-F31 -> 0
A32: 42855 | B32: POR COBRAR | C32: ABRIL | D32: LUZ | E32: 30.2 | G32: =+G31+E32-F32 -> 30.2
D33: AGUA | E33: 2 | G33: =+G32+E33-F33 -> 32.2
D34: G. ADM | E34: 60 | G34: =+G33+E34-F34 -> 92.2
D35: P. SOCIAL | E35: 2 | G35: =+G34+E35-F35 -> 94.2
D36: CAMBIO DE GIRO | E36: 300 | G36: =+G35+E36-F36 -> 394.2
A37: 42855 | B37: TARJETA | C37: ABRIL | D37: G. ADM | F37: 60 | G37: =+G36+E37-F37 -> 334.2
A38: 42828 | B38: TARJETA | C38: ABRIL | D38: P. SOCIAL | F38: 2 | G38: =+G37+E38-F38 -> 332.2
A39: 42885 | B39: 12875 | C39: ABRIL | D39: LUZ | F39: 30.2 | G39: =+G38+E39-F39 -> 302
A40: 42885 | B40: 12875 | C40: ABRIL | D40: AGUA | F40: 2 | G40: =+G39+E40-F40 -> 300
A41: 42830 | B41: 12631 | C41: ABRIL | D41: CAMBIO DE GIRO | F41: 300 | G41: =+G40+E41-F41 -> 0
A42: 42886 | B42: POR COBRAR | C42: MAYO | D42: LUZ | E42: 28.8 | G42: =+G41+E42-F42 -> 28.8
...

Sheet OQUENDO JESSICA
B2: OQUENDO QUISPE JESSICA
A4: FECHA | B4: DOCUMENTO | C4: PERIODO | D4: CONCEPTO | E4: POR COBRAR | F4: PAGADO | G4: SALDO POR COBRAR
A5: 42736 | B5: SALDO AL 2016 | G5: 113.1
A6: 42762 | B6: 12168 | C6: A CUENTA 2016 | F6: 113.1 | G6: =+G5+E6-F6 -> 0
A7: 42766 | B7: POR COBRAR | C7: ENERO | D7: LUZ | E7: 13.5 | G7: =+G6+E7-F7 -> 13.5
D8: AGUA | E8: 2.8 | G8: =+G7+E8-F8 -> 16.3
D9: G. ADM | E9: 60 | G9: =+G8+E9-F9 -> 76.3
D10: P. SOCIAL | E10: 2 | G10: =+G9+E10-F10 -> 78.3
A11: 42765 | B11: TARJETA | C11: ENERO | D11: G. ADM | F11: 60 | G11: =+G10+E11-F11 -> 18.3
A12: 42765 | B12: TARJETA | C12: ENERO | D12: P. SOCIAL | F12: 2 | G12: =+G11+E12-F12 -> 16.3
A13: 42786 | B13: 12295 | C13: ENERO | D13: LUZ | F13: 13.5 | G13: =+G12+E13-F13 -> 2.8
A14: 42786 | B14: 12295 | C14: ENERO | D14: AGUA | F14: 2.8 | G14: =+G13+E14-F14 -> 0
A15: 42794 | B15: POR COBRAR | C15: FEBRERO | D15: LUZ | E15: 13 | G15: =+G14+E15-F15 -> 13
D16: AGUA | E16: 2 | G16: =+G15+E16-F16 -> 15
D17: G. ADM | E17: 56 | G17: =+G16+E17-F17 -> 71
D18: P. SOCIAL | E18: 2 | G18: =+G17+E18-F18 -> 73
A19: 42794 | B19: TARJETA | C19: FEBRERO | D19: G. ADM | F19: 56 | G19: =+G18+E19-F19 -> 17
A20: 42794 | B20: TARJETA | C20: FEBRERO | D20: P. SOCIAL | F20: 2 | G20: =+G19+E20-F20 -> 15
A21: 42821 | B21: 12551 | C21: FEBRERO | D21: LUZ | F21: 13 | G21: =+G20+E21-F21 -> 2
A22: 42793 | B22: 12551 | C22: FEBRERO | D22: AGUA | F22: 2 | G22: =+G21+E22-F22 -> 0
A23: 42825 | B23: POR COBRAR | C23: MARZO | D23: LUZ | E23: 12 | G23: =+G22+E23-F23 -> 12
D24: AGUA | E24: 2 | G24: =+G23+E24-F24 -> 14
D25: G. ADM | E25: 60 | G25: =+G24+E25-F25 -> 74
D26: P. SOCIAL | E26: 2 | G26: =+G25+E26-F26 -> 76
A27: 42824 | B27: TARJETA | C27: MARZO | D27: G. ADM | F27: 60 | G27: =+G26+E27-F27 -> 16
A28: 42824 | B28: TARJETA | C28: MARZO | D28: P. SOCIAL | F28: 2 | G28: =+G27+E28-F28 -> 14
A29: 42864 | B29: 12738 | C29: MARZO | D29: LUZ | F29: 12 | G29: =+G28+E29-F29 -> 2
A30: 42864 | B30: 12738 | C30: MARZO | D30: AGUA | F30: 2 | G30: =+G29+E30-F30 -> 0
A31: 42855 | B31: POR COBRAR | C31: ABRIL | D31: LUZ | E31: 13 | G31: =+G30+E31-F31 -> 13
D32: AGUA | E32: 2 | G32: =+G31+E32-F32 -> 15
D33: G. ADM | E33: 60 | G33: =+G32+E33-F33 -> 75
D34: P. SOCIAL | E34: 2 | G34: =+G33+E34-F34 -> 77
A35: 42854 | B35: TARJETA | C35: ABRIL | D35: G. ADM | F35: 60 | G35: =+G34+E35-F35 -> 17
A36: 42854 | B36: TARJETA | C36: ABRIL | D36: P. SOCIAL | F36: 2 | G36: =+G35+E36-F36 -> 15
A37: 42887 | B37: 13022 | C37: ABRIL | D37: LUZ | F37: 13 | G37: =+G36+E37-F37 -> 2
A38: 42887 | B38: 13022 | C38: ABRIL | D38: AGUA | F38: 2 | G38: =+G37+E38-F38 -> 0
A39: 42886 | B39: POR COBRAR | C39: MAYO | D39: LUZ | E39: 13 | G39: =+G38+E39-F39 -> 13
D40: AGUA | E40: 2 | G40: =+G39+E40-F40 -> 15
D41: G. ADM | E41: 60 | G41: =+G40+E41-F41 -> 75
D42: P. SOCIAL | E42: 2 | G42: =+G41+E42-F42 -> 77
...

Sheet OQUENDO MIGUEL
B2: OQUENDO QUISPE MIGUEL
A4: FECHA | B4: DOCUMENTO | C4: PERIODO | D4: CONCEPTO | E4: POR COBRAR | F4: PAGADO | G4: SALDO POR COBRAR
A5: 42736 | B5: SALDO AL 2016 | G5: 1378.4
A6: 42786 | B6: 12275 | C6: A CUENTA DEL 2016 | F6: 62.4 | G6: =+G5+E6-F6 -> 1316
A7: 42786 | B7: 12276 | C7: A CUENTA DEL 2016 | F7: 321 | G7: =+G6+E7-F7 -> 995
A8: 42786 | B8: 12280 | C8: A CUENTA DEL 2016 | F8: 225 | G8: =+G7+E8-F8 -> 770
A9: 42786 | B9: 12281 | C9: A CUENTA DEL 2016 | F9: 450 | G9: =+G8+E9-F9 -> 320
A10: 42793 | B10: 12374 | C10: A CUENTA DEL 2016 | F10: 320 | G10: =+G9+E10-F10 -> 0
A11: 42766 | B11: POR COBRAR | C11: ENERO | D11: LUZ | E11: 13.5 | G11: =+G10+E11-F11 -> 13.5
D12: AGUA | E12: 2.8 | G12: =+G11+E12-F12 -> 16.3
D13: G. ADM | E13: 60 | G13: =+G12+E13-F13 -> 76.3
D14: P. SOCIAL | E14: 2 | G14: =+G13+E14-F14 -> 78.3
D15: P. SOCIAL XFALL. | E15: 10 | G15: =+G14+E15-F15 -> 88.3
A16: 42786 | B16: 12276 | C16: ENERO | D16: G. ADM | F16: 60 | G16: =+G15+E16-F16 -> 28.3
A17: 42786 | B17: 12276 | C17: ENERO | D17: P. SOCIAL | F17: 2 | G17: =+G16+E17-F17 -> 26.3
A18: 42793 | B18: 12373 | C18: ENERO | D18: P. SOCIAL XFALL. | F18: 10 | G18: =+G17+E18-F18 -> 16.3
A19: 42786 | B19: 12275 | C19: ENERO | D19: AGUA | F19: 2.8 | G19: =+G18+E19-F19 -> 13.5
A20: 42786 | B20: 12275 | C20: ENERO | D20: LUZ | F20: 13.5 | G20: =+G19+E20-F20 -> 0
A21: 42794 | B21: POR COBRAR | C21: FEBRERO | D21: LUZ | E21: 14.5 | G21: =+G20+E21-F21 -> 14.5
D22: AGUA | E22: 3 | G22: =+G21+E22-F22 -> 17.5
D23: G. ADM | E23: 56 | G23: =+G22+E23-F23 -> 73.5
D24: P. SOCIAL | E24: 2 | G24: =+G23+E24-F24 -> 75.5
D25: MULTA | E25: 85 | G25: =+G24+E25-F25 -> 160.5
A26: 42793 | B26: 12373 | C26: FEBRERO | D26: G. ADM | F26: 56 | G26: =+G25+E26-F26 -> 104.5
A27: 42793 | B27: 12373 | C27: FEBRERO | D27: P. SOCIAL | F27: 2 | G27: =+G26+E27-F27 -> 102.5
A28: 42793 | B28: 12373 | C28: FEBRERO | D28: LUZ | F28: 14.5 | G28: =+G27+E28-F28 -> 88
A29: 42793 | B29: 12373 | C29: FEBRERO | D29: AGUA | F29: 3 | G29: =+G28+E29-F29 -> 85
A30: 42793 | B30: 12375 | C30: FEBRERO | D30: MULTA | F30: 85 | G30: =+G29+E30-F30 -> 0
A31: 42825 | B31: POR COBRAR | C31: MARZO | D31: LUZ | E31: 12 | G31: =+G30+E31-F31 -> 12
D32: AGUA | E32: 0 | G32: =+G31+E32-F32 -> 12
D33: G. ADM | E33: 60 | G33: =+G32+E33-F33 -> 72
D34: P. SOCIAL | E34: 2 | G34: =+G33+E34-F34 -> 74
A35: 42870 | B35: 12751 | C35: MARZO | D35: G. ADM | F35: 60 | G35: =+G34+E35-F35 -> 14
A36: 42870 | B36: 12751 | C36: MARZO | D36: P. SOCIAL | F36: 2 | G36: =+G35+E36-F36 -> 12
A37: 42870 | B37: 12751 | C37: MARZO | D37: LUZ | F37: 12 | G37: =+G36+E37-F37 -> 0
A38: 42855 | B38: POR COBRAR | C38: ABRIL | D38: LUZ | E38: 13 | G38: =+G37+E38-F38 -> 13
D39: AGUA | E39: 2 | G39: =+G38+E39-F39 -> 15
D40: G. ADM | E40: 60 | G40: =+G39+E40-F40 -> 75
D41: P. SOCIAL | E41: 2 | G41: =+G40+E41-F41 -> 77
A42: 42870 | B42: 12751 | C42: ABRIL | D42: G. ADM | F42: 60 | G42: =+G41+E42-F42 -> 17
...

Sheet ORTIZ WELINTONH
B2: ORTIZ ÑAUPA WELINTONH
A4: FECHA | B4: DOCUMENTO | C4: PERIODO | D4: CONCEPTO | E4: POR COBRAR | F4: PAGADO | G4: SALDO POR COBRAR
A5: 42736 | B5: SALDO AL 2016 | G5: 1048.8
A6: 42889 | B6: 13044 | C6: A CUENTA 2016 | F6: 209.8 | G6: =+G5+E6-F6 -> 839
A7: 42885 | B7: TARJETA | C7: A CUENTA 2016 | F7: 80 | G7: =+G6+E7-F7 -> 759
A8: 42941 | B8: 13255 | C8: A CUENTA 2016 | F8: 64 | G8: =+G7+E8-F8 -> 695
A9: 42736 | B9: TARJETA | C9: A CUENTA 2016 | F9: 90 | G9: =+G8+E9-F9 -> 605
A10: 42794 | B10: TARJETA | C10: A CUENTA 2016 | F10: 100 | G10: =+G9+E10-F10 -> 505
A11: 42824 | B11: TARJETA | C11: A CUENTA 2016 | F11: 100 | G11: =+G10+E11-F11 -> 405
A12: 42855 | B12: TARJETA | C12: A CUENTA 2016 | F12: 90 | G12: =+G11+E12-F12 -> 315
A13: 43517 | B13: 17178 | C13: CANCELACION 2016 | F13: 315 | G13: =+G12+E13-F13 -> 0
A14: 42766 | B14: POR COBRAR | C14: ENERO | D14: LUZ | E14: 248.5 | G14: =+G13+E14-F14 -> 248.5
D15: AGUA | E15: 42.8 | G15: =+G14+E15-F15 -> 291.3
D16: G. ADM | E16: 60 | G16: =+G15+E16-F16 -> 351.3
D17: P. SOCIAL | E17: 2 | G17: =+G16+E17-F17 -> 353.3
A18: 42762 | B18: TARJETA | C18: ENERO | D18: G. ADM | F18: 18 | G18: =+G17+E18-F18 -> 335.3
A19: 42762 | B19: TARJETA | C19: ENERO | D19: LUZ | F19: 72 | G19: =+G18+E19-F19 -> 263.3
A20: 42889 | B20: 13044 | C20: ENERO | D20: LUZ | F20: 176.5 | G20: =+G19+E20-F20 -> 86.8
A21: 42892 | B21: 13074 | C21: ENERO | D21: AGUA | F21: 42.8 | G21: =+G20+E21-F21 -> 44
A22: 43517 | B22: 17178 | C22: ENERO | D22: G. ADM | F22: 35 | G22: =+G21+E22-F22 -> 9
A23: 43522 | B23: 17197 | C23: ENERO | D23: G. ADM | F23: 7 | G23: =+G22+E23-F23 -> 2
A24: 43522 | B24: 17197 | C24: ENERO | D24: P. SOCIAL | F24: 2 | G24: =+G23+E24-F24 -> 1.4210855e-14
A25: 42794 | B25: POR COBRAR | C25: FEBRERO | D25: LUZ | E25: 168.8 | G25: =+G24+E25-F25 -> 168.8
D26: AGUA | E26: 30 | G26: =+G25+E26-F26 -> 198.8
D27: G. ADM | E27: 56 | G27: =+G26+E27-F27 -> 254.8
D28: P. SOCIAL | E28: 2 | G28: =+G27+E28-F28 -> 256.8
D29: RECONEXION | E29: 30 | G29: =+G28+E29-F29 -> 286.8
D30: MULTA | E30: 85 | G30: =+G29+E30-F30 -> 371.8
A31: 42791 | B31: TARJETA | C31: FEBRERO | D31: G. ADM | F31: 20 | G31: =+G30+E31-F31 -> 351.8
A32: 42791 | B32: TARJETA | C32: FEBRERO | D32: LUZ | F32: 80 | G32: =+G31+E32-F32 -> 271.8
A33: 42889 | B33: 13044 | C33: FEBRERO | D33: LUZ | F33: 88.8 | G33: =+G32+E33-F33 -> 183
A34: 42889 | B34: 13044 | C34: FEBRERO | D34: RECONEXION | F34: 30 | G34: =+G33+E34-F34 -> 153
A35: 42892 | B35: 13074 | C35: FEBRERO | D35: AGUA | F35: 30 | G35: =+G34+E35-F35 -> 123
A36: 43067 | B36: EXONERACION | C36: FEBRERO | D36: MULTA | F36: 85 | G36: =+G35+E36-F36 -> 38
A37: 43522 | B37: 17197 | C37: FEBRERO | D37: G. ADM | F37: 36 | G37: =+G36+E37-F37 -> 2
A38: 43522 | B38: 17197 | C38: FEBRERO | D38: P. SOCIAL | F38: 2 | G38: =+G37+E38-F38 -> 0
A39: 42825 | B39: POR COBRAR | C39: MARZO | D39: LUZ | E39: 162.2 | G39: =+G38+E39-F39 -> 162.2
D40: AGUA | E40: 31.2 | G40: =+G39+E40-F40 -> 193.4
D41: G. ADM | E41: 60 | G41: =+G40+E41-F41 -> 253.4
D42: P. SOCIAL | E42: 2 | G42: =+G41+E42-F42 -> 255.4
...

Sheet PACOMPIA GIOVANNI
B2: PACOMPIA CARDEÑA GIOVANNI
A4: FECHA | B4: DOCUMENTO | C4: PERIODO | D4: CONCEPTO | E4: POR COBRAR | F4: PAGADO | G4: SALDO POR COBRAR
A5: 42736 | B5: SALDO AL 2016 | G5: 2263.2
A6: 42754 | B6: 12124 | C6: A CUENTA 2016 | F6: 65.7 | G6: =+G5+E6-F6 -> 2197.5
A7: 43026 | B7: 13831 | C7: A CUENTA 2016 | F7: 10 | G7: =+G6+E7-F7 -> 2187.5
A8: 42766 | B8: POR COBRAR | C8: ENERO | D8: LUZ | E8: 50.4 | G8: =+G7+E8-F8 -> 2237.9
D9: AGUA | E9: 2.8 | G9: =+G8+E9-F9 -> 2240.7
D10: G. ADM | E10: 60 | G10: =+G9+E10-F10 -> 2300.7
D11: P. SOCIAL | E11: 2 | G11: =+G10+E11-F11 -> 2302.7
A12: 42769 | B12: 12907 | C12: ENERO | D12: G. ADM | F12: 60 | G12: =+G11+E12-F12 -> 2242.7
A13: 42769 | B13: 12907 | C13: ENERO | D13: P. SOCIAL | F13: 2 | G13: =+G12+E13-F13 -> 2240.7
A14: 42790 | B14: 12364 | C14: ENERO | D14: LUZ | F14: 50.4 | G14: =+G13+E14-F14 -> 2190.3
A15: 42790 | B15: 12364 | C15: ENERO | D15: AGUA | F15: 2.8 | G15: =+G14+E15-F15 -> 2187.5
A16: 42794 | B16: POR COBRAR | C16: FEBRERO | D16: LUZ | E16: 72.4 | G16: =+G15+E16-F16 -> 2259.9
D17: AGUA | E17: 2 | G17: =+G16+E17-F17 -> 2261.9
D18: G. ADM | E18: 56 | G18: =+G17+E18-F18 -> 2317.9
D19: P. SOCIAL | E19: 2 | G19: =+G18+E19-F19 -> 2319.9
D20: MULTA | E20: 85 | G20: =+G19+E20-F20 -> 2404.9
A21: 42801 | B21: 12404 | C21: FEBRERO | D21: G. ADM | F21: 56 | G21: =+G20+E21-F21 -> 2348.9
A22: 42801 | B22: 12404 | C22: FEBRERO | D22: P. SOCIAL | F22: 2 | G22: =+G21+E22-F22 -> 2346.9
A23: 42815 | B23: 12427 | C23: FEBRERO | D23: LUZ | F23: 72.4 | G23: =+G22+E23-F23 -> 2274.5
A24: 42815 | B24: 12427 | C24: FEBRERO | D24: AGUA | F24: 2 | G24: =+G23+E24-F24 -> 2272.5
A25: 42825 | B25: POR COBRAR | C25: MARZO | D25: LUZ | E25: 68.7 | G25: =+G24+E25-F25 -> 2341.2
D26: AGUA | E26: 2 | G26: =+G25+E26-F26 -> 2343.2
D27: G. ADM | E27: 60 | G27: =+G26+E27-F27 -> 2403.2
D28: P. SOCIAL | E28: 2 | G28: =+G27+E28-F28 -> 2405.2
A29: 42831 | B29: 12633 | C29: MARZO | D29: G. ADM | F29: 60 | G29: =+G28+E29-F29 -> 2345.2
A30: 42831 | B30: 12633 | C30: MARZO | D30: P. SOCIAL | F30: 2 | G30: =+G29+E30-F30 -> 2343.2
A31: 42845 | B31: 12662 | C31: MARZO | D31: LUZ | F31: 68.7 | G31: =+G30+E31-F31 -> 2274.5
A32: 42845 | B32: 12662 | C32: MARZO | D32: AGUA | F32: 2 | G32: =+G31+E32-F32 -> 2272.5
A33: 42855 | B33: POR COBRAR | C33: ABRIL | D33: LUZ | E33: 49.7 | G33: =+G32+E33-F33 -> 2322.2
D34: AGUA | E34: 2 | G34: =+G33+E34-F34 -> 2324.2
D35: G. ADM | E35: 60 | G35: =+G34+E35-F35 -> 2384.2
D36: P. SOCIAL | E36: 2 | G36: =+G35+E36-F36 -> 2386.2
A37: 42863 | B37: 12729 | C37: ABRIL | D37: G. ADM | F37: 60 | G37: =+G36+E37-F37 -> 2326.2
A38: 42863 | B38: 12729 | C38: ABRIL | D38: P. SOCIAL | F38: 2 | G38: =+G37+E38-F38 -> 2324.2
A39: 42874 | B39: 12778 | C39: ABRIL | D39: LUZ | F39: 49.7 | G39: =+G38+E39-F39 -> 2274.5
A40: 42874 | B40: 12778 | C40: ABRIL | D40: AGUA | F40: 2 | G40: =+G39+E40-F40 -> 2272.5
A41: 42886 | B41: POR COBRAR | C41: MAYO | D41: LUZ | E41: 47.8 | G41: =+G40+E41-F41 -> 2320.3
D42: AGUA | E42: 2 | G42: =+G41+E42-F42 -> 2322.3
...

Sheet PALOMINO CECILIA
B2: PALOMINO HANCCO CECILIA
A4: FECHA | B4: DOCUMENTO | C4: PERIODO | D4: CONCEPTO | E4: POR COBRAR | F4: PAGADO | G4: SALDO POR COBRAR
A5: 42736 | B5: SALDO AL 2016 | G5: 175.7
A6: 42786 | B6: 12272 | C6: A CUENTA 2016 | F6: 95.7 | G6: =+G5+E6-F6 -> 80
A7: 42821 | B7: 12533 | C7: A CUENTA 2016 | F7: 80 | G7: =+G6+E7-F7 -> 0
A8: 42766 | B8: POR COBRAR | C8: ENERO | D8: LUZ | E8: 69.9 | G8: =+G7+E8-F8 -> 69.9
D9: AGUA | E9: 33 | G9: =+G8+E9-F9 -> 102.9
D10: G. ADM | E10: 60 | G10: =+G9+E10-F10 -> 162.9
D11: P. SOCIAL | E11: 2 | G11: =+G10+E11-F11 -> 164.9
A12: 42765 | B12: TARJETA | C12: ENERO | D12: G. ADM | F12: 60 | G12: =+G11+E12-F12 -> 104.9
A13: 42765 | B13: TARJETA | C13: ENERO | D13: P. SOCIAL | F13: 2 | G13: =+G12+E13-F13 -> 102.9
A14: 42786 | B14: 12272 | C14: ENERO | D14: LUZ | F14: 69.9 | G14: =+G13+E14-F14 -> 33
A15: 42786 | B15: 12272 | C15: ENERO | D15: AGUA | F15: 33 | G15: =+G14+E15-F15 -> 0
A16: 42794 | B16: POR COBRAR | C16: FEBRERO | D16: LUZ | E16: 73.8 | G16: =+G15+E16-F16 -> 73.8
D17: AGUA | E17: 21 | G17: =+G16+E17-F17 -> 94.8
D18: G. ADM | E18: 56 | G18: =+G17+E18-F18 -> 150.8
D19: P. SOCIAL | E19: 2 | G19: =+G18+E19-F19 -> 152.8
A20: 42793 | B20: TARJETA | C20: FEBRERO | D20: G. ADM | F20: 54 | G20: =+G19+E20-F20 -> 98.8
A21: 42795 | B21: 12383 | C21: FEBRERO | D21: G. ADM | F21: 2 | G21: =+G20+E21-F21 -> 96.8
A22: 42795 | B22: 12383 | C22: FEBRERO | D22: P. SOCIAL | F22: 2 | G22: =+G21+E22-F22 -> 94.8
A23: 42821 | B23: 12533 | C23: FEBRERO | D23: LUZ | F23: 73.8 | G23: =+G22+E23-F23 -> 21
A24: 42821 | B24: 12533 | C24: FEBRERO | D24: AGUA | F24: 21 | G24: =+G23+E24-F24 -> 0
A25: 42825 | B25: POR COBRAR | C25: MARZO | D25: LUZ | E25: 70.6 | G25: =+G24+E25-F25 -> 70.6
D26: AGUA | E26: 22.9 | G26: =+G25+E26-F26 -> 93.5
D27: G. ADM | E27: 60 | G27: =+G26+E27-F27 -> 153.5
D28: P. SOCIAL | E28: 2 | G28: =+G27+E28-F28 -> 155.5
A29: 42824 | B29: TARJETA | C29: MARZO | D29: G. ADM | F29: 60 | G29: =+G28+E29-F29 -> 95.5
A30: 42824 | B30: TARJETA | C30: MARZO | D30: P. SOCIAL | F30: 2 | G30: =+G29+E30-F30 -> 93.5
A31: 42888 | B31: 13037 | C31: MARZO | D31: LUZ | F31: 70.6 | G31: =+G30+E31-F31 -> 22.9
A32: 42888 | B32: 13037 | C32: MARZO | D32: AGUA | F32: 22.9 | G32: =+G31+E32-F32 -> 0
A33: 42855 | B33: POR COBRAR | C33: ABRIL | D33: LUZ | E33: 72.1 | G33: =+G32+E33-F33 -> 72.1
D34: AGUA | E34: 22.5 | G34: =+G33+E34-F34 -> 94.6
D35: G. ADM | E35: 60 | G35: =+G34+E35-F35 -> 154.6
D36: P. SOCIAL | E36: 2 | G36: =+G35+E36-F36 -> 156.6
A37: 42855 | B37: TARJETA | C37: ABRIL | D37: G. ADM | F37: 60 | G37: =+G36+E37-F37 -> 96.6
A38: 42855 | B38: TARJETA | C38: ABRIL | D38: P. SOCIAL | F38: 2 | G38: =+G37+E38-F38 -> 94.6
A39: 42888 | B39: 13037 | C39: ABRIL | D39: LUZ | F39: 72.1 | G39: =+G38+E39-F39 -> 22.5
A40: 42888 | B40: 13037 | C40: ABRIL | D40: AGUA | F40: 22.5 | G40: =+G39+E40-F40 -> 0
A41: 42886 | B41: POR COBRAR | C41: MAYO | D41: LUZ | E41: 67.5 | G41: =+G40+E41-F41 -> 67.5
D42: AGUA | E42: 22 | G42: =+G41+E42-F42 -> 89.5
...

Sheet PALOMINO SILVIO
B2: PALOMINO TENORIO SILVIO EDUARDO
A4: FECHA | B4: DOCUMENTO | C4: PERIODO | D4: CONCEPTO | E4: POR COBRAR | F4: PAGADO | G4: SALDO POR COBRAR
A5: 42736 | B5: SALDO AL 2016 | G5: 354
A6: 42781 | B6: 12952 | C6: A CUENTAS 2016 | F6: 274 | G6: =+G5+E6-F6 -> 80
A7: 43060 | B7: 10214 | C7: CANCELACION 2016 | F7: 80 | G7: =+G6+E7-F7 -> 0
A8: 42766 | B8: POR COBRAR | C8: ENERO | D8: LUZ | E8: 94.3 | G8: =+G7+E8-F8 -> 94.3
D9: AGUA | E9: 61 | G9: =+G8+E9-F9 -> 155.3
D10: G. ADM | E10: 60 | G10: =+G9+E10-F10 -> 215.3
D11: P. SOCIAL | E11: 2 | G11: =+G10+E11-F11 -> 217.3
D12: MULTA P. SEPTICO | E12: 100 | G12: =+G11+E12-F12 -> 317.3
A13: 42765 | B13: TARJETA | C13: ENERO | D13: G. ADM | F13: 60 | G13: =+G12+E13-F13 -> 257.3
A14: 42765 | B14: TARJETA | C14: ENERO | D14: P. SOCIAL | F14: 2 | G14: =+G13+E14-F14 -> 255.3
A15: 42784 | B15: 12992 | C15: ENERO | D15: MULTA P. SEPTICO | F15: 100 | G15: =+G14+E15-F15 -> 155.3
A16: 42784 | B16: 12993 | C16: ENERO | D16: LUZ | F16: 94.3 | G16: =+G15+E16-F16 -> 61
A17: 42784 | B17: 12993 | C17: ENERO | D17: AGUA | F17: 61 | G17: =+G16+E17-F17 -> 0
A18: 42794 | B18: POR COBRAR | C18: FEBRERO | D18: LUZ | E18: 102.5 | G18: =+G17+E18-F18 -> 102.5
D19: AGUA | E19: 43 | G19: =+G18+E19-F19 -> 145.5
D20: G. ADM | E20: 56 | G20: =+G19+E20-F20 -> 201.5
D21: P. SOCIAL | E21: 2 | G21: =+G20+E21-F21 -> 203.5
A22: 42794 | B22: TARJETA | C22: FEBRERO | D22: G. ADM | F22: 56 | G22: =+G21+E22-F22 -> 147.5
A23: 42794 | B23: TARJETA | C23: FEBRERO | D23: P. SOCIAL | F23: 2 | G23: =+G22+E23-F23 -> 145.5
A24: 42822 | B24: 12578 | C24: FEBRERO | D24: LUZ | F24: 102.5 | G24: =+G23+E24-F24 -> 43
A25: 42822 | B25: 12578 | C25: FEBRERO | D25: AGUA | F25: 43 | G25: =+G24+E25-F25 -> 0
A26: 42825 | B26: POR COBRAR | C26: MARZO | D26: LUZ | E26: 98.3 | G26: =+G25+E26-F26 -> 98.3
D27: AGUA | E27: 44.7 | G27: =+G26+E27-F27 -> 143
D28: G. ADM | E28: 60 | G28: =+G27+E28-F28 -> 203
D29: P. SOCIAL | E29: 2 | G29: =+G28+E29-F29 -> 205
A30: 42824 | B30: TARJETA | C30: MARZO | D30: G. ADM | F30: 60 | G30: =+G29+E30-F30 -> 145
A31: 42824 | B31: TARJETA | C31: MARZO | D31: P. SOCIAL | F31: 2 | G31: =+G30+E31-F31 -> 143
A32: 42850 | B32: 12697 | C32: MARZO | D32: LUZ | F32: 98.3 | G32: =+G31+E32-F32 -> 44.7
A33: 42850 | B33: 12697 | C33: MARZO | D33: AGUA | F33: 44.7 | G33: =+G32+E33-F33 -> 0
A34: 42855 | B34: POR COBRAR | C34: ABRIL | D34: LUZ | E34: 100.1 | G34: =+G33+E34-F34 -> 100.1
D35: AGUA | E35: 44 | G35: =+G34+E35-F35 -> 144.1
D36: G. ADM | E36: 60 | G36: =+G35+E36-F36 -> 204.1
D37: P. SOCIAL | E37: 2 | G37: =+G36+E37-F37 -> 206.1
A38: 42855 | B38: TARJETA | C38: ABRIL | D38: G. ADM | F38: 60 | G38: =+G37+E38-F38 -> 146.1
A39: 42855 | B39: TARJETA | C39: ABRIL | D39: P. SOCIAL | F39: 2 | G39: =+G38+E39-F39 -> 144.1
A40: 42877 | B40: 12797 | C40: ABRIL | D40: LUZ | F40: 100.1 | G40: =+G39+E40-F40 -> 44
A41: 42877 | B41: 12797 | C41: ABRIL | D41: AGUA | F41: 44 | G41: =+G40+E41-F41 -> 0
A42: 42886 | B42: POR COBRAR | C42: MAYO | D42: LUZ | E42: 60.5 | G42: =+G41+E42-F42 -> 60.5
...

Sheet PALOMINO EUSEBIO
B2: PALOMINO VELASQUEZ EUSEBIO
A4: FECHA | B4: DOCUMENTO | C4: PERIODO | D4: CONCEPTO | E4: POR COBRAR | F4: PAGADO | G4: SALDO POR COBRAR
A5: 42736 | B5: SALDO AL 2016 | G5: 448.2
A6: 42740 | B6: 12071 | C6: A CUENTA 2016 | F6: 199.5 | G6: =+G5+E6-F6 -> 248.7
A7: 42787 | B7: 12351 | C7: A CUENTA 2016 | F7: 168.7 | G7: =+G6+E7-F7 -> 80
A8: 43067 | B8: 14149 | C8: CANCELACION 2016 | F8: 80 | G8: =+G7+E8-F8 -> 0
A9: 42766 | B9: POR COBRAR | C9: ENERO | D9: LUZ | E9: 144.3 | G9: =+G8+E9-F9 -> 144.3
D10: AGUA | E10: 19.1 | G10: =+G9+E10-F10 -> 163.4
D11: G. ADM | E11: 60 | G11: =+G10+E11-F11 -> 223.4
D12: P. SOCIAL | E12: 2 | G12: =+G11+E12-F12 -> 225.4
A13: 42765 | B13: TARJETA | C13: ENERO | D13: G. ADM | F13: 60 | G13: =+G12+E13-F13 -> 165.4
A14: 42765 | B14: TARJETA | C14: ENERO | D14: P. SOCIAL | F14: 2 | G14: =+G13+E14-F14 -> 163.4
A15: 42787 | B15: 12356 | C15: ENERO | D15: LUZ | F15: 144.3 | G15: =+G14+E15-F15 -> 19.1
A16: 42787 | B16: 12356 | C16: ENERO | D16: AGUA | F16: 19.1 | G16: =+G15+E16-F16 -> 0
A17: 42794 | B17: POR COBRAR | C17: FEBRERO | D17: LUZ | E17: 171 | G17: =+G16+E17-F17 -> 171
D18: AGUA | E18: 13 | G18: =+G17+E18-F18 -> 184
D19: G. ADM | E19: 56 | G19: =+G18+E19-F19 -> 240
D20: P. SOCIAL | E20: 2 | G20: =+G19+E20-F20 -> 242
A21: 42794 | B21: TARJETA | C21: FEBRERO | D21: G. ADM | F21: 56 | G21: =+G20+E21-F21 -> 186
A22: 42794 | B22: TARJETA | C22: FEBRERO | D22: P. SOCIAL | F22: 2 | G22: =+G21+E22-F22 -> 184
A23: 42822 | B23: 12591 | C23: FEBRERO | D23: LUZ | F23: 171 | G23: =+G22+E23-F23 -> 13
A24: 42822 | B24: 12591 | C24: FEBRERO | D24: AGUA | F24: 13 | G24: =+G23+E24-F24 -> 0
A25: 42825 | B25: POR COBRAR | C25: MARZO | D25: LUZ | E25: 164.3 | G25: =+G24+E25-F25 -> 164.3
D26: AGUA | E26: 14 | G26: =+G25+E26-F26 -> 178.3
D27: G. ADM | E27: 60 | G27: =+G26+E27-F27 -> 238.3
D28: P. SOCIAL | E28: 2 | G28: =+G27+E28-F28 -> 240.3
A29: 42824 | B29: TARJETA | C29: MARZO | D29: G. ADM | F29: 60 | G29: =+G28+E29-F29 -> 180.3
A30: 42824 | B30: TARJETA | C30: MARZO | D30: P. SOCIAL | F30: 2 | G30: =+G29+E30-F30 -> 178.3
A31: 42887 | B31: 13027 | C31: MARZO | D31: LUZ | F31: 164.3 | G31: =+G30+E31-F31 -> 14
A32: 42887 | B32: 13027 | C32: MARZO | D32: AGUA | F32: 14 | G32: =+G31+E32-F32 -> 0
