Workbook

Sheet ROJAS LIONILA
B2: ROJAS IGNACIO LEONILA
A4: FECHA | B4: DOCUMENTO | C4: PERIODO | D4: CONCEPTO | E4: POR COBRAR | F4: PAGADO | G4: SALDO POR COBRAR
A5: 42736 | B5: SALDO AL 2016 | G5: 2385
A6: 42745 | B6: 12093 | C6: A CUENTA 2016 | F6: 62 | G6: =+G5+E6-F6 -> 2323
A7: 42802 | B7: 12409 | C7: A CUENTA 2016 | F7: 103 | G7: =+G6+E7-F7 -> 2220
A8: 42877 | B8: 12796 | C8: A CUENTA 2016 | F8: 73.8 | G8: =+G7+E8-F8 -> 2146.2
A9: 44848 | B9: R 25629 | C9: A CUENTA 2016 | F9: 914 | G9: =+G8+E9-F9 -> 1232.2
A10: 44848 | B10: R 25629 | C10: MULTAS 2016 | F10: 616.3 | G10: =+G9+E10-F10 -> 615.9
A11: 44847 | B11: EXONERACION | C11: MULTAS 50% | F11: 615.9 | G11: =+G10+E11-F11 -> 0
A12: 42766 | B12: POR COBRAR | C12: ENERO | D12: LUZ | E12: 79.1 | G12: =+G11+E12-F12 -> 79.1
D13: AGUA | E13: 2.7 | G13: =+G12+E13-F13 -> 81.8
D14: G. ADM | E14: 60 | G14: =+G13+E14-F14 -> 141.8
D15: P. SOCIAL | E15: 2 | G15: =+G14+E15-F15 -> 143.8
A16: 42774 | B16: 12928 | C16: ENERO | D16: G. ADM | F16: 60 | G16: =+G15+E16-F16 -> 83.8
A17: 42774 | B17: 12928 | C17: ENERO | D17: P. SOCIAL | F17: 2 | G17: =+G16+E17-F17 -> 81.8
A18: 42877 | B18: 12796 | C18: ENERO | D18: LUZ | F18: 79.1 | G18: =+G17+E18-F18 -> 2.7
A19: 42877 | B19: 12796 | C19: ENERO | D19: AGUA | F19: 2.7 | G19: =+G18+E19-F19 -> 1.687539e-14
A20: 42794 | B20: POR COBRAR | C20: FEBRERO | D20: LUZ | E20: 74.6 | G20: =+G19+E20-F20 -> 74.6
D21: AGUA | E21: 2 | G21: =+G20+E21-F21 -> 76.6
D22: G. ADM | E22: 56 | G22: =+G21+E22-F22 -> 132.6
D23: P. SOCIAL | E23: 2 | G23: =+G22+E23-F23 -> 134.6
D24: MULTA | E24: 85 | G24: =+G23+E24-F24 -> 219.6
A25: 42801 | B25: 12401 | C25: FEBRERO | D25: ALQUILER | F25: 56 | G25: =+G24+E25-F25 -> 163.6
A26: 42801 | B26: 12401 | C26: FEBRERO | D26: P. SOCIAL | F26: 2 | G26: =+G25+E26-F26 -> 161.6
A27: 42877 | B27: 12796 | C27: FEBRERO | D27: LUZ | F27: 74.6 | G27: =+G26+E27-F27 -> 87
A28: 42877 | B28: 12796 | C28: FEBRERO | D28: AGUA | F28: 2 | G28: =+G27+E28-F28 -> 85
A29: 43067 | B29: EXONERACION | C29: FEBRERO | D29: MULTA | F29: 85 | G29: =+G28+E29-F29 -> 0
A30: 42825 | B30: POR COBRAR | C30: MARZO | D30: LUZ | E30: 73.2 | G30: =+G29+E30-F30 -> 73.2
D31: AGUA | E31: 2 | G31: =+G30+E31-F31 -> 75.2
D32: G. ADM | E32: 60 | G32: =+G31+E32-F32 -> 135.2
D33: P. SOCIAL | E33: 2 | G33: =+G32+E33-F33 -> 137.2
A34: 42833 | B34: 12636 | C34: MARZO | D34: G. ADM | F34: 60 | G34: =+G33+E34-F34 -> 77.2
A35: 42833 | B35: 12636 | C35: MARZO | D35: P. SOCIAL | F35: 2 | G35: =+G34+E35-F35 -> 75.2
A36: 42885 | B36: 13002 | C36: MARZO | D36: LUZ | F36: 73.2 | G36: =+G35+E36-F36 -> 2
A37: 42885 | B37: 13002 | C37: MARZO | D37: AGUA | F37: 2 | G37: =+G36+E37-F37 -> -1.4210855e-14
A38: 42855 | B38: POR COBRAR | C38: ABRIL | D38: LUZ | E38: 51.8 | G38: =+G37+E38-F38 -> 51.8
D39: AGUA | E39: 2 | G39: =+G38+E39-F39 -> 53.8
D40: G. ADM | E40: 60 | G40: =+G39+E40-F40 -> 113.8
D41: P. SOCIAL | E41: 2 | G41: =+G40+E41-F41 -> 115.8
A42: 42861 | B42: 12728 | C42: ABRIL | D42: G. ADM | F42: 60 | G42: =+G41+E42-F42 -> 55.8
...

Sheet ROMERO JAVIER
B2: ROMERO NINAHUAMAN JAVIER
A4: FECHA | B4: DOCUMENTO | C4: PERIODO | D4: CONCEPTO | E4: POR COBRAR | F4: PAGADO | G4: SALDO POR COBRAR
A5: 42736 | B5: SALDO AL 2016 | G5: 324.7
A6: 42786 | B6: 12254 | C6: A CUENTA 2016 | F6: 318 | G6: =+G5+E6-F6 -> 6.7
A7: 42786 | B7: 12259 | C7: A CUENTA 2016 | F7: 6 | G7: =+G6+E7-F7 -> 0.7
A8: 43067 | B8: 14136 | C8: CANCELACION 2016 | F8: 0.7 | G8: =+G7+E8-F8 -> -1.1324275e-14
A9: 42766 | B9: POR COBRAR | C9: ENERO | D9: LUZ | E9: 68.5 | G9: =+G8+E9-F9 -> 68.5
D10: AGUA | E10: 2.8 | G10: =+G9+E10-F10 -> 71.3
D11: G. ADM | E11: 60 | G11: =+G10+E11-F11 -> 131.3
D12: P. SOCIAL | E12: 2 | G12: =+G11+E12-F12 -> 133.3
A13: 42786 | B13: 12254 | C13: ENERO | D13: G. ADM | F13: 60 | G13: =+G12+E13-F13 -> 73.3
A14: 42786 | B14: 12254 | C14: ENERO | D14: P. SOCIAL | F14: 2 | G14: =+G13+E14-F14 -> 71.3
A15: 42786 | B15: 12254 | C15: ENERO | D15: LUZ | F15: 68.5 | G15: =+G14+E15-F15 -> 2.8
A16: 42786 | B16: 12259 | C16: ENERO | D16: AGUA | F16: 2.8 | G16: =+G15+E16-F16 -> -1.687539e-14
A17: 42794 | B17: POR COBRAR | C17: FEBRERO | D17: LUZ | E17: 69.8 | G17: =+G16+E17-F17 -> 69.8
D18: AGUA | E18: 2 | G18: =+G17+E18-F18 -> 71.8
D19: G. ADM | E19: 56 | G19: =+G18+E19-F19 -> 127.8
D20: P. SOCIAL | E20: 2 | G20: =+G19+E20-F20 -> 129.8
A21: 42821 | B21: 12538 | C21: FEBRERO | D21: G. ADM | F21: 56 | G21: =+G20+E21-F21 -> 73.8
A22: 42821 | B22: 12538 | C22: FEBRERO | D22: P. SOCIAL | F22: 2 | G22: =+G21+E22-F22 -> 71.8
A23: 42821 | B23: 12538 | C23: FEBRERO | D23: LUZ | F23: 69.8 | G23: =+G22+E23-F23 -> 2
A24: 42821 | B24: 12538 | C24: FEBRERO | D24: AGUA | F24: 2 | G24: =+G23+E24-F24 -> -1.4210855e-14
A25: 42825 | B25: POR COBRAR | C25: MARZO | D25: LUZ | E25: 65.5 | G25: =+G24+E25-F25 -> 65.5
D26: AGUA | E26: 2 | G26: =+G25+E26-F26 -> 67.5
D27: G. ADM | E27: 60 | G27: =+G26+E27-F27 -> 127.5
D28: P. SOCIAL | E28: 2 | G28: =+G27+E28-F28 -> 129.5
A29: 42886 | B29: 13011 | C29: MARZO | D29: LUZ | F29: 65.5 | G29: =+G28+E29-F29 -> 64
A30: 42886 | B30: 13011 | C30: MARZO | D30: AGUA | F30: 2 | G30: =+G29+E30-F30 -> 62
A31: 43067 | B31: 14136 | C31: MARZO | D31: G. ADM | F31: 60 | G31: =+G30+E31-F31 -> 2
A32: 43067 | B32: 14136 | C32: MARZO | D32: P. SOCIAL | F32: 2 | G32: =+G31+E32-F32 -> 0
A33: 42855 | B33: POR COBRAR | C33: ABRIL | D33: LUZ | E33: 67.9 | G33: =+G32+E33-F33 -> 67.9
D34: AGUA | E34: 2 | G34: =+G33+E34-F34 -> 69.9
D35: G. ADM | E35: 60 | G35: =+G34+E35-F35 -> 129.9
D36: P. SOCIAL | E36: 2 | G36: =+G35+E36-F36 -> 131.9
A37: 42886 | B37: 13011 | C37: ABRIL | D37: LUZ | F37: 67.9 | G37: =+G36+E37-F37 -> 64
A38: 42886 | B38: 13011 | C38: ABRIL | D38: AGUA | F38: 2 | G38: =+G37+E38-F38 -> 62
A39: 43067 | B39: 14136 | C39: ABRIL | D39: G. ADM | F39: 60 | G39: =+G38+E39-F39 -> 2
A40: 43067 | B40: 14136 | C40: ABRIL | D40: P. SOCIAL | F40: 2 | G40: =+G39+E40-F40 -> 0
A41: 42886 | B41: POR COBRAR | C41: MAYO | D41: LUZ | E41: 64.6 | G41: =+G40+E41-F41 -> 64.6
D42: AGUA | E42: 2 | G42: =+G41+E42-F42 -> 66.6
...

Sheet ROMERO ESTEBAN
B2: ROMERO YSLA ESTEBAN LIDIO
A4: FECHA | B4: DOCUMENTO | C4: PERIODO | D4: CONCEPTO | E4: POR COBRAR | F4: PAGADO | G4: SALDO POR COBRAR
A5: 42736 | B5: SALDO AL 2016 | G5: 7584.3
A6: 42752 | B6: 12111 | C6: A CUENTA 2016 | F6: 49.8 | G6: =+G5+E6-F6 -> 7534.5
A7: 42761 | B7: 12161 | C7: A CUENTA 2016 | F7: 250 | G7: =+G6+E7-F7 -> 7284.5
A8: 42817 | B8: 12443 | C8: A CUENTA 2016 | F8: 250 | G8: =+G7+E8-F8 -> 7034.5
A9: 42847 | B9: 12685 | C9: A CUENTA 2016 | F9: 250 | G9: =+G8+E9-F9 -> 6784.5
A10: 43060 | B10: 10201 | C10: A CUENTA 2016 | F10: 250 | G10: =+G9+E10-F10 -> 6534.5
A11: 43125 | B11: 14580 | C11: A CUENTA 2016 | F11: 500 | G11: =+G10+E11-F11 -> 6034.5
A12: 43157 | B12: 14530 | C12: A CUENTA 2016 | F12: 250 | G12: =+G11+E12-F12 -> 5784.5
A13: 43270 | B13: 15511 | C13: A CUENTA 2016 | F13: 250 | G13: =+G12+E13-F13 -> 5534.5
A14: 43318 | B14: 15930 | C14: A CUENTA 2016 | F14: 250 | G14: =+G13+E14-F14 -> 5284.5
A15: 43354 | B15: 16110 | C15: A CUENTA 2016 | F15: 500 | G15: =+G14+E15-F15 -> 4784.5
A16: 43389 | B16: 16330 | C16: A CUENTA 2016 | F16: 250 | G16: =+G15+E16-F16 -> 4534.5
A17: 43426 | B17: 16586 | C17: A CUENTA 2016 | F17: 250 | G17: =+G16+E17-F17 -> 4284.5
... A29: 44648 | B29: 24669 | C29: A CUENTA 2016 | F29: 134.5 | G29: =+G28+E29-F29 -> 0
A30: 42766 | B30: POR COBRAR | C30: ENERO | D30: LUZ | E30: 32.7 | G30: =+G29+E30-F30 -> 32.7
D31: AGUA | E31: 2.8 | G31: =+G30+E31-F31 -> 35.5
D32: G. ADM | E32: 60 | G32: =+G31+E32-F32 -> 95.5
D33: P. SOCIAL | E33: 2 | G33: =+G32+E33-F33 -> 97.5
A34: 42815 | B34: 12425 | C34: ENERO | D34: LUZ | F34: 32.7 | G34: =+G33+E34-F34 -> 64.8
A35: 42815 | B35: 12425 | C35: ENERO | D35: AGUA | F35: 2.8 | G35: =+G34+E35-F35 -> 62
A36: 42817 | B36: 12444 | C36: ENERO | D36: G. ADM | F36: 60 | G36: =+G35+E36-F36 -> 2
A37: 42817 | B37: 12444 | C37: ENERO | D37: P. SOCIAL | F37: 2 | G37: =+G36+E37-F37 -> 0
A38: 42794 | B38: POR COBRAR | C38: FEBRERO | D38: LUZ | E38: 32.9 | G38: =+G37+E38-F38 -> 32.9
D39: AGUA | E39: 2 | G39: =+G38+E39-F39 -> 34.9
D40: G. ADM | E40: 56 | G40: =+G39+E40-F40 -> 90.9
D41: P. SOCIAL | E41: 2 | G41: =+G40+E41-F41 -> 92.9
D42: MULTA | E42: 85 | G42: =+G41+E42-F42 -> 177.9
A43: 42815 | B43: 12425 | C43: FEBRERO | D43: LUZ | F43: 32.9 | G43: =+G42+E43-F43 -> 145
A44: 42815 | B44: 12425 | C44: FEBRERO | D44: AGUA | F44: 2 | G44: =+G43+E44-F44 -> 143
A45: 42860 | B45: 12816 | C45: FEBRERO | D45: G. ADM | F45: 56 | G45: =+G44+E45-F45 -> 87
A46: 43060 | B46: 10201 | C46: FEBRERO | D46: P. SOCIAL | F46: 2 | G46: =+G45+E46-F46 -> 85
A47: 43067 | B47: EXONERACION | C47: FEBRERO | D47: MULTA | F47: 85 | G47: =+G46+E47-F47 -> 0
A48: 42825 | B48: POR COBRAR | C48: MARZO | D48: LUZ | E48: 31.2 | G48: =+G47+E48-F48 -> 31.2
D49: AGUA | E49: 2 | G49: =+G48+E49-F49 -> 33.2
D50: G. ADM | E50: 60 | G50: =+G49+E50-F50 -> 93.2
D51: P. SOCIAL | E51: 2 | G51: =+G50+E51-F51 -> 95.2
D52: MULTA | E52: 85 | G52: =+G51+E52-F52 -> 180.2
A53: 42864 | B53: 12737 | C53: MARZO | D53: LUZ | F53: 31.2 | G53: =+G52+E53-F53 -> 149
...

Sheet SAAVEDRA LUIS
A2: SAAVEDRA CURIPUMA LUIS HUMBERTO
A4: FECHA | B4: DOCUMENTO | C4: PERIODO | D4: CONCEPTO | E4: POR COBRAR | F4: PAGADO | G4: SALDO POR COBRAR
A5: 42736 | B5: SALDO AL 2016 | G5: 156.7
A6: 42786 | B6: 12288 | C6: A CUENTA 2016 | F6: 141.7 | G6: =+G5+E6-F6 -> 15
A7: 42786 | B7: 12292 | C7: A CUENTA 2016 | F7: 15 | G7: =+G6+E7-F7 -> 0
A8: 42766 | B8: POR COBRAR | C8: ENERO | D8: LUZ | E8: 68.5 | G8: =+G7+E8-F8 -> 68.5
D9: AGUA | E9: 2.8 | G9: =+G8+E9-F9 -> 71.3
D10: G. ADM | E10: 60 | G10: =+G9+E10-F10 -> 131.3
D11: P. SOCIAL | E11: 2 | G11: =+G10+E11-F11 -> 133.3
D12: P.S.FALLEC. | E12: 10 | G12: =+G11+E12-F12 -> 143.3
A13: 42765 | B13: TARJETA | C13: ENERO | D13: G. ADM | F13: 60 | G13: =+G12+E13-F13 -> 83.3
A14: 42765 | B14: TARJETA | C14: ENERO | D14: P. SOCIAL | F14: 2 | G14: =+G13+E14-F14 -> 81.3
A15: 42786 | B15: 12288 | C15: ENERO | D15: LUZ | F15: 68.5 | G15: =+G14+E15-F15 -> 12.8
A16: 42786 | B16: 12288 | C16: ENERO | D16: AGUA | F16: 2.8 | G16: =+G15+E16-F16 -> 10
A17: 42786 | B17: 12292 | C17: ENERO | D17: P.S.FALLEC. | F17: 10 | G17: =+G16+E17-F17 -> 0
A18: 42794 | B18: POR COBRAR | C18: FEBRERO | D18: LUZ | E18: 75.5 | G18: =+G17+E18-F18 -> 75.5
D19: AGUA | E19: 2 | G19: =+G18+E19-F19 -> 77.5
D20: G. ADM | E20: 56 | G20: =+G19+E20-F20 -> 133.5
D21: P. SOCIAL | E21: 2 | G21: =+G20+E21-F21 -> 135.5
A22: 42794 | B22: TARJETA | C22: FEBRERO | D22: G. ADM | F22: 56 | G22: =+G21+E22-F22 -> 79.5
A23: 42794 | B23: TARJETA | C23: FEBRERO | D23: P. SOCIAL | F23: 2 | G23: =+G22+E23-F23 -> 77.5
A24: 42822 | B24: 12598 | C24: FEBRERO | D24: LUZ | F24: 75.5 | G24: =+G23+E24-F24 -> 2
A25: 42822 | B25: 12598 | C25: FEBRERO | D25: AGUA | F25: 2 | G25: =+G24+E25-F25 -> 0
A26: 42825 | B26: POR COBRAR | C26: MARZO | D26: LUZ | E26: 71.9 | G26: =+G25+E26-F26 -> 71.9
D27: AGUA | E27: 2 | G27: =+G26+E27-F27 -> 73.9
D28: G. ADM | E28: 60 | G28: =+G27+E28-F28 -> 133.9
D29: P. SOCIAL | E29: 2 | G29: =+G28+E29-F29 -> 135.9
A30: 42824 | B30: TARJETA | C30: MARZO | D30: G. ADM | F30: 60 | G30: =+G29+E30-F30 -> 75.9
A31: 42824 | B31: TARJETA | C31: MARZO | D31: P. SOCIAL | F31: 2 | G31: =+G30+E31-F31 -> 73.9
A32: 42885 | B32: 12859 | C32: MARZO | D32: LUZ | F32: 71.9 | G32: =+G31+E32-F32 -> 2
A33: 42885 | B33: 12859 | C33: MARZO | D33: AGUA | F33: 2 | G33: =+G32+E33-F33 -> 0
A34: 42855 | B34: POR COBRAR | C34: ABRIL | D34: LUZ | E34: 74.4 | G34: =+G33+E34-F34 -> 74.4
D35: AGUA | E35: 2 | G35: =+G34+E35-F35 -> 76.4
D36: G. ADM | E36: 60 | G36: =+G35+E36-F36 -> 136.4
D37: P. SOCIAL | E37: 2 | G37: =+G36+E37-F37 -> 138.4
A38: 42855 | B38: TARJETA | C38: ABRIL | D38: G. ADM | F38: 60 | G38: =+G37+E38-F38 -> 78.4
A39: 42855 | B39: TARJETA | C39: ABRIL | D39: P. SOCIAL | F39: 2 | G39: =+G38+E39-F39 -> 76.4
A40: 42885 | B40: 12859 | C40: ABRIL | D40: LUZ | F40: 74.4 | G40: =+G39+E40-F40 -> 2
A41: 42885 | B41: 12859 | C41: ABRIL | D41: AGUA | F41: 2 | G41: =+G40+E41-F41 -> 0
A42: 42886 | B42: POR COBRAR | C42: MAYO | D42: LUZ | E42: 70.6 | G42: =+G41+E42-F42 -> 70.6
...

Sheet SALAS RUTH
B2: SALAS MONTALVO RUTH
A4: FECHA | B4: DOCUMENTO | C4: PERIODO | D4: CONCEPTO | E4: POR COBRAR | F4: PAGADO | G4: SALDO POR COBRAR
A5: 42736 | B5: SALDO AL 2016 | G5: 326.8
A6: 42786 | B6: 12260 | C6: A CUENTA 2016 | F6: 267.8 | G6: =+G5+E6-F6 -> 59
A7: 42786 | B7: 12261 | C7: A CUENTA 2016 | F7: 59 | G7: =+G6+E7-F7 -> 0
A8: 42766 | B8: POR COBRAR | C8: ENERO | D8: LUZ | E8: 69.6 | G8: =+G7+E8-F8 -> 69.6
D9: AGUA | E9: 2.8 | G9: =+G8+E9-F9 -> 72.4
D10: G. ADM | E10: 60 | G10: =+G9+E10-F10 -> 132.4
D11: P. SOCIAL | E11: 2 | G11: =+G10+E11-F11 -> 134.4
A12: 42786 | B12: 12260 | C12: ENERO | D12: G. ADM | F12: 60 | G12: =+G11+E12-F12 -> 74.4
A13: 42786 | B13: 12260 | C13: ENERO | D13: P. SOCIAL | F13: 2 | G13: =+G12+E13-F13 -> 72.4
A14: 42786 | B14: 12260 | C14: ENERO | D14: AGUA | F14: 2.8 | G14: =+G13+E14-F14 -> 69.6
A15: 42786 | B15: 12260 | C15: ENERO | D15: LUZ | F15: 69.6 | G15: =+G14+E15-F15 -> 0
A16: 42794 | B16: POR COBRAR | C16: FEBRERO | D16: LUZ | E16: 70.2 | G16: =+G15+E16-F16 -> 70.2
D17: AGUA | E17: 2 | G17: =+G16+E17-F17 -> 72.2
D18: G. ADM | E18: 56 | G18: =+G17+E18-F18 -> 128.2
D19: P. SOCIAL | E19: 2 | G19: =+G18+E19-F19 -> 130.2
A20: 42821 | B20: 12539 | C20: FEBRERO | D20: G. ADM | F20: 56 | G20: =+G19+E20-F20 -> 74.2
A21: 42821 | B21: 12539 | C21: FEBRERO | D21: P. SOCIAL | F21: 2 | G21: =+G20+E21-F21 -> 72.2
A22: 42821 | B22: 12539 | C22: FEBRERO | D22: LUZ | F22: 70.2 | G22: =+G21+E22-F22 -> 2
A23: 42821 | B23: 12539 | C23: FEBRERO | D23: AGUA | F23: 2 | G23: =+G22+E23-F23 -> -1.4210855e-14
A24: 42825 | B24: POR COBRAR | C24: MARZO | D24: LUZ | E24: 66.6 | G24: =+G23+E24-F24 -> 66.6
D25: AGUA | E25: 2 | G25: =+G24+E25-F25 -> 68.6
D26: G. ADM | E26: 60 | G26: =+G25+E26-F26 -> 128.6
D27: P. SOCIAL | E27: 2 | G27: =+G26+E27-F27 -> 130.6
A28: 42886 | B28: 13012 | C28: MARZO | D28: LUZ | F28: 66.6 | G28: =+G27+E28-F28 -> 64
A29: 42886 | B29: 13012 | C29: MARZO | D29: AGUA | F29: 2 | G29: =+G28+E29-F29 -> 62
A30: 42949 | B30: 13362 | C30: MARZO | D30: P. SOCIAL | F30: 2 | G30: =+G29+E30-F30 -> 60
A31: 42949 | B31: 13362 | C31: MARZO | D31: G. ADM | F31: 60 | G31: =+G30+E31-F31 -> 0
A32: 42855 | B32: POR COBRAR | C32: ABRIL | D32: LUZ | E32: 69 | G32: =+G31+E32-F32 -> 69
D33: AGUA | E33: 2 | G33: =+G32+E33-F33 -> 71
D34: G. ADM | E34: 60 | G34: =+G33+E34-F34 -> 131
D35: P. SOCIAL | E35: 2 | G35: =+G34+E35-F35 -> 133
A36: 42886 | B36: 13012 | C36: ABRIL | D36: LUZ | F36: 69 | G36: =+G35+E36-F36 -> 64
A37: 42886 | B37: 13012 | C37: ABRIL | D37: AGUA | F37: 2 | G37: =+G36+E37-F37 -> 62
A38: 42949 | B38: 13362 | C38: ABRIL | D38: G. ADM | F38: 60 | G38: =+G37+E38-F38 -> 2
A39: 42949 | B39: 13362 | C39: ABRIL | D39: P. SOCIAL | F39: 2 | G39: =+G38+E39-F39 -> 0
A40: 42886 | B40: POR COBRAR | C40: MAYO | D40: LUZ | E40: 65.6 | G40: =+G39+E40-F40 -> 65.6
D41: AGUA | E41: 2 | G41: =+G40+E41-F41 -> 67.6
D42: G. ADM | E42: 60 | G42: =+G41+E42-F42 -> 127.6
...

Sheet SALAZAR VICTORIA
B2: SALAZAR CONCEPCION VICTORIA
A4: FECHA | B4: DOCUMENTO | C4: PERIODO | D4: CONCEPTO | E4: POR COBRAR | F4: PAGADO | G4: SALDO POR COBRAR
A5: 42736 | B5: SALDO AL 2016 | G5: 23.1
A6: 42758 | B6: 12147 | C6: CANCELADO | F6: 23.1 | G6: =+G5+E6-F6 -> 0
A7: 42766 | B7: POR COBRAR | C7: ENERO | D7: LUZ | E7: 20.4 | G7: =+G6+E7-F7 -> 20.4
D8: AGUA | E8: 2.8 | G8: =+G7+E8-F8 -> 23.2
D9: G. ADM | E9: 60 | G9: =+G8+E9-F9 -> 83.2
D10: P. SOCIAL | E10: 2 | G10: =+G9+E10-F10 -> 85.2
A11: 42766 | B11: TARJETA | C11: ENERO | D11: G. ADM | F11: 60 | G11: =+G10+E11-F11 -> 25.2
A12: 42766 | B12: TARJETA | C12: ENERO | D12: P. SOCIAL | F12: 2 | G12: =+G11+E12-F12 -> 23.2
A13: 42783 | B13: 12982 | C13: ENERO | D13: LUZ | F13: 20.4 | G13: =+G12+E13-F13 -> 2.8
A14: 42783 | B14: 12982 | C14: ENERO | D14: AGUA | F14: 2.8 | G14: =+G13+E14-F14 -> 4.4408921e-15
A15: 42794 | B15: POR COBRAR | C15: FEBRERO | D15: LUZ | E15: 19.6 | G15: =+G14+E15-F15 -> 19.6
D16: AGUA | E16: 2 | G16: =+G15+E16-F16 -> 21.6
D17: G. ADM | E17: 56 | G17: =+G16+E17-F17 -> 77.6
D18: P. SOCIAL | E18: 2 | G18: =+G17+E18-F18 -> 79.6
A19: 42794 | B19: TARJETA | C19: FEBRERO | D19: G. ADM | F19: 56 | G19: =+G18+E19-F19 -> 23.6
A20: 42794 | B20: TARJETA | C20: FEBRERO | D20: P. SOCIAL | F20: 2 | G20: =+G19+E20-F20 -> 21.6
A21: 42818 | B21: 12470 | C21: FEBRERO | D21: LUZ | F21: 19.6 | G21: =+G20+E21-F21 -> 2
A22: 42818 | B22: 12470 | C22: FEBRERO | D22: AGUA | F22: 2 | G22: =+G21+E22-F22 -> 7.1054274e-15 | K22: 5
A23: 42825 | B23: POR COBRAR | C23: MARZO | D23: LUZ | E23: 18.4 | G23: =+G22+E23-F23 -> 18.4 | K23: 36000.15
D24: AGUA | E24: 2 | G24: =+G23+E24-F24 -> 20.4 | K24: 3799.6
D25: G. ADM | E25: 60 | G25: =+G24+E25-F25 -> 80.4
D26: P. SOCIAL | E26: 2 | G26: =+G25+E26-F26 -> 82.4
A27: 42824 | B27: TARJETA | C27: MARZO | D27: G. ADM | F27: 60 | G27: =+G26+E27-F27 -> 22.4
A28: 42824 | B28: TARJETA | C28: MARZO | D28: P. SOCIAL | F28: 2 | G28: =+G27+E28-F28 -> 20.4
A29: 42857 | B29: 12713 | C29: MARZO | D29: LUZ | F29: 18.4 | G29: =+G28+E29-F29 -> 2
A30: 42857 | B30: 12713 | C30: MARZO | D30: AGUA | F30: 2 | G30: =+G29+E30-F30 -> 7.1054274e-15
A31: 42855 | B31: POR COBRAR | C31: ABRIL | D31: LUZ | E31: 19.5 | G31: =+G30+E31-F31 -> 19.5
D32: AGUA | E32: 2 | G32: =+G31+E32-F32 -> 21.5
D33: G. ADM | E33: 60 | G33: =+G32+E33-F33 -> 81.5
D34: P. SOCIAL | E34: 2 | G34: =+G33+E34-F34 -> 83.5
A35: 42854 | B35: TARJETA | C35: ABRIL | D35: G. ADM | F35: 60 | G35: =+G34+E35-F35 -> 23.5
A36: 42854 | B36: TARJETA | C36: ABRIL | D36: P. SOCIAL | F36: 2 | G36: =+G35+E36-F36 -> 21.5
A37: 42948 | B37: 13314 | C37: ABRIL | D37: LUZ | F37: 19.5 | G37: =+G36+E37-F37 -> 2
A38: 42948 | B38: 13314 | C38: ABRIL | D38: AGUA | F38: 2 | G38: =+G37+E38-F38 -> 0
A39: 42886 | B39: POR COBRAR | C39: MAYO | D39: LUZ | E39: 18.9 | G39: =+G38+E39-F39 -> 18.9
D40: AGUA | E40: 2 | G40: =+G39+E40-F40 -> 20.9
D41: G. ADM | E41: 60 | G41: =+G40+E41-F41 -> 80.9
D42: P. SOCIAL | E42: 2 | G42: =+G41+E42-F42 -> 82.9
...

Sheet SALVATIERRA ALLISON
A1: SALVATIERRA OQUENDO ALLISON ADRIANA | J1: SALVATIERRA AYALA JUAN
A4: FECHA | B4: DOCUMENTO | C4: PERIODO | D4: CONCEPTO | E4: POR COBRAR | F4: PAGADO | G4: SALDO POR COBRAR
A5: 42736 | B5: SALDO AL 2016 | G5: 425
A6: 42786 | B6: 12264 | C6: A CUENTA 2016 | F6: 359 | G6: =+G5+E6-F6 -> 66
A7: 42817 | B7: 12445 | C7: A CUENTA 2016 | F7: 66 | G7: =+G6+E7-F7 -> 0
A8: 42766 | B8: POR COBRAR | C8: ENERO | D8: LUZ | E8: 97 | G8: =+G7+E8-F8 -> 97
D9: AGUA | E9: 44.6 | G9: =+G8+E9-F9 -> 141.6
D10: G. ADM | E10: 60 | G10: =+G9+E10-F10 -> 201.6
D11: P. SOCIAL | E11: 2 | G11: =+G10+E11-F11 -> 203.6
D12: P.S.FALLEC. | E12: 10 | G12: =+G11+E12-F12 -> 213.6
A13: 42765 | B13: TARJETA | C13: ENERO | D13: G. ADM | F13: 60 | G13: =+G12+E13-F13 -> 153.6
A14: 42765 | B14: TARJETA | C14: ENERO | D14: P. SOCIAL | F14: 2 | G14: =+G13+E14-F14 -> 151.6
A15: 42817 | B15: 12446 | C15: ENERO | D15: P.S.FALLEC. | F15: 10 | G15: =+G14+E15-F15 -> 141.6
A16: 42844 | B16: 12652 | C16: ENERO | D16: LUZ | F16: 97 | G16: =+G15+E16-F16 -> 44.6
A17: 42844 | B17: 12652 | C17: ENERO | D17: AGUA | F17: 36 | G17: =+G16+E17-F17 -> 8.6
A18: 42841 | B18: 12656 | C18: ENERO | D18: AGUA | F18: 8.6 | G18: =+G17+E18-F18 -> 0
A19: 42794 | B19: POR COBRAR | C19: FEBRERO | D19: LUZ | E19: 97 | G19: =+G18+E19-F19 -> 97
D20: AGUA | E20: 36 | G20: =+G19+E20-F20 -> 133
D21: G. ADM | E21: 56 | G21: =+G20+E21-F21 -> 189
D22: P. SOCIAL | E22: 2 | G22: =+G21+E22-F22 -> 191
A23: 42793 | B23: TARJETA | D23: G. ADM | F23: 54 | G23: =+G22+E23-F23 -> 137
A24: 42795 | B24: 12387 | C24: FEBRERO | D24: G. ADM | F24: 2 | G24: =+G23+E24-F24 -> 135
A25: 42795 | B25: 12387 | C25: FEBRERO | D25: P. SOCIAL | F25: 2 | G25: =+G24+E25-F25 -> 133
A26: 42844 | B26: 12652 | C26: FEBRERO | D26: LUZ | F26: 67 | G26: =+G25+E26-F26 -> 66
A27: 42873 | B27: 12764 | C27: FEBRERO | D27: LUZ | F27: 30 | G27: =+G26+E27-F27 -> 36
A28: 42873 | B28: 12764 | C28: FEBRERO | D28: AGUA | F28: 36 | G28: =+G27+E28-F28 -> 0
A29: 42825 | B29: POR COBRAR | C29: MARZO | D29: LUZ | E29: 92.9 | G29: =+G28+E29-F29 -> 92.9
D30: AGUA | E30: 37.8 | G30: =+G29+E30-F30 -> 130.7
D31: G. ADM | E31: 60 | G31: =+G30+E31-F31 -> 190.7
D32: P. SOCIAL | E32: 2 | G32: =+G31+E32-F32 -> 192.7
A33: 42824 | B33: TARJETA | C33: MARZO | D33: G. ADM | F33: 60 | G33: =+G32+E33-F33 -> 132.7
A34: 42824 | B34: TARJETA | C34: MARZO | D34: P. SOCIAL | F34: 2 | G34: =+G33+E34-F34 -> 130.7
A35: 42873 | B35: 12764 | C35: MARZO | D35: LUZ | F35: 92.9 | G35: =+G34+E35-F35 -> 37.8
A36: 42873 | B36: 12764 | C36: MARZO | D36: AGUA | F36: 37.8 | G36: =+G35+E36-F36 -> 0
A37: 42855 | B37: POR COBRAR | C37: ABRIL | D37: LUZ | E37: 77.5 | G37: =+G36+E37-F37 -> 77.5
D38: AGUA | E38: 37 | G38: =+G37+E38-F38 -> 114.5
D39: G. ADM | E39: 60 | G39: =+G38+E39-F39 -> 174.5
D40: P. SOCIAL | E40: 2 | G40: =+G39+E40-F40 -> 176.5
A41: 42855 | B41: TARJETA | C41: ABRIL | D41: G. ADM | F41: 60 | G41: =+G40+E41-F41 -> 116.5
A42: 42855 | B42: TARJETA | C42: ABRIL | D42: P. SOCIAL | F42: 2 | G42: =+G41+E42-F42 -> 114.5
...

Sheet SANCHEZ JUDITH
B2: SANCHEZ RODRIGUEZ JUDITH IRIS
A4: FECHA | B4: DOCUMENTO | C4: PERIODO | D4: CONCEPTO | E4: POR COBRAR | F4: PAGADO | G4: SALDO POR COBRAR
A5: 42736 | B5: SALDO AL 2016 | G5: 479.3
A6: 42736 | B6: AGAU RESIDUAL | E6: 80 | G6: =+G5+E6-F6 -> 559.3
A7: 42736 | B7: 12059 | C7: A CUENTA 2016 | F7: 20 | G7: =+G6+E7-F7 -> 539.3
A8: 42740 | B8: 12073 | C8: A CUENTA 2016 | F8: 8 | G8: =+G7+E8-F8 -> 531.3
A9: 42758 | B9: 12136 | C9: A CUENTA 2016 | F9: 75.3 | G9: =+G8+E9-F9 -> 456
A10: 44847 | B10: 25615 | C10: A CUENTA 2016 | F10: 456 | G10: =+G9+E10-F10 -> 0
A11: 42766 | B11: POR COBRAR | C11: ENERO | D11: LUZ | E11: 57.1 | G11: =+G10+E11-F11 -> 57.1
D12: AGUA | E12: 15.5 | G12: =+G11+E12-F12 -> 72.6
D13: G. ADM | E13: 60 | G13: =+G12+E13-F13 -> 132.6
D14: P. SOCIAL | E14: 2 | G14: =+G13+E14-F14 -> 134.6
A15: 42763 | B15: TARJETA | C15: ENERO | D15: G. ADM | F15: 60 | G15: =+G14+E15-F15 -> 74.6
A16: 42763 | B16: TARJETA | C16: ENERO | D16: P. SOCIAL | F16: 2 | G16: =+G15+E16-F16 -> 72.6
A17: 42786 | B17: 12247 | C17: ENERO | D17: LUZ | F17: 57.1 | G17: =+G16+E17-F17 -> 15.5
A18: 42786 | B18: 12247 | C18: ENERO | D18: AGUA | F18: 15.5 | G18: =+G17+E18-F18 -> 0
A19: 42794 | B19: POR COBRAR | C19: FEBRERO | D19: LUZ | E19: 58.3 | G19: =+G18+E19-F19 -> 58.3
D20: AGUA | E20: 11 | G20: =+G19+E20-F20 -> 69.3
D21: G. ADM | E21: 56 | G21: =+G20+E21-F21 -> 125.3
D22: P. SOCIAL | E22: 2 | G22: =+G21+E22-F22 -> 127.3
A23: 42768 | B23: TARJETA | C23: FEBRERO | D23: G. ADM | F23: 56 | G23: =+G22+E23-F23 -> 71.3
A24: 42794 | B24: TARJETA | C24: FEBRERO | D24: P. SOCIAL | F24: 2 | G24: =+G23+E24-F24 -> 69.3
A25: 42816 | B25: 12436 | C25: FEBRERO | D25: LUZ | F25: 58.3 | G25: =+G24+E25-F25 -> 11
A26: 42816 | B26: 12436 | C26: FEBRERO | D26: AGUA | F26: 11 | G26: =+G25+E26-F26 -> 0
A27: 42825 | B27: POR COBRAR | C27: MARZO | D27: LUZ | E27: 55.7 | G27: =+G26+E27-F27 -> 55.7
D28: AGUA | E28: 11.3 | G28: =+G27+E28-F28 -> 67
D29: G. ADM | E29: 60 | G29: =+G28+E29-F29 -> 127
D30: P. SOCIAL | E30: 2 | G30: =+G29+E30-F30 -> 129
A31: 42825 | B31: TARJETA | C31: MARZO | D31: G. ADM | F31: 60 | G31: =+G30+E31-F31 -> 69
A32: 42825 | B32: TARJETA | C32: MARZO | D32: P. SOCIAL | F32: 2 | G32: =+G31+E32-F32 -> 67
A33: 42847 | B33: 12684 | C33: MARZO | D33: LUZ | F33: 55.7 | G33: =+G32+E33-F33 -> 11.3
A34: 42847 | B34: 12684 | C34: MARZO | D34: AGUA | F34: 11.3 | G34: =+G33+E34-F34 -> 0
A35: 42855 | B35: POR COBRAR | C35: ABRIL | D35: LUZ | E35: 57.1 | G35: =+G34+E35-F35 -> 57.1
D36: AGUA | E36: 11 | G36: =+G35+E36-F36 -> 68.1
D37: G. ADM | E37: 60 | G37: =+G36+E37-F37 -> 128.1
D38: P. SOCIAL | E38: 2 | G38: =+G37+E38-F38 -> 130.1
A39: 42854 | B39: TARJETA | C39: ABRIL | D39: G. ADM | F39: 60 | G39: =+G38+E39-F39 -> 70.1
A40: 42854 | B40: TARJETA | C40: ABRIL | D40: P. SOCIAL | F40: 2 | G40: =+G39+E40-F40 -> 68.1
A41: 42879 | B41: 12808 | C41: ABRIL | D41: LUZ | F41: 57.1 | G41: =+G40+E41-F41 -> 11
A42: 42879 | B42: 12808 | C42: ABRIL | D42: AGUA | F42: 11 | G42: =+G41+E42-F42 -> 0
...

Sheet SANCHEZ ASTO YOLANDA
B2: SANCHEZ ASTO DE TORRES YOLANDA
A4: FECHA | B4: DOCUMENTO | C4: PERIODO | D4: CONCEPTO | E4: POR COBRAR | F4: PAGADO | G4: SALDO POR COBRAR
A5: 42736 | B5: SALDO AL 2016 | G5: 153.4
A6: 42783 | B6: 12968 | C6: A CUENTA 2016 | F6: 153.4 | G6: =+G5+E6-F6 -> 0
A7: 42766 | B7: POR COBRAR | C7: ENERO | D7: LUZ | E7: 35.5 | G7: =+G6+E7-F7 -> 35.5
D8: AGUA | E8: 2.8 | G8: =+G7+E8-F8 -> 38.3
D9: G. ADM | E9: 60 | G9: =+G8+E9-F9 -> 98.3
D10: P. SOCIAL | E10: 2 | G10: =+G9+E10-F10 -> 100.3
B11: TARJETA | C11: ENERO | D11: G. ADM | F11: 60 | G11: =+G10+E11-F11 -> 40.3
B12: TARJETA | C12: ENERO | D12: P. SOCIAL | F12: 2 | G12: =+G11+E12-F12 -> 38.3
A13: 42786 | B13: 12228 | C13: ENERO | D13: AGUA | F13: 2.8 | G13: =+G12+E13-F13 -> 35.5
A14: 42786 | B14: 12228 | C14: ENERO | D14: LUZ | F14: 35.5 | G14: =+G13+E14-F14 -> 0
A15: 42794 | B15: POR COBRAR | C15: FEBRERO | D15: LUZ | E15: 43.7 | G15: =+G14+E15-F15 -> 43.7
D16: AGUA | E16: 2 | G16: =+G15+E16-F16 -> 45.7
D17: G. ADM | E17: 56 | G17: =+G16+E17-F17 -> 101.7
D18: P. SOCIAL | E18: 2 | G18: =+G17+E18-F18 -> 103.7
B19: TARJETA | C19: FEBRERO | D19: G. ADM | F19: 56 | G19: =+G18+E19-F19 -> 47.7
B20: TARJETA | C20: FEBRERO | D20: P. SOCIAL | F20: 2 | G20: =+G19+E20-F20 -> 45.7
A21: 42819 | B21: 12476 | C21: FEBRERO | D21: LUZ | F21: 43.7 | G21: =+G20+E21-F21 -> 2
A22: 42819 | B22: 12476 | C22: FEBRERO | D22: AGUA | F22: 2 | G22: =+G21+E22-F22 -> 0
A23: 42825 | B23: POR COBRAR | C23: MARZO | D23: LUZ | E23: 41 | G23: =+G22+E23-F23 -> 41
D24: AGUA | E24: 2 | G24: =+G23+E24-F24 -> 43
D25: G. ADM | E25: 60 | G25: =+G24+E25-F25 -> 103
D26: P. SOCIAL | E26: 2 | G26: =+G25+E26-F26 -> 105
B27: TARJETA | C27: MARZO | D27: G. ADM | F27: 60 | G27: =+G26+E27-F27 -> 45
B28: TARJETA | C28: MARZO | D28: P. SOCIAL | F28: 2 | G28: =+G27+E28-F28 -> 43
A29: 42884 | B29: 12854 | C29: MARZO | D29: LUZ | F29: 41 | G29: =+G28+E29-F29 -> 2
A30: 42884 | B30: 12854 | C30: MARZO | D30: AGUA | F30: 2 | G30: =+G29+E30-F30 -> 0
A31: 42855 | B31: POR COBRAR | C31: ABRIL | D31: LUZ | E31: 43.2 | G31: =+G30+E31-F31 -> 43.2
D32: AGUA | E32: 2 | G32: =+G31+E32-F32 -> 45.2
D33: G. ADM | E33: 60 | G33: =+G32+E33-F33 -> 105.2
D34: P. SOCIAL | E34: 2 | G34: =+G33+E34-F34 -> 107.2
B35: TARJETA | C35: ABRIL | D35: G. ADM | F35: 60 | G35: =+G34+E35-F35 -> 47.2
B36: TARJETA | C36: ABRIL | D36: P. SOCIAL | F36: 2 | G36: =+G35+E36-F36 -> 45.2
A37: 42884 | B37: 12854 | C37: ABRIL | D37: LUZ | F37: 43.2 | G37: =+G36+E37-F37 -> 2
A38: 42884 | B38: 12854 | C38: ABRIL | D38: AGUA | F38: 2 | G38: =+G37+E38-F38 -> 0
A39: 42886 | B39: POR COBRAR | C39: MAYO | D39: LUZ | E39: 41.8 | G39: =+G38+E39-F39 -> 41.8
D40: AGUA | E40: 2 | G40: =+G39+E40-F40 -> 43.8
D41: G. ADM | E41: 60 | G41: =+G40+E41-F41 -> 103.8
D42: P. SOCIAL | E42: 2 | G42: =+G41+E42-F42 -> 105.8
...

Sheet SANCHEZ LUCIA
B2: SANCHEZ SOTOS LUCIA
A4: FECHA | B4: DOCUMENTO | C4: PERIODO | D4: CONCEPTO | E4: POR COBRAR | F4: PAGADO | G4: SALDO POR COBRAR
A5: 42736 | B5: SALDO AL 2016 | G5: 122.9
A6: 42772 | B6: 12922 | C6: CANCELADO | F6: 122.9 | G6: =+G5+E6-F6 -> 0
A7: 42766 | B7: POR COBRAR | C7: ENERO | D7: LUZ | E7: 58.9 | G7: =+G6+E7-F7 -> 58.9
D8: AGUA | E8: 2.8 | G8: =+G7+E8-F8 -> 61.7
D9: G. ADM | E9: 60 | G9: =+G8+E9-F9 -> 121.7
D10: P. SOCIAL | E10: 2 | G10: =+G9+E10-F10 -> 123.7
A11: 42765 | B11: TARJETA | C11: ENERO | D11: G. ADM | F11: 60 | G11: =+G10+E11-F11 -> 63.7
A12: 42765 | B12: TARJETA | C12: ENERO | D12: P. SOCIAL | F12: 2 | G12: =+G11+E12-F12 -> 61.7
A13: 42803 | B13: 12410 | C13: ENERO | D13: AGUA | F13: 2.8 | G13: =+G12+E13-F13 -> 58.9
A14: 42803 | B14: 12410 | C14: ENERO | D14: LUZ | F14: 58.9 | G14: =+G13+E14-F14 -> 0
A15: 42794 | B15: POR COBRAR | C15: FEBRERO | D15: LUZ | E15: 59.2 | G15: =+G14+E15-F15 -> 59.2
D16: AGUA | E16: 2 | G16: =+G15+E16-F16 -> 61.2
D17: G. ADM | E17: 56 | G17: =+G16+E17-F17 -> 117.2
D18: P. SOCIAL | E18: 2 | G18: =+G17+E18-F18 -> 119.2
D19: MULTA | E19: 85 | G19: =+G18+E19-F19 -> 204.2
A20: 42794 | B20: TARJETA | C20: FEBRERO | D20: G. ADM | F20: 56 | G20: =+G19+E20-F20 -> 148.2
A21: 42794 | B21: TARJETA | C21: FEBRERO | D21: P. SOCIAL | F21: 2 | G21: =+G20+E21-F21 -> 146.2
A22: 42817 | B22: 12453 | C22: FEBRERO | D22: LUZ | F22: 59.2 | G22: =+G21+E22-F22 -> 87
A23: 42817 | B23: 12453 | C23: FEBRERO | D23: AGUA | F23: 2 | G23: =+G22+E23-F23 -> 85
A24: 42818 | B24: 12472 | C24: FEBRERO | D24: MULTA | F24: 85 | G24: =+G23+E24-F24 -> 0
A25: 42825 | B25: POR COBRAR | C25: MARZO | D25: LUZ | E25: 56 | G25: =+G24+E25-F25 -> 56
D26: AGUA | E26: 2 | G26: =+G25+E26-F26 -> 58
D27: G. ADM | E27: 60 | G27: =+G26+E27-F27 -> 118
D28: P. SOCIAL | E28: 2 | G28: =+G27+E28-F28 -> 120
A29: 42824 | B29: TARJETA | C29: MARZO | D29: G. ADM | F29: 60 | G29: =+G28+E29-F29 -> 60
A30: 42824 | B30: TARJETA | C30: MARZO | D30: P. SOCIAL | F30: 2 | G30: =+G29+E30-F30 -> 58
A31: 42849 | B31: 12694 | C31: MARZO | D31: LUZ | F31: 56 | G31: =+G30+E31-F31 -> 2
A32: 42849 | B32: 12694 | C32: MARZO | D32: AGUA | F32: 2 | G32: =+G31+E32-F32 -> 0
A33: 42855 | B33: POR COBRAR | C33: ABRIL | D33: LUZ | E33: 58.3 | G33: =+G32+E33-F33 -> 58.3
D34: AGUA | E34: 2 | G34: =+G33+E34-F34 -> 60.3
D35: G. ADM | E35: 60 | G35: =+G34+E35-F35 -> 120.3
D36: P. SOCIAL | E36: 2 | G36: =+G35+E36-F36 -> 122.3
A37: 42855 | B37: TARJETA | C37: ABRIL | D37: G. ADM | F37: 60 | G37: =+G36+E37-F37 -> 62.3
A38: 42855 | B38: TARJETA | C38: ABRIL | D38: P. SOCIAL | F38: 2 | G38: =+G37+E38-F38 -> 60.3
A39: 42884 | B39: 12857 | C39: ABRIL | D39: LUZ | F39: 58.3 | G39: =+G38+E39-F39 -> 2
A40: 42884 | B40: 12857 | C40: ABRIL | D40: AGUA | F40: 2 | G40: =+G39+E40-F40 -> 0
A41: 42886 | B41: POR COBRAR | C41: MAYO | D41: LUZ | E41: 55.7 | G41: =+G40+E41-F41 -> 55.7
D42: AGUA | E42: 2 | G42: =+G41+E42-F42 -> 57.7
...

Sheet SANTILLAN ZOILA
B2: SANTILLAN MESIA ZOILA
A4: FECHA | B4: DOCUMENTO | C4: PERIODO | D4: CONCEPTO | E4: POR COBRAR | F4: PAGADO | G4: SALDO POR COBRAR
A5: 42736 | B5: SALDO AL 2016 | G5: 186.8
A6: 42787 | B6: 12324 | C6: A CUENTA 2016 | F6: 62.8 | G6: =+G5+E6-F6 -> 124
A7: 42787 | B7: 12327 | C7: CANCELADO | F7: 124 | G7: =+G6+E7-F7 -> 0
A8: 42766 | B8: POR COBRAR | C8: ENERO | D8: LUZ | E8: 29.6 | G8: =+G7+E8-F8 -> 29.6
D9: AGUA | E9: 2.8 | G9: =+G8+E9-F9 -> 32.4
D10: G. ADM | E10: 60 | G10: =+G9+E10-F10 -> 92.4
D11: P. SOCIAL | E11: 2 | G11: =+G10+E11-F11 -> 94.4
A12: 42787 | B12: 12324 | C12: ENERO | D12: LUZ | F12: 29.6 | G12: =+G11+E12-F12 -> 64.8
A13: 42787 | B13: 12324 | C13: ENERO | D13: AGUA | F13: 2.8 | G13: =+G12+E13-F13 -> 62
A14: 42787 | B14: 12327 | C14: ENERO | D14: G. ADM | F14: 60 | G14: =+G13+E14-F14 -> 2
A15: 42787 | B15: 12327 | C15: ENERO | D15: P. SOCIAL | F15: 2 | G15: =+G14+E15-F15 -> 1.4210855e-14
A16: 42794 | B16: POR COBRAR | C16: FEBRERO | D16: LUZ | E16: 28.5 | G16: =+G15+E16-F16 -> 28.5
D17: AGUA | E17: 2 | G17: =+G16+E17-F17 -> 30.5
D18: G. ADM | E18: 56 | G18: =+G17+E18-F18 -> 86.5
D19: P. SOCIAL | E19: 2 | G19: =+G18+E19-F19 -> 88.5
A20: 42822 | B20: 12596 | C20: FEBRERO | D20: G. ADM | F20: 56 | G20: =+G19+E20-F20 -> 32.5
A21: 42822 | B21: 12596 | C21: FEBRERO | D21: P. SOCIAL | F21: 2 | G21: =+G20+E21-F21 -> 30.5
A22: 42822 | B22: 12596 | C22: FEBRERO | D22: LUZ | F22: 28.5 | G22: =+G21+E22-F22 -> 2
A23: 42822 | B23: 12596 | C23: FEBRERO | D23: AGUA | F23: 2 | G23: =+G22+E23-F23 -> 1.4210855e-14
A24: 42825 | B24: POR COBRAR | C24: MARZO | D24: LUZ | E24: 26.9 | G24: =+G23+E24-F24 -> 26.9
D25: AGUA | E25: 2 | G25: =+G24+E25-F25 -> 28.9
D26: G. ADM | E26: 60 | G26: =+G25+E26-F26 -> 88.9
D27: P. SOCIAL | E27: 2 | G27: =+G26+E27-F27 -> 90.9
A28: 42893 | B28: 13078 | C28: MARZO | D28: LUZ | F28: 26.9 | G28: =+G27+E28-F28 -> 64
A29: 42893 | B29: 13078 | C29: MARZO | D29: AGUA | F29: 2 | G29: =+G28+E29-F29 -> 62
A30: 42950 | B30: 13420 | C30: MARZO | D30: G. ADM | F30: 60 | G30: =+G29+E30-F30 -> 2
A31: 42950 | B31: 13420 | C31: MARZO | D31: P. SOCIAL | F31: 2 | G31: =+G30+E31-F31 -> 0
A32: 42855 | B32: POR COBRAR | C32: ABRIL | D32: LUZ | E32: 28.1 | G32: =+G31+E32-F32 -> 28.1
D33: AGUA | E33: 2 | G33: =+G32+E33-F33 -> 30.1
D34: G. ADM | E34: 60 | G34: =+G33+E34-F34 -> 90.1
D35: P. SOCIAL | E35: 2 | G35: =+G34+E35-F35 -> 92.1
A36: 42893 | B36: 13078 | C36: ABRIL | D36: LUZ | F36: 28.1 | G36: =+G35+E36-F36 -> 64
A37: 42893 | B37: 13078 | C37: ABRIL | D37: AGUA | F37: 2 | G37: =+G36+E37-F37 -> 62
A38: 42950 | B38: 13392 | C38: ABRIL | D38: P. SOCIAL | F38: 2 | G38: =+G37+E38-F38 -> 60
A39: 42950 | B39: 13392 | C39: ABRIL | D39: G. ADM | F39: 60 | G39: =+G38+E39-F39 -> 0
A40: 42886 | B40: POR COBRAR | C40: MAYO | D40: LUZ | E40: 26.9 | G40: =+G39+E40-F40 -> 26.9
D41: AGUA | E41: 2 | G41: =+G40+E41-F41 -> 28.9
D42: G. ADM | E42: 60 | G42: =+G41+E42-F42 -> 88.9
...

Sheet SEGOVIA  VILLAFUERTE
B2: SEGOVIA VILLAFUERTE DE PONCE JUSTINA
A4: FECHA | B4: DOCUMENTO | C4: PERIODO | D4: CONCEPTO | E4: POR COBRAR | F4: PAGADO | G4: SALDO POR COBRAR
A5: 42736 | B5: SALDO AL 2016 | G5: 183.8
A6: 42765 | B6: 12175 | C6: A CUENTA 2016 | F6: 62 | G6: =+G5+E6-F6 -> 121.8
A7: 42786 | B7: 12297 | C7: CANCELACION 2016 | F7: 121.8 | G7: =+G6+E7-F7 -> 0
A8: 42766 | B8: POR COBRAR | C8: ENERO | D8: LUZ | E8: 50.4 | G8: =+G7+E8-F8 -> 50.4
D9: AGUA | E9: 2.8 | G9: =+G8+E9-F9 -> 53.2
D10: G. ADM | E10: 60 | G10: =+G9+E10-F10 -> 113.2
D11: P. SOCIAL | E11: 2 | G11: =+G10+E11-F11 -> 115.2
A12: 42822 | B12: 12617 | C12: ENERO | D12: G. ADM | F12: 40 | G12: =+G11+E12-F12 -> 75.2
A13: 42766 | B13: TARJETA | C13: ENERO | D13: G. ADM | F13: 20 | G13: =+G12+E13-F13 -> 55.2
A14: 42766 | B14: TARJETA | C14: ENERO | D14: P. SOCIAL | F14: 2 | G14: =+G13+E14-F14 -> 53.2
A15: 42786 | B15: 12297 | C15: ENERO | D15: LUZ | F15: 50.4 | G15: =+G14+E15-F15 -> 2.8
A16: 42786 | B16: 12297 | C16: ENERO | D16: AGUA | F16: 2.8 | G16: =+G15+E16-F16 -> -9.7699626e-15
A17: 42794 | B17: POR COBRAR | C17: FEBRERO | D17: LUZ | E17: 72.4 | G17: =+G16+E17-F17 -> 72.4
D18: AGUA | E18: 2 | G18: =+G17+E18-F18 -> 74.4
D19: G. ADM | E19: 56 | G19: =+G18+E19-F19 -> 130.4 | K19: 16
D20: P. SOCIAL | E20: 2 | G20: =+G19+E20-F20 -> 132.4 | K20: 13 | M20: 164
D21: FALLECIMIENTO | E21: 10 | G21: =+G20+E21-F21 -> 142.4 | K21: 16 | M21: =185-M20 -> 21
A22: 42788 | B22: TARJETA | C22: FEBRERO | D22: FALLECIMIENTO | F22: 10 | G22: =+G21+E22-F22 -> 132.4 | K22: 16
A23: 42788 | B23: TARJETA | C23: FEBRERO | D23: G. ADM | F23: 56 | G23: =+G22+E23-F23 -> 76.4 | K23: 13
A24: 42788 | B24: TARJETA | C24: FEBRERO | D24: P. SOCIAL | F24: 2 | G24: =+G23+E24-F24 -> 74.4 | K24: 12
A25: 42822 | B25: 12618 | C25: FEBRERO | D25: LUZ | F25: 72.4 | G25: =+G24+E25-F25 -> 2 | K25: 2
A26: 42822 | B26: 12618 | C26: FEBRERO | D26: AGUA | F26: 2 | G26: =+G25+E26-F26 -> -2.8421709e-14
A27: 42825 | B27: POR COBRAR | C27: MARZO | D27: LUZ | E27: 47.4 | G27: =+G26+E27-F27 -> 47.4
D28: AGUA | E28: 2 | G28: =+G27+E28-F28 -> 49.4
D29: G. ADM | E29: 60 | G29: =+G28+E29-F29 -> 109.4
D30: P. SOCIAL | E30: 2 | G30: =+G29+E30-F30 -> 111.4
D31: P. SOCIAL X FALLEC. | E31: 10 | G31: =+G30+E31-F31 -> 121.4
A32: 42822 | B32: 12617 | C32: MARZO | D32: P. SOCIAL X FALLEC. | F32: 10 | G32: =+G31+E32-F32 -> 111.4
A33: 42825 | B33: 12625 | C33: MARZO | D33: G. ADM | F33: 60 | G33: =+G32+E33-F33 -> 51.4
A34: 42825 | B34: 12625 | C34: MARZO | D34: P. SOCIAL | F34: 2 | G34: =+G33+E34-F34 -> 49.4
A35: 42893 | B35: 13083 | C35: MARZO | D35: LUZ | F35: 47.4 | G35: =+G34+E35-F35 -> 2
A36: 42893 | B36: 13083 | C36: MARZO | D36: AGUA | F36: 2 | G36: =+G35+E36-F36 -> -2.1316282e-14
A37: 42855 | B37: POR COBRAR | C37: ABRIL | D37: LUZ | E37: 49.7 | G37: =+G36+E37-F37 -> 49.7
D38: AGUA | E38: 2 | G38: =+G37+E38-F38 -> 51.7
D39: G. ADM | E39: 60 | G39: =+G38+E39-F39 -> 111.7
D40: P. SOCIAL | E40: 2 | G40: =+G39+E40-F40 -> 113.7
A41: 42893 | B41: 13083 | C41: ABRIL | D41: LUZ | F41: 49.7 | G41: =+G40+E41-F41 -> 64
A42: 42893 | B42: 13083 | C42: ABRIL | D42: AGUA | F42: 2 | G42: =+G41+E42-F42 -> 62
...

Sheet SERMEÑO JAVIER
B2: SERMEÑO GUTIERREZ JAVIER YGNACIO
A4: FECHA | B4: DOCUMENTO | C4: PERIODO | D4: CONCEPTO | E4: POR COBRAR | F4: PAGADO | G4: SALDO POR COBRAR
A5: 42736 | B5: SALDO AL 2016 | G5: 433.3
A6: 42752 | B6: 12112 | C6: CANCELADO | F6: 433.3 | G6: =+G5+E6-F6 -> 0
A7: 42766 | B7: POR COBRAR | C7: ENERO | D7: LUZ | E7: 174.8 | G7: =+G6+E7-F7 -> 174.8
D8: AGUA | E8: 19.2 | G8: =+G7+E8-F8 -> 194
D9: G. ADM | E9: 60 | G9: =+G8+E9-F9 -> 254
D10: P. SOCIAL | E10: 2 | G10: =+G9+E10-F10 -> 256
A11: 42765 | B11: TARJETA | C11: ENERO | D11: G. ADM | F11: 60 | G11: =+G10+E11-F11 -> 196
A12: 42765 | B12: TARJETA | C12: ENERO | D12: P. SOCIAL | F12: 2 | G12: =+G11+E12-F12 -> 194
A13: 42786 | B13: 12206 | C13: ENERO | D13: LUZ | F13: 174.8 | G13: =+G12+E13-F13 -> 19.2
A14: 42786 | B14: 12206 | C14: ENERO | D14: AGUA | F14: 19.2 | G14: =+G13+E14-F14 -> 0
A15: 42794 | B15: POR COBRAR | C15: FEBRERO | D15: LUZ | E15: 179.6 | G15: =+G14+E15-F15 -> 179.6
D16: AGUA | E16: 13 | G16: =+G15+E16-F16 -> 192.6
D17: G. ADM | E17: 56 | G17: =+G16+E17-F17 -> 248.6
D18: P. SOCIAL | E18: 2 | G18: =+G17+E18-F18 -> 250.6
A19: 42794 | B19: TARJETA | C19: FEBRERO | D19: G. ADM | F19: 56 | G19: =+G18+E19-F19 -> 194.6
A20: 42794 | B20: TARJETA | C20: FEBRERO | D20: P. SOCIAL | F20: 2 | G20: =+G19+E20-F20 -> 192.6
A21: 42821 | B21: 12534 | C21: FEBRERO | D21: LUZ | F21: 179.6 | G21: =+G20+E21-F21 -> 13
A22: 42821 | B22: 12534 | C22: FEBRERO | D22: AGUA | F22: 13 | G22: =+G21+E22-F22 -> 0
A23: 42825 | B23: POR COBRAR | C23: MARZO | D23: LUZ | E23: 172 | G23: =+G22+E23-F23 -> 172
D24: AGUA | E24: 14 | G24: =+G23+E24-F24 -> 186
D25: G. ADM | E25: 60 | G25: =+G24+E25-F25 -> 246
D26: P. SOCIAL | E26: 2 | G26: =+G25+E26-F26 -> 248
D27: P. SOCIAL X FALLEC. | E27: 10 | G27: =+G26+E27-F27 -> 258
A28: 42822 | B28: 12581 | C28: MARZO | D28: P. SOCIAL X FALLEC. | F28: 10 | G28: =+G27+E28-F28 -> 248
A29: 42825 | B29: TARJETA | C29: MARZO | D29: G. ADM | F29: 60 | G29: =+G28+E29-F29 -> 188
A30: 42825 | B30: TARJETA | C30: MARZO | D30: P. SOCIAL | F30: 2 | G30: =+G29+E30-F30 -> 186
A31: 42846 | B31: 12678 | C31: MARZO | D31: LUZ | F31: 172 | G31: =+G30+E31-F31 -> 14
A32: 42846 | B32: 12678 | C32: MARZO | D32: AGUA | F32: 14 | G32: =+G31+E32-F32 -> 0
A33: 42855 | B33: POR COBRAR | C33: ABRIL | D33: LUZ | E33: 175.4 | G33: =+G32+E33-F33 -> 175.4
D34: AGUA | E34: 13.7 | G34: =+G33+E34-F34 -> 189.1
D35: G. ADM | E35: 60 | G35: =+G34+E35-F35 -> 249.1
D36: P. SOCIAL | E36: 2 | G36: =+G35+E36-F36 -> 251.1
A37: 42854 | B37: TARJETA | C37: ABRIL | D37: G. ADM | F37: 60 | G37: =+G36+E37-F37 -> 191.1
A38: 42854 | B38: TARJETA | C38: ABRIL | D38: P. SOCIAL | F38: 2 | G38: =+G37+E38-F38 -> 189.1
A39: 42886 | B39: 13009 | C39: ABRIL | D39: LUZ | F39: 175.4 | G39: =+G38+E39-F39 -> 13.7
A40: 42886 | B40: 13009 | C40: ABRIL | D40: AGUA | F40: 13.7 | G40: =+G39+E40-F40 -> 0
A41: 42886 | B41: POR COBRAR | C41: MAYO | D41: LUZ | E41: 163.6 | G41: =+G40+E41-F41 -> 163.6
D42: AGUA | E42: 13.4 | G42: =+G41+E42-F42 -> 177
...

Sheet Soria Tapia Edith
B2: EDITH CATALINA SORIA TAPIA
A4: FECHA | B4: DOCUMENTO | C4: PERIODO | D4: CONCEPTO | E4: POR COBRAR | F4: PAGADO | G4: SALDO POR COBRAR
A5: 42736 | B5: SALDO AL 2016 | G5: 763.6
A6: 42739 | B6: 12065 | C6: A CUENTA 2016 | F6: 496.5 | G6: =+G5+E6-F6 -> 267.1
A7: 42739 | B7: 12066 | C7: A CUENTA 2016 | F7: 9 | G7: =+G6+E7-F7 -> 258.1
A8: 42910 | B8: 13149 | C8: A CUENTA 2016 | F8: 171.1 | G8: =+G7+E8-F8 -> 87
A9: 42912 | B9: 13153 | C9: A CUENTA 2016 | F9: 3 | G9: =+G8+E9-F9 -> 84
A10: 43368 | B10: 16248 | C10: A CUENTA 2016 | F10: 59 | G10: =+G9+E10-F10 -> 25
F11: 25 | G11: =+G10+E11-F11 -> 2.8421709e-14
A12: 42766 | B12: POR COBRAR | C12: ENERO | D12: LUZ | E12: 163 | G12: =+G11+E12-F12 -> 163
D13: AGUA | E13: 2 | G13: =+G12+E13-F13 -> 165
D14: G. ADM | E14: 60 | G14: =+G13+E14-F14 -> 225
D15: P. SOCIAL | E15: 2 | G15: =+G14+E15-F15 -> 227
A16: 42875 | B16: 12785 | C16: ENERO | D16: G. ADM | F16: 60 | G16: =+G15+E16-F16 -> 167
A17: 42875 | B17: 12785 | C17: ENERO | D17: P. SOCIAL | F17: 2 | G17: =+G16+E17-F17 -> 165
A18: 42910 | B18: 13149 | C18: ENERO | D18: LUZ | F18: 163 | G18: =+G17+E18-F18 -> 2
A19: 42912 | B19: 13153 | C19: ENERO | D19: AGUA | F19: 2 | G19: =+G18+E19-F19 -> 2.8421709e-14
A20: 42794 | B20: POR COBRAR | C20: FEBRERO | D20: LUZ | E20: 167 | G20: =+G19+E20-F20 -> 167
D21: AGUA | E21: 2 | G21: =+G20+E21-F21 -> 169
D22: G. ADM | E22: 56 | G22: =+G21+E22-F22 -> 225
D23: P. SOCIAL | E23: 2 | G23: =+G22+E23-F23 -> 227
D24: MULTA | E24: 85 | G24: =+G23+E24-F24 -> 312
A25: 42875 | B25: 12785 | C25: FEBRERO | D25: G. ADM | F25: 56 | G25: =+G24+E25-F25 -> 256
A26: 42875 | B26: 12785 | C26: FEBRERO | D26: P. SOCIAL | F26: 2 | G26: =+G25+E26-F26 -> 254
A27: 42910 | B27: 13149 | C27: FEBRERO | D27: LUZ | F27: 167 | G27: =+G26+E27-F27 -> 87
A28: 42912 | B28: 13153 | C28: FEBRERO | D28: AGUA | F28: 2 | G28: =+G27+E28-F28 -> 85
A29: 43067 | B29: EXONERACION | C29: FEBRERO | D29: MULTA | F29: 85 | G29: =+G28+E29-F29 -> 0
A30: 42825 | B30: POR COBRAR | C30: MARZO | D30: LUZ | E30: 160.3 | G30: =+G29+E30-F30 -> 160.3
D31: AGUA | E31: 2 | G31: =+G30+E31-F31 -> 162.3
D32: G. ADM | E32: 60 | G32: =+G31+E32-F32 -> 222.3
D33: P. SOCIAL | E33: 2 | G33: =+G32+E33-F33 -> 224.3
A34: 42875 | B34: 12785 | C34: MARZO | D34: G. ADM | F34: 60 | G34: =+G33+E34-F34 -> 164.3
A35: 42875 | B35: 12785 | C35: MARZO | D35: P. SOCIAL | F35: 2 | G35: =+G34+E35-F35 -> 162.3
A36: 42910 | B36: 13149 | C36: MARZO | D36: LUZ | F36: 160.3 | G36: =+G35+E36-F36 -> 2
A37: 42912 | B37: 13153 | C37: MARZO | D37: AGUA | F37: 2 | G37: =+G36+E37-F37 -> 0
A38: 42855 | B38: POR COBRAR | C38: ABRIL | D38: LUZ | E38: 164.2 | G38: =+G37+E38-F38 -> 164.2
D39: AGUA | E39: 2 | G39: =+G38+E39-F39 -> 166.2
D40: G. ADM | E40: 60 | G40: =+G39+E40-F40 -> 226.2
D41: P. SOCIAL | E41: 2 | G41: =+G40+E41-F41 -> 228.2
A42: 42875 | B42: 12785 | C42: ABRIL | D42: G. ADM | F42: 60 | G42: =+G41+E42-F42 -> 168.2
...

Sheet SOSA JUANA
B2: SOSA VALDIVIA JUANA
A4: FECHA | B4: DOCUMENTO | C4: PERIODO | D4: CONCEPTO | E4: POR COBRAR | F4: PAGADO | G4: SALDO POR COBRAR
A5: 42736 | B5: SALDO AL 2016 | G5: 38.9
A6: 42786 | B6: 12278 | C6: CANCELADO | F6: 38.9 | G6: =+G5+E6-F6 -> 0
A7: 42766 | B7: POR COBRAR | C7: ENERO | D7: LUZ | E7: 44.1 | G7: =+G6+E7-F7 -> 44.1
D8: AGUA | E8: 2.8 | G8: =+G7+E8-F8 -> 46.9
D9: G. ADM | E9: 60 | G9: =+G8+E9-F9 -> 106.9
D10: P. SOCIAL | E10: 2 | G10: =+G9+E10-F10 -> 108.9
A11: 42756 | B11: 12130 | C11: ENERO | D11: G. ADM | F11: 60 | G11: =+G10+E11-F11 -> 48.9
A12: 42756 | B12: 12130 | C12: ENERO | D12: P. SOCIAL | F12: 2 | G12: =+G11+E12-F12 -> 46.9
A13: 42786 | B13: 12278 | C13: ENERO | D13: LUZ | F13: 44.1 | G13: =+G12+E13-F13 -> 2.8
A14: 42786 | B14: 12278 | C14: ENERO | D14: AGUA | F14: 2.8 | G14: =+G13+E14-F14 -> 4.4408921e-15
A15: 42794 | B15: POR COBRAR | C15: FEBRERO | D15: LUZ | E15: 43.7 | G15: =+G14+E15-F15 -> 43.7
D16: AGUA | E16: 2 | G16: =+G15+E16-F16 -> 45.7
D17: G. ADM | E17: 60 | G17: =+G16+E17-F17 -> 105.7
D18: P. SOCIAL | E18: 2 | G18: =+G17+E18-F18 -> 107.7
A19: 42782 | B19: 12960 | C19: FEBRERO | D19: G. ADM | F19: 60 | G19: =+G18+E19-F19 -> 47.7
A20: 42782 | B20: 12960 | C20: FEBRERO | D20: P. SOCIAL | F20: 2 | G20: =+G19+E20-F20 -> 45.7
A21: 42822 | B21: 12603 | C21: FEBRERO | D21: AGUA | F21: 2 | G21: =+G20+E21-F21 -> 43.7
A22: 42822 | B22: 12603 | C22: FEBRERO | D22: LUZ | F22: 43.7 | G22: =+G21+E22-F22 -> 0
A23: 42825 | B23: POR COBRAR | C23: MARZO | D23: LUZ | E23: 41 | G23: =+G22+E23-F23 -> 41
D24: AGUA | E24: 2 | G24: =+G23+E24-F24 -> 43
D25: G. ADM | E25: 60 | G25: =+G24+E25-F25 -> 103
D26: P. SOCIAL | E26: 2 | G26: =+G25+E26-F26 -> 105
A27: 42821 | B27: 12492 | C27: MARZO | D27: G. ADM | F27: 60 | G27: =+G26+E27-F27 -> 45
A28: 42821 | B28: 12492 | C28: MARZO | D28: P. SOCIAL | F28: 2 | G28: =+G27+E28-F28 -> 43
A29: 42885 | B29: 12876 | C29: MARZO | D29: AGUA | F29: 2 | G29: =+G28+E29-F29 -> 41
A30: 42885 | B30: 12876 | C30: MARZO | D30: LUZ | F30: 41 | G30: =+G29+E30-F30 -> 0
A31: 42855 | B31: POR COBRAR | C31: ABRIL | D31: LUZ | E31: 43.2 | G31: =+G30+E31-F31 -> 43.2
D32: AGUA | E32: 2 | G32: =+G31+E32-F32 -> 45.2
D33: G. ADM | E33: 60 | G33: =+G32+E33-F33 -> 105.2
D34: P. SOCIAL | E34: 2 | G34: =+G33+E34-F34 -> 107.2
A35: 42877 | B35: 12801 | C35: ABRIL | D35: G. ADM | F35: 60 | G35: =+G34+E35-F35 -> 47.2
A36: 42877 | B36: 12801 | C36: ABRIL | D36: P. SOCIAL | F36: 2 | G36: =+G35+E36-F36 -> 45.2
A37: 42885 | B37: 12876 | C37: ABRIL | D37: AGUA | F37: 2 | G37: =+G36+E37-F37 -> 43.2
A38: 42885 | B38: 12876 | C38: ABRIL | D38: LUZ | F38: 43.2 | G38: =+G37+E38-F38 -> 0
A39: 42886 | B39: POR COBRAR | C39: MAYO | D39: LUZ | E39: 41.8 | G39: =+G38+E39-F39 -> 41.8
D40: AGUA | E40: 2 | G40: =+G39+E40-F40 -> 43.8
D41: G. ADM | E41: 60 | G41: =+G40+E41-F41 -> 103.8
D42: P. SOCIAL | E42: 2 | G42: =+G41+E42-F42 -> 105.8
...

Sheet SOTO SOFIA
B2: SOTO GALLEGO DE VALERO SOFIA
A4: FECHA | B4: DOCUMENTO | C4: PERIODO | D4: CONCEPTO | E4: POR COBRAR | F4: PAGADO | G4: SALDO POR COBRAR
A5: 42736 | B5: SALDO AL 2016 | G5: 372
A6: 42887 | B6: AGUA RESIDUAL | E6: 45.6 | G6: =+G5+E6-F6 -> 417.6
A7: 42745 | B7: 12088 | C7: A CUENTA 2016 | F7: 372 | G7: =+G6+E7-F7 -> 45.6
A8: 42887 | B8: 13025 | C8: CANCELACION DEL 2016 | F8: 45.6 | G8: =+G7+E8-F8 -> 0
A9: 42766 | B9: POR COBRAR | C9: ENERO | D9: LUZ | E9: 19.9 | G9: =+G8+E9-F9 -> 19.9
D10: AGUA | E10: 2.7 | G10: =+G9+E10-F10 -> 22.6
D11: G. ADM | E11: 60 | G11: =+G10+E11-F11 -> 82.6
D12: P. SOCIAL | E12: 2 | G12: =+G11+E12-F12 -> 84.6
A13: 42818 | B13: 12462 | C13: ENERO | D13: G. ADM | F13: 60 | G13: =+G12+E13-F13 -> 24.6
A14: 42818 | B14: 12462 | C14: ENERO | D14: P. SOCIAL | F14: 2 | G14: =+G13+E14-F14 -> 22.6
A15: 42887 | B15: 13025 | C15: ENERO | D15: LUZ | F15: 2.7 | G15: =+G14+E15-F15 -> 19.9
A16: 42887 | B16: 13025 | C16: ENERO | D16: AGUA | F16: 19.9 | G16: =+G15+E16-F16 -> 0
A17: 42794 | B17: POR COBRAR | C17: FEBRERO | D17: LUZ | E17: 19.6 | G17: =+G16+E17-F17 -> 19.6
D18: AGUA | E18: 2 | G18: =+G17+E18-F18 -> 21.6
D19: G. ADM | E19: 56 | G19: =+G18+E19-F19 -> 77.6
D20: P. SOCIAL | E20: 2 | G20: =+G19+E20-F20 -> 79.6
A21: 42818 | B21: 12462 | C21: FEBRERO | D21: G. ADM | F21: 56 | G21: =+G20+E21-F21 -> 23.6
A22: 42818 | B22: 12462 | C22: FEBRERO | D22: P. SOCIAL | F22: 2 | G22: =+G21+E22-F22 -> 21.6
A23: 42887 | B23: 13025 | C23: FEBRERO | D23: LUZ | F23: 19.6 | G23: =+G22+E23-F23 -> 2
A24: 42887 | B24: 13025 | C24: FEBRERO | D24: AGUA | F24: 2 | G24: =+G23+E24-F24 -> -7.1054274e-15
A25: 42825 | B25: POR COBRAR | C25: MARZO | D25: LUZ | E25: 18.4 | G25: =+G24+E25-F25 -> 18.4
D26: AGUA | E26: 2 | G26: =+G25+E26-F26 -> 20.4
D27: G. ADM | E27: 60 | G27: =+G26+E27-F27 -> 80.4
D28: P. SOCIAL | E28: 2 | G28: =+G27+E28-F28 -> 82.4
A29: 42887 | B29: 13025 | C29: MARZO | D29: LUZ | F29: 18.4 | G29: =+G28+E29-F29 -> 64
A30: 42887 | B30: 13025 | C30: MARZO | D30: AGUA | F30: 2 | G30: =+G29+E30-F30 -> 62
A31: 42926 | B31: 13193 | C31: MARZO | D31: G. ADM | F31: 60 | G31: =+G30+E31-F31 -> 2
A32: 42926 | B32: 13193 | C32: MARZO | D32: P. SOCIAL | F32: 2 | G32: =+G31+E32-F32 -> -7.1054274e-15
A33: 42855 | B33: POR COBRAR | C33: ABRIL | D33: LUZ | E33: 19.5 | G33: =+G32+E33-F33 -> 19.5
D34: AGUA | E34: 2 | G34: =+G33+E34-F34 -> 21.5
D35: G. ADM | E35: 60 | G35: =+G34+E35-F35 -> 81.5
D36: P. SOCIAL | E36: 2 | G36: =+G35+E36-F36 -> 83.5
A37: 42887 | B37: 13025 | C37: ABRIL | D37: LUZ | F37: 19.5 | G37: =+G36+E37-F37 -> 64
A38: 42887 | B38: 13025 | C38: ABRIL | D38: AGUA | F38: 2 | G38: =+G37+E38-F38 -> 62
A39: 42926 | B39: 13193 | C39: ABRIL | D39: G. ADM | F39: 60 | G39: =+G38+E39-F39 -> 2
A40: 42926 | B40: 13193 | C40: ABRIL | D40: P. SOCIAL | F40: 2 | G40: =+G39+E40-F40 -> 0
A41: 42886 | B41: POR COBRAR | C41: MAYO | D41: LUZ | E41: 18.9 | G41: =+G40+E41-F41 -> 18.9
D42: AGUA | E42: 2 | G42: =+G41+E42-F42 -> 20.9
...

Sheet SOTO MARIA 
B2: SOTO VARGAS DE FLORES MARIA DEL CARMEN
A4: FECHA | B4: DOCUMENTO | C4: PERIODO | D4: CONCEPTO | E4: POR COBRAR | F4: PAGADO | G4: SALDO POR COBRAR
A5: 42736 | B5: SALDO AL 2016 | G5: 23.1
A6: 42787 | B6: 12354 | C6: A CUENTA 2016 | F6: 23.1 | G6: =+G5+E6-F6 -> 0
A7: 42766 | B7: POR COBRAR | C7: ENERO | D7: LUZ | E7: 19.9 | G7: =+G6+E7-F7 -> 19.9
D8: AGUA | E8: 2.8 | G8: =+G7+E8-F8 -> 22.7
D9: G. ADM | E9: 60 | G9: =+G8+E9-F9 -> 82.7
D10: P. SOCIAL | E10: 2 | G10: =+G9+E10-F10 -> 84.7
A11: 42766 | B11: TARJETA | C11: ENERO | D11: G. ADM | F11: 60 | G11: =+G10+E11-F11 -> 24.7
A12: 42766 | B12: TARJETA | C12: ENERO | D12: P. SOCIAL | F12: 2 | G12: =+G11+E12-F12 -> 22.7
A13: 42787 | B13: 12353 | C13: ENERO | D13: LUZ | F13: 19.9 | G13: =+G12+E13-F13 -> 2.8
A14: 42787 | B14: 12353 | C14: ENERO | D14: AGUA | F14: 2.8 | G14: =+G13+E14-F14 -> 4.4408921e-15
A15: 42794 | B15: POR COBRAR | C15: FEBRERO | D15: LUZ | E15: 21.8 | G15: =+G14+E15-F15 -> 21.8
D16: AGUA | E16: 2 | G16: =+G15+E16-F16 -> 23.8
D17: G. ADM | E17: 56 | G17: =+G16+E17-F17 -> 79.8
D18: P. SOCIAL | E18: 2 | G18: =+G17+E18-F18 -> 81.8
A19: 42794 | B19: TARJETA | C19: FEBRERO | D19: G. ADM | F19: 56 | G19: =+G18+E19-F19 -> 25.8
A20: 42794 | B20: TARJETA | C20: FEBRERO | D20: P. SOCIAL | F20: 2 | G20: =+G19+E20-F20 -> 23.8
A21: 42819 | B21: 12477 | C21: FEBRERO | D21: LUZ | F21: 21.8 | G21: =+G20+E21-F21 -> 2
A22: 42819 | B22: 12477 | C22: FEBRERO | D22: AGUA | F22: 2 | G22: =+G21+E22-F22 -> 1.0658141e-14
A23: 42825 | B23: POR COBRAR | C23: MARZO | D23: LUZ | E23: 20.5 | G23: =+G22+E23-F23 -> 20.5
D24: AGUA | E24: 2 | G24: =+G23+E24-F24 -> 22.5
D25: G. ADM | E25: 60 | G25: =+G24+E25-F25 -> 82.5
D26: P. SOCIAL | E26: 2 | G26: =+G25+E26-F26 -> 84.5
A27: 42823 | B27: TARJETA | C27: MARZO | D27: G. ADM | F27: 60 | G27: =+G26+E27-F27 -> 24.5
A28: 42823 | B28: TARJETA | C28: MARZO | D28: P. SOCIAL | F28: 2 | G28: =+G27+E28-F28 -> 22.5
A29: 42884 | B29: 12858 | C29: MARZO | D29: LUZ | F29: 20.5 | G29: =+G28+E29-F29 -> 2
A30: 42884 | B30: 12858 | C30: MARZO | D30: AGUA | F30: 2 | G30: =+G29+E30-F30 -> 1.4210855e-14
A31: 42855 | B31: POR COBRAR | C31: ABRIL | D31: LUZ | E31: 21.6 | G31: =+G30+E31-F31 -> 21.6
D32: AGUA | E32: 2 | G32: =+G31+E32-F32 -> 23.6
D33: G. ADM | E33: 60 | G33: =+G32+E33-F33 -> 83.6
D34: P. SOCIAL | E34: 2 | G34: =+G33+E34-F34 -> 85.6
A35: 42855 | B35: TARJETA | C35: ABRIL | D35: G. ADM | F35: 60 | G35: =+G34+E35-F35 -> 25.6
A36: 42855 | B36: TARJETA | C36: ABRIL | D36: P. SOCIAL | F36: 2 | G36: =+G35+E36-F36 -> 23.6
A37: 42884 | B37: 12858 | C37: ABRIL | D37: LUZ | F37: 21.6 | G37: =+G36+E37-F37 -> 2
A38: 42884 | B38: 12858 | C38: ABRIL | D38: AGUA | F38: 2 | G38: =+G37+E38-F38 -> 2.1316282e-14
A39: 42886 | B39: POR COBRAR | C39: MAYO | D39: LUZ | E39: 20.9 | G39: =+G38+E39-F39 -> 20.9
D40: AGUA | E40: 2 | G40: =+G39+E40-F40 -> 22.9
D41: G. ADM | E41: 60 | G41: =+G40+E41-F41 -> 82.9
D42: P. SOCIAL | E42: 2 | G42: =+G41+E42-F42 -> 84.9
...

Sheet ORDOÑEZ AZUL
B2: ORDOÑEZ NICHO AZUL CARILE
A4: FECHA | B4: DOCUMENTO | C4: PERIODO | D4: CONCEPTO | E4: POR COBRAR | F4: PAGADO | G4: SALDO POR COBRAR
A5: 42736 | B5: SALDO AL 2016 | G5: 384.6
A6: 42784 | B6: 12991 | C6: A CUENTA 2016 | F6: 299.6 | G6: =+G5+E6-F6 -> 85
A7: 185-02 | B7: 12994 | C7: A CUENTA 2016 | F7: 85 | G7: =+G6+E7-F7 -> 0
A8: 42766 | B8: POR COBRAR | C8: ENERO | D8: LUZ | E8: 66.7 | G8: =+G7+E8-F8 -> 66.7
D9: AGUA | E9: 2.8 | G9: =+G8+E9-F9 -> 69.5
D10: G. ADM | E10: 60 | G10: =+G9+E10-F10 -> 129.5
D11: P. SOCIAL | E11: 2 | G11: =+G10+E11-F11 -> 131.5
A12: 42784 | B12: 12991 | C12: ENERO | D12: LUZ | F12: 66.7 | G12: =+G11+E12-F12 -> 64.8
A13: 42784 | B13: 12991 | C13: ENERO | D13: AGUA | F13: 2.8 | G13: =+G12+E13-F13 -> 62
A14: 42784 | B14: 12991 | C14: ENERO | D14: G. ADM | F14: 60 | G14: =+G13+E14-F14 -> 2
A15: 42784 | B15: 12991 | C15: ENERO | D15: P. SOCIAL | F15: 2 | G15: =+G14+E15-F15 -> 0
A16: 42794 | B16: POR COBRAR | C16: FEBRERO | D16: LUZ | E16: 68.3 | G16: =+G15+E16-F16 -> 68.3
D17: AGUA | E17: 2 | G17: =+G16+E17-F17 -> 70.3
D18: G. ADM | E18: 56 | G18: =+G17+E18-F18 -> 126.3
D19: P. SOCIAL | E19: 2 | G19: =+G18+E19-F19 -> 128.3
A20: 42882 | B20: 12833 | C20: FEBRERO | D20: LUZ | F20: 68.3 | G20: =+G19+E20-F20 -> 60
A21: 42882 | B21: 12833 | C21: FEBRERO | D21: AGUA | F21: 2 | G21: =+G20+E21-F21 -> 58
A22: 42882 | B22: 12834 | C22: FEBRERO | D22: G. ADM | F22: 56 | G22: =+G21+E22-F22 -> 2
A23: 42882 | B23: 12834 | C23: FEBRERO | D23: P. SOCIAL | F23: 2 | G23: =+G22+E23-F23 -> 1.4210855e-14
A24: 42825 | B24: POR COBRAR | C24: MARZO | D24: LUZ | E24: 65.3 | G24: =+G23+E24-F24 -> 65.3
D25: AGUA | E25: 2 | G25: =+G24+E25-F25 -> 67.3
D26: G. ADM | E26: 60 | G26: =+G25+E26-F26 -> 127.3
D27: P. SOCIAL | E27: 2 | G27: =+G26+E27-F27 -> 129.3
A28: 42882 | B28: 12833 | C28: MARZO | D28: LUZ | F28: 65.3 | G28: =+G27+E28-F28 -> 64
A29: 42882 | B29: 12833 | C29: MARZO | D29: AGUA | F29: 2 | G29: =+G28+E29-F29 -> 62
A30: 42882 | B30: 12834 | C30: MARZO | D30: G. ADM | F30: 60 | G30: =+G29+E30-F30 -> 2
A31: 42882 | B31: 12834 | C31: MARZO | D31: P. SOCIAL | F31: 2 | G31: =+G30+E31-F31 -> 1.4210855e-14
A32: 42855 | B32: POR COBRAR | C32: ABRIL | D32: LUZ | E32: 66.8 | G32: =+G31+E32-F32 -> 66.8
D33: AGUA | E33: 2 | G33: =+G32+E33-F33 -> 68.8
D34: G. ADM | E34: 60 | G34: =+G33+E34-F34 -> 128.8
D35: P. SOCIAL | E35: 2 | G35: =+G34+E35-F35 -> 130.8
A36: 42882 | B36: 12833 | C36: ABRIL | D36: LUZ | F36: 66.8 | G36: =+G35+E36-F36 -> 64
A37: 42882 | B37: 12833 | C37: ABRIL | D37: AGUA | F37: 2 | G37: =+G36+E37-F37 -> 62
A38: 42882 | B38: 12834 | C38: ABRIL | D38: G. ADM | F38: 60 | G38: =+G37+E38-F38 -> 2
A39: 42882 | B39: 12834 | C39: ABRIL | D39: P. SOCIAL | F39: 2 | G39: =+G38+E39-F39 -> 1.4210855e-14
A40: 42886 | B40: POR COBRAR | C40: MAYO | D40: LUZ | E40: 62 | G40: =+G39+E40-F40 -> 62
D41: AGUA | E41: 2 | G41: =+G40+E41-F41 -> 64
D42: G. ADM | E42: 60 | G42: =+G41+E42-F42 -> 124
...

Sheet TAIPE EUGENIO
B2: TAIPE OQUENDO EUGENIO JOEL
A4: FECHA | B4: DOCUMENTO | C4: PERIODO | D4: CONCEPTO | E4: POR COBRAR | F4: PAGADO | G4: SALDO POR COBRAR
A5: 42736 | B5: SALDO AL 2016 | G5: 110.4
A6: 42783 | B6: 12969 | C6: A CUENTA 2016 | F6: 110.4 | G6: =+G5+E6-F6 -> 0
A7: 42766 | B7: POR COBRAR | C7: ENERO | D7: LUZ | E7: 52.6 | G7: =+G6+E7-F7 -> 52.6
D8: AGUA | E8: 2.8 | G8: =+G7+E8-F8 -> 55.4
D9: G. ADM | E9: 60 | G9: =+G8+E9-F9 -> 115.4
D10: P. SOCIAL | E10: 2 | G10: =+G9+E10-F10 -> 117.4
A11: 42765 | B11: TARJETA | D11: G. ADM | F11: 60 | G11: =+G10+E11-F11 -> 57.4
A12: 42765 | B12: TARJETA | D12: P. SOCIAL | F12: 2 | G12: =+G11+E12-F12 -> 55.4
A13: 42786 | B13: 12226 | C13: ENERO | D13: AGUA | F13: 2.8 | G13: =+G12+E13-F13 -> 52.6
A14: 42786 | B14: 12226 | C14: ENERO | D14: LUZ | F14: 52.6 | G14: =+G13+E14-F14 -> 0
A15: 42794 | B15: POR COBRAR | C15: FEBRERO | D15: LUZ | E15: 52.5 | G15: =+G14+E15-F15 -> 52.5
D16: AGUA | E16: 2 | G16: =+G15+E16-F16 -> 54.5
D17: G. ADM | E17: 56 | G17: =+G16+E17-F17 -> 110.5
D18: P. SOCIAL | E18: 2 | G18: =+G17+E18-F18 -> 112.5
A19: 42794 | B19: TARJETA | D19: G. ADM | F19: 56 | G19: =+G18+E19-F19 -> 56.5
A20: 42794 | B20: TARJETA | D20: P. SOCIAL | F20: 2 | G20: =+G19+E20-F20 -> 54.5
A21: 42819 | B21: 12475 | C21: FEBRERO | D21: LUZ | F21: 52.5 | G21: =+G20+E21-F21 -> 2
A22: 42819 | B22: 12475 | C22: FEBRERO | D22: AGUA | F22: 2 | G22: =+G21+E22-F22 -> 0
A23: 42825 | B23: POR COBRAR | C23: MARZO | D23: LUZ | E23: 49.6 | G23: =+G22+E23-F23 -> 49.6
D24: AGUA | E24: 2 | G24: =+G23+E24-F24 -> 51.6
D25: G. ADM | E25: 60 | G25: =+G24+E25-F25 -> 111.6
D26: P. SOCIAL | E26: 2 | G26: =+G25+E26-F26 -> 113.6
A27: 42824 | B27: TARJETA | D27: G. ADM | F27: 60 | G27: =+G26+E27-F27 -> 53.6
A28: 42824 | B28: TARJETA | D28: P. SOCIAL | F28: 2 | G28: =+G27+E28-F28 -> 51.6
A29: 42884 | B29: 12853 | C29: MARZO | D29: AGUA | F29: 2 | G29: =+G28+E29-F29 -> 49.6
A30: 42884 | B30: 12853 | C30: MARZO | D30: LUZ | F30: 49.6 | G30: =+G29+E30-F30 -> 0
A31: 42855 | B31: POR COBRAR | C31: ABRIL | D31: LUZ | E31: 51.8 | G31: =+G30+E31-F31 -> 51.8
D32: AGUA | E32: 2 | G32: =+G31+E32-F32 -> 53.8
D33: G. ADM | E33: 60 | G33: =+G32+E33-F33 -> 113.8
D34: P. SOCIAL | E34: 2 | G34: =+G33+E34-F34 -> 115.8
A35: 42855 | B35: TARJETA | D35: G. ADM | F35: 60 | G35: =+G34+E35-F35 -> 55.8
A36: 42855 | B36: TARJETA | D36: P. SOCIAL | F36: 2 | G36: =+G35+E36-F36 -> 53.8
A37: 42884 | B37: 12853 | C37: ABRIL | D37: LUZ | F37: 51.8 | G37: =+G36+E37-F37 -> 2
A38: 42884 | B38: 12853 | C38: ABRIL | D38: AGUA | F38: 2 | G38: =+G37+E38-F38 -> 0
A39: 42886 | B39: POR COBRAR | C39: MAYO | D39: LUZ | E39: 49.8 | G39: =+G38+E39-F39 -> 49.8
D40: AGUA | E40: 2 | G40: =+G39+E40-F40 -> 51.8
D41: G. ADM | E41: 60 | G41: =+G40+E41-F41 -> 111.8
D42: P. SOCIAL | E42: 2 | G42: =+G41+E42-F42 -> 113.8
...

Sheet TELLO MARINO
B2: TELLO ALVAREZ MARINO
A4: FECHA | B4: DOCUMENTO | C4: PERIODO | D4: CONCEPTO | E4: POR COBRAR | F4: PAGADO | G4: SALDO POR COBRAR
A5: 42736 | B5: SALDO AL 2016 | G5: 1892.1
A6: 42888 | B6: 13034 | C6: A CUENTA 2016 | D6: DEUDA | F6: 455.9 | G6: =+G5+E6-F6 -> 1436.2
A7: 42888 | B7: 13036 | C7: A CUENTA 2016 | D7: DEUDA | F7: 300 | G7: =+G6+E7-F7 -> 1136.2
A8: 44858 | B8: R25667 | C8: A CUENTA 2016 | D8: DEUDA | F8: 500 | G8: =+G7+E8-F8 -> 636.2
A9: 44896 | B9: R 25887 | C9: A CUENTA 2016 | D9: DEUDA | F9: 500 | G9: =+G8+E9-F9 -> 136.2
A10: 44925 | B10: R 26042 | C10: A CUENTA 2016 | D10: DEUDA | F10: 136.2 | G10: =+G9+E10-F10 -> 0
A11: 42766 | B11: POR COBRAR | C11: ENERO | D11: LUZ | E11: 110.9 | G11: =+G10+E11-F11 -> 110.9
D12: AGUA | E12: 2.8 | G12: =+G11+E12-F12 -> 113.7
D13: G. ADM | E13: 60 | G13: =+G12+E13-F13 -> 173.7
D14: P. SOCIAL | E14: 2 | G14: =+G13+E14-F14 -> 175.7
A15: 42765 | B15: TARJETA | C15: ENERO | D15: LUZ | F15: 103 | G15: =+G14+E15-F15 -> 72.7
A16: 42765 | B16: TARJETA | C16: ENERO | D16: G. ADM | F16: 60 | G16: =+G15+E16-F16 -> 12.7
A17: 42765 | B17: TARJETA | C17: ENERO | D17: P. SOCIAL | F17: 2 | G17: =+G16+E17-F17 -> 10.7
A18: 42888 | B18: 13033 | C18: ENERO | D18: LUZ | F18: 7.9 | G18: =+G17+E18-F18 -> 2.8
A19: 42888 | B19: 13033 | C19: ENERO | D19: AGUA | F19: 2.8 | G19: =+G18+E19-F19 -> -1.1546319e-14
A20: 42794 | B20: POR COBRAR | C20: FEBRERO | D20: LUZ | E20: 117.7 | G20: =+G19+E20-F20 -> 117.7
D21: AGUA | E21: 2 | G21: =+G20+E21-F21 -> 119.7
D22: G. ADM | E22: 56 | G22: =+G21+E22-F22 -> 175.7
D23: P. SOCIAL | E23: 2 | G23: =+G22+E23-F23 -> 177.7
D24: MULTA | E24: 85 | G24: =+G23+E24-F24 -> 262.7
A25: 42788 | B25: TARJETA | C25: FEBRERO | D25: LUZ | F25: 49 | G25: =+G24+E25-F25 -> 213.7
A26: 42788 | B26: TARJETA | C26: FEBRERO | D26: G. ADM | F26: 28 | G26: =+G25+E26-F26 -> 185.7
A27: 42888 | B27: 13033 | C27: FEBRERO | D27: LUZ | F27: 68.7 | G27: =+G26+E27-F27 -> 117
A28: 42888 | B28: 13033 | C28: FEBRERO | D28: AGUA | F28: 2 | G28: =+G27+E28-F28 -> 115
A29: 42947 | B29: TARJETA | C29: FEBRERO | D29: P. SOCIAL | F29: 2 | G29: =+G28+E29-F29 -> 113
A30: 43067 | B30: EXONERACION | C30: FEBRERO | D30: MULTA | F30: 85 | G30: =+G29+E30-F30 -> 28
A31: 44925 | B31: R 26042 | C31: FEBRERO | D31: G. ADM | F31: 28 | G31: =+G30+E31-F31 -> 0
A32: 42825 | B32: POR COBRAR | C32: MARZO | D32: LUZ | E32: 112.4 | G32: =+G31+E32-F32 -> 112.4
D33: AGUA | E33: 2 | G33: =+G32+E33-F33 -> 114.4
D34: G. ADM | E34: 60 | G34: =+G33+E34-F34 -> 174.4
D35: P. SOCIAL | E35: 2 | G35: =+G34+E35-F35 -> 176.4
A36: 42825 | B36: TARJETA | C36: MARZO | D36: LUZ | F36: 73.5 | G36: =+G35+E36-F36 -> 102.9
A37: 42825 | B37: TARJETA | C37: MARZO | D37: G. ADM | F37: 42 | G37: =+G36+E37-F37 -> 60.9
A38: 42888 | B38: 13033 | C38: MARZO | D38: LUZ | F38: 38.9 | G38: =+G37+E38-F38 -> 22
A39: 42888 | B39: 13033 | C39: MARZO | D39: AGUA | F39: 2 | G39: =+G38+E39-F39 -> 20
A40: 42947 | B40: TARJETA | C40: MARZO | D40: P. SOCIAL | F40: 2 | G40: =+G39+E40-F40 -> 18
A41: 44925 | B41: R 26042 | C41: MARZO | D41: G. ADM | F41: 18 | G41: =+G40+E41-F41 -> 0
A42: 42855 | B42: POR COBRAR | C42: ABRIL | D42: LUZ | E42: 115.5 | G42: =+G41+E42-F42 -> 115.5
...

Sheet TELLO EDGAR
B2: TELLO QUINTANA EDGAR
