Workbook

Sheet 01-04-2026
A1: INGRESOS DEL DIA 01-04-2026
A3: INQUILINO | B3: COMPROBANTE | C3: DETALLE | D3: LUZ | E3: AGUA | F3: ALQUILER | G3: ESPACIO | H3: PARQUEO | I3: TICKET | J3: TOTAL
A4: JOSE | B4: TK 50817 | C4: 46113 | I4: 10 | J4: =SUM(D4:I4) -> 10
J5: =SUM(D5:I5) -> 0
A6: SEVEN DAYS CORPORATION S.A.C. | B6: E001-356 | C6: 46113 | G6: 60 | J6: =SUM(D6:I6) -> 60
A7: ARGUELLO MANZANILLA NARCYS ALEXANDER | B7: E001-357 | C7: 46082 | F7: 130 | J7: =SUM(D7:I7) -> 130
J8: =SUM(D8:I8) -> 0
A9: MARI SOL QUISPE CHAVEZ | B9: EB01-7111 | C9: 46054 | F9: 100 | J9: =SUM(D9:I9) -> 100
A10: DIANA ZENAIDA SANCHEZ PRADO | B10: EB01-7112 | C10: 46082 | F10: 1000 | J10: =SUM(D10:I10) -> 1000
A11: ANATOLIA CHIPANA DE VARGAS | B11: EB01-7113 | C11: 46082 | F11: 200 | J11: =SUM(D11:I11) -> 200
A12: JANETT CONSUELO CASTRO RODRIGUEZ | B12: EB01-7114 | C12: 46023 | F12: 150 | J12: =SUM(D12:I12) -> 150
A13: DOMINICA LUCIANA FLORES LAREDO | B13: EB01-7115 | C13: 46023 | F13: 100 | J13: =SUM(D13:I13) -> 100
C14: 46054 | F14: 100 | J14: =SUM(D14:I14) -> 100
A15: MARY CRISPIN FLORES | B15: EB01-7116 | C15: 46113 | G15: 30 | J15: =SUM(D15:I15) -> 30
A16: PARQUEO | B16: EB01-7119 | C16: 46113 | J16: =SUM(D16:I16) -> 0
H17: 72.5 | J17: =SUM(D17:I17) -> 72.5
J18: =SUM(D18:I18) -> 0
J19: =SUM(D19:I19) -> 0
J20: =SUM(D20:I20) -> 0
J21: =SUM(D21:I21) -> 0
J22: =SUM(D22:I22) -> 0
J23: =SUM(D23:I23) -> 0
A24: TOTAL | D24: =SUM(D4:D23) -> 0 | E24: =SUM(E4:E23) -> 0 | F24: =SUM(F4:F23) -> 1780 | G24: =SUM(G4:G23) -> 90 | H24: =SUM(H4:H23) -> 72.5 | I24: =SUM(I4:I23) -> 10 | J24: =SUM(J4:J23) -> 1952.5
A26: BBVA
A27: INQUILINOS | B27: COMPROBANTE | C27: DETALLE | D27: LUZ | E27: AGUA | F27: ALQUILER | G27: ESPACIO | H27: DEPOSITO | I27: TICKET | J27: TOTAL
A28: SAYDA YUPANQUI QUISPE | B28: EB01-7117 | C28: 46082 | F28: 500 | J28: =SUM(D28:I28) -> 500
J29: =SUM(D29:I29) -> 0
J30: =SUM(D30:I30) -> 0
J31: =SUM(D31:I31) -> 0 | L31: TOTAL QR | M31: =J32+J40 -> 500
A32: TOTAL | J32: =SUM(J28:J31) -> 500
A34: BBVA
A35: SOCIOS | B35: RECIBO DE SERVICIO | C35: DETALLE | D35: LUZ | E35: AGUA | F35: G. ADM | G35: P. SOCIAL | H35: DEPOSITO | I35: P.S X FALLECIMIENTO | J35: TOTAL
J36: =SUM(D36:I36) -> 0
J37: =SUM(D37:I37) -> 0
J38: =SUM(D38:I38) -> 0
J39: =SUM(D39:I39) -> 0
A40: TOTAL | J40: =SUM(J36:J39) -> 0
A44: SOCIO | B44: RECIBO DE SERVICIO | C44: DETALLE | D44: LUZ | E44: AGUA | F44: G. ADM | G44: P. SOCIAL | H44: P.S X FALLECIMIENTO | I44: DEPOSITO | J44: TOTAL
J45: =SUM(D45:I45) -> 0
J46: =SUM(D46:I46) -> 0
...

Sheet 02-04-2026
A1: INGRESOS DEL DIA 02-04-2026
A3: INQUILINO | B3: COMPROBANTE | C3: DETALLE | D3: LUZ | E3: AGUA | F3: ALQUILER | G3: ESPACIO | H3: PARQUEO | I3: TICKET | J3: TOTAL
A4: PARQUEO | B4: EB01-7120 | C4: 46113 | H4: 59 | J4: =SUM(D4:I4) -> 59
J5: =SUM(D5:I5) -> 0
J6: =SUM(D6:I6) -> 0
J7: =SUM(D7:I7) -> 0
J8: =SUM(D8:I8) -> 0
J9: =SUM(D9:I9) -> 0
J10: =SUM(D10:I10) -> 0
J11: =SUM(D11:I11) -> 0
J12: =SUM(D12:I12) -> 0
J13: =SUM(D13:I13) -> 0
J14: =SUM(D14:I14) -> 0
J15: =SUM(D15:I15) -> 0
J16: =SUM(D16:I16) -> 0
... J21: =SUM(D21:I21) -> 0
A22: TOTAL | D22: =SUM(D4:D21) -> 0 | E22: =SUM(E4:E21) -> 0 | F22: =SUM(F4:F21) -> 0 | G22: =SUM(G4:G21) -> 0 | H22: =SUM(H4:H21) -> 59 | I22: =SUM(I4:I21) -> 0 | J22: =SUM(J4:J21) -> 59
A24: BBVA
A25: INQUILINOS | B25: COMPROBANTE | C25: DETALLE | D25: LUZ | E25: AGUA | F25: ALQUILER | G25: ESPACIO | H25: DEPOSITO | I25: TICKET | J25: TOTAL
J26: =SUM(D26:I26) -> 0
J27: =SUM(D27:I27) -> 0
J28: =SUM(D28:I28) -> 0
J29: =SUM(D29:I29) -> 0 | L29: TOTAL QR | M29: =J30+J38 -> 0
A30: TOTAL | J30: =SUM(J26:J29) -> 0
A32: BBVA
A33: SOCIOS | B33: RECIBO DE SERVICIO | C33: DETALLE | D33: LUZ | E33: AGUA | F33: G. ADM | G33: P. SOCIAL | H33: DEPOSITO | I33: P.S X FALLECIMIENTO | J33: TOTAL
J34: =SUM(D34:I34) -> 0
J35: =SUM(D35:I35) -> 0
J36: =SUM(D36:I36) -> 0
J37: =SUM(D37:I37) -> 0
A38: TOTAL | J38: =SUM(J34:J37) -> 0
A42: SOCIO | B42: RECIBO DE SERVICIO | C42: DETALLE | D42: LUZ | E42: AGUA | F42: G. ADM | G42: P. SOCIAL | H42: P.S X FALLECIMIENTO | I42: DEPOSITO | J42: TOTAL
J43: =SUM(D43:I43) -> 0
J44: =SUM(D44:I44) -> 0
J45: =SUM(D45:I45) -> 0
J46: =SUM(D46:I46) -> 0
J47: =SUM(D47:I47) -> 0
J48: =SUM(D48:I48) -> 0
J49: =SUM(D49:I49) -> 0
J50: =SUM(D50:I50) -> 0
...

Sheet 03-04-2026
A1: INGRESOS DEL DIA 03-04-2026
A3: INQUILINO | B3: COMPROBANTE | C3: DETALLE | D3: LUZ | E3: AGUA | F3: ALQUILER | G3: ESPACIO | H3: PARQUEO | I3: TICKET | J3: TOTAL
A4: PARQUEO | B4: EB01-7123 | C4: 46113 | H4: 30.9 | J4: =SUM(D4:I4) -> 30.9
J5: =SUM(D5:I5) -> 0
J6: =SUM(D6:I6) -> 0
J7: =SUM(D7:I7) -> 0
J8: =SUM(D8:I8) -> 0
J9: =SUM(D9:I9) -> 0
J10: =SUM(D10:I10) -> 0
J11: =SUM(D11:I11) -> 0
J12: =SUM(D12:I12) -> 0
J13: =SUM(D13:I13) -> 0
J14: =SUM(D14:I14) -> 0
J15: =SUM(D15:I15) -> 0
J16: =SUM(D16:I16) -> 0
... J21: =SUM(D21:I21) -> 0
A22: TOTAL | D22: =SUM(D4:D21) -> 0 | E22: =SUM(E4:E21) -> 0 | F22: =SUM(F4:F21) -> 0 | G22: =SUM(G4:G21) -> 0 | H22: =SUM(H4:H21) -> 30.9 | I22: =SUM(I4:I21) -> 0 | J22: =SUM(J4:J21) -> 30.9
A24: BBVA
A25: INQUILINOS | B25: COMPROBANTE | C25: DETALLE | D25: LUZ | E25: AGUA | F25: ALQUILER | G25: ESPACIO | H25: DEPOSITO | I25: TICKET | J25: TOTAL
J26: =SUM(D26:I26) -> 0
J27: =SUM(D27:I27) -> 0
J28: =SUM(D28:I28) -> 0
J29: =SUM(D29:I29) -> 0 | L29: TOTAL QR | M29: =J30+J38 -> 0
A30: TOTAL | J30: =SUM(J26:J29) -> 0
A32: BBVA
A33: SOCIOS | B33: RECIBO DE SERVICIO | C33: DETALLE | D33: LUZ | E33: AGUA | F33: G. ADM | G33: P. SOCIAL | H33: DEPOSITO | I33: P.S X FALLECIMIENTO | J33: TOTAL
J34: =SUM(D34:I34) -> 0
J35: =SUM(D35:I35) -> 0
J36: =SUM(D36:I36) -> 0
J37: =SUM(D37:I37) -> 0
A38: TOTAL | J38: =SUM(J34:J37) -> 0
A42: SOCIO | B42: RECIBO DE SERVICIO | C42: DETALLE | D42: LUZ | E42: AGUA | F42: G. ADM | G42: P. SOCIAL | H42: P.S X FALLECIMIENTO | I42: DEPOSITO | J42: TOTAL
J43: =SUM(D43:I43) -> 0
J44: =SUM(D44:I44) -> 0
J45: =SUM(D45:I45) -> 0
J46: =SUM(D46:I46) -> 0
J47: =SUM(D47:I47) -> 0
J48: =SUM(D48:I48) -> 0
J49: =SUM(D49:I49) -> 0
J50: =SUM(D50:I50) -> 0
...

Sheet 04-04-2026
A1: INGRESOS DEL DIA 04-04-2026
A3: INQUILINO | B3: COMPROBANTE | C3: DETALLE | D3: LUZ | E3: AGUA | F3: ALQUILER | G3: LOCAL 2DO PISO | H3: PARQUEO | I3: TICKET | J3: TOTAL
A4: JOSE | B4: TK 50818 | I4: 10 | J4: =SUM(D4:I4) -> 10
J5: =SUM(D5:I5) -> 0
A6: VIOLETA ANANI RETAMOZO ORE | B6: EB01-7124 | C6: 46113 | G6: 650 | J6: =SUM(D6:I6) -> 650
A7: PRUDENCIO TUEROS QUISPE | B7: EB01-7125 | C7: 46082 | F7: 500 | J7: =SUM(D7:I7) -> 500
J8: =SUM(D8:I8) -> 0
J9: =SUM(D9:I9) -> 0
J10: =SUM(D10:I10) -> 0
J11: =SUM(D11:I11) -> 0
J12: =SUM(D12:I12) -> 0
J13: =SUM(D13:I13) -> 0
J14: =SUM(D14:I14) -> 0
J15: =SUM(D15:I15) -> 0
J16: =SUM(D16:I16) -> 0
J17: =SUM(D17:I17) -> 0
J18: =SUM(D18:I18) -> 0
J19: =SUM(D19:I19) -> 0
... J21: =SUM(D21:I21) -> 0
A22: TOTAL | D22: =SUM(D4:D21) -> 0 | E22: =SUM(E4:E21) -> 0 | F22: =SUM(F4:F21) -> 500 | G22: =SUM(G4:G21) -> 650 | H22: =SUM(H4:H21) -> 0 | I22: =SUM(I4:I21) -> 10 | J22: =SUM(J4:J21) -> 1160
A24: BBVA
A25: INQUILINOS | B25: COMPROBANTE | C25: DETALLE | D25: LUZ | E25: AGUA | F25: ALQUILER | G25: ESPACIO | H25: DEPOSITO | I25: TICKET | J25: TOTAL
J26: =SUM(D26:I26) -> 0
J27: =SUM(D27:I27) -> 0
J28: =SUM(D28:I28) -> 0
J29: =SUM(D29:I29) -> 0 | L29: TOTAL QR | M29: =J30+J38 -> 0
A30: TOTAL | J30: =SUM(J26:J29) -> 0
A32: BBVA
A33: SOCIOS | B33: RECIBO DE SERVICIO | C33: DETALLE | D33: LUZ | E33: AGUA | F33: G. ADM | G33: P. SOCIAL | H33: DEPOSITO | I33: P.S X FALLECIMIENTO | J33: TOTAL
J34: =SUM(D34:I34) -> 0
J35: =SUM(D35:I35) -> 0
J36: =SUM(D36:I36) -> 0
J37: =SUM(D37:I37) -> 0
A38: TOTAL | J38: =SUM(J34:J37) -> 0
A42: SOCIO | B42: RECIBO DE SERVICIO | C42: DETALLE | D42: LUZ | E42: AGUA | F42: G. ADM | G42: P. SOCIAL | H42: P.S X FALLECIMIENTO | I42: DEPOSITO | J42: TOTAL
J43: =SUM(D43:I43) -> 0
J44: =SUM(D44:I44) -> 0
J45: =SUM(D45:I45) -> 0
J46: =SUM(D46:I46) -> 0
J47: =SUM(D47:I47) -> 0
...

Sheet 05-04-2026
A1: INGRESOS DEL DIA 05-04-2026
A3: INQUILINO | B3: COMPROBANTE | C3: DETALLE | D3: LUZ | E3: AGUA | F3: ALQUILER | G3: ESPACIO | H3: PARQUEO | I3: TICKET | J3: TOTAL
A4: MARI SOL QUISPE CHAVEZ | B4: EB01-7128 | F4: 100 | J4: =SUM(D4:I4) -> 100
J5: =SUM(D5:I5) -> 0
J6: =SUM(D6:I6) -> 0
J7: =SUM(D7:I7) -> 0
J8: =SUM(D8:I8) -> 0
J9: =SUM(D9:I9) -> 0
J10: =SUM(D10:I10) -> 0
J11: =SUM(D11:I11) -> 0
J12: =SUM(D12:I12) -> 0
J13: =SUM(D13:I13) -> 0
J14: =SUM(D14:I14) -> 0
J15: =SUM(D15:I15) -> 0
J16: =SUM(D16:I16) -> 0
... J21: =SUM(D21:I21) -> 0
A22: TOTAL | D22: =SUM(D4:D21) -> 0 | E22: =SUM(E4:E21) -> 0 | F22: =SUM(F4:F21) -> 100 | H22: =SUM(H4:H21) -> 0 | I22: =SUM(I4:I21) -> 0 | J22: =SUM(J4:J21) -> 100
A24: BBVA
A25: INQUILINOS | B25: COMPROBANTE | C25: DETALLE | D25: LUZ | E25: AGUA | F25: ALQUILER | G25: ESPACIO | H25: DEPOSITO | I25: TICKET | J25: TOTAL
J26: =SUM(D26:I26) -> 0
J27: =SUM(D27:I27) -> 0
J28: =SUM(D28:I28) -> 0
J29: =SUM(D29:I29) -> 0 | L29: TOTAL QR | M29: =J30+J38 -> 0
A30: TOTAL | J30: =SUM(J26:J29) -> 0
A32: BBVA
A33: SOCIOS | B33: RECIBO DE SERVICIO | C33: DETALLE | D33: LUZ | E33: AGUA | F33: G. ADM | G33: P. SOCIAL | H33: DEPOSITO | I33: P.S X FALLECIMIENTO | J33: TOTAL
J34: =SUM(D34:I34) -> 0
J35: =SUM(D35:I35) -> 0
J36: =SUM(D36:I36) -> 0
J37: =SUM(D37:I37) -> 0
A38: TOTAL | J38: =SUM(J34:J37) -> 0
A42: SOCIO | B42: RECIBO DE SERVICIO | C42: DETALLE | D42: LUZ | E42: AGUA | F42: G. ADM | G42: P. SOCIAL | H42: P.S X FALLECIMIENTO | I42: DEPOSITO | J42: TOTAL
J43: =SUM(D43:I43) -> 0
J44: =SUM(D44:I44) -> 0
J45: =SUM(D45:I45) -> 0
J46: =SUM(D46:I46) -> 0
J47: =SUM(D47:I47) -> 0
J48: =SUM(D48:I48) -> 0
J49: =SUM(D49:I49) -> 0
J50: =SUM(D50:I50) -> 0
...

Sheet 06-04-2026
A1: INGRESOS DEL DIA 06-04-2026
A3: INQUILINO | B3: COMPROBANTE | C3: DETALLE | D3: LUZ | E3: AGUA | F3: ALQUILER | G3: ESPACIO | H3: PARQUEO | I3: TICKET | J3: TOTAL
A4: MARI SOL QUISPE CHAVEZ | B4: EB01-7129 | C4: 46054 | F4: 100 | J4: =SUM(D4:I4) -> 100
A5: EDGAR SALVADOR ALVAREZ CHIARA | B5: EB01-7130 | C5: 46082 | F5: 450 | J5: =SUM(D5:I5) -> 450
A6: OBDULIA CERRON GALVAN | B6: EB01-7131 | C6: 46114 | F6: 450 | J6: =SUM(D6:I6) -> 450
A7: PARQUEO | B7: EB01-7132 | C7: 46114 | H7: 60.4 | J7: =SUM(D7:I7) -> 60.4
A8: MARLENE YAUYOS MENDIETA | B8: EB01-7133 | C8: 46023 | F8: 200 | J8: =SUM(D8:I8) -> 200
A9: PATRICIA PAOLA QUISPE MAMANI | B9: EB01-7134 | C9: 46082 | F9: 700 | J9: =SUM(D9:I9) -> 700
A10: PARQUEO | B10: EB01-7136 | C10: 46114 | H10: 76 | J10: =SUM(D10:I10) -> 76
J11: =SUM(D11:I11) -> 0
A12: JOSE | B12: TK 50819 | C12: 46114 | I12: 10 | J12: =SUM(D12:I12) -> 10
A13: JOSE DESARMADORES | B13: TK 50820 | C13: 46114 | I13: 10 | J13: =SUM(D13:I13) -> 10
J14: =SUM(D14:I14) -> 0
A15: NOTA DE CREDITO | B15: EB01-95 | F15: -100 | J15: =SUM(D15:I15) -> -100
J16: =SUM(D16:I16) -> 0
J17: =SUM(D17:I17) -> 0
J18: =SUM(D18:I18) -> 0
J19: =SUM(D19:I19) -> 0
J20: =SUM(D20:I20) -> 0
J21: =SUM(D21:I21) -> 0
J22: =SUM(D22:I22) -> 0
J23: =SUM(D23:I23) -> 0
A24: TOTAL | D24: =SUM(D4:D23) -> 0 | E24: =SUM(E4:E23) -> 0 | F24: =SUM(F4:F23) -> 1800 | G24: =SUM(G4:G23) -> 0 | H24: =SUM(H4:H23) -> 136.4 | I24: =SUM(I4:I23) -> 20 | J24: =SUM(J4:J23) -> 1956.4
A26: BBVA
A27: INQUILINOS | B27: COMPROBANTE | C27: DETALLE | D27: LUZ | E27: AGUA | F27: ALQUILER | G27: ESPACIO | H27: DEPOSITO | I27: TICKET | J27: TOTAL
J28: =SUM(D28:I28) -> 0
J29: =SUM(D29:I29) -> 0
J30: =SUM(D30:I30) -> 0
J31: =SUM(D31:I31) -> 0 | L31: TOTAL QR | M31: =J32+J40 -> 65
A32: TOTAL | J32: =SUM(J28:J31) -> 0
A34: BBVA
A35: SOCIOS | B35: RECIBO DE SERVICIO | C35: DETALLE | D35: LUZ | E35: AGUA | F35: G. ADM | G35: P. SOCIAL | H35: DEPOSITO | I35: P.S X FALLECIMIENTO | J35: TOTAL
A36: PRADO ZOZIMA | B36: RI 32929 | C36: 46082 | F36: 60 | G36: 5 | J36: =SUM(D36:I36) -> 65
J37: =SUM(D37:I37) -> 0
J38: =SUM(D38:I38) -> 0
J39: =SUM(D39:I39) -> 0
A40: TOTAL | J40: =SUM(J36:J39) -> 65
A44: SOCIO | B44: RECIBO DE SERVICIO | C44: DETALLE | D44: LUZ | E44: AGUA | F44: G. ADM | G44: P. SOCIAL | H44: P.S X FALLECIMIENTO | I44: DEPOSITO | J44: TOTAL
J45: =SUM(D45:I45) -> 0
J46: =SUM(D46:I46) -> 0
...

Sheet 07-04-2026
A1: INGRESOS DEL DIA 07-04-2026
A3: INQUILINO | B3: COMPROBANTE | C3: DETALLE | D3: LUZ | E3: AGUA | F3: ALQUILER | G3: LOCAL DEL 2DO PISO | H3: PARQUEO | I3: TICKET | J3: TOTAL
A4: FEDERICO MANUEL LEONARDO AMARILLO | B4: EB01-7137 | C4: 46082 | F4: 140 | J4: =SUM(D4:I4) -> 140
A5: ROSANA PILAR LEONARDO AMARILLO | B5: EB01-7138 | C5: 46082 | F5: 140 | J5: =SUM(D5:I5) -> 140
A6: FERNANDO MARTIN OBREGON CASTILLO | B6: EB01-7139 | C6: 46082 | F6: 140 | J6: =SUM(D6:I6) -> 140
A7: IDALINA MONTENEGRO BAUTISTA | B7: EB01-7140 | C7: 46054 | F7: 300 | J7: =SUM(D7:I7) -> 300
A8: ROMULO HUAMANI JANAMPA | B8: EB01-7141 | C8: 46174 | G8: 350 | J8: =SUM(D8:I8) -> 350
A9: HAYDEE LOPEZ CERRON | B9: EB01-7142 | C9: 46082 | F9: 500 | J9: =SUM(D9:I9) -> 500
A10: GRACIELA BUSTAMANTE CHILON | B10: EB01-7143 | C10: 46082 | F10: 500 | J10: =SUM(D10:I10) -> 500
A11: REYNALDO RIGOBERTO VERA ROMERO | B11: EB01-7146 | C11: 46113 | G11: 300 | J11: =SUM(D11:I11) -> 300
A12: PARQUEO | B12: EB01-7147 | C12: 46113 | H12: 67 | J12: =SUM(D12:I12) -> 67
J13: =SUM(D13:I13) -> 0
A14: FERNANDO MARTIN OBREGON CASTILLO | B14: RII 3318 | C14: 45962 | D14: 42.7 | E14: 5 | J14: =SUM(D14:I14) -> 47.7
C15: 45992 | D15: 42.9 | E15: 5 | J15: =SUM(D15:I15) -> 47.9
C16: 46023 | D16: 38.3 | E16: 3 | J16: =SUM(D16:I16) -> 41.3
C17: 46054 | D17: 37.9 | E17: 6 | J17: =SUM(D17:I17) -> 43.9
A18: HAYDEE LOPEZ CERRON | B18: RII 3319 | C18: 46054 | D18: 14.4 | E18: 6 | J18: =SUM(D18:I18) -> 20.4
A19: YAURIMUCHA URSULA | B19: RII 3320 | C19: 46054 | D19: 14.4 | E19: 6 | J19: =SUM(D19:I19) -> 20.4
A20: GRACIELA BUSTAMANTE CHILON | B20: RII 3321 | C20: 46054 | D20: 6.6 | E20: 6 | J20: =SUM(D20:I20) -> 12.6
J21: =SUM(D21:I21) -> 0
J22: =SUM(D22:I22) -> 0
A23: TOTAL | D23: =SUM(D4:D22) -> 197.2 | E23: =SUM(E4:E22) -> 37 | F23: =SUM(F4:F22) -> 1720 | G23: =SUM(G4:G22) -> 650 | H23: =SUM(H4:H22) -> 67 | I23: =SUM(I4:I22) -> 0 | J23: =SUM(J4:J22) -> 2671.2
A25: BBVA
A26: INQUILINOS | B26: COMPROBANTE | C26: DETALLE | D26: LUZ | E26: AGUA | F26: ALQUILER | G26: ESPACIO | H26: DEPOSITO | I26: TICKET | J26: TOTAL
A27: ROMINA DEL CARMEN HERRERA PEVES | B27: EB01-7144 | C27: 46082 | F27: 600 | J27: =SUM(D27:I27) -> 600
B28: RII 3322 | C28: 46054 | D28: 30 | E28: 15 | J28: =SUM(D28:I28) -> 45
J29: =SUM(D29:I29) -> 0
J30: =SUM(D30:I30) -> 0 | L30: TOTAL QR | M30: =J31+J39 -> 645
A31: TOTAL | J31: =SUM(J27:J30) -> 645
A33: BBVA
A34: SOCIOS | B34: RECIBO DE SERVICIO | C34: DETALLE | D34: LUZ | E34: AGUA | F34: G. ADM | G34: P. SOCIAL | H34: DEPOSITO | I34: P.S X FALLECIMIENTO | J34: TOTAL
J35: =SUM(D35:I35) -> 0
J36: =SUM(D36:I36) -> 0
J37: =SUM(D37:I37) -> 0
J38: =SUM(D38:I38) -> 0
A39: TOTAL | J39: =SUM(J35:J38) -> 0
A43: SOCIO | B43: RECIBO DE SERVICIO | C43: DETALLE | D43: LUZ | E43: AGUA | F43: G. ADM | G43: P. SOCIAL | H43: P.S X FALLECIMIENTO | I43: DEPOSITO | J43: TOTAL
J44: =SUM(D44:I44) -> 0
J45: =SUM(D45:I45) -> 0
J46: =SUM(D46:I46) -> 0
...

Sheet 08-04-2026
A1: INGRESOS DEL DIA 08-04-2026
A3: INQUILINO | B3: COMPROBANTE | C3: DETALLE | D3: LUZ | E3: AGUA | F3: ALQUILER | G3: ESPACIO | H3: PARQUEO | I3: MULTA POR CAPACITACION | J3: TOTAL
A4: CLAROS TORRES SANTOS JESUS | B4: E001-358 | C4: 46054 | F4: 250 | J4: =SUM(D4:I4) -> 250
A5: IMPULSO SALUD S.A.C. | B5: E001-359 | C5: 46113 | G5: 40 | J5: =SUM(D5:I5) -> 40
J6: =SUM(D6:I6) -> 0
A7: MARI SOL QUISPE CHAVEZ | B7: EB01-7148 | C7: 46082 | F7: 100 | J7: =SUM(D7:I7) -> 100
A8: ASAEL CASTILLO ZAPATA | B8: EB01-7149 | C8: 46054 | F8: 700 | J8: =SUM(D8:I8) -> 700
A9: CLEMENCIA BEATRIZ GARCIA MEDINA VDA DE MOLINA | B9: EB01-7150 | C9: 46082 | F9: 250 | J9: =SUM(D9:I9) -> 250
A10: LISBETH KARITO QUISPE NAPUCHE | B10: EB01-7151 | C10: 46023 | F10: 300 | J10: =SUM(D10:I10) -> 300
A11: CASILDA CATALINA REBAZA REBAZA | B11: EB01-7152 | C11: 46054 | F11: 150 | J11: =SUM(D11:I11) -> 150
A12: DAYSI ELIZABETH AZURZA TRIBIÑOS | B12: EB01-7154 | C12: 46082 | F12: 129.6 | J12: =SUM(D12:I12) -> 129.6
A13: ERIKA BENITES TRIBIÑOS | B13: EB01-7155 | C13: 46054 | F13: 300 | J13: =SUM(D13:I13) -> 300
C14: 46082 | F14: 129.6 | J14: =SUM(D14:I14) -> 129.6
A15: SANDRA LIZ MUJICA PALOMINO | B15: EB01-7157 | C15: 46054 | F15: 19.5 | J15: =SUM(D15:I15) -> 19.5
A16: JESSICA PATRICIA SALDAÑA DONAYRE | B16: EB01-7159 | C16: 46023 | F16: 300 | J16: =SUM(D16:I16) -> 300
A17: DAVID VICENTE CCENCHO CARRASCO | B17: EB01-7161 | C17: 46082 | F17: 500 | J17: =SUM(D17:I17) -> 500
A18: YESENIA BEATRIZ DAVILA HILARES | B18: EB01-7162 | C18: 46082 | F18: 500 | J18: =SUM(D18:I18) -> 500
A19: ASHLEY MARYORI PEÑA VILLANUEVA | B19: EB01-7164 | C19: 46113 | F19: 1000 | J19: =SUM(D19:I19) -> 1000
A20: ELMER BURGA CARRASCO | B20: EB01-7165 | C20: 46054 | F20: 58 | J20: =SUM(D20:I20) -> 58
C21: 46023 | F21: 242 | J21: =SUM(D21:I21) -> 242
A22: DOMINICA LUCIANA FLORES LAREDO | B22: EB01-7166 | C22: 46054 | F22: 200 | J22: =SUM(D22:I22) -> 200
A23: JANETT CONSUELO CASTRO RODRIGUEZ | B23: EB01-7167 | C23: 46054 | F23: 150 | J23: =SUM(D23:I23) -> 150
A24: LIDIA AGRIPINA CONDORI MAMANI | B24: EB01-7168 | C24: 46023 | F24: 50 | J24: =SUM(D24:I24) -> 50
C25: 46054 | F25: 150 | J25: =SUM(D25:I25) -> 150
A26: PARQUEO | B26: EB01-7170 | C26: 46113 | H26: 64.5 | J26: =SUM(D26:I26) -> 64.5
J27: =SUM(D27:I27) -> 0
J28: =SUM(D28:I28) -> 0
A29: CLEMENCIA BEATRIZ GARCIA MEDINA VDA DE MOLINA | B29: RII 3324 | C29: 45992 | D29: 10 | E29: 5 | J29: =SUM(D29:I29) -> 15
C30: 46023 | D30: 15 | E30: 3 | J30: =SUM(D30:I30) -> 18
C31: 46054 | D31: 14.4 | E31: 6 | J31: =SUM(D31:I31) -> 20.4
A32: REBAZA CASILDA | B32: RII 3325 | C32: 46023 | I32: 28.3 | J32: =SUM(D32:I32) -> 28.3
C33: 46054 | D33: 9.2 | E33: 6 | J33: =SUM(D33:I33) -> 15.2
A34: AZURZA DAYSI | B34: RII 3327 | C34: 46054 | D34: 4.4 | E34: 6 | J34: =SUM(D34:I34) -> 10.4
A35: BENITES ERIKA | B35: RII 3328 | C35: 46054 | D35: 14.4 | E35: 6 | J35: =SUM(D35:I35) -> 20.4
A36: MUJICA SANDRA | B36: RII 3329 | C36: 46023 | D36: 21.1 | E36: 3 | I36: 28.3 | J36: =SUM(D36:I36) -> 52.4
C37: 46054 | D37: 22.1 | E37: 6 | J37: =SUM(D37:I37) -> 28.1
A38: CCENCHO DAVID | B38: RII 3332 | C38: 46023 | I38: 28.3 | J38: =SUM(D38:I38) -> 28.3
C39: 46054 | D39: 14.4 | E39: 6 | J39: =SUM(D39:I39) -> 20.4
A40: DAVILA YESENIA | B40: RII 3333 | C40: 46023 | I40: 28.3 | J40: =SUM(D40:I40) -> 28.3
C41: 46054 | D41: 14.4 | E41: 6 | J41: =SUM(D41:I41) -> 20.4
...

Sheet 09-04-2026
A1: INGRESOS DEL DIA 09-04-2026
A3: INQUILINO | B3: COMPROBANTE | C3: DETALLE | D3: LUZ | E3: AGUA | F3: ALQUILER | G3: ESPACIO | H3: PARQUEO | I3: MULTA POR CAPACITACION | J3: TOTAL
A4: ADMINISTRADORA DE SERVICIOS FUNERARIOS SAC | B4: E001-361 | C4: 46113 | G4: 30 | J4: =SUM(D4:I4) -> 30
J5: =SUM(D5:I5) -> 0
A6: CARLOS ARTURO CERVANTES GARCIA | B6: EB01-7171 | C6: 46082 | F6: 500 | J6: =SUM(D6:I6) -> 500
A7: DORIS MAYHUASCA BASTIDAS | B7: EB01-7172 | C7: 46082 | F7: 230 | J7: =SUM(D7:I7) -> 230
A8: MARIBEL GOMEZ MITMA | B8: EB01-7173 | C8: 46054 | F8: 50 | J8: =SUM(D8:I8) -> 50
C9: 46082 | F9: 200 | J9: =SUM(D9:I9) -> 200
A10: PARQUEO | B10: EB01-7174 | C10: 46113 | H10: 44.9 | J10: =SUM(D10:I10) -> 44.9
J11: =SUM(D11:I11) -> 0
J12: =SUM(D12:I12) -> 0
J13: =SUM(D13:I13) -> 0
J14: =SUM(D14:I14) -> 0
J15: =SUM(D15:I15) -> 0
J16: =SUM(D16:I16) -> 0
A17: CARLOS ARTURO CERVANTES GARCIA | B17: RII 3339 | C17: 46023 | I17: 28.3 | J17: =SUM(D17:I17) -> 28.3
C18: 46054 | D18: 14.4 | E18: 6 | J18: =SUM(D18:I18) -> 20.4
A19: MAYHUASCA DORIS | B19: RII 3340 | C19: 46023 | D19: 9.9 | E19: 3 | J19: =SUM(D19:I19) -> 12.9
C20: 46054 | D20: 9 | E20: 6 | J20: =SUM(D20:I20) -> 15
J21: =SUM(D21:I21) -> 0
J22: =SUM(D22:I22) -> 0
J23: =SUM(D23:I23) -> 0
J24: =SUM(D24:I24) -> 0
J25: =SUM(D25:I25) -> 0
J26: =SUM(D26:I26) -> 0
A27: TOTAL | D27: =SUM(D4:D26) -> 33.3 | E27: =SUM(E4:E26) -> 15 | F27: =SUM(F4:F26) -> 980 | G27: =SUM(G4:G26) -> 30 | H27: =SUM(H4:H26) -> 44.9 | I27: =SUM(I4:I26) -> 28.3 | J27: =SUM(J4:J26) -> 1131.5
A29: BBVA
A30: INQUILINOS | B30: COMPROBANTE | C30: DETALLE | D30: LUZ | E30: AGUA | F30: ALQUILER | G30: ESPACIO | H30: DEPOSITO | I30: TICKET | J30: TOTAL
A31: VASQUEZ TAFUR SONIA ALBERTINA | B31: E001-360 | C31: 46113 | G31: 60 | J31: =SUM(D31:I31) -> 60
A32: COLINA SIRLEY | B32: RII 3341 | C32: 46023 | D32: 89.9 | E32: 6.4 | J32: =SUM(D32:I32) -> 96.3
C33: 46054 | D33: 88.6 | E33: 15 | J33: =SUM(D33:I33) -> 103.6
J36: =SUM(D36:I36) -> 0 | L36: TOTAL QR | M36: =J37+J47 -> 642.8
A37: TOTAL | J37: =SUM(J31:J36) -> 259.9
A39: BBVA
A40: SOCIOS | B40: RECIBO DE SERVICIO | C40: DETALLE | D40: LUZ | E40: AGUA | F40: G. ADM | G40: P. SOCIAL | H40: DEPOSITO | I40: P.S X FALLECIMIENTO | J40: TOTAL
A41: CUEVAS ENRIQUE | B41: RI 32933 | C41: 46082 | F41: 60 | G41: 5 | J41: =SUM(D41:I41) -> 65
A42: LUJAN JUAN | B42: RI 32934 | C42: 46054 | D42: 96.5 | E42: 21.4 | J42: =SUM(D42:I42) -> 117.9
A43: CALLE ALVAREZ MARCO | B43: RI 32935 | C43: 46082 | H43: 200 | J43: =SUM(D43:I43) -> 200
J44: =SUM(D44:I44) -> 0
J45: =SUM(D45:I45) -> 0
...

Sheet 10-04-2026
A1: INGRESOS DEL DIA 10-04-2026
A3: INQUILINO | B3: COMPROBANTE | C3: DETALLE | D3: LUZ | E3: AGUA | F3: ALQUILER | G3: ESPACIO | H3: PARQUEO | I3: TICKET | J3: TOTAL
A4: JOSE | B4: TK 50821 | C4: 46113 | I4: 10 | J4: =SUM(D4:I4) -> 10
J5: =SUM(D5:I5) -> 0
A6: ANATOLIA CHIPANA DE VARGAS | B6: EB01-7176 | C6: 46082 | G6: 100 | J6: =SUM(D6:I6) -> 100
A7: ORFELITA HERRERA CAMPOS | B7: EB01-7178 | C7: 46082 | F7: 200 | J7: =SUM(D7:I7) -> 200
A8: PARQUEO | B8: EB01-7181 | C8: 46113 | H8: 72 | J8: =SUM(D8:I8) -> 72
J9: =SUM(D9:I9) -> 0
J10: =SUM(D10:I10) -> 0
J11: =SUM(D11:I11) -> 0
J12: =SUM(D12:I12) -> 0
J13: =SUM(D13:I13) -> 0
J14: =SUM(D14:I14) -> 0
J15: =SUM(D15:I15) -> 0 | N15: 0
J16: =SUM(D16:I16) -> 0
J17: =SUM(D17:I17) -> 0
J18: =SUM(D18:I18) -> 0
J19: =SUM(D19:I19) -> 0
J20: =SUM(D20:I20) -> 0
J21: =SUM(D21:I21) -> 0
A22: TOTAL | D22: =SUM(D4:D21) -> 0 | E22: =SUM(E4:E21) -> 0 | F22: =SUM(F4:F21) -> 200 | G22: =SUM(G4:G21) -> 100 | H22: =SUM(H4:H21) -> 72 | I22: =SUM(I4:I21) -> 10 | J22: =SUM(J4:J21) -> 382
A24: BBVA
A25: INQUILINOS | B25: COMPROBANTE | C25: DETALLE | D25: LUZ | E25: AGUA | F25: ALQUILER | G25: ESPACIO | H25: DEPOSITO | I25: TICKET | J25: TOTAL
A26: ECO PLAZA MERCADO XI S.A.C. | B26: E001-362 | C26: 46113 | G26: 200 | J26: =SUM(D26:I26) -> 200
A27: ORFELITA HERRERA CAMPOS | B27: EB01-7177 | C27: 46082 | F27: 400 | J27: =SUM(D27:I27) -> 400
A28: MARCO ANTONIO SOTOMAYOR CARBAJAL | B28: EB01-7180 | C28: 46113 | G28: 30 | J28: =SUM(D28:I28) -> 30
J29: =SUM(D29:I29) -> 0 | L29: TOTAL QR | M29: =J30+J38 -> 756
A30: TOTAL | J30: =SUM(J26:J29) -> 630
A32: BBVA
A33: SOCIOS | B33: RECIBO DE SERVICIO | C33: DETALLE | D33: LUZ | E33: AGUA | F33: G. ADM | G33: P. SOCIAL | H33: DEPOSITO | I33: P.S X FALLECIMIENTO | J33: TOTAL
A34: LUJAN JUAN | B34: RI 32936 | C34: 46054 | F34: 56 | G34: 5 | J34: =SUM(D34:I34) -> 61
C35: 46082 | F35: 60 | G35: 5 | J35: =SUM(D35:I35) -> 65
J36: =SUM(D36:I36) -> 0
J37: =SUM(D37:I37) -> 0
A38: TOTAL | J38: =SUM(J34:J37) -> 126
A42: SOCIO | B42: RECIBO DE SERVICIO | C42: DETALLE | D42: LUZ | E42: AGUA | F42: G. ADM | G42: P. SOCIAL | H42: P.S X FALLECIMIENTO | I42: TALONARIO SANTA ROSA | J42: TOTAL
A43: ANULADO | B43: RI 32937 | J43: =SUM(D43:I43) -> 0
A44: FALCON HECTOR | B44: RI 32938 | C44: 45870 | I44: 15 | J44: =SUM(D44:I44) -> 15
C45: 46023 | F45: 60 | G45: 5 | H45: 10 | J45: =SUM(D45:I45) -> 75
C46: 46054 | F46: 56 | G46: 5 | J46: =SUM(D46:I46) -> 61
...

Sheet 11-04-2026
A1: INGRESOS DEL DIA 11-04-2026
A3: INQUILINO | B3: COMPROBANTE | C3: DETALLE | D3: LUZ | E3: AGUA | F3: ALQUILER | G3: ESPACIO | H3: PARQUEO | I3: TICKET | J3: TOTAL
A4: ADMINISTRADORA DE SERVICIOS FUNERARIOS SAC | B4: E001-363 | C4: 46113 | G4: 30 | J4: =SUM(D4:I4) -> 30
J5: =SUM(D5:I5) -> 0
A6: JOSE | B6: TK 50822 | C6: 46113 | I6: 10 | J6: =SUM(D6:I6) -> 10
J7: =SUM(D7:I7) -> 0
A8: PARQUEO | B8: EB01-7183 | C8: 46113 | H8: 65 | J8: =SUM(D8:I8) -> 65
J9: =SUM(D9:I9) -> 0
J10: =SUM(D10:I10) -> 0
J11: =SUM(D11:I11) -> 0
J12: =SUM(D12:I12) -> 0
J13: =SUM(D13:I13) -> 0
J14: =SUM(D14:I14) -> 0
J15: =SUM(D15:I15) -> 0
J16: =SUM(D16:I16) -> 0
J17: =SUM(D17:I17) -> 0
J18: =SUM(D18:I18) -> 0
J19: =SUM(D19:I19) -> 0
J20: =SUM(D20:I20) -> 0
J21: =SUM(D21:I21) -> 0
A22: TOTAL | D22: =SUM(D4:D21) -> 0 | E22: =SUM(E4:E21) -> 0 | F22: =SUM(F4:F21) -> 0 | G22: =SUM(G4:G21) -> 30 | H22: =SUM(H4:H21) -> 65 | I22: =SUM(I4:I21) -> 10 | J22: =SUM(J4:J21) -> 105
A24: BBVA
A25: INQUILINOS | B25: COMPROBANTE | C25: DETALLE | D25: LUZ | E25: AGUA | F25: ALQUILER | G25: ESPACIO | H25: GARANTIA DE ALQ. | I25: TICKET | J25: TOTAL
A26: ROSA ARMANDINA RENTERIA HUANCAS | B26: EB01-7182 | C26: 46113 | F26: 500 | J26: =SUM(D26:I26) -> 500
B27: RII 3342 | C27: 46113 | H27: 1000 | J27: =SUM(D27:I27) -> 1000
J28: =SUM(D28:I28) -> 0
J29: =SUM(D29:I29) -> 0 | L29: TOTAL QR | M29: =J30+J38 -> 1500
A30: TOTAL | J30: =SUM(J26:J29) -> 1500
A32: BBVA
A33: SOCIOS | B33: RECIBO DE SERVICIO | C33: DETALLE | D33: LUZ | E33: AGUA | F33: G. ADM | G33: P. SOCIAL | H33: DEPOSITO | I33: P.S X FALLECIMIENTO | J33: TOTAL
J34: =SUM(D34:I34) -> 0
J35: =SUM(D35:I35) -> 0
J36: =SUM(D36:I36) -> 0
J37: =SUM(D37:I37) -> 0
A38: TOTAL | J38: =SUM(J34:J37) -> 0
A42: SOCIO | B42: RECIBO DE SERVICIO | C42: DETALLE | D42: LUZ | E42: AGUA | F42: G. ADM | G42: P. SOCIAL | H42: P.S X FALLECIMIENTO | I42: DEPOSITO | J42: TOTAL
J43: =SUM(D43:I43) -> 0
J44: =SUM(D44:I44) -> 0
J45: =SUM(D45:I45) -> 0
J46: =SUM(D46:I46) -> 0
...

Sheet 12-04-2026
A1: INGRESOS DEL DIA 12-04-2026
A3: INQUILINO | B3: COMPROBANTE | C3: DETALLE | D3: LUZ | E3: AGUA | F3: ALQUILER | G3: ESPACIO | H3: PARQUEO | I3: TICKET | J3: TOTAL
J4: =SUM(D4:I4) -> 0
J5: =SUM(D5:I5) -> 0
J6: =SUM(D6:I6) -> 0
J7: =SUM(D7:I7) -> 0
J8: =SUM(D8:I8) -> 0
J9: =SUM(D9:I9) -> 0
J10: =SUM(D10:I10) -> 0
J11: =SUM(D11:I11) -> 0
J12: =SUM(D12:I12) -> 0
J13: =SUM(D13:I13) -> 0
J14: =SUM(D14:I14) -> 0
J15: =SUM(D15:I15) -> 0
... J21: =SUM(D21:I21) -> 0
A22: TOTAL | D22: =SUM(D4:D21) -> 0 | E22: =SUM(E4:E21) -> 0 | F22: =SUM(F4:F21) -> 0 | H22: =SUM(H4:H21) -> 0 | I22: =SUM(I4:I21) -> 0 | J22: =SUM(J4:J21) -> 0
A24: BBVA
A25: INQUILINOS | B25: COMPROBANTE | C25: DETALLE | D25: LUZ | E25: AGUA | F25: ALQUILER | G25: ESPACIO | H25: DEPOSITO | I25: TICKET | J25: TOTAL
J26: =SUM(D26:I26) -> 0
J27: =SUM(D27:I27) -> 0
J28: =SUM(D28:I28) -> 0
J29: =SUM(D29:I29) -> 0 | L29: TOTAL QR | M29: =J30+J38 -> 0
A30: TOTAL | J30: =SUM(J26:J29) -> 0
A32: BBVA
A33: SOCIOS | B33: RECIBO DE SERVICIO | C33: DETALLE | D33: LUZ | E33: AGUA | F33: G. ADM | G33: P. SOCIAL | H33: DEPOSITO | I33: P.S X FALLECIMIENTO | J33: TOTAL
J34: =SUM(D34:I34) -> 0
J35: =SUM(D35:I35) -> 0
J36: =SUM(D36:I36) -> 0
J37: =SUM(D37:I37) -> 0
A38: TOTAL | J38: =SUM(J34:J37) -> 0
A42: SOCIO | B42: RECIBO DE SERVICIO | C42: DETALLE | D42: LUZ | E42: AGUA | F42: G. ADM | G42: P. SOCIAL | H42: P.S X FALLECIMIENTO | I42: DEPOSITO | J42: TOTAL
J43: =SUM(D43:I43) -> 0
J44: =SUM(D44:I44) -> 0
J45: =SUM(D45:I45) -> 0
J46: =SUM(D46:I46) -> 0
J47: =SUM(D47:I47) -> 0
J48: =SUM(D48:I48) -> 0
J49: =SUM(D49:I49) -> 0
J50: =SUM(D50:I50) -> 0
J51: =SUM(D51:I51) -> 0
...

Sheet 13-04-2026
A1: INGRESOS DEL DIA 13-04-2026
A3: INQUILINO | B3: COMPROBANTE | C3: DETALLE | D3: LUZ | E3: AGUA | F3: ALQUILER | G3: ESPACIO | H3: PARQUEO | I3: TICKET | J3: TOTAL
A4: JOSE | B4: TK 50823 | C4: 46113 | I4: 10 | J4: =SUM(D4:I4) -> 10
B5: TK 50824 | C5: 46113 | I5: 10 | J5: =SUM(D5:I5) -> 10
J6: =SUM(D6:I6) -> 0
J7: =SUM(D7:I7) -> 0
J8: =SUM(D8:I8) -> 0
J9: =SUM(D9:I9) -> 0
J10: =SUM(D10:I10) -> 0
J11: =SUM(D11:I11) -> 0
J12: =SUM(D12:I12) -> 0
J13: =SUM(D13:I13) -> 0
J14: =SUM(D14:I14) -> 0
J15: =SUM(D15:I15) -> 0
J16: =SUM(D16:I16) -> 0
J17: =SUM(D17:I17) -> 0
... J21: =SUM(D21:I21) -> 0
A22: TOTAL | D22: =SUM(D4:D21) -> 0 | E22: =SUM(E4:E21) -> 0 | F22: =SUM(F4:F21) -> 0 | H22: =SUM(H4:H21) -> 0 | I22: =SUM(I4:I21) -> 20 | J22: =SUM(J4:J21) -> 20
A24: BBVA
A25: INQUILINOS | B25: COMPROBANTE | C25: DETALLE | D25: LUZ | E25: AGUA | F25: ALQUILER | G25: ESPACIO | H25: DEPOSITO | I25: TICKET | J25: TOTAL
A26: ORFELITA HERRERA CAMPOS | B26: RII 3343 | C26: 46054 | D26: 30.4 | E26: 6 | J26: =SUM(D26:I26) -> 36.4
J27: =SUM(D27:I27) -> 0
J28: =SUM(D28:I28) -> 0
J29: =SUM(D29:I29) -> 0 | L29: TOTAL QR | M29: =J30+J38 -> 36.4
A30: TOTAL | J30: =SUM(J26:J29) -> 36.4
A32: BBVA
A33: SOCIOS | B33: RECIBO DE SERVICIO | C33: DETALLE | D33: LUZ | E33: AGUA | F33: G. ADM | G33: P. SOCIAL | H33: DEPOSITO | I33: P.S X FALLECIMIENTO | J33: TOTAL
J34: =SUM(D34:I34) -> 0
J35: =SUM(D35:I35) -> 0
J36: =SUM(D36:I36) -> 0
J37: =SUM(D37:I37) -> 0
A38: TOTAL | J38: =SUM(J34:J37) -> 0
A42: SOCIO | B42: RECIBO DE SERVICIO | C42: DETALLE | D42: LUZ | E42: AGUA | F42: G. ADM | G42: P. SOCIAL | H42: P.S X FALLECIMIENTO | I42: DEPOSITO | J42: TOTAL
A43: PORRAS OLIMPIA | B43: RI 32942 | C43: 46054 | D43: 5.9 | E43: 10 | F43: 56 | G43: 5 | J43: =SUM(D43:I43) -> 76.9
C44: 46082 | F44: 60 | G44: 5 | J44: =SUM(D44:I44) -> 65
J45: =SUM(D45:I45) -> 0
J46: =SUM(D46:I46) -> 0
J47: =SUM(D47:I47) -> 0
J48: =SUM(D48:I48) -> 0
J49: =SUM(D49:I49) -> 0
...

Sheet 14-04-2026
A1: INGRESOS DEL DIA 14-04-2026
A3: INQUILINO | B3: COMPROBANTE | C3: DETALLE | D3: LUZ | E3: AGUA | F3: DEPOSITO | G3: ESPACIO | H3: PARQUEO | I3: TICKET | J3: TOTAL
A4: JOSE | B4: TK 50825 | C4: 46113 | I4: 10 | J4: =SUM(D4:I4) -> 10
J5: =SUM(D5:I5) -> 0
A6: ACCO VICTOR | B6: RII 3344 | C6: 46054 | F6: 150 | J6: =SUM(D6:I6) -> 150
C7: 46054 | F7: 150 | J7: =SUM(D7:I7) -> 150
C8: 46082 | F8: 150 | J8: =SUM(D8:I8) -> 150
C9: 46082 | F9: 150 | J9: =SUM(D9:I9) -> 150
J10: =SUM(D10:I10) -> 0
A11: PARQUEO | B11: EB01-7188 | C11: 46113 | H11: 70 | J11: =SUM(D11:I11) -> 70
J12: =SUM(D12:I12) -> 0
J13: =SUM(D13:I13) -> 0
J14: =SUM(D14:I14) -> 0
J15: =SUM(D15:I15) -> 0
J16: =SUM(D16:I16) -> 0
J17: =SUM(D17:I17) -> 0
J18: =SUM(D18:I18) -> 0
J19: =SUM(D19:I19) -> 0
J20: =SUM(D20:I20) -> 0
J21: =SUM(D21:I21) -> 0
A22: TOTAL | D22: =SUM(D4:D21) -> 0 | E22: =SUM(E4:E21) -> 0 | F22: =SUM(F4:F21) -> 600 | H22: =SUM(H4:H21) -> 70 | I22: =SUM(I4:I21) -> 10 | J22: =SUM(J4:J21) -> 680
A24: BBVA
A25: INQUILINOS | B25: COMPROBANTE | C25: DETALLE | D25: LUZ | E25: AGUA | F25: ALQUILER | G25: ESPACIO | H25: DEPOSITO | I25: TICKET | J25: TOTAL
A26: ADMINISTRADORA DE SERVICIOS FUNERARIOS SAC | B26: E001-364 | C26: 46113 | G26: 60 | J26: =SUM(D26:I26) -> 60
J27: =SUM(D27:I27) -> 0
J28: =SUM(D28:I28) -> 0
J29: =SUM(D29:I29) -> 0 | L29: TOTAL QR | M29: =J30+J38 -> 60
A30: TOTAL | J30: =SUM(J26:J29) -> 60
A32: BBVA
A33: SOCIOS | B33: RECIBO DE SERVICIO | C33: DETALLE | D33: LUZ | E33: AGUA | F33: G. ADM | G33: P. SOCIAL | H33: DEPOSITO | I33: P.S X FALLECIMIENTO | J33: TOTAL
J34: =SUM(D34:I34) -> 0
J35: =SUM(D35:I35) -> 0
J36: =SUM(D36:I36) -> 0
J37: =SUM(D37:I37) -> 0
A38: TOTAL | J38: =SUM(J34:J37) -> 0
A42: SOCIO | B42: RECIBO DE SERVICIO | C42: DETALLE | D42: LUZ | E42: AGUA | F42: G. ADM | G42: P. SOCIAL | H42: P.S X FALLECIMIENTO | I42: DEPOSITO | J42: TOTAL
A43: HUAMAN VISITACION | B43: RI 32943 | C43: 46082 | F43: 60 | G43: 5 | J43: =SUM(D43:I43) -> 65
J44: =SUM(D44:I44) -> 0
J45: =SUM(D45:I45) -> 0
J46: =SUM(D46:I46) -> 0
...

Sheet 15-04-2026
A1: INGRESOS DEL DIA 15-04-2026
A3: INQUILINO | B3: COMPROBANTE | C3: DETALLE | D3: LUZ | E3: AGUA | F3: ALQUILER | G3: MULTA POR CAPACITACION | H3: PARQUEO | I3: TICKET | J3: TOTAL
A4: JOSE | B4: TK 50826 | C4: 46113 | I4: 10 | J4: =SUM(D4:I4) -> 10
J5: =SUM(D5:I5) -> 0
A6: QUISPE MARISOL | B6: EB01-7189 | C6: 46082 | F6: 100 | J6: =SUM(D6:I6) -> 100
A7: MARTHA ESPERANZA ALARCON ESPINOZA | B7: EB01-7191 | C7: 46082 | F7: 550 | J7: =SUM(D7:I7) -> 550
A8: ROSA PALOMINO CUSI | B8: EB01-7192 | C8: 46113 | F8: 650 | J8: =SUM(D8:I8) -> 650
A9: MIRIAN MILAGROS PRADO CATAÑO | B9: EB01-7193 | C9: 46082 | F9: 600 | J9: =SUM(D9:I9) -> 600
A10: ABEL ANCHAYA HUAMAN | B10: EB01-7194 | C10: 46023 | F10: 400 | J10: =SUM(D10:I10) -> 400
A11: SIMONA CHAMBI APAZA | B11: EB01-7195 | C11: 46054 | F11: 200 | J11: =SUM(D11:I11) -> 200
A12: JOSE ULISES BUSTAMANTE DE LA CRUZ | B12: EB01-7196 | C12: 45870 | F12: 150 | J12: =SUM(D12:I12) -> 150
C13: 45901 | F13: 150 | J13: =SUM(D13:I13) -> 150
A14: HECTOR AIRE MALPARTIDA | B14: EB01-7197 | C14: 46082 | F14: 100 | J14: =SUM(D14:I14) -> 100
A15: MERY RUTH CARRASCO PICHIHUA | B15: EB01-7198 | C15: 46082 | F15: 188 | J15: =SUM(D15:I15) -> 188
A16: LISBETH LUCIA MALLMA CONDORI | B16: EB01-7199 | C16: 46054 | F16: 191.6 | J16: =SUM(D16:I16) -> 191.6
A17: JANETT CONSUELO CASTRO RODRIGUEZ | B17: EB01-7200 | C17: 46054 | F17: 100 | J17: =SUM(D17:I17) -> 100
A18: DOMINICA LUCIANA FLORES LAREDO | B18: EB01-7201 | C18: 46054 | F18: 100 | J18: =SUM(D18:I18) -> 100
A19: ALEX ENRIQUE CAHUANA PUCURIMAY | B19: EB01-7202 | C19: 45992 | F19: 109 | J19: =SUM(D19:I19) -> 109
C20: 46023 | F20: 311.6 | J20: =SUM(D20:I20) -> 311.6
A21: MARLENE YAUYOS MENDIETA | B21: EB01-7204 | C21: 46023 | F21: 300 | J21: =SUM(D21:I21) -> 300
C22: 46054 | F22: 500 | J22: =SUM(D22:I22) -> 500
C23: 46082 | F23: 500 | J23: =SUM(D23:I23) -> 500
A24: PARQUEO | B24: EB01-7206 | C24: 46113 | H24: 74.5 | J24: =SUM(D24:I24) -> 74.5
J25: =SUM(D25:I25) -> 0
A26: CLAROS TORRES SANTOS JESUS | B26: RII 3346 | C26: 46054 | D26: 20 | J26: =SUM(D26:I26) -> 20
A27: MARTHA ESPERANZA ALARCON ESPINOZA | B27: RII 3348 | C27: 46082 | D27: 36 | E27: 15 | J27: =SUM(D27:I27) -> 51
A28: ROSA PALOMINO CUSI | B28: RII 3349 | C28: 46054 | D28: 21.4 | E28: 6 | J28: =SUM(D28:I28) -> 27.4
A29: PRADO MILAGROS | B29: RII 3350 | C29: 46054 | D29: 44 | E29: 6 | J29: =SUM(D29:I29) -> 50
A30: CHAMBI SIMONA | B30: RII 3351 | C30: 46023 | D30: 15 | E30: 3 | G30: 28.3 | J30: =SUM(D30:I30) -> 46.3
C31: 46054 | D31: 14.4 | E31: 6 | J31: =SUM(D31:I31) -> 20.4
A32: HECTOR AIRE MALPARTIDA | B32: RII 3352 | C32: 46023 | G32: 28.3 | J32: =SUM(D32:I32) -> 28.3
C33: 46054 | D33: 16 | E33: 11 | J33: =SUM(D33:I33) -> 27
A34: LISBETH LUCIA MALLMA CONDORI | B34: RII 3354 | C34: 46023 | D34: 36.2 | E34: 3 | G34: 28.3 | J34: =SUM(D34:I34) -> 67.5
C35: 46054 | D35: 34.9 | E35: 6 | J35: =SUM(D35:I35) -> 40.9
A36: ALEX ENRIQUE CAHUANA PUCURIMAY | B36: RII 3355 | C36: 46023 | D36: 20 | E36: 59.4 | J36: =SUM(D36:I36) -> 79.4
A37: MARLENE YAUYOS MENDIETA | B37: RII 3356 | C37: 45992 | D37: 10 | E37: 5 | J37: =SUM(D37:I37) -> 15
C38: 46023 | D38: 15 | E38: 3 | J38: =SUM(D38:I38) -> 18
C39: 46054 | D39: 14.4 | E39: 6 | J39: =SUM(D39:I39) -> 20.4
J40: =SUM(D40:I40) -> 0
J41: =SUM(D41:I41) -> 0
...

Sheet 16-04-2026
A1: INGRESOS DEL DIA 16-04-2026
A3: INQUILINO | B3: COMPROBANTE | C3: DETALLE | D3: LUZ | E3: AGUA | F3: ALQUILER | G3: ESPACIO | H3: PARQUEO | I3: TICKET | J3: TOTAL
A4: JOSE | B4: TK 50827 | C4: 46113 | I4: 10 | J4: =SUM(D4:I4) -> 10
J5: =SUM(D5:I5) -> 0
A6: LISBETH KARITO QUISPE NAPUCHE | B6: EB01-7207 | C6: 46054 | F6: 300 | J6: =SUM(D6:I6) -> 300
A7: LUIS ABRAHAM SUAREZ REBAZA | B7: EB01-7208 | C7: 46082 | F7: 500 | J7: =SUM(D7:I7) -> 500
A8: SIRLEY KARINA COLINA CORREA | B8: EB01-7209 | C8: 46082 | F8: 1200 | J8: =SUM(D8:I8) -> 1200
A9: FLORENCIA ASUNTA ALVAREZ BERRIO | B9: EB01-7211 | C9: 46082 | F9: 700 | J9: =SUM(D9:I9) -> 700
A10: PARQUEO | B10: EB01-7213 | C10: 46113 | H10: 68 | J10: =SUM(D10:I10) -> 68
J11: =SUM(D11:I11) -> 0
J12: =SUM(D12:I12) -> 0
J13: =SUM(D13:I13) -> 0
J14: =SUM(D14:I14) -> 0
J15: =SUM(D15:I15) -> 0
J16: =SUM(D16:I16) -> 0
A17: TOTAL | D17: =SUM(D4:D16) -> 0 | E17: =SUM(E4:E16) -> 0 | F17: =SUM(F4:F16) -> 2700 | H17: =SUM(H4:H16) -> 68 | I17: =SUM(I4:I16) -> 10 | J17: =SUM(J4:J16) -> 2778
A19: BBVA
A20: INQUILINOS | B20: COMPROBANTE | C20: DETALLE | D20: LUZ | E20: AGUA | F20: ALQUILER | G20: ESPACIO | H20: DEPOSITO | I20: TICKET | J20: TOTAL
A21: ENTREMENTES SAC | B21: E001-366 | C21: 46113 | G21: 60 | J21: =SUM(D21:I21) -> 60
A22: MARIBEL GOMEZ MITMA | B22: EB01-7210 | C22: 46082 | G22: 100 | J22: =SUM(D22:I22) -> 100
J23: =SUM(D23:I23) -> 0
J24: =SUM(D24:I24) -> 0 | L24: TOTAL QR | M24: =J25+J33 -> 550.2
A25: TOTAL | J25: =SUM(J21:J24) -> 160
A27: BBVA
A28: SOCIOS | B28: RECIBO DE SERVICIO | C28: DETALLE | D28: LUZ | E28: AGUA | F28: G. ADM | G28: P. SOCIAL | H28: DEPOSITO | I28: P.S X FALLECIMIENTO | J28: TOTAL
A29: MARIN MARIA LUZ | B29: RI 32944 | C29: 46023 | H29: 97.2 | J29: =SUM(D29:I29) -> 97.2
C30: 46054 | D30: 22 | E30: 10 | F30: 56 | G30: 5 | H30: 200 | J30: =SUM(D30:I30) -> 293
J31: =SUM(D31:I31) -> 0
J32: =SUM(D32:I32) -> 0
A33: TOTAL | J33: =SUM(J29:J32) -> 390.2
A37: SOCIO | B37: RECIBO DE SERVICIO | C37: DETALLE | D37: LUZ | E37: AGUA | F37: G. ADM | G37: P. SOCIAL | H37: P.S X FALLECIMIENTO | I37: DEPOSITO | J37: TOTAL
A38: SALAZAR VICTORIA | B38: RI 32945 | C38: 46082 | F38: 60 | G38: 5 | J38: =SUM(D38:I38) -> 65
A39: ROJAS ERICK | B39: RI 32946 | C39: 46082 | F39: 20 | G39: 5 | J39: =SUM(D39:I39) -> 25
J40: =SUM(D40:I40) -> 0
J41: =SUM(D41:I41) -> 0
J42: =SUM(D42:I42) -> 0
J43: =SUM(D43:I43) -> 0
J44: =SUM(D44:I44) -> 0
J45: =SUM(D45:I45) -> 0
J46: =SUM(D46:I46) -> 0
...

Sheet 17-04-2026
A1: INGRESOS DEL DIA 17-04-2026
A3: INQUILINO | B3: COMPROBANTE | C3: DETALLE | D3: LUZ | E3: AGUA | F3: ALQUILER | G3: ESPACIO | H3: PARQUEO | I3: TICKET | J3: ALQUILER LOCAL 2DO PISO | K3: TOTAL
K4: =SUM(D4:J4) -> 0
K5: =SUM(D5:J5) -> 0
A6: ROMULO HUAMANI JANAMPA | B6: EB01-7214 | C6: 46113 | J6: 100 | K6: =SUM(D6:J6) -> 100
A7: BACILIO ANTONIO CAYO HUAMANI | B7: EB01-7216 | C7: 46082 | F7: 300 | K7: =SUM(D7:J7) -> 300
A8: PARQUEO | B8: EB01-7218 | C8: 46113 | H8: 54.6 | K8: =SUM(D8:J8) -> 54.6
K9: =SUM(D9:J9) -> 0
A10: ADMINISTRADORA DE SERVICIOS FUNERARIOS SAC | B10: E001-367 | C10: 46113 | G10: 30 | K10: =SUM(D10:J10) -> 30
K11: =SUM(D11:J11) -> 0
K12: =SUM(D12:J12) -> 0
K13: =SUM(D13:J13) -> 0
K14: =SUM(D14:J14) -> 0
K15: =SUM(D15:J15) -> 0
K16: =SUM(D16:J16) -> 0
K17: =SUM(D17:J17) -> 0
K18: =SUM(D18:J18) -> 0
K19: =SUM(D19:J19) -> 0
K20: =SUM(D20:J20) -> 0
K21: =SUM(D21:J21) -> 0
K22: =SUM(D22:J22) -> 0
A23: TOTAL | D23: =SUM(D4:D22) -> 0 | E23: =SUM(E4:E22) -> 0 | F23: =SUM(F4:F22) -> 300 | G23: =SUM(G4:G22) -> 30 | H23: =SUM(H4:H22) -> 54.6 | I23: =SUM(I4:I22) -> 0 | J23: =SUM(J4:J22) -> 100 | K23: =SUM(K4:K22) -> 484.6
A25: BBVA
A26: INQUILINOS | B26: COMPROBANTE | C26: DETALLE | D26: LUZ | E26: AGUA | F26: ALQUILER | G26: ESPACIO | H26: DEPOSITO | I26: TICKET | K26: TOTAL
A27: MARIANNE OLGA CELIA SANTIAGO JIMENEZ | B27: EB01-7215 | C27: 46113 | G27: 30 | K27: =SUM(D27:I27) -> 30
K29: =SUM(D29:I29) -> 0
K30: =SUM(D30:I30) -> 0 | M30: TOTAL QR | N30: =K31+K39 -> 30
A31: TOTAL | D31: =SUM(D27:D30) -> 0 | E31: =SUM(E27:E30) -> 0 | F31: =SUM(F27:F30) -> 0 | G31: =SUM(G27:G30) -> 30 | H31: =SUM(H27:H30) -> 0 | I31: =SUM(I27:I30) -> 0 | J31: =SUM(J27:J30) -> 0 | K31: =SUM(K27:K30) -> 30
A33: BBVA
A34: SOCIOS | B34: RECIBO DE SERVICIO | C34: DETALLE | D34: LUZ | E34: AGUA | F34: G. ADM | G34: P. SOCIAL | H34: DEPOSITO | I34: P.S X FALLECIMIENTO | K34: TOTAL
K35: =SUM(D35:I35) -> 0
K36: =SUM(D36:I36) -> 0
K37: =SUM(D37:I37) -> 0
K38: =SUM(D38:I38) -> 0
A39: TOTAL | D39: =SUM(D35:D38) -> 0 | E39: =SUM(E35:E38) -> 0 | F39: =SUM(F35:F38) -> 0 | G39: =SUM(G35:G38) -> 0 | H39: =SUM(H35:H38) -> 0 | I39: =SUM(I35:I38) -> 0 | J39: =SUM(J35:J38) -> 0 | K39: =SUM(K35:K38) -> 0
A43: SOCIO | B43: RECIBO DE SERVICIO | C43: DETALLE | D43: LUZ | E43: AGUA | F43: G. ADM | G43: P. SOCIAL | H43: P.S X FALLECIMIENTO | I43: DEPOSITO | J43: MULTA | K43: TOTAL
A44: ORTIZ WELINTONH | B44: RI 32947 | C44: 45962 | J44: 113 | K44: =SUM(D44:J44) -> 113
C45: 46054 | D45: 172.6 | E45: 13.3 | K45: =SUM(D45:J45) -> 185.9
C46: 46082 | J46: 113 | K46: =SUM(D46:J46) -> 113
A47: YRUPAILLA ISIDRO | B47: RI 32948 | C47: 46082 | F47: 60 | G47: 5 | K47: =SUM(D47:J47) -> 65
...

Sheet 18-04-2026
A1: INGRESOS DEL DIA 18-04-2026
A3: INQUILINO | B3: COMPROBANTE | C3: DETALLE | D3: LUZ | E3: AGUA | F3: ALQUILER | G3: ESPACIO | H3: PARQUEO | I3: TICKET | J3: ALQUILER LOCAL 2DO PISO | K3: TOTAL
A4: PARQUEO | B4: EB01-7219 | C4: 46113 | H4: 71.6 | K4: =SUM(D4:J4) -> 71.6
K5: =SUM(D5:J5) -> 0
K6: =SUM(D6:J6) -> 0
K7: =SUM(D7:J7) -> 0
K8: =SUM(D8:J8) -> 0
K9: =SUM(D9:J9) -> 0
K10: =SUM(D10:J10) -> 0
K11: =SUM(D11:J11) -> 0
K12: =SUM(D12:J12) -> 0
K13: =SUM(D13:J13) -> 0
K14: =SUM(D14:J14) -> 0
K15: =SUM(D15:J15) -> 0
K16: =SUM(D16:J16) -> 0
... K22: =SUM(D22:J22) -> 0
A23: TOTAL | D23: =SUM(D4:D22) -> 0 | E23: =SUM(E4:E22) -> 0 | F23: =SUM(F4:F22) -> 0 | G23: =SUM(G4:G22) -> 0 | H23: =SUM(H4:H22) -> 71.6 | I23: =SUM(I4:I22) -> 0 | J23: =SUM(J4:J22) -> 0 | K23: =SUM(K4:K22) -> 71.6
A25: BBVA
A26: INQUILINOS | B26: COMPROBANTE | C26: DETALLE | D26: LUZ | E26: AGUA | F26: ALQUILER | G26: ESPACIO | H26: DEPOSITO | I26: TICKET | K26: TOTAL
A27: VASQUEZ TAFUR SONIA ALBERTINA | B27: E001-368 | C27: 46113 | G27: 30 | K27: =SUM(D27:I27) -> 30
K29: =SUM(D29:I29) -> 0
K30: =SUM(D30:I30) -> 0 | M30: TOTAL QR | N30: =K31+K39 -> 30
A31: TOTAL | D31: =SUM(D27:D30) -> 0 | E31: =SUM(E27:E30) -> 0 | F31: =SUM(F27:F30) -> 0 | G31: =SUM(G27:G30) -> 30 | H31: =SUM(H27:H30) -> 0 | I31: =SUM(I27:I30) -> 0 | J31: =SUM(J27:J30) -> 0 | K31: =SUM(K27:K30) -> 30
A33: BBVA
A34: SOCIOS | B34: RECIBO DE SERVICIO | C34: DETALLE | D34: LUZ | E34: AGUA | F34: G. ADM | G34: P. SOCIAL | H34: DEPOSITO | I34: P.S X FALLECIMIENTO | K34: TOTAL
K35: =SUM(D35:I35) -> 0
K36: =SUM(D36:I36) -> 0
K37: =SUM(D37:I37) -> 0
K38: =SUM(D38:I38) -> 0
A39: TOTAL | D39: =SUM(D35:D38) -> 0 | E39: =SUM(E35:E38) -> 0 | F39: =SUM(F35:F38) -> 0 | G39: =SUM(G35:G38) -> 0 | H39: =SUM(H35:H38) -> 0 | I39: =SUM(I35:I38) -> 0 | J39: =SUM(J35:J38) -> 0 | K39: =SUM(K35:K38) -> 0
A43: SOCIO | B43: RECIBO DE SERVICIO | C43: DETALLE | D43: LUZ | E43: AGUA | F43: G. ADM | G43: P. SOCIAL | H43: P.S X FALLECIMIENTO | I43: DEPOSITO | J43: MULTA | K43: TOTAL
K50: =SUM(D50:J50) -> 0
K51: =SUM(D51:J51) -> 0
K52: =SUM(D52:J52) -> 0
K53: =SUM(D53:J53) -> 0
K54: =SUM(D54:J54) -> 0
K55: =SUM(D55:J55) -> 0
K56: =SUM(D56:J56) -> 0
K57: =SUM(D57:J57) -> 0
A58: TOTAL | D58: =SUM(D44:D57) -> 0 | E58: =SUM(E44:E57) -> 0 | F58: =SUM(F44:F57) -> 0 | G58: =SUM(G44:G57) -> 0 | H58: =SUM(H44:H57) -> 0 | I58: =SUM(I44:I57) -> 0 | K58: =SUM(K44:K57) -> 0
...

Sheet 19-04-2026
A1: INGRESOS DEL DIA 19-04-2026
A3: INQUILINO | B3: COMPROBANTE | C3: DETALLE | D3: LUZ | E3: AGUA | F3: ALQUILER | G3: ESPACIO | H3: PARQUEO | I3: TICKET | J3: ALQUILER LOCAL 2DO PISO | K3: TOTAL
K4: =SUM(D4:J4) -> 0
K5: =SUM(D5:J5) -> 0
K6: =SUM(D6:J6) -> 0
K7: =SUM(D7:J7) -> 0
K8: =SUM(D8:J8) -> 0
K9: =SUM(D9:J9) -> 0
K10: =SUM(D10:J10) -> 0
K11: =SUM(D11:J11) -> 0
K12: =SUM(D12:J12) -> 0
K13: =SUM(D13:J13) -> 0
K14: =SUM(D14:J14) -> 0
K15: =SUM(D15:J15) -> 0
... K22: =SUM(D22:J22) -> 0
A23: TOTAL | D23: =SUM(D4:D22) -> 0 | E23: =SUM(E4:E22) -> 0 | F23: =SUM(F4:F22) -> 0 | G23: =SUM(G4:G22) -> 0 | H23: =SUM(H4:H22) -> 0 | I23: =SUM(I4:I22) -> 0 | J23: =SUM(J4:J22) -> 0 | K23: =SUM(K4:K22) -> 0
A25: BBVA
A26: INQUILINOS | B26: COMPROBANTE | C26: DETALLE | D26: LUZ | E26: AGUA | F26: ALQUILER | G26: ESPACIO | H26: DEPOSITO | I26: TICKET | K26: TOTAL
K27: =SUM(D27:I27) -> 0
K29: =SUM(D29:I29) -> 0
K30: =SUM(D30:I30) -> 0 | M30: TOTAL QR | N30: =K31+K39 -> 0
A31: TOTAL | D31: =SUM(D27:D30) -> 0 | E31: =SUM(E27:E30) -> 0 | F31: =SUM(F27:F30) -> 0 | G31: =SUM(G27:G30) -> 0 | H31: =SUM(H27:H30) -> 0 | I31: =SUM(I27:I30) -> 0 | J31: =SUM(J27:J30) -> 0 | K31: =SUM(K27:K30) -> 0
A33: BBVA
A34: SOCIOS | B34: RECIBO DE SERVICIO | C34: DETALLE | D34: LUZ | E34: AGUA | F34: G. ADM | G34: P. SOCIAL | H34: DEPOSITO | I34: P.S X FALLECIMIENTO | K34: TOTAL
K35: =SUM(D35:I35) -> 0
K36: =SUM(D36:I36) -> 0
K37: =SUM(D37:I37) -> 0
K38: =SUM(D38:I38) -> 0
A39: TOTAL | D39: =SUM(D35:D38) -> 0 | E39: =SUM(E35:E38) -> 0 | F39: =SUM(F35:F38) -> 0 | G39: =SUM(G35:G38) -> 0 | H39: =SUM(H35:H38) -> 0 | I39: =SUM(I35:I38) -> 0 | J39: =SUM(J35:J38) -> 0 | K39: =SUM(K35:K38) -> 0
A43: SOCIO | B43: RECIBO DE SERVICIO | C43: DETALLE | D43: LUZ | E43: AGUA | F43: G. ADM | G43: P. SOCIAL | H43: P.S X FALLECIMIENTO | I43: DEPOSITO | J43: MULTA | K43: TOTAL
K44: =SUM(D44:J44) -> 0
K45: =SUM(D45:J45) -> 0
K46: =SUM(D46:J46) -> 0
K47: =SUM(D47:J47) -> 0
K48: =SUM(D48:J48) -> 0
K49: =SUM(D49:J49) -> 0
K50: =SUM(D50:J50) -> 0
K51: =SUM(D51:J51) -> 0
K52: =SUM(D52:J52) -> 0
K53: =SUM(D53:J53) -> 0
...

Sheet 20-04-2026
A1: INGRESOS DEL DIA 20-04-2026
A3: INQUILINO | B3: COMPROBANTE | C3: DETALLE | D3: LUZ | E3: AGUA | F3: ALQUILER | G3: ESPACIO | H3: PARQUEO | I3: TICKET | J3: ALQUILER LOCAL 2DO PISO | K3: TOTAL
A4: JOSE | B4: TK 50828 | C4: 46113 | I4: 10 | K4: =SUM(D4:J4) -> 10
A5: JOSE DESARMADORES | B5: TK 50829 | C5: 46113 | I5: 10 | K5: =SUM(D5:J5) -> 10
A6: JOSE | B6: TK 50830 | C6: 46113 | I6: 10 | K6: =SUM(D6:J6) -> 10
K7: =SUM(D7:J7) -> 0
A8: TERESA PEÑA VDA DE VILLANUEVA | B8: EB01-7222 | C8: 46082 | F8: 600 | K8: =SUM(D8:J8) -> 600
A9: KARINA LUZ LUCIANO INGA | B9: EB01-7223 | C9: 46082 | F9: 300 | K9: =SUM(D9:J9) -> 300
A10: PARQUEO | B10: EB01-7225 | C10: 46113 | H10: 75.3 | K10: =SUM(D10:J10) -> 75.3
K11: =SUM(D11:J11) -> 0
A12: TERESA PEÑA VDA DE VILLANUEVA | B12: RII 33580 | C12: 46054 | D12: 14.4 | E12: 6 | K12: =SUM(D12:J12) -> 20.4
K13: =SUM(D13:J13) -> 0
K14: =SUM(D14:J14) -> 0
K15: =SUM(D15:J15) -> 0
K16: =SUM(D16:J16) -> 0
K17: =SUM(D17:J17) -> 0
K18: =SUM(D18:J18) -> 0
K19: =SUM(D19:J19) -> 0
K20: =SUM(D20:J20) -> 0
K21: =SUM(D21:J21) -> 0
K22: =SUM(D22:J22) -> 0
K23: =SUM(D23:J23) -> 0
K24: =SUM(D24:J24) -> 0
A25: TOTAL | D25: =SUM(D4:D24) -> 14.4 | E25: =SUM(E4:E24) -> 6 | F25: =SUM(F4:F24) -> 900 | G25: =SUM(G4:G24) -> 0 | H25: =SUM(H4:H24) -> 75.3 | I25: =SUM(I4:I24) -> 30 | J25: =SUM(J4:J24) -> 0 | K25: =SUM(K4:K24) -> 1025.7
A27: BBVA
A28: INQUILINOS | B28: COMPROBANTE | C28: DETALLE | D28: LUZ | E28: AGUA | F28: ALQUILER | G28: ESPACIO | H28: DEPOSITO | I28: TICKET | K28: TOTAL
A29: VISIONA TRADE S.A.C. | B29: E001-369 | C29: 46113 | G29: 30 | K29: =SUM(D29:I29) -> 30
A30: MARIELA CUNIAS SANTOS | B30: EB01-7224 | C30: 46113 | F30: 500 | K30: =SUM(D30:I30) -> 500
K31: =SUM(D31:I31) -> 0
K32: =SUM(D32:I32) -> 0 | M32: TOTAL QR | N32: =K33+K41 -> 1266.2
A33: TOTAL | D33: =SUM(D29:D32) -> 0 | E33: =SUM(E29:E32) -> 0 | F33: =SUM(F29:F32) -> 500 | G33: =SUM(G29:G32) -> 30 | H33: =SUM(H29:H32) -> 0 | I33: =SUM(I29:I32) -> 0 | J33: =SUM(J29:J32) -> 0 | K33: =SUM(K29:K32) -> 530
A35: BBVA
A36: SOCIOS | B36: RECIBO DE SERVICIO | C36: DETALLE | D36: LUZ | E36: AGUA | F36: G. ADM | G36: P. SOCIAL | H36: DEPOSITO | I36: P.S X FALLECIMIENTO | K36: TOTAL
A37: FLORES FLORES IRENE | B37: RI 32949 | C37: 46082 | D37: 552.8 | E37: 118.4 | F37: 60 | G37: 5 | K37: =SUM(D37:I37) -> 736.2
K38: =SUM(D38:I38) -> 0
K39: =SUM(D39:I39) -> 0
K40: =SUM(D40:I40) -> 0
A41: TOTAL | D41: =SUM(D37:D40) -> 552.8 | E41: =SUM(E37:E40) -> 118.4 | F41: =SUM(F37:F40) -> 60 | G41: =SUM(G37:G40) -> 5 | H41: =SUM(H37:H40) -> 0 | I41: =SUM(I37:I40) -> 0 | J41: =SUM(J37:J40) -> 0 | K41: =SUM(K37:K40) -> 736.2
A45: SOCIO | B45: RECIBO DE SERVICIO | C45: DETALLE | D45: LUZ | E45: AGUA | F45: G. ADM | G45: P. SOCIAL | H45: P.S X FALLECIMIENTO | I45: DEPOSITO | J45: MULTA | K45: TOTAL
K46: =SUM(D46:J46) -> 0
...

Sheet 21-04-2026
A1: INGRESOS DEL DIA 21-04-2026
A3: INQUILINO | B3: COMPROBANTE | C3: DETALLE | D3: LUZ | E3: AGUA | F3: ALQUILER | G3: ESPACIO | H3: PARQUEO | I3: TICKET | J3: ALQUILER LOCAL 2DO PISO | K3: TOTAL
A4: JOSE | B4: TK 50831 | C4: 46113 | I4: 10 | K4: =SUM(D4:J4) -> 10
K5: =SUM(D5:J5) -> 0
A6: LILIA RUFINA ZANABRIA LADERA DE COCHACHI | B6: EB01-7227 | C6: 46082 | F6: 350 | K6: =SUM(D6:J6) -> 350
A7: PARQUEO | B7: EB01-7228 | C7: 46113 | H7: 55 | K7: =SUM(D7:J7) -> 55
K8: =SUM(D8:J8) -> 0
K9: =SUM(D9:J9) -> 0
K10: =SUM(D10:J10) -> 0
K11: =SUM(D11:J11) -> 0
K12: =SUM(D12:J12) -> 0
K13: =SUM(D13:J13) -> 0
A14: LILIA RUFINA ZANABRIA LADERA DE COCHACHI | B14: RII 3359 | C14: 46054 | D14: 19.1 | E14: 6 | K14: =SUM(D14:J14) -> 25.1
K15: =SUM(D15:J15) -> 0
K16: =SUM(D16:J16) -> 0
K17: =SUM(D17:J17) -> 0
K18: =SUM(D18:J18) -> 0
K19: =SUM(D19:J19) -> 0
K20: =SUM(D20:J20) -> 0
K21: =SUM(D21:J21) -> 0
K22: =SUM(D22:J22) -> 0
A23: TOTAL | D23: =SUM(D4:D22) -> 19.1 | E23: =SUM(E4:E22) -> 6 | F23: =SUM(F4:F22) -> 350 | G23: =SUM(G4:G22) -> 0 | H23: =SUM(H4:H22) -> 55 | I23: =SUM(I4:I22) -> 10 | J23: =SUM(J4:J22) -> 0 | K23: =SUM(K4:K22) -> 440.1
A25: BBVA
A26: INQUILINOS | B26: COMPROBANTE | C26: DETALLE | D26: LUZ | E26: AGUA | F26: ALQUILER | G26: ESPACIO | H26: DEPOSITO | I26: TICKET | K26: TOTAL
K27: =SUM(D27:I27) -> 0
K29: =SUM(D29:I29) -> 0
K30: =SUM(D30:I30) -> 0 | M30: TOTAL QR | N30: =K31+K39 -> 0
A31: TOTAL | D31: =SUM(D27:D30) -> 0 | E31: =SUM(E27:E30) -> 0 | F31: =SUM(F27:F30) -> 0 | G31: =SUM(G27:G30) -> 0 | H31: =SUM(H27:H30) -> 0 | I31: =SUM(I27:I30) -> 0 | J31: =SUM(J27:J30) -> 0 | K31: =SUM(K27:K30) -> 0
A33: BBVA
A34: SOCIOS | B34: RECIBO DE SERVICIO | C34: DETALLE | D34: LUZ | E34: AGUA | F34: G. ADM | G34: P. SOCIAL | H34: DEPOSITO | I34: P.S X FALLECIMIENTO | K34: TOTAL
K35: =SUM(D35:I35) -> 0
K36: =SUM(D36:I36) -> 0
K37: =SUM(D37:I37) -> 0
K38: =SUM(D38:I38) -> 0
A39: TOTAL | D39: =SUM(D35:D38) -> 0 | E39: =SUM(E35:E38) -> 0 | F39: =SUM(F35:F38) -> 0 | G39: =SUM(G35:G38) -> 0 | H39: =SUM(H35:H38) -> 0 | I39: =SUM(I35:I38) -> 0 | J39: =SUM(J35:J38) -> 0 | K39: =SUM(K35:K38) -> 0
A43: SOCIO | B43: RECIBO DE SERVICIO | C43: DETALLE | D43: LUZ | E43: AGUA | F43: G. ADM | G43: P. SOCIAL | H43: P.S X FALLECIMIENTO | I43: DEPOSITO | J43: MULTA | K43: TOTAL
A44: VILCHEZ LOURDES | B44: RI 32950 | C44: 46082 | D44: 766.5 | E44: 76 | I44: 200 | K44: =SUM(D44:J44) -> 1042.5
K45: =SUM(D45:J45) -> 0
K46: =SUM(D46:J46) -> 0
K47: =SUM(D47:J47) -> 0
...

Sheet 22-04-2026
A1: INGRESOS DEL DIA 22-04-2026
A3: INQUILINO | B3: COMPROBANTE | C3: DETALLE | D3: LUZ | E3: AGUA | F3: ALQUILER | G3: TALONARIO SANTA ROSA | H3: PARQUEO | I3: TICKET | J3: ALQUILER LOCAL 2DO PISO | K3: TOTAL
A4: JOSE | B4: TK 50832 | C4: 46113 | I4: 10 | K4: =SUM(D4:J4) -> 10
K5: =SUM(D5:J5) -> 0
A6: CLAROS TORRES SANTOS JESUS | B6: E001-370 | C6: 46082 | F6: 150 | K6: =SUM(D6:J6) -> 150
K7: =SUM(D7:J7) -> 0
A8: JESSICA PATRICIA SALDAÑA DONAYRE | B8: EB01-7231 | C8: 46054 | F8: 100 | K8: =SUM(D8:J8) -> 100
A9: MARI SOL QUISPE CHAVEZ | B9: EB01-7232 | C9: 46082 | F9: 100 | K9: =SUM(D9:J9) -> 100
A10: MAXIMO FLAVIO HUAMANÍ CONTRERAS | B10: EB01-7233 | C10: 46113 | F10: 400 | K10: =SUM(D10:J10) -> 400
A11: CASILDA CATALINA REBAZA REBAZA | B11: EB01-7234 | C11: 46082 | F11: 350 | K11: =SUM(D11:J11) -> 350
A12: ABEL ANCHAYA HUAMAN | B12: EB01-7235 | C12: 46023 | F12: 200 | K12: =SUM(D12:J12) -> 200
C13: 46054 | F13: 100 | K13: =SUM(D13:J13) -> 100
A14: IDALINA MONTENEGRO BAUTISTA | B14: EB01-7237 | C14: 46082 | F14: 200 | K14: =SUM(D14:J14) -> 200
A15: JANETT CONSUELO CASTRO RODRIGUEZ | B15: EB01-7238 | C15: 46054 | F15: 100 | K15: =SUM(D15:J15) -> 100
A16: DAYSI ELIZABETH AZURZA TRIBIÑOS | B16: EB01-7239 | C16: 46082 | F16: 150 | K16: =SUM(D16:J16) -> 150
A17: ERIKA BENITES TRIBIÑOS | B17: EB01-7240 | C17: 46082 | F17: 150 | K17: =SUM(D17:J17) -> 150
A18: ASAEL CASTILLO ZAPATA | B18: EB01-7242 | C18: 46082 | F18: 300 | K18: =SUM(D18:J18) -> 300
A19: GLADIS ARREDONDO GARCIA | B19: EB01-7243 | C19: 46082 | F19: 100 | K19: =SUM(D19:J19) -> 100
A20: DOMINICA LUCIANA FLORES LAREDO | B20: EB01-7244 | C20: 46082 | F20: 100 | K20: =SUM(D20:J20) -> 100
A21: ELMER BURGA CARRASCO | B21: EB01-7245 | C21: 46082 | F21: 300 | K21: =SUM(D21:J21) -> 300
A22: LIDIA AGRIPINA CONDORI MAMANI | B22: EB01-7246 | C22: 46054 | F22: 200 | K22: =SUM(D22:J22) -> 200
A23: MERY RUTH CARRASCO PICHIHUA | B23: EB01-7249 | C23: 46082 | F23: 100 | K23: =SUM(D23:J23) -> 100
A24: HERNANDEZ HERNANDEZ LILIBETH MARIA | B24: EB01-7250 | C24: 46082 | F24: 200 | K24: =SUM(D24:J24) -> 200
A25: PARQUEO | B25: EB01-7252 | C25: 46113 | H25: 64 | K25: =SUM(D25:J25) -> 64
A27: REBAZA CASILDA | B27: RII 3360 | C27: 46082 | D27: 8 | E27: 6 | K27: =SUM(D27:J27) -> 14
A28: QUISPE PATRICIA | B28: RII 3362 | C28: 46054 | D28: 14.4 | E28: 6 | K28: =SUM(D28:J28) -> 20.4
C29: 46082 | D29: 5.6 | E29: 6 | K29: =SUM(D29:J29) -> 11.6
A30: CHOQUEHUANCA DERSE | B30: RII 3363 | C30: 46082 | D30: 6.3 | E30: 6 | K30: =SUM(D30:J30) -> 12.3
A31: CONDORI LIDIA | B31: RII 3364 | C31: 45870 | G31: 15 | K31: =SUM(D31:J31) -> 15
C32: 46054 | D32: 8.9 | E32: 6 | K32: =SUM(D32:J32) -> 14.9
C33: 46082 | D33: 6.5 | E33: 6 | K33: =SUM(D33:J33) -> 12.5
A34: ARMESTA JUANA | B34: RII 3368 | C34: 45931 | D34: 10.6 | E34: 6 | K34: =SUM(D34:J34) -> 16.6
C35: 45962 | D35: 8.5 | E35: 5 | K35: =SUM(D35:J35) -> 13.5
C36: 45992 | D36: 9.4 | E36: 5 | K36: =SUM(D36:J36) -> 14.4
C37: 46023 | D37: 11.6 | E37: 3 | K37: =SUM(D37:J37) -> 14.6
C38: 46054 | D38: 11.6 | E38: 6 | K38: =SUM(D38:J38) -> 17.6
B39: RII 3369 | C39: 46082 | D39: 9.6 | E39: 6 | K39: =SUM(D39:J39) -> 15.6
A40: MERY RUTH CARRASCO PICHIHUA | B40: RII 3370 | C40: 46082 | D40: 5.6 | E40: 15 | K40: =SUM(D40:J40) -> 20.6
A41: HERNANDEZ HERNANDEZ LILIBETH MARIA | B41: RII 3371 | C41: 46082 | D41: 34 | E41: 6 | K41: =SUM(D41:J41) -> 40
K42: =SUM(D42:J42) -> 0
...

Sheet 23-04-2026
A1: INGRESOS DEL DIA 23-04-2026
A3: INQUILINO | B3: COMPROBANTE | C3: DETALLE | D3: LUZ | E3: AGUA | F3: ALQUILER | G3: ESPACIO | H3: PARQUEO | I3: TICKET | J3: ALQUILER LOCAL 2DO PISO | K3: TOTAL
A4: JOSE | B4: TK 50833 | C4: 46113 | I4: 10 | K4: =SUM(D4:J4) -> 10
K5: =SUM(D5:J5) -> 0
A6: PARQUEO | B6: EB01-7255 | C6: 46113 | H6: 59.5 | K6: =SUM(D6:J6) -> 59.5
K7: =SUM(D7:J7) -> 0
K8: =SUM(D8:J8) -> 0
K9: =SUM(D9:J9) -> 0
K10: =SUM(D10:J10) -> 0
K11: =SUM(D11:J11) -> 0
K12: =SUM(D12:J12) -> 0
K13: =SUM(D13:J13) -> 0
K14: =SUM(D14:J14) -> 0
K15: =SUM(D15:J15) -> 0
K16: =SUM(D16:J16) -> 0
K17: =SUM(D17:J17) -> 0
K18: =SUM(D18:J18) -> 0
... K22: =SUM(D22:J22) -> 0
A23: TOTAL | D23: =SUM(D4:D22) -> 0 | E23: =SUM(E4:E22) -> 0 | F23: =SUM(F4:F22) -> 0 | G23: =SUM(G4:G22) -> 0 | H23: =SUM(H4:H22) -> 59.5 | I23: =SUM(I4:I22) -> 10 | J23: =SUM(J4:J22) -> 0 | K23: =SUM(K4:K22) -> 69.5
A25: BBVA
A26: INQUILINOS | B26: COMPROBANTE | C26: DETALLE | D26: LUZ | E26: AGUA | F26: ALQUILER | G26: ESPACIO | H26: DEPOSITO | I26: TICKET | K26: TOTAL
A27: GLADYS ENCARNACION PAUCARPOMA | B27: EB01-7253 | C27: 46082 | F27: 500 | K27: =SUM(D27:I27) -> 500
B28: RII 3372 | C28: 46082 | D28: 29 | E28: 6 | K28: =SUM(D28:I28) -> 35
A29: MAPFRE PERU COMPAÑIA DE SEGUROS Y REASEGUROS | B29: E001-372 | C29: 46113 | G29: 30 | K29: =SUM(D29:I29) -> 30
K30: =SUM(D30:I30) -> 0 | M30: TOTAL QR | N30: =K31+K39 -> 565
A31: TOTAL | D31: =SUM(D27:D30) -> 29 | E31: =SUM(E27:E30) -> 6 | F31: =SUM(F27:F30) -> 500 | G31: =SUM(G27:G30) -> 30 | H31: =SUM(H27:H30) -> 0 | I31: =SUM(I27:I30) -> 0 | J31: =SUM(J27:J30) -> 0 | K31: =SUM(K27:K30) -> 565
A33: BBVA
A34: SOCIOS | B34: RECIBO DE SERVICIO | C34: DETALLE | D34: LUZ | E34: AGUA | F34: G. ADM | G34: P. SOCIAL | H34: DEPOSITO | I34: P.S X FALLECIMIENTO | K34: TOTAL
K35: =SUM(D35:I35) -> 0
K36: =SUM(D36:I36) -> 0
K37: =SUM(D37:I37) -> 0
K38: =SUM(D38:I38) -> 0
A39: TOTAL | D39: =SUM(D35:D38) -> 0 | E39: =SUM(E35:E38) -> 0 | F39: =SUM(F35:F38) -> 0 | G39: =SUM(G35:G38) -> 0 | H39: =SUM(H35:H38) -> 0 | I39: =SUM(I35:I38) -> 0 | J39: =SUM(J35:J38) -> 0 | K39: =SUM(K35:K38) -> 0
A43: SOCIO | B43: RECIBO DE SERVICIO | C43: DETALLE | D43: LUZ | E43: AGUA | F43: G. ADM | G43: P. SOCIAL | H43: P.S X FALLECIMIENTO | I43: DEPOSITO | J43: MULTA | K43: TOTAL
A44: TORRES FRANCISCO | B44: RI 32955 | C44: 46082 | D44: 52.4 | E44: 75 | K44: =SUM(D44:J44) -> 127.4
C45: 46113 | F45: 60 | G45: 5 | K45: =SUM(D45:J45) -> 65
A46: SALAS JUDITH | B46: RI 32956 | C46: 46082 | D46: 56.1 | K46: =SUM(D46:J46) -> 56.1
A47: QUISPE VIDAL | B47: RI 32957 | C47: 46082 | D47: 586.2 | E47: 17.2 | F47: 60 | G47: 5 | K47: =SUM(D47:J47) -> 668.4
A48: ESTELA ELVIA | B48: RI 32958 | C48: 46082 | D48: 232.4 | E48: 70.4 | F48: 60 | G48: 5 | K48: =SUM(D48:J48) -> 367.8
A49: SALAS JUDITH | B49: RI 32959 | C49: 46113 | F49: 60 | G49: 5 | K49: =SUM(D49:J49) -> 65
...

Sheet 24-04-2026
A1: INGRESOS DEL DIA 24-04-2026
A3: INQUILINO | B3: COMPROBANTE | C3: DETALLE | D3: LUZ | E3: AGUA | F3: ALQUILER | G3: ESPACIO | H3: PARQUEO | I3: TICKET | J3: ALQUILER LOCAL 2DO PISO | K3: TOTAL
A4: JOSE | B4: TK 50834 | C4: 46113 | I4: 10 | K4: =SUM(D4:J4) -> 10
K5: =SUM(D5:J5) -> 0
A6: LISBETH KARITO QUISPE NAPUCHE | B6: EB01-7256 | C6: 46082 | F6: 300 | K6: =SUM(D6:J6) -> 300
A7: PARQUEO | B7: EB01-7258 | C7: 46113 | H7: 61.2 | K7: =SUM(D7:J7) -> 61.2
K8: =SUM(D8:J8) -> 0
K9: =SUM(D9:J9) -> 0
K10: =SUM(D10:J10) -> 0
K11: =SUM(D11:J11) -> 0
K12: =SUM(D12:J12) -> 0
K13: =SUM(D13:J13) -> 0
K14: =SUM(D14:J14) -> 0
K15: =SUM(D15:J15) -> 0
K16: =SUM(D16:J16) -> 0
K17: =SUM(D17:J17) -> 0
K18: =SUM(D18:J18) -> 0
K19: =SUM(D19:J19) -> 0
... K22: =SUM(D22:J22) -> 0
A23: TOTAL | D23: =SUM(D4:D22) -> 0 | E23: =SUM(E4:E22) -> 0 | F23: =SUM(F4:F22) -> 300 | G23: =SUM(G4:G22) -> 0 | H23: =SUM(H4:H22) -> 61.2 | I23: =SUM(I4:I22) -> 10 | J23: =SUM(J4:J22) -> 0 | K23: =SUM(K4:K22) -> 371.2
A25: BBVA
A26: INQUILINOS | B26: COMPROBANTE | C26: DETALLE | D26: LUZ | E26: AGUA | F26: ALQUILER | G26: ESPACIO | H26: DEPOSITO | I26: TICKET | K26: TOTAL
A27: VASQUEZ TAFUR SONIA ALBERTINA | B27: E001-373 | C27: 46113 | G27: 30 | K27: =SUM(D27:I27) -> 30
K29: =SUM(D29:I29) -> 0
K30: =SUM(D30:I30) -> 0 | M30: TOTAL QR | N30: =K31+K39 -> 30
A31: TOTAL | D31: =SUM(D27:D30) -> 0 | E31: =SUM(E27:E30) -> 0 | F31: =SUM(F27:F30) -> 0 | G31: =SUM(G27:G30) -> 30 | H31: =SUM(H27:H30) -> 0 | I31: =SUM(I27:I30) -> 0 | J31: =SUM(J27:J30) -> 0 | K31: =SUM(K27:K30) -> 30
A33: BBVA
A34: SOCIOS | B34: RECIBO DE SERVICIO | C34: DETALLE | D34: LUZ | E34: AGUA | F34: G. ADM | G34: P. SOCIAL | H34: DEPOSITO | I34: P.S X FALLECIMIENTO | K34: TOTAL
K35: =SUM(D35:I35) -> 0
K36: =SUM(D36:I36) -> 0
K37: =SUM(D37:I37) -> 0
K38: =SUM(D38:I38) -> 0
A39: TOTAL | D39: =SUM(D35:D38) -> 0 | E39: =SUM(E35:E38) -> 0 | F39: =SUM(F35:F38) -> 0 | G39: =SUM(G35:G38) -> 0 | H39: =SUM(H35:H38) -> 0 | I39: =SUM(I35:I38) -> 0 | J39: =SUM(J35:J38) -> 0 | K39: =SUM(K35:K38) -> 0
A43: SOCIO | B43: RECIBO DE SERVICIO | C43: DETALLE | D43: LUZ | E43: AGUA | F43: G. ADM | G43: P. SOCIAL | H43: P.S X FALLECIMIENTO | I43: DEPOSITO | J43: MULTA | K43: TOTAL
A44: CRUZ LUIS | B44: RI 32960 | C44: 46082 | D44: 23.3 | E44: 6 | K44: =SUM(D44:J44) -> 29.3
A45: BERNAOLA FLORENCIA | B45: RI 32961 | C45: 46082 | F45: 60 | G45: 5 | K45: =SUM(D45:J45) -> 65
K46: =SUM(D46:J46) -> 0
K47: =SUM(D47:J47) -> 0
K48: =SUM(D48:J48) -> 0
K49: =SUM(D49:J49) -> 0
...

Sheet 25-04-2026
A1: INGRESOS DEL DIA 25-04-2026
A3: INQUILINO | B3: COMPROBANTE | C3: DETALLE | D3: LUZ | E3: AGUA | F3: ALQUILER | G3: ESPACIO | H3: PARQUEO | I3: TICKET | J3: ALQUILER LOCAL 2DO PISO | K3: TOTAL
A4: JOSE | B4: TK 50835 | C4: 46113 | I4: 10 | K4: =SUM(D4:J4) -> 10
K5: =SUM(D5:J5) -> 0
A6: PARQUEO | B6: EB01-7260 | C6: 46113 | H6: 61.5 | K6: =SUM(D6:J6) -> 61.5
K7: =SUM(D7:J7) -> 0
K8: =SUM(D8:J8) -> 0
K9: =SUM(D9:J9) -> 0
K10: =SUM(D10:J10) -> 0
K11: =SUM(D11:J11) -> 0
K12: =SUM(D12:J12) -> 0
K13: =SUM(D13:J13) -> 0
K14: =SUM(D14:J14) -> 0
K15: =SUM(D15:J15) -> 0
K16: =SUM(D16:J16) -> 0
K17: =SUM(D17:J17) -> 0
K18: =SUM(D18:J18) -> 0
... K22: =SUM(D22:J22) -> 0
A23: TOTAL | D23: =SUM(D4:D22) -> 0 | E23: =SUM(E4:E22) -> 0 | F23: =SUM(F4:F22) -> 0 | G23: =SUM(G4:G22) -> 0 | H23: =SUM(H4:H22) -> 61.5 | I23: =SUM(I4:I22) -> 10 | J23: =SUM(J4:J22) -> 0 | K23: =SUM(K4:K22) -> 71.5
A25: BBVA
A26: INQUILINOS | B26: COMPROBANTE | C26: DETALLE | D26: LUZ | E26: AGUA | F26: ALQUILER | G26: ESPACIO | H26: DEPOSITO | I26: TICKET | K26: TOTAL
A27: VASQUEZ TAFUR SONIA ALBERTINA | B27: E001-374 | C27: 46113 | F27: 30 | K27: =SUM(D27:I27) -> 30
K29: =SUM(D29:I29) -> 0
K30: =SUM(D30:I30) -> 0 | M30: TOTAL QR | N30: =K31+K39 -> 30
A31: TOTAL | D31: =SUM(D27:D30) -> 0 | E31: =SUM(E27:E30) -> 0 | F31: =SUM(F27:F30) -> 30 | G31: =SUM(G27:G30) -> 0 | H31: =SUM(H27:H30) -> 0 | I31: =SUM(I27:I30) -> 0 | J31: =SUM(J27:J30) -> 0 | K31: =SUM(K27:K30) -> 30
A33: BBVA
A34: SOCIOS | B34: RECIBO DE SERVICIO | C34: DETALLE | D34: LUZ | E34: AGUA | F34: G. ADM | G34: P. SOCIAL | H34: DEPOSITO | I34: P.S X FALLECIMIENTO | K34: TOTAL
K35: =SUM(D35:I35) -> 0
