Workbook

Sheet 2016
D1: Enero | J1: Febrero | P1: Marzo | V1: Abril | AB1: 42491 | AH1: 42522 | AN1: 42552 | AT1: 42583 | AZ1: set-16 | BF1: 42644 | BL1: 42675 | BR1: 42705 | BX1: DEUDA | BY1: DEUDA | BZ1: TOTAL DE DEUDA | CC1: DETALLE DE DEUDA 2016
A2: N° | B2: APELLIDOS Y NOMBRES | C2: 2015 | D2: Gast. Adm. | E2: Prev. Social | F2: Luz | G2: Agua | H2: Deposito | I2: Multa | J2: Gast. Adm. | K2: Prev. Social | L2: Luz | M2: Agua | N2: Deposito | O2: Multa | P2: Gast. Adm. | Q2: Prev. Social | R2: Luz | S2: Agua | T2: Deposito | U2: Multa | V2: Gast. Adm. | W2: Prev. Social | X2: Luz | Y2: Agua | Z2: Deposito | AA2: Multa | AB2: Gast. Adm. | AC2: Prev. Social | AD2: Luz | AE2: Agua | AF2: Deposito | AG2: Multa | AH2: Gast. Adm. | AI2: Prev. Social | AJ2: Luz | AK2: Agua | AL2: Deposito | AM2: Multa | AN2: Gast. Adm. | AO2: Prev. Social | AP2: Luz | AQ2: Agua | AR2: Deposito | AS2: Multa | AT2: Gast. Adm. | AU2: Prev. Social | AV2: Luz | AW2: Agua | AX2: Deposito | AY2: Multa | AZ2: Gast. Adm. | BA2: Prev. Social | BB2: Luz | BC2: Agua | BD2: Deposito | BE2: Multa | BF2: Gast. Adm. | BG2: Prev. Social | BH2: Luz | BI2: Agua | BJ2: Deposito | BK2: Multa | BL2: Gast. Adm. | BM2: Prev. Social | BN2: Luz | BO2: Agua | BP2: Deposito | BQ2: Multa | BR2: Gast. Adm. | BS2: Prev. Social | BT2: Luz | BU2: Agua | BV2: Deposito | BW2: Multa | BX2: 2016 | BY2: 2015 | CC2: G.A. | CD2: P.S. | CE2: LUZ | CF2: AGUA | CG2: DEPOSITO | CH2: MULTA y/o VARIOS
A3: 1 | B3: AGUIRRE QUISPE WILFREDO GILMER | C3: 0 | D3: 0 | E3: 0 | F3: 0 | G3: 0 | H3: 0 | I3: 0 | J3: 0 | K3: 0 | L3: 0 | M3: 0 | N3: 0 | O3: 0 | P3: 0 | Q3: 0 | R3: 0 | S3: 0 | T3: 0 | V3: 0 | W3: 0 | X3: 0 | Y3: 0 | Z3: 0 | AA3: 0 | AB3: 0 | AC3: 0 | AD3: 0 | AE3: 0 | AF3: 0 | AG3: 0 | AH3: 0 | AI3: 0 | AJ3: 0 | AK3: 0 | AL3: 0 | AN3: 0 | AO3: 0 | AP3: 0 | AQ3: 0 | AR3: 0 | AT3: 0 | AU3: 0 | AV3: 0 | AW3: 0 | AX3: 0 | AY3: 0 | AZ3: 0 | BA3: 0 | BB3: 0 | BC3: 0 | BF3: 0 | BG3: 0 | BH3: 0 | BI3: 0 | BL3: 0 | BM3: 0 | BN3: 0 | BO3: 0 | BR3: 0 | BS3: 0 | BT3: 57.2 | BU3: 3 | BX3: =SUM(D3:BW3) -> 60.2 | BY3: =C3 -> 0 | BZ3: =BX3+BY3 -> 60.2 | CC3: =D3+J3+P3+V3+AB3+AH3+AN3+AT3+AZ3+BF3+BL3+BR3 -> 0 | CD3: =E3+K3+Q3+W3+AC3+AI3+AO3+AU3+BA3+BG3+BM3+BS3 -> 0 | CE3: =F3+L3+R3+X3+AD3+AJ3+AP3+AV3+BB3+BH3+BN3+BT3 -> 57.2 | CF3: =G3+M3+S3+Y3+AE3+AK3+AQ3+AW3+BC3+BI3+BO3+BU3 -> 3 | CG3: =H3+N3+T3+Z3+AF3+AL3+AR3+AX3+BJ3+BP3+BV3+BD3 -> 0 | CH3: =I3+O3+U3+AA3+AG3+AM3+AS3+AY3+BE3+BK3+BQ3+BW3 -> 0
A4: 2 | B4: ALARCON ANAMPA NANCY GUISELA | C4: 0 | D4: 0 | E4: 0 | F4: 0 | G4: 0 | H4: 0 | I4: 0 | J4: 0 | K4: 0 | L4: 0 | M4: 0 | N4: 0 | O4: 0 | P4: 0 | Q4: 0 | R4: 0 | S4: 0 | T4: 0 | U4: 0 | V4: 0 | W4: 0 | X4: 0 | Y4: 0 | Z4: 0 | AA4: 0 | AB4: 0 | AC4: 0 | AD4: 0 | AE4: 0 | AF4: 0 | AG4: 0 | AH4: 0 | AI4: 0 | AJ4: 0 | AK4: 0 | AL4: 0 | AM4: 0 | AN4: 0 | AO4: 0 | AP4: 0 | AQ4: 0 | AR4: 0 | AS4: 0 | AT4: 0 | AU4: 0 | AV4: 0 | AW4: 0 | AX4: 0 | AY4: 0 | AZ4: 0 | BA4: 0 | BB4: 0 | BC4: 0 | BF4: 0 | BG4: 0 | BH4: 0 | BI4: 0 | BL4: 0 | BM4: 0 | BN4: 0 | BO4: 0 | BR4: 60 | BS4: 2 | BT4: 42.5 | BU4: 3 | BX4: =SUM(D4:BW4) -> 107.5 | BY4: =C4 -> 0 | BZ4: =BX4+BY4 -> 107.5 | CC4: =D4+J4+P4+V4+AB4+AH4+AN4+AT4+AZ4+BF4+BL4+BR4 -> 60 | CD4: =E4+K4+Q4+W4+AC4+AI4+AO4+AU4+BA4+BG4+BM4+BS4 -> 2 | CE4: =F4+L4+R4+X4+AD4+AJ4+AP4+AV4+BB4+BH4+BN4+BT4 -> 42.5 | CF4: =G4+M4+S4+Y4+AE4+AK4+AQ4+AW4+BC4+BI4+BO4+BU4 -> 3 | CG4: =H4+N4+T4+Z4+AF4+AL4+AR4+AX4+BJ4+BP4+BV4+BD4 -> 0 | CH4: =I4+O4+U4+AA4+AG4+AM4+AS4+AY4+BE4+BK4+BQ4+BW4 -> 0
A5: 3 | B5: ALHUAY PALOMINO DE ALHUAY JUANA | C5: 0 | D5: 0 | E5: 0 | F5: 0 | G5: 0 | H5: 0 | I5: 0 | J5: 0 | K5: 0 | L5: 0 | M5: 0 | N5: 0 | O5: 0 | P5: 0 | Q5: 0 | R5: 0 | S5: 0 | T5: 0 | U5: 0 | V5: 0 | W5: 0 | X5: 0 | Y5: 0 | Z5: 0 | AA5: 0 | AB5: 0 | AC5: 0 | AD5: 0 | AE5: 0 | AF5: 0 | AG5: 0 | AH5: 0 | AI5: 0 | AJ5: 0 | AK5: 0 | AL5: 0 | AM5: 0 | AN5: 0 | AO5: 0 | AP5: 0 | AQ5: 0 | AR5: 0 | AS5: 0 | AT5: 0 | AU5: 0 | AV5: 0 | AW5: 0 | AX5: 0 | AY5: 0 | AZ5: 0 | BA5: 0 | BB5: 0 | BC5: 0 | BE5: 0 | BF5: 0 | BG5: 0 | BH5: 0 | BI5: 0 | BL5: 0 | BM5: 0 | BN5: 84.5 | BO5: 39 | BR5: 0 | BS5: 0 | BT5: 91 | BU5: 39 | BW5: 80 | BX5: =SUM(D5:BW5) -> 333.5 | BY5: =C5 -> 0 | BZ5: =BX5+BY5 -> 333.5 | CC5: =D5+J5+P5+V5+AB5+AH5+AN5+AT5+AZ5+BF5+BL5+BR5 -> 0 | CD5: =E5+K5+Q5+W5+AC5+AI5+AO5+AU5+BA5+BG5+BM5+BS5 -> 0 | CE5: =F5+L5+R5+X5+AD5+AJ5+AP5+AV5+BB5+BH5+BN5+BT5 -> 175.5 | CF5: =G5+M5+S5+Y5+AE5+AK5+AQ5+AW5+BC5+BI5+BO5+BU5 -> 78 | CG5: =H5+N5+T5+Z5+AF5+AL5+AR5+AX5+BJ5+BP5+BV5+BD5 -> 0 | CH5: =I5+O5+U5+AA5+AG5+AM5+AS5+AY5+BE5+BK5+BQ5+BW5 -> 80
A6: 4 | B6: ALVAREZ CAMPOS LELIA AMERICA | C6: 0 | D6: 0 | E6: 0 | F6: 0 | G6: 0 | H6: 0 | I6: 0 | J6: 0 | K6: 0 | L6: 0 | M6: 0 | N6: 0 | O6: 0 | P6: 0 | Q6: 0 | R6: 0 | S6: 0 | T6: 0 | U6: 0 | V6: 0 | W6: 0 | X6: 0 | Y6: 0 | Z6: 0 | AA6: 0 | AB6: 0 | AC6: 0 | AD6: 0 | AE6: 0 | AF6: 0 | AG6: 0 | AH6: 0 | AI6: 0 | AJ6: 0 | AK6: 0 | AL6: 0 | AM6: 0 | AN6: 0 | AO6: 0 | AP6: 0 | AQ6: 0 | AR6: 0 | AS6: 0 | AT6: 0 | AU6: 0 | AV6: 0 | AW6: 0 | AX6: 0 | AY6: 0 | AZ6: 0 | BA6: 0 | BB6: 0 | BC6: 0 | BF6: 0 | BG6: 0 | BH6: 0 | BI6: 0 | BL6: 0 | BM6: 0 | BN6: 35.5 | BO6: 3 | BQ6: 59 | BR6: 0 | BS6: 0 | BT6: 37.6 | BU6: 3 | BX6: =SUM(D6:BW6) -> 138.1 | BY6: =C6 -> 0 | BZ6: =BX6+BY6 -> 138.1 | CC6: =D6+J6+P6+V6+AB6+AH6+AN6+AT6+AZ6+BF6+BL6+BR6 -> 0 | CD6: =E6+K6+Q6+W6+AC6+AI6+AO6+AU6+BA6+BG6+BM6+BS6 -> 0 | CE6: =F6+L6+R6+X6+AD6+AJ6+AP6+AV6+BB6+BH6+BN6+BT6 -> 73.1 | CF6: =G6+M6+S6+Y6+AE6+AK6+AQ6+AW6+BC6+BI6+BO6+BU6 -> 6 | CG6: =H6+N6+T6+Z6+AF6+AL6+AR6+AX6+BJ6+BP6+BV6+BD6 -> 0 | CH6: =I6+O6+U6+AA6+AG6+AM6+AS6+AY6+BE6+BK6+BQ6+BW6 -> 59
A7: 5 | B7: ALVAREZ CAMPOS ROLANDO | C7: 0 | D7: 0 | E7: 0 | F7: 0 | G7: 0 | H7: 0 | I7: 0 | J7: 0 | K7: 0 | L7: 0 | M7: 0 | N7: 0 | O7: 0 | P7: 0 | Q7: 0 | R7: 0 | S7: 0 | T7: 0 | U7: 0 | V7: 0 | W7: 0 | X7: 0 | Y7: 0 | Z7: 0 | AA7: 0 | AB7: 0 | AC7: 0 | AD7: 0 | AE7: 0 | AF7: 0 | AG7: 0 | AH7: 0 | AI7: 0 | AJ7: 0 | AK7: 0 | AL7: 0 | AM7: 0 | AN7: 0 | AO7: 0 | AP7: 0 | AQ7: 0 | AR7: 0 | AS7: 0 | AT7: 0 | AU7: 0 | AV7: 0 | AW7: 0 | AX7: 0 | AY7: 0 | AZ7: 0 | BA7: 0 | BB7: 0 | BC7: 0 | BD7: 0 | BE7: 0 | BF7: 0 | BG7: 0 | BH7: 0 | BI7: 0 | BJ7: 0 | BL7: 60 | BM7: 2 | BN7: 71 | BO7: 3 | BP7: 70 | BR7: 60 | BS7: 2 | BT7: 75.2 | BU7: 3 | BV7: 70 | BX7: =SUM(D7:BW7) -> 416.2 | BY7: =C7 -> 0 | BZ7: =BX7+BY7 -> 416.2 | CC7: =D7+J7+P7+V7+AB7+AH7+AN7+AT7+AZ7+BF7+BL7+BR7 -> 120 | CD7: =E7+K7+Q7+W7+AC7+AI7+AO7+AU7+BA7+BG7+BM7+BS7 -> 4 | CE7: =F7+L7+R7+X7+AD7+AJ7+AP7+AV7+BB7+BH7+BN7+BT7 -> 146.2 | CF7: =G7+M7+S7+Y7+AE7+AK7+AQ7+AW7+BC7+BI7+BO7+BU7 -> 6 | CG7: =H7+N7+T7+Z7+AF7+AL7+AR7+AX7+BJ7+BP7+BV7+BD7 -> 140 | CH7: =I7+O7+U7+AA7+AG7+AM7+AS7+AY7+BE7+BK7+BQ7+BW7 -> 0
A8: 6 | B8: ALVAREZ CAMPOS VICTOR | C8: 0 | D8: 0 | E8: 0 | F8: 0 | G8: 0 | H8: 0 | I8: 0 | J8: 0 | K8: 0 | L8: 0 | M8: 0 | N8: 0 | O8: 0 | P8: 0 | Q8: 0 | R8: 0 | S8: 0 | T8: 0 | U8: 0 | V8: 0 | W8: 0 | X8: 0 | Y8: 0 | Z8: 0 | AA8: 0 | AB8: 0 | AC8: 0 | AD8: 0 | AE8: 0 | AF8: 0 | AG8: 0 | AH8: 0 | AI8: 0 | AJ8: 0 | AK8: 0 | AL8: 0 | AM8: 0 | AN8: 0 | AO8: 0 | AP8: 0 | AQ8: 0 | AR8: 0 | AS8: 0 | AT8: 0 | AU8: 0 | AV8: 0 | AW8: 0 | AX8: 0 | AY8: 0 | AZ8: 0 | BA8: 0 | BB8: 0 | BC8: 0 | BF8: 0 | BG8: 0 | BH8: 0 | BI8: 0 | BL8: 0 | BM8: 0 | BN8: 0 | BO8: 0 | BR8: 0 | BS8: 0 | BT8: 44.1 | BU8: 3 | BX8: =SUM(D8:BW8) -> 47.1 | BY8: =C8 -> 0 | BZ8: =BX8+BY8 -> 47.1 | CC8: =D8+J8+P8+V8+AB8+AH8+AN8+AT8+AZ8+BF8+BL8+BR8 -> 0 | CD8: =E8+K8+Q8+W8+AC8+AI8+AO8+AU8+BA8+BG8+BM8+BS8 -> 0 | CE8: =F8+L8+R8+X8+AD8+AJ8+AP8+AV8+BB8+BH8+BN8+BT8 -> 44.1 | CF8: =G8+M8+S8+Y8+AE8+AK8+AQ8+AW8+BC8+BI8+BO8+BU8 -> 3 | CG8: =H8+N8+T8+Z8+AF8+AL8+AR8+AX8+BJ8+BP8+BV8+BD8 -> 0 | CH8: =I8+O8+U8+AA8+AG8+AM8+AS8+AY8+BE8+BK8+BQ8+BW8 -> 0
A9: 7 | B9: ALVAREZ MARIN MARIANELA | C9: 2327 | D9: 0 | E9: 0 | F9: 0 | G9: 0 | H9: 0 | I9: 0 | J9: 0 | K9: 0 | L9: 0 | M9: 0 | N9: 0 | O9: 0 | P9: 0 | Q9: 0 | R9: 0 | S9: 0 | T9: 0 | V9: 0 | W9: 0 | X9: 0 | Y9: 0 | Z9: 0 | AA9: 0 | AB9: 0 | AC9: 0 | AD9: 0 | AE9: 0 | AF9: 0 | AG9: 0 | AH9: 0 | AI9: 0 | AJ9: 0 | AK9: 0 | AL9: 0 | AN9: 0 | AO9: 0 | AP9: 0 | AQ9: 0 | AR9: 0 | AT9: 0 | AU9: 0 | AV9: 0 | AW9: 0 | AX9: 0 | AY9: 0 | AZ9: 0 | BA9: 0 | BB9: 0 | BC9: 0 | BF9: 0 | BG9: 0 | BH9: 0 | BI9: 0 | BL9: 0 | BM9: 0 | BN9: 13.5 | BO9: 3 | BQ9: 59 | BR9: 0 | BS9: 0 | BT9: 13.6 | BU9: 3 | BX9: =SUM(D9:BW9) -> 92.1 | BY9: =C9 -> 2327 | BZ9: =BX9+BY9 -> 2419.1 | CC9: =D9+J9+P9+V9+AB9+AH9+AN9+AT9+AZ9+BF9+BL9+BR9 -> 0 | CD9: =E9+K9+Q9+W9+AC9+AI9+AO9+AU9+BA9+BG9+BM9+BS9 -> 0 | CE9: =F9+L9+R9+X9+AD9+AJ9+AP9+AV9+BB9+BH9+BN9+BT9 -> 27.1 | CF9: =G9+M9+S9+Y9+AE9+AK9+AQ9+AW9+BC9+BI9+BO9+BU9 -> 6 | CG9: =H9+N9+T9+Z9+AF9+AL9+AR9+AX9+BJ9+BP9+BV9+BD9 -> 0 | CH9: =I9+O9+U9+AA9+AG9+AM9+AS9+AY9+BE9+BK9+BQ9+BW9 -> 59
A10: 8 | B10: ALVAREZ MARIN NEIL ROLANDO | C10: 3190.5 | D10: 60 | E10: 2 | F10: 16 | G10: 3 | H10: 0 | I10: 0 | J10: 58 | K10: 2 | L10: 19.5 | M10: 3.5 | N10: 0 | O10: 0 | P10: 60 | Q10: 2 | R10: 18 | S10: 3 | T10: 0 | U10: 75 | V10: 60 | W10: 2 | X10: 12 | Y10: 3.5 | Z10: 0 | AA10: 0 | AB10: 60 | AC10: 2 | AD10: 11 | AE10: 4 | AF10: 0 | AG10: 0 | AH10: 60 | AI10: 2 | AJ10: 10 | AK10: 3 | AL10: 0 | AM10: 75 | AN10: 60 | AO10: 2 | AP10: 8.5 | AQ10: 3 | AR10: 0 | AS10: 85 | AT10: 60 | AU10: 2 | AV10: 0 | AW10: 0 | AX10: 0 | AY10: 25 | AZ10: 60 | BA10: 2 | BB10: 0 | BC10: 0 | BF10: 60 | BG10: 2 | BH10: 9.5 | BI10: 6 | BL10: 60 | BM10: 2 | BN10: 13.5 | BO10: 3 | BQ10: =59+85 -> 144 | BR10: 60 | BS10: 2 | BT10: 13.6 | BU10: 2.8 | BX10: =SUM(D10:BW10) -> 1312.4 | BY10: =C10 -> 3190.5 | BZ10: =BX10+BY10 -> 4502.9 | CC10: =D10+J10+P10+V10+AB10+AH10+AN10+AT10+AZ10+BF10+BL10+BR10 -> 718 | CD10: =E10+K10+Q10+W10+AC10+AI10+AO10+AU10+BA10+BG10+BM10+BS10 -> 24 | CE10: =F10+L10+R10+X10+AD10+AJ10+AP10+AV10+BB10+BH10+BN10+BT10 -> 131.6 | CF10: =G10+M10+S10+Y10+AE10+AK10+AQ10+AW10+BC10+BI10+BO10+BU10 -> 34.8 | CG10: =H10+N10+T10+Z10+AF10+AL10+AR10+AX10+BJ10+BP10+BV10+BD10 -> 0 | CH10: =I10+O10+U10+AA10+AG10+AM10+AS10+AY10+BE10+BK10+BQ10+BW10 -> 404
A11: 9 | B11: ANAMPA CORAHUA CLEMENCIA MIGDONIA | C11: 0 | D11: 0 | E11: 0 | F11: 0 | G11: 0 | H11: 0 | I11: 0 | J11: 0 | K11: 0 | L11: 0 | M11: 0 | N11: 0 | O11: 0 | P11: 0 | Q11: 0 | R11: 0 | S11: 0 | T11: 0 | V11: 0 | W11: 0 | X11: 0 | Y11: 0 | Z11: 0 | AA11: 0 | AB11: 0 | AC11: 0 | AD11: 0 | AE11: 0 | AF11: 0 | AG11: 0 | AH11: 0 | AI11: 0 | AJ11: 0 | AK11: 0 | AL11: 0 | AM11: 0 | AN11: 0 | AO11: 0 | AP11: 0 | AQ11: 0 | AR11: 0 | AT11: 0 | AU11: 0 | AV11: 0 | AW11: 0 | AX11: 0 | AZ11: 0 | BA11: 0 | BB11: 0 | BC11: 0 | BD11: 0 | BF11: 0 | BG11: 0 | BH11: 0 | BI11: 0 | BJ11: 0 | BL11: 0 | BM11: 0 | BN11: 0 | BO11: 0 | BP11: 0 | BR11: 60 | BS11: 2 | BT11: 64.3 | BU11: 3 | BV11: 60 | BX11: =SUM(D11:BW11) -> 189.3 | BY11: =C11 -> 0 | BZ11: =BX11+BY11 -> 189.3 | CC11: =D11+J11+P11+V11+AB11+AH11+AN11+AT11+AZ11+BF11+BL11+BR11 -> 60 | CD11: =E11+K11+Q11+W11+AC11+AI11+AO11+AU11+BA11+BG11+BM11+BS11 -> 2 | CE11: =F11+L11+R11+X11+AD11+AJ11+AP11+AV11+BB11+BH11+BN11+BT11 -> 64.3 | CF11: =G11+M11+S11+Y11+AE11+AK11+AQ11+AW11+BC11+BI11+BO11+BU11 -> 3 | CG11: =H11+N11+T11+Z11+AF11+AL11+AR11+AX11+BJ11+BP11+BV11+BD11 -> 60 | CH11: =I11+O11+U11+AA11+AG11+AM11+AS11+AY11+BE11+BK11+BQ11+BW11 -> 0
A12: 10 | B12: ANCCO LEON VALENTINA | C12: 0 | D12: 0 | E12: 0 | F12: 0 | G12: 0 | H12: 0 | I12: 0 | J12: 0 | K12: 0 | L12: 0 | M12: 0 | N12: 0 | O12: 0 | P12: 0 | Q12: 0 | R12: 0 | S12: 0 | T12: 0 | V12: 0 | W12: 0 | X12: 0 | Y12: 0 | Z12: 0 | AB12: 0 | AC12: 0 | AD12: 0 | AE12: 0 | AF12: 0 | AH12: 0 | AI12: 0 | AJ12: 0 | AK12: 0 | AL12: 0 | AN12: 0 | AO12: 0 | AP12: 0 | AQ12: 0 | AR12: 0 | AT12: 0 | AU12: 0 | AV12: 0 | AW12: 0 | AX12: 0 | AZ12: 0 | BA12: 0 | BB12: 0 | BC12: 0 | BF12: 0 | BG12: 0 | BH12: 0 | BI12: 0 | BL12: 60 | BM12: 2 | BN12: 51 | BO12: 3 | BQ12: 59 | BR12: 60 | BS12: 2 | BT12: 53.4 | BU12: 3 | BX12: =SUM(D12:BW12) -> 293.4 | BY12: =C12 -> 0 | BZ12: =BX12+BY12 -> 293.4 | CC12: =D12+J12+P12+V12+AB12+AH12+AN12+AT12+AZ12+BF12+BL12+BR12 -> 120 | CD12: =E12+K12+Q12+W12+AC12+AI12+AO12+AU12+BA12+BG12+BM12+BS12 -> 4 | CE12: =F12+L12+R12+X12+AD12+AJ12+AP12+AV12+BB12+BH12+BN12+BT12 -> 104.4 | CF12: =G12+M12+S12+Y12+AE12+AK12+AQ12+AW12+BC12+BI12+BO12+BU12 -> 6 | CG12: =H12+N12+T12+Z12+AF12+AL12+AR12+AX12+BJ12+BP12+BV12+BD12 -> 0 | CH12: =I12+O12+U12+AA12+AG12+AM12+AS12+AY12+BE12+BK12+BQ12+BW12 -> 59
A13: 11 | B13: ATANASIO ORTEGA MAXIMILIANA | C13: 362 | D13: 0 | E13: 0 | F13: 0 | G13: 0 | H13: 0 | J13: 0 | K13: 0 | L13: 0 | M13: 0 | N13: 0 | P13: 0 | Q13: 0 | R13: 0 | S13: 0 | T13: 0 | V13: 0 | W13: 0 | X13: 0 | Y13: 0 | Z13: 0 | AB13: 0 | AC13: 0 | AD13: 0 | AE13: 0 | AF13: 0 | AH13: 0 | AI13: 0 | AJ13: 0 | AK13: 0 | AL13: 0 | AN13: 0 | AO13: 0 | AP13: 0 | AQ13: 0 | AR13: 0 | AT13: 0 | AU13: 0 | AV13: 0 | AW13: 0 | AX13: 0 | AZ13: 0 | BA13: 0 | BB13: 0 | BC13: 0 | BF13: 0 | BG13: 0 | BH13: 0 | BI13: 0 | BL13: 0 | BM13: 0 | BN13: 51.5 | BO13: 3 | BQ13: 59 | BR13: 0 | BS13: 0 | BT13: 55 | BU13: 3 | BX13: =SUM(D13:BW13) -> 171.5 | BY13: =C13 -> 362 | BZ13: =BX13+BY13 -> 533.5 | CC13: =D13+J13+P13+V13+AB13+AH13+AN13+AT13+AZ13+BF13+BL13+BR13 -> 0 | CD13: =E13+K13+Q13+W13+AC13+AI13+AO13+AU13+BA13+BG13+BM13+BS13 -> 0 | CE13: =F13+L13+R13+X13+AD13+AJ13+AP13+AV13+BB13+BH13+BN13+BT13 -> 106.5 | CF13: =G13+M13+S13+Y13+AE13+AK13+AQ13+AW13+BC13+BI13+BO13+BU13 -> 6 | CG13: =H13+N13+T13+Z13+AF13+AL13+AR13+AX13+BJ13+BP13+BV13+BD13 -> 0 | CH13: =I13+O13+U13+AA13+AG13+AM13+AS13+AY13+BE13+BK13+BQ13+BW13 -> 59
A14: 12 | B14: AYALA HUASHUAYO NORMA GLADYS | C14: 75 | D14: 0 | E14: 0 | F14: 0 | G14: 0 | H14: 0 | J14: 0 | K14: 0 | L14: 0 | M14: 0 | N14: 0 | P14: 0 | Q14: 0 | R14: 0 | S14: 0 | T14: 0 | V14: 0 | W14: 0 | X14: 0 | Y14: 0 | Z14: 0 | AB14: 0 | AC14: 0 | AD14: 0 | AE14: 0 | AF14: 0 | AH14: 0 | AI14: 0 | AJ14: 0 | AK14: 0 | AL14: 0 | AN14: 0 | AO14: 0 | AP14: 0 | AQ14: 0 | AR14: 0 | AT14: 0 | AU14: 0 | AV14: 0 | AW14: 0 | AX14: 0 | AZ14: 0 | BA14: 0 | BB14: 0 | BC14: 0 | BF14: 0 | BG14: 0 | BH14: 0 | BI14: 0 | BL14: 0 | BM14: 0 | BN14: 35 | BO14: 3 | BR14: 60 | BS14: 2 | BT14: 35.9 | BU14: 3 | BX14: =SUM(D14:BW14) -> 138.9 | BY14: =C14 -> 75 | BZ14: =BX14+BY14 -> 213.9 | CC14: =D14+J14+P14+V14+AB14+AH14+AN14+AT14+AZ14+BF14+BL14+BR14 -> 60 | CD14: =E14+K14+Q14+W14+AC14+AI14+AO14+AU14+BA14+BG14+BM14+BS14 -> 2 | CE14: =F14+L14+R14+X14+AD14+AJ14+AP14+AV14+BB14+BH14+BN14+BT14 -> 70.9 | CF14: =G14+M14+S14+Y14+AE14+AK14+AQ14+AW14+BC14+BI14+BO14+BU14 -> 6 | CG14: =H14+N14+T14+Z14+AF14+AL14+AR14+AX14+BJ14+BP14+BV14+BD14 -> 0 | CH14: =I14+O14+U14+AA14+AG14+AM14+AS14+AY14+BE14+BK14+BQ14+BW14 -> 0
A15: 13 | B15: AYALA TABOADA ELISEO | C15: 0 | D15: 0 | E15: 0 | F15: 0 | G15: 0 | H15: 0 | J15: 0 | K15: 0 | L15: 0 | M15: 0 | N15: 0 | P15: 0 | Q15: 0 | R15: 0 | S15: 0 | T15: 0 | V15: 0 | W15: 0 | X15: 0 | Y15: 0 | Z15: 0 | AB15: 0 | AC15: 0 | AD15: 0 | AE15: 0 | AF15: 0 | AH15: 0 | AI15: 0 | AJ15: 0 | AK15: 0 | AL15: 0 | AN15: 0 | AO15: 0 | AP15: 0 | AQ15: 0 | AR15: 0 | AT15: 0 | AU15: 0 | AV15: 0 | AW15: 0 | AX15: 0 | AZ15: 0 | BA15: 0 | BB15: 0 | BC15: 0 | BD15: 0 | BF15: 0 | BG15: 0 | BH15: 0 | BI15: 0 | BJ15: 0 | BL15: 0 | BM15: 0 | BN15: 79 | BO15: 3 | BP15: 0 | BR15: 60 | BS15: 2 | BT15: 83.9 | BU15: 3 | BV15: 80 | BX15: =SUM(D15:BW15) -> 310.9 | BY15: =C15 -> 0 | BZ15: =BX15+BY15 -> 310.9 | CC15: =D15+J15+P15+V15+AB15+AH15+AN15+AT15+AZ15+BF15+BL15+BR15 -> 60 | CD15: =E15+K15+Q15+W15+AC15+AI15+AO15+AU15+BA15+BG15+BM15+BS15 -> 2 | CE15: =F15+L15+R15+X15+AD15+AJ15+AP15+AV15+BB15+BH15+BN15+BT15 -> 162.9 | CF15: =G15+M15+S15+Y15+AE15+AK15+AQ15+AW15+BC15+BI15+BO15+BU15 -> 6 | CG15: =H15+N15+T15+Z15+AF15+AL15+AR15+AX15+BJ15+BP15+BV15+BD15 -> 80 | CH15: =I15+O15+U15+AA15+AG15+AM15+AS15+AY15+BE15+BK15+BQ15+BW15 -> 0
A16: 14 | B16: BASTIDAS MEDINA DINA | C16: 275 | D16: 0 | E16: 0 | F16: 0 | G16: 0 | H16: 0 | J16: 0 | K16: 0 | L16: 0 | M16: 0 | N16: 0 | P16: 0 | Q16: 0 | R16: 0 | S16: 0 | T16: 0 | U16: 75 | V16: 60 | W16: 2 | X16: 0 | Y16: 0 | Z16: 0 | AB16: 60 | AC16: 2 | AD16: 0 | AE16: 0 | AF16: 0 | AH16: 60 | AI16: 2 | AJ16: 0 | AK16: 0 | AL16: 0 | AM16: 75 | AN16: 60 | AO16: 2 | AP16: 0 | AQ16: 0 | AR16: 0 | AS16: 85 | AT16: 60 | AU16: 2 | AV16: 0 | AW16: 0 | AX16: 0 | AZ16: 60 | BA16: 2 | BB16: 0 | BC16: 0 | BF16: 60 | BG16: 2 | BH16: 0 | BI16: 0 | BL16: 60 | BM16: 2 | BN16: 45.5 | BO16: 3 | BQ16: =59+85 -> 144 | BR16: 60 | BS16: 2 | BT16: 48.5 | BU16: 3 | BX16: =SUM(D16:BW16) -> 1037 | BY16: =C16 -> 275 | BZ16: =BX16+BY16 -> 1312 | CC16: =D16+J16+P16+V16+AB16+AH16+AN16+AT16+AZ16+BF16+BL16+BR16 -> 540 | CD16: =E16+K16+Q16+W16+AC16+AI16+AO16+AU16+BA16+BG16+BM16+BS16 -> 18 | CE16: =F16+L16+R16+X16+AD16+AJ16+AP16+AV16+BB16+BH16+BN16+BT16 -> 94 | CF16: =G16+M16+S16+Y16+AE16+AK16+AQ16+AW16+BC16+BI16+BO16+BU16 -> 6 | CG16: =H16+N16+T16+Z16+AF16+AL16+AR16+AX16+BJ16+BP16+BV16+BD16 -> 0 | CH16: =I16+O16+U16+AA16+AG16+AM16+AS16+AY16+BE16+BK16+BQ16+BW16 -> 379
A17: 15 | B17: BASTIDAS MEDINA HERMENEGILDO | C17: 0 | D17: 0 | E17: 0 | F17: 0 | G17: 0 | H17: 0 | J17: 0 | K17: 0 | L17: 0 | M17: 0 | N17: 0 | P17: 0 | Q17: 0 | R17: 0 | S17: 0 | T17: 0 | V17: 0 | W17: 0 | X17: 0 | Y17: 0 | Z17: 0 | AB17: 0 | AC17: 0 | AD17: 0 | AE17: 0 | AF17: 0 | AH17: 0 | AI17: 0 | AJ17: 0 | AK17: 0 | AL17: 0 | AN17: 0 | AO17: 0 | AP17: 0 | AQ17: 0 | AR17: 0 | AT17: 0 | AU17: 0 | AV17: 0 | AW17: 0 | AX17: 0 | AZ17: 0 | BA17: 0 | BB17: 0 | BC17: 0 | BF17: 0 | BG17: 0 | BH17: 0 | BI17: 0 | BL17: 60 | BM17: 2 | BN17: 33.5 | BO17: 3 | BR17: 60 | BS17: 2 | BT17: 35.4 | BU17: 3 | BW17: 80 | BX17: =SUM(D17:BW17) -> 278.9 | BY17: =C17 -> 0 | BZ17: =BX17+BY17 -> 278.9 | CC17: =D17+J17+P17+V17+AB17+AH17+AN17+AT17+AZ17+BF17+BL17+BR17 -> 120 | CD17: =E17+K17+Q17+W17+AC17+AI17+AO17+AU17+BA17+BG17+BM17+BS17 -> 4 | CE17: =F17+L17+R17+X17+AD17+AJ17+AP17+AV17+BB17+BH17+BN17+BT17 -> 68.9 | CF17: =G17+M17+S17+Y17+AE17+AK17+AQ17+AW17+BC17+BI17+BO17+BU17 -> 6 | CG17: =H17+N17+T17+Z17+AF17+AL17+AR17+AX17+BJ17+BP17+BV17+BD17 -> 0 | CH17: =I17+O17+U17+AA17+AG17+AM17+AS17+AY17+BE17+BK17+BQ17+BW17 -> 80
A18: 16 | B18: BERNAOLA DE PRADO FLORENCIA | C18: 0 | D18: 0 | E18: 0 | F18: 0 | G18: 0 | H18: 0 | J18: 0 | K18: 0 | L18: 0 | M18: 0 | N18: 0 | P18: 0 | Q18: 0 | R18: 0 | S18: 0 | T18: 0 | V18: 0 | W18: 0 | X18: 0 | Y18: 0 | Z18: 0 | AB18: 0 | AC18: 0 | AD18: 0 | AE18: 0 | AF18: 0 | AH18: 0 | AI18: 0 | AJ18: 0 | AK18: 0 | AL18: 0 | AN18: 0 | AO18: 0 | AP18: 0 | AQ18: 0 | AR18: 0 | AT18: 0 | AU18: 0 | AV18: 0 | AW18: 0 | AX18: 0 | AZ18: 0 | BA18: 0 | BB18: 0 | BC18: 0 | BF18: 0 | BG18: 0 | BH18: 0 | BI18: 0 | BL18: 0 | BM18: 0 | BN18: 0 | BO18: 0 | BR18: 0 | BS18: 0 | BT18: 69.2 | BU18: 19 | BW18: 80 | BX18: =SUM(D18:BW18) -> 168.2 | BY18: =C18 -> 0 | BZ18: =BX18+BY18 -> 168.2 | CC18: =D18+J18+P18+V18+AB18+AH18+AN18+AT18+AZ18+BF18+BL18+BR18 -> 0 | CD18: =E18+K18+Q18+W18+AC18+AI18+AO18+AU18+BA18+BG18+BM18+BS18 -> 0 | CE18: =F18+L18+R18+X18+AD18+AJ18+AP18+AV18+BB18+BH18+BN18+BT18 -> 69.2 | CF18: =G18+M18+S18+Y18+AE18+AK18+AQ18+AW18+BC18+BI18+BO18+BU18 -> 19 | CG18: =H18+N18+T18+Z18+AF18+AL18+AR18+AX18+BJ18+BP18+BV18+BD18 -> 0 | CH18: =I18+O18+U18+AA18+AG18+AM18+AS18+AY18+BE18+BK18+BQ18+BW18 -> 80
A19: 17 | B19: BRAVO HEREDIA ANA MARITZA | C19: 3464.5 | D19: 0 | E19: 0 | F19: 0 | G19: 0 | H19: 0 | J19: 0 | K19: 0 | L19: 0 | M19: 0 | N19: 0 | P19: 0 | Q19: 0 | R19: 0 | S19: 0 | T19: 0 | U19: 75 | V19: 0 | W19: 0 | X19: 0 | Y19: 0 | Z19: 0 | AB19: 0 | AC19: 0 | AD19: 0 | AE19: 0 | AF19: 0 | AH19: 0 | AI19: 0 | AJ19: 0 | AK19: 0 | AL19: 0 | AM19: 75 | AN19: 0 | AO19: 0 | AP19: 0 | AQ19: 0 | AR19: 0 | AS19: 85 | AT19: 0 | AU19: 0 | AV19: 0 | AW19: 0 | AX19: 0 | AZ19: 0 | BA19: 0 | BB19: 0 | BC19: 0 | BF19: 0 | BG19: 0 | BH19: 0 | BI19: 0 | BL19: 0 | BM19: 0 | BN19: 0 | BO19: 0 | BQ19: 85 | BR19: 0 | BS19: 0 | BT19: 51.2 | BU19: 3 | BX19: =SUM(D19:BW19) -> 374.2 | BY19: =C19 -> 3464.5 | BZ19: =BX19+BY19 -> 3838.7 | CC19: =D19+J19+P19+V19+AB19+AH19+AN19+AT19+AZ19+BF19+BL19+BR19 -> 0 | CD19: =E19+K19+Q19+W19+AC19+AI19+AO19+AU19+BA19+BG19+BM19+BS19 -> 0 | CE19: =F19+L19+R19+X19+AD19+AJ19+AP19+AV19+BB19+BH19+BN19+BT19 -> 51.2 | CF19: =G19+M19+S19+Y19+AE19+AK19+AQ19+AW19+BC19+BI19+BO19+BU19 -> 3 | CG19: =H19+N19+T19+Z19+AF19+AL19+AR19+AX19+BJ19+BP19+BV19+BD19 -> 0 | CH19: =I19+O19+U19+AA19+AG19+AM19+AS19+AY19+BE19+BK19+BQ19+BW19 -> 320
A20: 18 | B20: BURGA CARRASCO ELIDA | C20: 0 | D20: 0 | E20: 0 | F20: 0 | G20: 0 | H20: 0 | J20: 0 | K20: 0 | L20: 0 | M20: 0 | N20: 0 | P20: 0 | Q20: 0 | R20: 0 | S20: 0 | T20: 0 | V20: 0 | W20: 0 | X20: 0 | Y20: 0 | Z20: 0 | AB20: 0 | AC20: 0 | AD20: 0 | AE20: 0 | AF20: 0 | AH20: 0 | AI20: 0 | AJ20: 0 | AK20: 0 | AL20: 0 | AN20: 0 | AO20: 0 | AP20: 0 | AQ20: 0 | AR20: 0 | AT20: 0 | AU20: 0 | AV20: 0 | AW20: 0 | AX20: 0 | AZ20: 0 | BA20: 0 | BB20: 0 | BC20: 0 | BF20: 0 | BG20: 0 | BH20: 0 | BI20: 0 | BL20: 0 | BM20: 0 | BN20: 0 | BO20: 0 | BQ20: 85 | BR20: 0 | BS20: 0 | BT20: 105.7 | BU20: 3 | BX20: =SUM(D20:BW20) -> 193.7 | BY20: =C20 -> 0 | BZ20: =BX20+BY20 -> 193.7 | CC20: =D20+J20+P20+V20+AB20+AH20+AN20+AT20+AZ20+BF20+BL20+BR20 -> 0 | CD20: =E20+K20+Q20+W20+AC20+AI20+AO20+AU20+BA20+BG20+BM20+BS20 -> 0 | CE20: =F20+L20+R20+X20+AD20+AJ20+AP20+AV20+BB20+BH20+BN20+BT20 -> 105.7 | CF20: =G20+M20+S20+Y20+AE20+AK20+AQ20+AW20+BC20+BI20+BO20+BU20 -> 3 | CG20: =H20+N20+T20+Z20+AF20+AL20+AR20+AX20+BJ20+BP20+BV20+BD20 -> 0 | CH20: =I20+O20+U20+AA20+AG20+AM20+AS20+AY20+BE20+BK20+BQ20+BW20 -> 85
A21: 19 | B21: CABALLERO CALZADO GLADYS VICTORIA | C21: 0 | D21: 0 | E21: 0 | F21: 0 | G21: 0 | H21: 0 | J21: 0 | K21: 0 | L21: 0 | M21: 0 | N21: 0 | P21: 0 | Q21: 0 | R21: 0 | S21: 0 | T21: 0 | V21: 0 | W21: 0 | X21: 0 | Y21: 0 | Z21: 0 | AB21: 0 | AC21: 0 | AD21: 0 | AE21: 0 | AF21: 0 | AH21: 0 | AI21: 0 | AJ21: 0 | AK21: 0 | AL21: 0 | AN21: 0 | AO21: 0 | AP21: 0 | AQ21: 0 | AR21: 0 | AT21: 0 | AU21: 0 | AV21: 0 | AW21: 0 | AX21: 0 | AZ21: 0 | BA21: 0 | BB21: 0 | BC21: 0 | BF21: 0 | BG21: 0 | BH21: 0 | BI21: 0 | BL21: 0 | BM21: 0 | BN21: 21.5 | BO21: 3 | BR21: 0 | BS21: 0 | BT21: 22.3 | BU21: 3 | BX21: =SUM(D21:BW21) -> 49.8 | BY21: =C21 -> 0 | BZ21: =BX21+BY21 -> 49.8 | CC21: =D21+J21+P21+V21+AB21+AH21+AN21+AT21+AZ21+BF21+BL21+BR21 -> 0 | CD21: =E21+K21+Q21+W21+AC21+AI21+AO21+AU21+BA21+BG21+BM21+BS21 -> 0 | CE21: =F21+L21+R21+X21+AD21+AJ21+AP21+AV21+BB21+BH21+BN21+BT21 -> 43.8 | CF21: =G21+M21+S21+Y21+AE21+AK21+AQ21+AW21+BC21+BI21+BO21+BU21 -> 6 | CG21: =H21+N21+T21+Z21+AF21+AL21+AR21+AX21+BJ21+BP21+BV21+BD21 -> 0 | CH21: =I21+O21+U21+AA21+AG21+AM21+AS21+AY21+BE21+BK21+BQ21+BW21 -> 0
A22: 20 | B22: CAHUANA VDA DE DAVILA VICENTINA | C22: 0 | D22: 0 | E22: 0 | F22: 0 | G22: 0 | H22: 0 | J22: 0 | K22: 0 | L22: 0 | M22: 0 | N22: 0 | P22: 0 | Q22: 0 | R22: 0 | S22: 0 | T22: 0 | V22: 0 | W22: 0 | X22: 0 | Y22: 0 | Z22: 0 | AB22: 0 | AC22: 0 | AD22: 0 | AE22: 0 | AF22: 0 | AH22: 0 | AI22: 0 | AJ22: 0 | AK22: 0 | AL22: 0 | AN22: 0 | AO22: 0 | AP22: 0 | AQ22: 0 | AR22: 0 | AT22: 0 | AU22: 0 | AV22: 0 | AW22: 0 | AX22: 0 | AZ22: 0 | BA22: 0 | BB22: 0 | BC22: 0 | BF22: 0 | BG22: 0 | BH22: 0 | BI22: 0 | BL22: 0 | BM22: 0 | BN22: 64.5 | BO22: 42 | BR22: 0 | BS22: 0 | BT22: 69.2 | BU22: 42 | BW22: 80 | BX22: =SUM(D22:BW22) -> 297.7 | BY22: =C22 -> 0 | BZ22: =BX22+BY22 -> 297.7 | CC22: =D22+J22+P22+V22+AB22+AH22+AN22+AT22+AZ22+BF22+BL22+BR22 -> 0 | CD22: =E22+K22+Q22+W22+AC22+AI22+AO22+AU22+BA22+BG22+BM22+BS22 -> 0 | CE22: =F22+L22+R22+X22+AD22+AJ22+AP22+AV22+BB22+BH22+BN22+BT22 -> 133.7 | CF22: =G22+M22+S22+Y22+AE22+AK22+AQ22+AW22+BC22+BI22+BO22+BU22 -> 84 | CG22: =H22+N22+T22+Z22+AF22+AL22+AR22+AX22+BJ22+BP22+BV22+BD22 -> 0 | CH22: =I22+O22+U22+AA22+AG22+AM22+AS22+AY22+BE22+BK22+BQ22+BW22 -> 80
A23: 21 | B23: CAJALEON CARRASCO LUIS ENRIQUE | C23: 100 | D23: 0 | E23: 0 | F23: 0 | G23: 0 | H23: 0 | J23: 0 | K23: 0 | L23: 0 | M23: 0 | N23: 0 | P23: 0 | Q23: 0 | R23: 0 | S23: 0 | T23: 0 | V23: 0 | W23: 0 | X23: 0 | Y23: 0 | Z23: 0 | AB23: 0 | AC23: 0 | AD23: 0 | AE23: 0 | AF23: 0 | AH23: 0 | AI23: 0 | AJ23: 0 | AK23: 0 | AL23: 0 | AN23: 0 | AO23: 0 | AP23: 0 | AQ23: 0 | AR23: 0 | AT23: 0 | AU23: 0 | AV23: 0 | AW23: 0 | AX23: 0 | AZ23: 0 | BA23: 0 | BB23: 0 | BC23: 0 | BF23: 0 | BG23: 0 | BH23: 0 | BI23: 0 | BL23: 0 | BM23: 0 | BN23: 0 | BO23: 9 | BR23: 0 | BS23: 0 | BU23: 15.2 | BW23: 80 | BX23: =SUM(D23:BW23) -> 104.2 | BY23: =C23 -> 100 | BZ23: =BX23+BY23 -> 204.2 | CC23: =D23+J23+P23+V23+AB23+AH23+AN23+AT23+AZ23+BF23+BL23+BR23 -> 0 | CD23: =E23+K23+Q23+W23+AC23+AI23+AO23+AU23+BA23+BG23+BM23+BS23 -> 0 | CE23: =F23+L23+R23+X23+AD23+AJ23+AP23+AV23+BB23+BH23+BN23+BT23 -> 0 | CF23: =G23+M23+S23+Y23+AE23+AK23+AQ23+AW23+BC23+BI23+BO23+BU23 -> 24.2 | CG23: =H23+N23+T23+Z23+AF23+AL23+AR23+AX23+BJ23+BP23+BV23+BD23 -> 0 | CH23: =I23+O23+U23+AA23+AG23+AM23+AS23+AY23+BE23+BK23+BQ23+BW23 -> 80
A24: 22 | B24: CAJALEON HIDALGO TEODORO | C24: 0 | D24: 0 | E24: 0 | F24: 0 | G24: 0 | H24: 0 | J24: 0 | K24: 0 | L24: 0 | M24: 0 | N24: 0 | P24: 0 | Q24: 0 | R24: 0 | S24: 0 | T24: 0 | V24: 0 | W24: 0 | X24: 0 | Y24: 0 | Z24: 0 | AB24: 0 | AC24: 0 | AD24: 0 | AE24: 0 | AF24: 0 | AH24: 0 | AI24: 0 | AJ24: 0 | AK24: 0 | AL24: 0 | AN24: 0 | AO24: 0 | AP24: 0 | AQ24: 0 | AR24: 0 | AT24: 0 | AU24: 0 | AV24: 0 | AW24: 0 | AX24: 0 | AZ24: 0 | BA24: 0 | BB24: 0 | BC24: 0 | BE24: 15 | BF24: 0 | BG24: 0 | BH24: 0 | BI24: 0 | BL24: 0 | BM24: 0 | BN24: 0 | BO24: 0 | BR24: 14 | BS24: 2 | BU24: 37.5 | BV24: 84.5 | BW24: 80 | BX24: =SUM(D24:BW24) -> 233 | BY24: =C24 -> 0 | BZ24: =BX24+BY24 -> 233 | CC24: =D24+J24+P24+V24+AB24+AH24+AN24+AT24+AZ24+BF24+BL24+BR24 -> 14 | CD24: =E24+K24+Q24+W24+AC24+AI24+AO24+AU24+BA24+BG24+BM24+BS24 -> 2 | CE24: =F24+L24+R24+X24+AD24+AJ24+AP24+AV24+BB24+BH24+BN24+BT24 -> 0 | CF24: =G24+M24+S24+Y24+AE24+AK24+AQ24+AW24+BC24+BI24+BO24+BU24 -> 37.5 | CG24: =H24+N24+T24+Z24+AF24+AL24+AR24+AX24+BJ24+BP24+BV24+BD24 -> 84.5 | CH24: =I24+O24+U24+AA24+AG24+AM24+AS24+AY24+BE24+BK24+BQ24+BW24 -> 95
A25: 23 | B25: CALDERON TORRES ALDO EDGAR | C25: 2821.5 | D25: 60 | E25: 2 | F25: 86 | G25: 3 | H25: 0 | J25: 58 | K25: 2 | L25: 89.5 | M25: 3.5 | N25: 0 | P25: 60 | Q25: 2 | R25: 88 | S25: 3 | T25: 0 | U25: 75 | V25: 60 | W25: 2 | X25: 24 | Y25: 3.5 | Z25: 0 | AB25: 60 | AC25: 2 | AD25: 23 | AE25: 4 | AF25: 0 | AG25: 30 | AH25: 60 | AI25: 2 | AJ25: 20 | AK25: 3 | AL25: 0 | AM25: 75 | AN25: 60 | AO25: 2 | AP25: 18.5 | AQ25: 3 | AR25: 0 | AS25: 85 | AT25: 60 | AU25: 2 | AV25: 17.5 | AW25: 2.5 | AX25: 0 | AY25: 25 | AZ25: 60 | BA25: 2 | BB25: 20.5 | BC25: 2 | BE25: 15 | BF25: 60 | BG25: 2 | BH25: 19 | BI25: 6 | BL25: 60 | BM25: 2 | BN25: 27 | BO25: 3 | BQ25: =59+85 -> 144 | BR25: 60 | BS25: 2 | BT25: 27.2 | BU25: 3 | BX25: =SUM(D25:BW25) -> 1690.7 | BY25: =C25 -> 2821.5 | BZ25: =BX25+BY25 -> 4512.2 | CC25: =D25+J25+P25+V25+AB25+AH25+AN25+AT25+AZ25+BF25+BL25+BR25 -> 718 | CD25: =E25+K25+Q25+W25+AC25+AI25+AO25+AU25+BA25+BG25+BM25+BS25 -> 24 | CE25: =F25+L25+R25+X25+AD25+AJ25+AP25+AV25+BB25+BH25+BN25+BT25 -> 460.2 | CF25: =G25+M25+S25+Y25+AE25+AK25+AQ25+AW25+BC25+BI25+BO25+BU25 -> 39.5 | CG25: =H25+N25+T25+Z25+AF25+AL25+AR25+AX25+BJ25+BP25+BV25+BD25 -> 0 | CH25: =I25+O25+U25+AA25+AG25+AM25+AS25+AY25+BE25+BK25+BQ25+BW25 -> 449
A26: 24 | B26: CALDERON VERA SEGUNDO ALCIDES | C26: 10 | D26: 0 | E26: 0 | F26: 0 | G26: 0 | H26: 0 | J26: 0 | K26: 0 | L26: 0 | M26: 0 | N26: 0 | P26: 0 | Q26: 0 | R26: 0 | S26: 0 | T26: 0 | V26: 0 | W26: 0 | X26: 0 | Y26: 0 | Z26: 0 | AB26: 0 | AC26: 0 | AD26: 0 | AE26: 0 | AF26: 0 | AH26: 0 | AI26: 0 | AJ26: 0 | AK26: 0 | AL26: 0 | AN26: 0 | AO26: 0 | AP26: 0 | AQ26: 0 | AR26: 0 | AT26: 0 | AU26: 0 | AV26: 0 | AW26: 0 | AX26: 0 | AZ26: 0 | BA26: 0 | BB26: 0 | BC26: 0 | BF26: 0 | BG26: 0 | BH26: 0 | BI26: 0 | BL26: 60 | BM26: 2 | BN26: 81.5 | BO26: 55 | BR26: 60 | BS26: 2 | BT26: 87.7 | BU26: 55 | BW26: 80 | BX26: =SUM(D26:BW26) -> 483.2 | BY26: =C26 -> 10 | BZ26: =BX26+BY26 -> 493.2 | CC26: =D26+J26+P26+V26+AB26+AH26+AN26+AT26+AZ26+BF26+BL26+BR26 -> 120 | CD26: =E26+K26+Q26+W26+AC26+AI26+AO26+AU26+BA26+BG26+BM26+BS26 -> 4 | CE26: =F26+L26+R26+X26+AD26+AJ26+AP26+AV26+BB26+BH26+BN26+BT26 -> 169.2 | CF26: =G26+M26+S26+Y26+AE26+AK26+AQ26+AW26+BC26+BI26+BO26+BU26 -> 110 | CG26: =H26+N26+T26+Z26+AF26+AL26+AR26+AX26+BJ26+BP26+BV26+BD26 -> 0 | CH26: =I26+O26+U26+AA26+AG26+AM26+AS26+AY26+BE26+BK26+BQ26+BW26 -> 80
A27: 25 | B27: CALLE CALLE FIDEL | C27: 0 | D27: 0 | E27: 0 | F27: 0 | G27: 0 | H27: 0 | J27: 0 | K27: 0 | L27: 0 | M27: 0 | N27: 0 | P27: 0 | Q27: 0 | R27: 0 | S27: 0 | T27: 0 | V27: 0 | W27: 0 | X27: 0 | Y27: 0 | Z27: 0 | AB27: 0 | AC27: 0 | AD27: 0 | AE27: 0 | AF27: 0 | AH27: 0 | AI27: 0 | AJ27: 0 | AK27: 0 | AL27: 0 | AN27: 0 | AO27: 0 | AP27: 0 | AQ27: 0 | AR27: 0 | AT27: 0 | AU27: 0 | AV27: 0 | AW27: 0 | AX27: 0 | AZ27: 0 | BA27: 0 | BB27: 0 | BC27: 0 | BF27: 0 | BG27: 0 | BH27: 0 | BI27: 0 | BL27: 0 | BM27: 0 | BN27: 68 | BO27: 3 | BQ27: 59 | BR27: 0 | BS27: 0 | BT27: 71.9 | BU27: 3 | BX27: =SUM(D27:BW27) -> 204.9 | BY27: =C27 -> 0 | BZ27: =BX27+BY27 -> 204.9 | CC27: =D27+J27+P27+V27+AB27+AH27+AN27+AT27+AZ27+BF27+BL27+BR27 -> 0 | CD27: =E27+K27+Q27+W27+AC27+AI27+AO27+AU27+BA27+BG27+BM27+BS27 -> 0 | CE27: =F27+L27+R27+X27+AD27+AJ27+AP27+AV27+BB27+BH27+BN27+BT27 -> 139.9 | CF27: =G27+M27+S27+Y27+AE27+AK27+AQ27+AW27+BC27+BI27+BO27+BU27 -> 6 | CG27: =H27+N27+T27+Z27+AF27+AL27+AR27+AX27+BJ27+BP27+BV27+BD27 -> 0 | CH27: =I27+O27+U27+AA27+AG27+AM27+AS27+AY27+BE27+BK27+BQ27+BW27 -> 59
A28: 26 | B28: CAMPUZANO CABELLO VICENTA DONATILA | C28: 144 | D28: 60 | E28: 2 | F28: 0 | G28: 0 | H28: 0 | J28: 58 | K28: 2 | L28: 0 | M28: 0 | N28: 0 | P28: 60 | Q28: 2 | R28: 0 | S28: 0 | T28: 0 | U28: 75 | V28: 60 | W28: 2 | X28: 0 | Y28: 0 | Z28: 0 | AB28: 60 | AC28: 2 | AD28: 0 | AE28: 0 | AF28: 0 | AH28: 60 | AI28: 2 | AJ28: 0 | AK28: 0 | AL28: 0 | AM28: 75 | AN28: 60 | AO28: 2 | AP28: 0 | AQ28: 0 | AR28: 0 | AS28: 85 | AT28: 60 | AU28: 2 | AV28: 0 | AW28: 0 | AX28: 0 | AY28: 25 | AZ28: 60 | BA28: 2 | BB28: 0 | BC28: 0 | BF28: 60 | BG28: 2 | BH28: 0 | BI28: 0 | BL28: 60 | BM28: 2 | BN28: 35.5 | BO28: 3 | BQ28: =59+85 -> 144 | BR28: 60 | BS28: 2 | BT28: 37.6 | BU28: 3 | BW28: 80 | BX28: =SUM(D28:BW28) -> 1305.1 | BY28: =C28 -> 144 | BZ28: =BX28+BY28 -> 1449.1 | CC28: =D28+J28+P28+V28+AB28+AH28+AN28+AT28+AZ28+BF28+BL28+BR28 -> 718 | CD28: =E28+K28+Q28+W28+AC28+AI28+AO28+AU28+BA28+BG28+BM28+BS28 -> 24 | CE28: =F28+L28+R28+X28+AD28+AJ28+AP28+AV28+BB28+BH28+BN28+BT28 -> 73.1 | CF28: =G28+M28+S28+Y28+AE28+AK28+AQ28+AW28+BC28+BI28+BO28+BU28 -> 6 | CG28: =H28+N28+T28+Z28+AF28+AL28+AR28+AX28+BJ28+BP28+BV28+BD28 -> 0 | CH28: =I28+O28+U28+AA28+AG28+AM28+AS28+AY28+BE28+BK28+BQ28+BW28 -> 484
A29: 27 | B29: CARDEÑA VILLAFUERTE ALEJANDRINA | C29: 1897.5 | D29: 0 | E29: 0 | F29: 0 | G29: 0 | H29: 0 | J29: 0 | K29: 0 | L29: 0 | M29: 0 | N29: 0 | P29: 0 | Q29: 0 | R29: 0 | S29: 0 | T29: 0 | U29: 75 | V29: 0 | W29: 0 | X29: 0 | Y29: 0 | Z29: 0 | AB29: 0 | AC29: 0 | AD29: 0 | AE29: 0 | AF29: 0 | AH29: 0 | AI29: 0 | AJ29: 0 | AK29: 0 | AL29: 0 | AM29: 75 | AN29: 0 | AO29: 0 | AP29: 0 | AQ29: 0 | AR29: 0 | AS29: 85 | AT29: 0 | AU29: 0 | AV29: 0 | AW29: 0 | AX29: 0 | AZ29: 0 | BA29: 0 | BB29: 0 | BC29: 0 | BF29: 0 | BG29: 0 | BH29: 0 | BI29: 0 | BL29: 0 | BM29: 0 | BN29: 0 | BO29: 0 | BQ29: 85 | BR29: 0 | BS29: 0 | BT29: 148.2 | BU29: 39 | BW29: 80 | BX29: =SUM(D29:BW29) -> 587.2 | BY29: =C29 -> 1897.5 | BZ29: =BX29+BY29 -> 2484.7 | CC29: =D29+J29+P29+V29+AB29+AH29+AN29+AT29+AZ29+BF29+BL29+BR29 -> 0 | CD29: =E29+K29+Q29+W29+AC29+AI29+AO29+AU29+BA29+BG29+BM29+BS29 -> 0 | CE29: =F29+L29+R29+X29+AD29+AJ29+AP29+AV29+BB29+BH29+BN29+BT29 -> 148.2 | CF29: =G29+M29+S29+Y29+AE29+AK29+AQ29+AW29+BC29+BI29+BO29+BU29 -> 39 | CG29: =H29+N29+T29+Z29+AF29+AL29+AR29+AX29+BJ29+BP29+BV29+BD29 -> 0 | CH29: =I29+O29+U29+AA29+AG29+AM29+AS29+AY29+BE29+BK29+BQ29+BW29 -> 400
A30: 28 | B30: CARPIO VASQUEZ TEOFILA | C30: 0 | D30: 0 | E30: 0 | F30: 0 | G30: 0 | H30: 0 | J30: 0 | K30: 0 | L30: 0 | M30: 0 | N30: 0 | P30: 0 | Q30: 0 | R30: 0 | S30: 0 | T30: 0 | V30: 0 | W30: 0 | X30: 0 | Y30: 0 | Z30: 0 | AB30: 0 | AC30: 0 | AD30: 0 | AE30: 0 | AF30: 0 | AH30: 0 | AI30: 0 | AJ30: 0 | AK30: 0 | AL30: 0 | AN30: 0 | AO30: 0 | AP30: 0 | AQ30: 0 | AR30: 0 | AT30: 0 | AU30: 0 | AV30: 0 | AW30: 0 | AX30: 0 | AZ30: 0 | BA30: 0 | BB30: 0 | BC30: 0 | BF30: 0 | BG30: 0 | BH30: 0 | BI30: 0 | BL30: 60 | BM30: 2 | BN30: 13.5 | BO30: 3 | BR30: 60 | BS30: 2 | BT30: 22.3 | BU30: 3 | BX30: =SUM(D30:BW30) -> 165.8 | BY30: =C30 -> 0 | BZ30: =BX30+BY30 -> 165.8 | CC30: =D30+J30+P30+V30+AB30+AH30+AN30+AT30+AZ30+BF30+BL30+BR30 -> 120 | CD30: =E30+K30+Q30+W30+AC30+AI30+AO30+AU30+BA30+BG30+BM30+BS30 -> 4 | CE30: =F30+L30+R30+X30+AD30+AJ30+AP30+AV30+BB30+BH30+BN30+BT30 -> 35.8 | CF30: =G30+M30+S30+Y30+AE30+AK30+AQ30+AW30+BC30+BI30+BO30+BU30 -> 6 | CG30: =H30+N30+T30+Z30+AF30+AL30+AR30+AX30+BJ30+BP30+BV30+BD30 -> 0 | CH30: =I30+O30+U30+AA30+AG30+AM30+AS30+AY30+BE30+BK30+BQ30+BW30 -> 0
A31: 29 | B31: CARRASCO SALVATIERRA FELICITA | C31: 0 | D31: 0 | E31: 0 | F31: 0 | G31: 0 | H31: 0 | J31: 0 | K31: 0 | L31: 0 | M31: 0 | N31: 0 | P31: 0 | Q31: 0 | R31: 0 | S31: 0 | T31: 0 | V31: 0 | W31: 0 | X31: 0 | Y31: 0 | Z31: 0 | AB31: 0 | AC31: 0 | AD31: 0 | AE31: 0 | AF31: 0 | AH31: 0 | AI31: 0 | AJ31: 0 | AK31: 0 | AL31: 0 | AN31: 0 | AO31: 0 | AP31: 0 | AQ31: 0 | AR31: 0 | AT31: 0 | AU31: 0 | AV31: 0 | AW31: 0 | AX31: 0 | AZ31: 0 | BA31: 0 | BB31: 0 | BC31: 0 | BF31: 0 | BG31: 0 | BH31: 0 | BI31: 0 | BL31: 0 | BM31: 0 | BN31: 0 | BO31: 14 | BR31: 0 | BS31: 0 | BU31: 8.7 | BW31: 80 | BX31: =SUM(D31:BW31) -> 102.7 | BY31: =C31 -> 0 | BZ31: =BX31+BY31 -> 102.7 | CC31: =D31+J31+P31+V31+AB31+AH31+AN31+AT31+AZ31+BF31+BL31+BR31 -> 0 | CD31: =E31+K31+Q31+W31+AC31+AI31+AO31+AU31+BA31+BG31+BM31+BS31 -> 0 | CE31: =F31+L31+R31+X31+AD31+AJ31+AP31+AV31+BB31+BH31+BN31+BT31 -> 0 | CF31: =G31+M31+S31+Y31+AE31+AK31+AQ31+AW31+BC31+BI31+BO31+BU31 -> 22.7 | CG31: =H31+N31+T31+Z31+AF31+AL31+AR31+AX31+BJ31+BP31+BV31+BD31 -> 0 | CH31: =I31+O31+U31+AA31+AG31+AM31+AS31+AY31+BE31+BK31+BQ31+BW31 -> 80
A32: 30 | B32: CARTAJENA MAMANI BENJAMIN D | C32: 0 | D32: 0 | E32: 0 | F32: 0 | G32: 0 | H32: 0 | J32: 0 | K32: 0 | L32: 0 | M32: 0 | N32: 0 | P32: 0 | Q32: 0 | R32: 0 | S32: 0 | T32: 0 | V32: 0 | W32: 0 | X32: 0 | Y32: 0 | Z32: 0 | AB32: 0 | AC32: 0 | AD32: 0 | AE32: 0 | AF32: 0 | AH32: 0 | AI32: 0 | AJ32: 0 | AK32: 0 | AL32: 0 | AN32: 0 | AO32: 0 | AP32: 0 | AQ32: 0 | AR32: 0 | AT32: 0 | AU32: 0 | AV32: 0 | AW32: 0 | AX32: 0 | AZ32: 0 | BA32: 0 | BB32: 0 | BC32: 0 | BF32: 0 | BG32: 0 | BH32: 0 | BI32: 0 | BL32: 0 | BM32: 0 | BR32: 0 | BS32: 0 | BT32: 41.9 | BU32: 3 | BW32: 80 | BX32: =SUM(D32:BW32) -> 124.9 | BY32: =C32 -> 0 | BZ32: =BX32+BY32 -> 124.9 | CC32: =D32+J32+P32+V32+AB32+AH32+AN32+AT32+AZ32+BF32+BL32+BR32 -> 0 | CD32: =E32+K32+Q32+W32+AC32+AI32+AO32+AU32+BA32+BG32+BM32+BS32 -> 0 | CE32: =F32+L32+R32+X32+AD32+AJ32+AP32+AV32+BB32+BH32+BN32+BT32 -> 41.9 | CF32: =G32+M32+S32+Y32+AE32+AK32+AQ32+AW32+BC32+BI32+BO32+BU32 -> 3 | CG32: =H32+N32+T32+Z32+AF32+AL32+AR32+AX32+BJ32+BP32+BV32+BD32 -> 0 | CH32: =I32+O32+U32+AA32+AG32+AM32+AS32+AY32+BE32+BK32+BQ32+BW32 -> 80
A33: 31 | B33: CARTAJENA PALOMINO ALVARO BENJAMIN | C33: 0 | D33: 0 | E33: 0 | F33: 0 | G33: 0 | H33: 0 | J33: 0 | K33: 0 | L33: 0 | M33: 0 | N33: 0 | P33: 0 | Q33: 0 | R33: 0 | S33: 0 | T33: 0 | V33: 0 | W33: 0 | X33: 0 | Y33: 0 | Z33: 0 | AB33: 0 | AC33: 0 | AD33: 0 | AE33: 0 | AF33: 0 | AH33: 0 | AI33: 0 | AJ33: 0 | AK33: 0 | AL33: 0 | AN33: 0 | AO33: 0 | AP33: 0 | AQ33: 0 | AR33: 0 | AT33: 0 | AU33: 0 | AV33: 0 | AW33: 0 | AX33: 0 | AZ33: 0 | BA33: 0 | BB33: 0 | BC33: 0 | BF33: 0 | BG33: 0 | BH33: 0 | BI33: 0 | BL33: 0 | BM33: 0 | BN33: 35.5 | BO33: 3 | BR33: 0 | BS33: 0 | BT33: 37.6 | BU33: 3 | BW33: 80 | BX33: =SUM(D33:BW33) -> 159.1 | BY33: =C33 -> 0 | BZ33: =BX33+BY33 -> 159.1 | CC33: =D33+J33+P33+V33+AB33+AH33+AN33+AT33+AZ33+BF33+BL33+BR33 -> 0 | CD33: =E33+K33+Q33+W33+AC33+AI33+AO33+AU33+BA33+BG33+BM33+BS33 -> 0 | CE33: =F33+L33+R33+X33+AD33+AJ33+AP33+AV33+BB33+BH33+BN33+BT33 -> 73.1 | CF33: =G33+M33+S33+Y33+AE33+AK33+AQ33+AW33+BC33+BI33+BO33+BU33 -> 6 | CG33: =H33+N33+T33+Z33+AF33+AL33+AR33+AX33+BJ33+BP33+BV33+BD33 -> 0 | CH33: =I33+O33+U33+AA33+AG33+AM33+AS33+AY33+BE33+BK33+BQ33+BW33 -> 80
A34: 32 | B34: CASTRO ALEJANDRO HORTENCIA LUCILA | C34: 0 | D34: 0 | E34: 0 | F34: 0 | G34: 0 | H34: 0 | J34: 0 | K34: 0 | L34: 0 | M34: 0 | N34: 0 | P34: 0 | Q34: 0 | R34: 0 | S34: 0 | T34: 0 | V34: 0 | W34: 0 | X34: 0 | Y34: 0 | Z34: 0 | AB34: 0 | AC34: 0 | AD34: 0 | AE34: 0 | AF34: 0 | AH34: 0 | AI34: 0 | AJ34: 0 | AK34: 0 | AL34: 0 | AN34: 0 | AO34: 0 | AP34: 0 | AQ34: 0 | AR34: 0 | AT34: 0 | AU34: 0 | AV34: 0 | AW34: 0 | AX34: 0 | AZ34: 0 | BA34: 0 | BB34: 0 | BC34: 0 | BF34: 0 | BG34: 0 | BH34: 0 | BI34: 0 | BL34: 0 | BM34: 0 | BN34: 21.5 | BO34: 3 | BQ34: 59 | BR34: 0 | BS34: 0 | BT34: 22.3 | BU34: 3 | BX34: =SUM(D34:BW34) -> 108.8 | BY34: =C34 -> 0 | BZ34: =BX34+BY34 -> 108.8 | CC34: =D34+J34+P34+V34+AB34+AH34+AN34+AT34+AZ34+BF34+BL34+BR34 -> 0 | CD34: =E34+K34+Q34+W34+AC34+AI34+AO34+AU34+BA34+BG34+BM34+BS34 -> 0 | CE34: =F34+L34+R34+X34+AD34+AJ34+AP34+AV34+BB34+BH34+BN34+BT34 -> 43.8 | CF34: =G34+M34+S34+Y34+AE34+AK34+AQ34+AW34+BC34+BI34+BO34+BU34 -> 6 | CG34: =H34+N34+T34+Z34+AF34+AL34+AR34+AX34+BJ34+BP34+BV34+BD34 -> 0 | CH34: =I34+O34+U34+AA34+AG34+AM34+AS34+AY34+BE34+BK34+BQ34+BW34 -> 59
A35: 33 | B35: CASTRO GUTIERREZ AQUILA LUCRECIA | C35: 0 | D35: 0 | E35: 0 | F35: 0 | G35: 0 | H35: 0 | J35: 0 | K35: 0 | L35: 0 | M35: 0 | N35: 0 | P35: 0 | Q35: 0 | R35: 0 | S35: 0 | T35: 0 | V35: 0 | W35: 0 | X35: 0 | Y35: 0 | Z35: 0 | AB35: 0 | AC35: 0 | AD35: 0 | AE35: 0 | AF35: 0 | AH35: 0 | AI35: 0 | AJ35: 0 | AK35: 0 | AL35: 0 | AN35: 0 | AO35: 0 | AP35: 0 | AQ35: 0 | AR35: 0 | AT35: 0 | AU35: 0 | AV35: 0 | AW35: 0 | AX35: 0 | AZ35: 0 | BA35: 0 | BB35: 0 | BC35: 0 | BF35: 0 | BG35: 0 | BH35: 0 | BI35: 0 | BL35: 0 | BM35: 0 | BN35: 76 | BO35: 3 | BR35: 60 | BS35: 2 | BT35: 80.6 | BU35: 3 | BX35: =SUM(D35:BW35) -> 224.6 | BY35: =C35 -> 0 | BZ35: =BX35+BY35 -> 224.6 | CC35: =D35+J35+P35+V35+AB35+AH35+AN35+AT35+AZ35+BF35+BL35+BR35 -> 60 | CD35: =E35+K35+Q35+W35+AC35+AI35+AO35+AU35+BA35+BG35+BM35+BS35 -> 2 | CE35: =F35+L35+R35+X35+AD35+AJ35+AP35+AV35+BB35+BH35+BN35+BT35 -> 156.6 | CF35: =G35+M35+S35+Y35+AE35+AK35+AQ35+AW35+BC35+BI35+BO35+BU35 -> 6 | CG35: =H35+N35+T35+Z35+AF35+AL35+AR35+AX35+BJ35+BP35+BV35+BD35 -> 0 | CH35: =I35+O35+U35+AA35+AG35+AM35+AS35+AY35+BE35+BK35+BQ35+BW35 -> 0
A36: 34 | B36: CCOYLLO CHINCHAY DANIEL MASIA | C36: 633.6 | D36: 0 | E36: 0 | F36: 0 | G36: 0 | H36: 0 | J36: 0 | K36: 0 | L36: 0 | M36: 0 | N36: 0 | P36: 0 | Q36: 0 | R36: 0 | S36: 0 | T36: 0 | V36: 0 | W36: 0 | X36: 0 | Y36: 0 | Z36: 0 | AB36: 0 | AC36: 0 | AD36: 0 | AE36: 0 | AF36: 0 | AH36: 0 | AI36: 0 | AJ36: 0 | AK36: 0 | AL36: 0 | AN36: 0 | AO36: 0 | AP36: 0 | AQ36: 0 | AR36: 0 | AS36: 50.5 | AT36: 0 | AU36: 0 | AV36: 0 | AW36: 0 | AX36: 0 | AZ36: 0 | BA36: 0 | BB36: 0 | BC36: 0 | BF36: 0 | BG36: 0 | BH36: 0 | BI36: 0 | BJ36: 0 | BL36: 0 | BM36: 0 | BN36: 0 | BO36: 0 | BR36: 0 | BS36: 0 | BV36: 0 | BX36: =SUM(D36:BW36) -> 50.5 | BY36: =C36 -> 633.6 | BZ36: =BX36+BY36 -> 684.1 | CC36: =D36+J36+P36+V36+AB36+AH36+AN36+AT36+AZ36+BF36+BL36+BR36 -> 0 | CD36: =E36+K36+Q36+W36+AC36+AI36+AO36+AU36+BA36+BG36+BM36+BS36 -> 0 | CE36: =F36+L36+R36+X36+AD36+AJ36+AP36+AV36+BB36+BH36+BN36+BT36 -> 0 | CF36: =G36+M36+S36+Y36+AE36+AK36+AQ36+AW36+BC36+BI36+BO36+BU36 -> 0 | CG36: =H36+N36+T36+Z36+AF36+AL36+AR36+AX36+BJ36+BP36+BV36+BD36 -> 0 | CH36: =I36+O36+U36+AA36+AG36+AM36+AS36+AY36+BE36+BK36+BQ36+BW36 -> 50.5
A37: 35 | B37: CCOYLLO CHINCHAY JUDITH NATY | C37: 492 | D37: 0 | E37: 0 | F37: 0 | G37: 0 | H37: 0 | J37: 0 | K37: 0 | L37: 0 | M37: 0 | N37: 0 | P37: 0 | Q37: 0 | R37: 0 | S37: 0 | T37: 0 | U37: 72.5 | V37: 0 | W37: 0 | X37: 0 | Y37: 0 | Z37: 0 | AB37: 0 | AC37: 0 | AD37: 0 | AE37: 0 | AF37: 0 | AH37: 0 | AI37: 0 | AJ37: 0 | AK37: 0 | AL37: 0 | AM37: 75 | AN37: 0 | AO37: 0 | AP37: 0 | AQ37: 0 | AR37: 0 | AS37: 85 | AT37: 0 | AU37: 0 | AV37: 0 | AW37: 0 | AX37: 0 | AZ37: 0 | BA37: 0 | BB37: 0 | BC37: 0 | BF37: 0 | BG37: 0 | BH37: 0 | BI37: 0 | BL37: 0 | BM37: 0 | BN37: 0 | BO37: 0 | BR37: 0 | BS37: 0 | BX37: =SUM(D37:BW37) -> 232.5 | BY37: =C37 -> 492 | BZ37: =BX37+BY37 -> 724.5 | CC37: =D37+J37+P37+V37+AB37+AH37+AN37+AT37+AZ37+BF37+BL37+BR37 -> 0 | CD37: =E37+K37+Q37+W37+AC37+AI37+AO37+AU37+BA37+BG37+BM37+BS37 -> 0 | CE37: =F37+L37+R37+X37+AD37+AJ37+AP37+AV37+BB37+BH37+BN37+BT37 -> 0 | CF37: =G37+M37+S37+Y37+AE37+AK37+AQ37+AW37+BC37+BI37+BO37+BU37 -> 0 | CG37: =H37+N37+T37+Z37+AF37+AL37+AR37+AX37+BJ37+BP37+BV37+BD37 -> 0 | CH37: =I37+O37+U37+AA37+AG37+AM37+AS37+AY37+BE37+BK37+BQ37+BW37 -> 232.5
A38: 36 | B38: CCOYLLO POLANCO DANIEL | C38: 0 | D38: 0 | E38: 0 | F38: 0 | G38: 0 | H38: 0 | J38: 0 | K38: 0 | L38: 0 | M38: 0 | N38: 0 | P38: 0 | Q38: 0 | R38: 0 | S38: 0 | T38: 0 | V38: 0 | W38: 0 | X38: 0 | Y38: 0 | Z38: 0 | AB38: 0 | AC38: 0 | AD38: 0 | AE38: 0 | AF38: 0 | AH38: 0 | AI38: 0 | AJ38: 0 | AK38: 0 | AL38: 0 | AN38: 0 | AO38: 0 | AP38: 0 | AQ38: 0 | AR38: 0 | AT38: 0 | AU38: 0 | AV38: 0 | AW38: 0 | AX38: 0 | AZ38: 0 | BA38: 0 | BB38: 0 | BC38: 0 | BF38: 0 | BG38: 0 | BH38: 0 | BI38: 0 | BL38: 0 | BM38: 0 | BN38: 0 | BO38: 0 | BR38: 0 | BS38: 0 | BT38: 13.6 | BU38: 3 | BX38: =SUM(D38:BW38) -> 16.6 | BY38: =C38 -> 0 | BZ38: =BX38+BY38 -> 16.6 | CC38: =D38+J38+P38+V38+AB38+AH38+AN38+AT38+AZ38+BF38+BL38+BR38 -> 0 | CD38: =E38+K38+Q38+W38+AC38+AI38+AO38+AU38+BA38+BG38+BM38+BS38 -> 0 | CE38: =F38+L38+R38+X38+AD38+AJ38+AP38+AV38+BB38+BH38+BN38+BT38 -> 13.6 | CF38: =G38+M38+S38+Y38+AE38+AK38+AQ38+AW38+BC38+BI38+BO38+BU38 -> 3 | CG38: =H38+N38+T38+Z38+AF38+AL38+AR38+AX38+BJ38+BP38+BV38+BD38 -> 0 | CH38: =I38+O38+U38+AA38+AG38+AM38+AS38+AY38+BE38+BK38+BQ38+BW38 -> 0
A39: 37 | B39: CCOYLLO POLANCO GERMAN | C39: 0 | D39: 0 | E39: 0 | F39: 0 | G39: 0 | H39: 0 | J39: 0 | K39: 0 | L39: 0 | M39: 0 | N39: 0 | P39: 0 | Q39: 0 | R39: 0 | S39: 0 | T39: 0 | V39: 0 | W39: 0 | X39: 0 | Y39: 0 | Z39: 0 | AB39: 0 | AC39: 0 | AD39: 0 | AE39: 0 | AF39: 0 | AH39: 0 | AI39: 0 | AJ39: 0 | AK39: 0 | AL39: 0 | AN39: 0 | AO39: 0 | AP39: 0 | AQ39: 0 | AR39: 0 | AS39: 0 | AT39: 0 | AU39: 0 | AV39: 0 | AW39: 0 | AX39: 0 | AZ39: 0 | BA39: 0 | BB39: 0 | BC39: 0 | BD39: 0 | BF39: 0 | BG39: 0 | BH39: 0 | BI39: 0 | BJ39: 0 | BL39: 0 | BM39: 0 | BN39: 49 | BO39: 3 | BR39: 0 | BS39: 0 | BX39: =SUM(D39:BW39) -> 52 | BY39: =C39 -> 0 | BZ39: =BX39+BY39 -> 52 | CC39: =D39+J39+P39+V39+AB39+AH39+AN39+AT39+AZ39+BF39+BL39+BR39 -> 0 | CD39: =E39+K39+Q39+W39+AC39+AI39+AO39+AU39+BA39+BG39+BM39+BS39 -> 0 | CE39: =F39+L39+R39+X39+AD39+AJ39+AP39+AV39+BB39+BH39+BN39+BT39 -> 49 | CF39: =G39+M39+S39+Y39+AE39+AK39+AQ39+AW39+BC39+BI39+BO39+BU39 -> 3 | CG39: =H39+N39+T39+Z39+AF39+AL39+AR39+AX39+BJ39+BP39+BV39+BD39 -> 0 | CH39: =I39+O39+U39+AA39+AG39+AM39+AS39+AY39+BE39+BK39+BQ39+BW39 -> 0
A40: 38 | B40: CERDA YUPANQUI CARMEN ROSA | C40: 0 | D40: 0 | E40: 0 | F40: 0 | G40: 0 | H40: 0 | J40: 0 | K40: 0 | L40: 0 | M40: 0 | N40: 0 | P40: 0 | Q40: 0 | R40: 0 | S40: 0 | T40: 0 | V40: 0 | W40: 0 | X40: 0 | Y40: 0 | Z40: 0 | AB40: 0 | AC40: 0 | AD40: 0 | AE40: 0 | AF40: 0 | AH40: 0 | AI40: 0 | AJ40: 0 | AK40: 0 | AL40: 0 | AN40: 0 | AO40: 0 | AP40: 0 | AQ40: 0 | AR40: 0 | AT40: 0 | AU40: 0 | AV40: 0 | AW40: 0 | AX40: 0 | AZ40: 0 | BA40: 0 | BB40: 0 | BC40: 0 | BF40: 0 | BG40: 0 | BH40: 0 | BI40: 0 | BL40: 60 | BM40: 2 | BN40: 27.5 | BO40: 3 | BR40: 60 | BS40: 2 | BT40: 28.9 | BU40: 3 | BX40: =SUM(D40:BW40) -> 186.4 | BY40: =C40 -> 0 | BZ40: =BX40+BY40 -> 186.4 | CC40: =D40+J40+P40+V40+AB40+AH40+AN40+AT40+AZ40+BF40+BL40+BR40 -> 120 | CD40: =E40+K40+Q40+W40+AC40+AI40+AO40+AU40+BA40+BG40+BM40+BS40 -> 4 | CE40: =F40+L40+R40+X40+AD40+AJ40+AP40+AV40+BB40+BH40+BN40+BT40 -> 56.4 | CF40: =G40+M40+S40+Y40+AE40+AK40+AQ40+AW40+BC40+BI40+BO40+BU40 -> 6 | CG40: =H40+N40+T40+Z40+AF40+AL40+AR40+AX40+BJ40+BP40+BV40+BD40 -> 0 | CH40: =I40+O40+U40+AA40+AG40+AM40+AS40+AY40+BE40+BK40+BQ40+BW40 -> 0
...

Sheet Choquehuanca David
A2: CHOQUEHUANCA HUAMAN DAVID
A4: FECHA | B4: DOCUMENTO | C4: PERIODO | D4: CONCEPTO | E4: POR COBRAR | F4: PAGADO | G4: SALDO POR COBRAR
G5: 0
A6: 45200 | B6: POR COBRAR | C6: OCTUBRE | D6: GARANTIA | E6: 500 | G6: =+G5+E6-F6 -> 500
D7: ALQUILER | E7: 500 | G7: =+G6+E7-F7 -> 1000
D8: LUZ | E8: 24.3 | G8: =+G7+E8-F8 -> 1024.3
D9: AGUA | E9: 2 | G9: =+G8+E9-F9 -> 1026.3
A10: 45198 | B10: EB01-2687 | C10: OCTUBRE | D10: GARANTIA | F10: 500 | G10: =+G9+E10-F10 -> 526.3
A11: 45198 | B11: EB01-2688 | C11: OCTUBRE | D11: ALQUILER | F11: 500 | G11: =+G10+E11-F11 -> 26.3
A12: 45264 | B12: RII 1921 | C12: OCTUBRE | D12: LUZ | F12: 24.3 | G12: =+G11+E12-F12 -> 2
A13: 45264 | B13: RII 1921 | C13: OCTUBRE | D13: AGUA | F13: 2 | G13: =+G12+E13-F13 -> -4.6185278e-14
A14: 45260 | B14: POR COBRAR | C14: NOVIEMBRE | D14: LUZ | E14: 26.4 | G14: =+G13+E14-F14 -> 26.4
D15: AGUA | E15: 10 | G15: =+G14+E15-F15 -> 36.4
D16: ALQUILER | E16: 500 | G16: =+G15+E16-F16 -> 536.4
A17: 45234 | B17: EB01-2869 | C17: MOVIEMBRE | D17: ALQUILER | F17: 500 | G17: =+G16+E17-F17 -> 36.4
A18: 45299 | B18: RII 1984 | C18: MOVIEMBRE | D18: LUZ | F18: 26.4 | G18: =+G17+E18-F18 -> 10
A19: 45299 | B19: RII 1984 | C19: MOVIEMBRE | D19: AGUA | F19: 10 | G19: =+G18+E19-F19 -> -2.1316282e-14
A20: 45291 | B20: POR COBRAR | C20: DICIEMBRE | D20: LUZ | E20: 28.2 | G20: =+G19+E20-F20 -> 28.2
D21: AGUA | E21: 5 | G21: =+G20+E21-F21 -> 33.2
D22: ALQUILER | E22: 500 | G22: =+G21+E22-F22 -> 533.2
A23: 45264 | B23: EB01-3005 | C23: DICIEMBRE | D23: ALQUILER | F23: 500 | G23: =+G22+E23-F23 -> 33.2
A24: 45331 | B24: RII 2045 | C24: DICIEMBRE | D24: LUZ | F24: 28.2 | G24: =+G23+E24-F24 -> 5
A25: 45331 | B25: RII 2045 | C25: DICIEMBRE | D25: AGUA | F25: 5 | G25: =+G24+E25-F25 -> -6.750156e-14
A26: 45322 | B26: POR COBRAR | C26: ENERO | D26: LUZ | E26: 31.5 | G26: =+G25+E26-F26 -> 31.5
D27: AGUA | E27: 8.8 | G27: =+G26+E27-F27 -> 40.3
D28: ALQUILER | E28: 500 | G28: =+G27+E28-F28 -> 540.3
A29: 45299 | B29: EB01-3164 | C29: ENERO | D29: ALQUILER | F29: 500 | G29: =+G28+E29-F29 -> 40.3
A30: 45362 | B30: RII 2088 | C30: ENERO | D30: LUZ | F30: 31.5 | G30: =+G29+E30-F30 -> 8.8
A31: 45362 | B31: RII 2088 | C31: ENERO | D31: AGUA | F31: 8.8 | G31: =+G30+E31-F31 -> -4.6185278e-14
A32: 45351 | B32: POR COBRAR | C32: FEBRERO | D32: LUZ | E32: 32.6 | G32: =+G31+E32-F32 -> 32.6
D33: AGUA | E33: 5 | G33: =+G32+E33-F33 -> 37.6
D34: ALQUILER | E34: 500 | G34: =+G33+E34-F34 -> 537.6
A35: 45331 | B35: EB01-3312 | C35: FEBRERO | D35: ALQUILER | F35: 500 | G35: =+G34+E35-F35 -> 37.6
A36: 45434 | B36: RII 2198 | C36: FEBRERO | D36: LUZ | F36: 32.6 | G36: =+G35+E36-F36 -> 5
A37: 45434 | B37: RII 2198 | C37: FEBRERO | D37: AGUA | F37: 5 | G37: =+G36+E37-F37 -> -9.2370556e-14
A38: 45382 | B38: POR COBRAR | C38: MARZO | D38: LUZ | E38: 31.6 | G38: =+G37+E38-F38 -> 31.6
D39: AGUA | E39: 5 | G39: =+G38+E39-F39 -> 36.6
D40: ALQUILER | E40: 500 | G40: =+G39+E40-F40 -> 536.6
A41: 45362 | B41: EB01-3419 | C41: MARZO | D41: ALQUILER | F41: 500 | G41: =+G40+E41-F41 -> 36.6
A42: 45434 | B42: RII 2198 | C42: MARZO | D42: LUZ | F42: 31.6 | G42: =+G41+E42-F42 -> 5
...

Sheet MALLMA CONDORI LISBETH
A3: MALLMA CONDORI LIZBETH LUCIA
A5: FECHA | B5: DOCUMENTO | C5: PERIODO | D5: CONCEPTO | E5: POR COBRAR | F5: PAGADO | G5: SALDO POR COBRAR
A6: 42736 | B6: SALDO AL 2016 | G6: 1037.4
A7: 42739 | B7: 12014 | C7: A CUENTA DEL 2016 | F7: 292.5 | G7: =+G6+E7-F7 -> 744.9
A8: 42774 | B8: 12229 | C8: A CUENTA DEL 2016 | F8: 100 | G8: =+G7+E8-F8 -> 644.9
A9: 42782 | B9: 12267 | C9: A CUENTA DEL 2016 | F9: 100 | G9: =+G8+E9-F9 -> 544.9
A10: 42797 | B10: 12329 | C10: A CUENTA DEL 2016 | F10: 44.9 | G10: =+G9+E10-F10 -> 500
A11: 42766 | B11: 12189 | C11: A CUENTA DEL 2016 | F11: 500 | G11: =+G10+E11-F11 -> 0
A12: 42766 | B12: POR COBRAR | C12: ENERO | D12: LUZ | E12: 41.2 | G12: =+G11+E12-F12 -> 41.2
D13: AGUA | E13: 2.8 | G13: =+G12+E13-F13 -> 44
D14: ALQUILER | E14: 300 | G14: =+G13+E14-F14 -> 344
A15: 42797 | B15: 12329 | C15: ENERO | D15: LUZ | F15: 41.2 | G15: =+G14+E15-F15 -> 302.8
A16: 42797 | B16: 12329 | C16: ENERO | D16: AGUA | F16: 2.8 | G16: =+G15+E16-F16 -> 300
A17: 42800 | B17: 12332 | C17: ENERO | D17: ALQUILER | F17: 50 | G17: =+G16+E17-F17 -> 250
A18: 42800 | B18: 12348 | C18: ENERO | D18: ALQUILER | F18: 50 | G18: =+G17+E18-F18 -> 200
A19: 42802 | B19: 12369 | C19: ENERO | D19: ALQUILER | F19: 50 | G19: =+G18+E19-F19 -> 150
A20: 42804 | B20: 12376 | C20: ENERO | D20: ALQUILER | F20: 50 | G20: =+G19+E20-F20 -> 100
A21: 42808 | B21: 12399 | C21: ENERO | D21: ALQUILER | F21: 50 | G21: =+G20+E21-F21 -> 50
A22: 42808 | B22: 12402 | C22: ENERO | D22: ALQUILER | F22: 50 | G22: =+G21+E22-F22 -> 0
A23: 42794 | B23: POR COBRAR | C23: FEBRERO | D23: LUZ | E23: 41.7 | G23: =+G22+E23-F23 -> 41.7
D24: AGUA | E24: 2 | G24: =+G23+E24-F24 -> 43.7
D25: ALQUILER | E25: 300 | G25: =+G24+E25-F25 -> 343.7
A26: 42859 | B26: 12614 | C26: FEBRERO | D26: ALQUILER | F26: 300 | G26: =+G25+E26-F26 -> 43.7
A27: 42859 | B27: 12614 | C27: FEBRERO | D27: LUZ | F27: 41.7 | G27: =+G26+E27-F27 -> 2
A28: 42859 | B28: 12614 | C28: FEBRERO | D28: AGUA | F28: 2 | G28: =+G27+E28-F28 -> -1.4210855e-14
A29: 42825 | B29: POR COBRAR | C29: MARZO | D29: LUZ | E29: 39.7 | G29: =+G28+E29-F29 -> 39.7
D30: AGUA | E30: 2 | G30: =+G29+E30-F30 -> 41.7
D31: ALQUILER | E31: 300 | G31: =+G30+E31-F31 -> 341.7
A32: 42859 | B32: 12614 | C32: MARZO | D32: ALQUILER | F32: 6.3 | G32: =+G31+E32-F32 -> 335.4
A33: 42885 | B33: 12729 | C33: MARZO | D33: LUZ | F33: 39.7 | G33: =+G32+E33-F33 -> 295.7
A34: 42885 | B34: 12729 | C34: MARZO | D34: AGUA | F34: 2 | G34: =+G33+E34-F34 -> 293.7
A35: 42898 | B35: 12818 | C35: MARZO | D35: ALQUILER | F35: 293.7 | G35: =+G34+E35-F35 -> 0
A36: 42855 | B36: POR COBRAR | C36: ABRIL | D36: LUZ | E36: 41 | G36: =+G35+E36-F36 -> 41
D37: AGUA | E37: 2 | G37: =+G36+E37-F37 -> 43
D38: ALQUILER | E38: 300 | G38: =+G37+E38-F38 -> 343
A39: 42882 | B39: 12714 | C39: ABRIL | D39: ALQUILER | F39: 100 | G39: =+G38+E39-F39 -> 243
A40: 42898 | B40: 12818 | C40: ABRIL | D40: ALQUILER | F40: 1.3 | G40: =+G39+E40-F40 -> 241.7
A41: 42894 | B41: 12802 | C41: ABRIL | D41: ALQUILER | F41: 100 | G41: =+G40+E41-F41 -> 141.7
A42: 42916 | B42: 12901 | C42: ABRIL | D42: ALQUILER | F42: 98.7 | G42: =+G41+E42-F42 -> 43
A43: 42928 | B43: 12996 | C43: ABRIL | D43: LUZ | F43: 41 | G43: =+G42+E43-F43 -> 2
...

Sheet MAYHUASCA DORIS
B3: MAYHUASCA BASTIDAS DORIS
A5: FECHA | B5: DOCUMENTO | C5: PERIODO | D5: CONCEPTO | E5: POR COBRAR | F5: PAGADO | G5: SALDO POR COBRAR
A6: 42736 | B6: SALDO AL 2016 | G6: 438.1
A7: 42737 | B7: 12000 | C7: A CUENTA DEL 2016 | F7: 41.5 | G7: =+G6+E7-F7 -> 396.6
A8: 42744 | B8: 12052 | C8: A CUENTA DEL 2016 | F8: 300 | G8: =+G7+E8-F8 -> 96.6
A9: 42752 | B9: 12106 | C9: A CUENTA DEL 2016 | F9: 16.6 | G9: =+G8+E9-F9 -> 80
A10: 42830 | B10: 12489 | C10: CANCELACION DEL 2016 | F10: 80 | G10: =+G9+E10-F10 -> 0
A11: 42766 | B11: POR COBRAR | C11: ENERO | D11: LUZ | E11: 13.5 | G11: =+G10+E11-F11 -> 13.5
D12: AGUA | E12: 2.8 | G12: =+G11+E12-F12 -> 16.3
D13: ALQUILER | E13: 300 | G13: =+G12+E13-F13 -> 316.3
A14: 42800 | B14: 12343 | C14: ENERO | D14: LUZ | F14: 13.5 | G14: =+G13+E14-F14 -> 302.8
A15: 42800 | B15: 12343 | C15: ENERO | D15: AGUA | F15: 2.8 | G15: =+G14+E15-F15 -> 300
A16: 42779 | B16: 12253 | C16: ENERO | D16: ALQUILER | F16: 300 | G16: =+G15+E16-F16 -> 0
A17: 42794 | B17: POR COBRAR | C17: FEBRERO | D17: LUZ | E17: 13 | G17: =+G16+E17-F17 -> 13
D18: AGUA | E18: 2 | G18: =+G17+E18-F18 -> 15
D19: ALQUILER | E19: 300 | G19: =+G18+E19-F19 -> 315
A20: 42800 | B20: 12343 | C20: FEBRERO | D20: ALQUILER | F20: 300 | G20: =+G19+E20-F20 -> 15
A21: 42817 | B21: 12437 | C21: FEBRERO | D21: LUZ | F21: 13 | G21: =+G20+E21-F21 -> 2
A22: 42817 | B22: 12437 | C22: FEBRERO | D22: AGUA | F22: 2 | G22: =+G21+E22-F22 -> 0
A23: 42825 | B23: POR COBRAR | C23: MARZO | D23: LUZ | E23: 12 | G23: =+G22+E23-F23 -> 12
D24: AGUA | E24: 2 | G24: =+G23+E24-F24 -> 14
D25: ALQUILER | E25: 300 | G25: =+G24+E25-F25 -> 314
A26: 42830 | B26: 12489 | C26: MARZO | D26: ALQUILER | F26: 300 | G26: =+G25+E26-F26 -> 14
A27: 42846 | B27: 12566 | C27: MARZO | D27: LUZ | F27: 12 | G27: =+G26+E27-F27 -> 2
A28: 42846 | B28: 12566 | C28: MARZO | D28: AGUA | F28: 2 | G28: =+G27+E28-F28 -> 0
A29: 42855 | B29: POR COBRAR | C29: ABRIL | D29: LUZ | E29: 13 | G29: =+G28+E29-F29 -> 13
D30: AGUA | E30: 2 | G30: =+G29+E30-F30 -> 15
D31: ALQUILER | E31: 300 | G31: =+G30+E31-F31 -> 315
A32: 42863 | B32: 12653 | C32: ABRIL | D32: ALQUILER | F32: 300 | G32: =+G31+E32-F32 -> 15
A33: 42881 | B33: 12713 | C33: ABRIL | D33: LUZ | F33: 13 | G33: =+G32+E33-F33 -> 2
A34: 42881 | B34: 12713 | C34: ABRIL | D34: AGUA | F34: 2 | G34: =+G33+E34-F34 -> 0
A35: 42886 | B35: POR COBRAR | C35: MAYO | D35: LUZ | E35: 13 | G35: =+G34+E35-F35 -> 13
D36: AGUA | E36: 2 | G36: =+G35+E36-F36 -> 15
D37: ALQUILER | E37: 300 | G37: =+G36+E37-F37 -> 315
A38: 42891 | B38: 12780 | C38: MAYO | D38: ALQUILER | F38: 300 | G38: =+G37+E38-F38 -> 15
A39: 42921 | B39: 12955 | C39: MAYO | D39: LUZ | F39: 13 | G39: =+G38+E39-F39 -> 2
A40: 42921 | B40: 12955 | C40: MAYO | D40: AGUA | F40: 2 | G40: =+G39+E40-F40 -> 0
A41: 42946 | B41: POR COBRAR | C41: JUNIO | D41: LUZ | E41: 12.5 | G41: =+G40+E41-F41 -> 12.5
D42: AGUA | E42: 2 | G42: =+G41+E42-F42 -> 14.5
D43: ALQUILER | E43: 300 | G43: =+G42+E43-F43 -> 314.5
...

Sheet MIRANDA FELICITA
B3: MIRANDA CACERES FELICITA
A5: FECHA | B5: DOCUMENTO | C5: PERIODO | D5: CONCEPTO | E5: POR COBRAR | F5: PAGADO | G5: SALDO POR COBRAR
A6: 42736 | B6: SALDO AL 2016 | G6: 273.3
A7: 42738 | B7: 12008 | C7: A CUENTA DEL 2016 | F7: 150 | G7: =+G6+E7-F7 -> 123.3
A8: 42751 | B8: 12091 | C8: A CUENTA DEL 2016 | F8: 43.3 | G8: =+G7+E8-F8 -> 80
A9: 42831 | B9: 12488 | C9: A CUENTA DEL 2016 | F9: 10 | G9: =+G8+E9-F9 -> 70
A10: 42858 | B10: 12606 | C10: A CUENTA DEL 2016 | F10: 10 | G10: =+G9+E10-F10 -> 60
A11: 42919 | B11: 12939 | C11: A CUENTA DEL 2016 | F11: 10 | G11: =+G10+E11-F11 -> 50
A12: 42947 | B12: 13072 | C12: A CUENTA DEL 2016 | F12: 10 | G12: =+G11+E12-F12 -> 40
A13: 43073 | B13: 13902 | C13: A CUENTA DEL 2016 | F13: 20 | G13: =+G12+E13-F13 -> 20
A14: 43098 | B14: 13999 | C14: CANCELACION DEL 2016 | F14: 20 | G14: =+G13+E14-F14 -> 0
A15: 42766 | B15: POR COBRAR | C15: ENERO | D15: LUZ | E15: 41.3 | G15: =+G14+E15-F15 -> 41.3
D16: AGUA | E16: 2.8 | G16: =+G15+E16-F16 -> 44.1
D17: ALQUILER | E17: 210 | G17: =+G16+E17-F17 -> 254.1
A18: 42800 | B18: 12345 | C18: ENERO | D18: ALQUILER | F18: 100 | G18: =+G17+E18-F18 -> 154.1
A19: 42786 | B19: 12279 | C19: ENERO | D19: LUZ | F19: 41.3 | G19: =+G18+E19-F19 -> 112.8
A20: 42786 | B20: 12779 | C20: ENERO | D20: AGUA | F20: 2.8 | G20: =+G19+E20-F20 -> 110
A21: 42786 | B21: 12779 | C21: ENERO | D21: ALQUILER | F21: 50 | G21: =+G20+E21-F21 -> 60
A22: 42751 | B22: 12091 | C22: ENERO | D22: ALQUILER | F22: 60 | G22: =+G21+E22-F22 -> 0
A23: 42794 | B23: POR COBRAR | C23: FEBRERO | D23: LUZ | E23: 50.6 | G23: =+G22+E23-F23 -> 50.6
D24: AGUA | E24: 2 | G24: =+G23+E24-F24 -> 52.6
D25: ALQUILER | E25: 210 | G25: =+G24+E25-F25 -> 262.6
A26: 42808 | B26: 12401 | C26: FEBRERO | D26: ALQUILER | F26: 100 | G26: =+G25+E26-F26 -> 162.6
A27: 42821 | B27: 12446 | C27: FEBRERO | D27: LUZ | F27: 50.6 | G27: =+G26+E27-F27 -> 112
A28: 42821 | B28: 12446 | C28: FEBRERO | D28: AGUA | F28: 2 | G28: =+G27+E28-F28 -> 110
A29: 42814 | B29: 12416 | C29: FEBRERO | D29: ALQUILER | F29: 110 | G29: =+G28+E29-F29 -> 0
A30: 42825 | B30: POR COBRAR | C30: MARZO | D30: LUZ | E30: 48.2 | G30: =+G29+E30-F30 -> 48.2
D31: AGUA | E31: 2 | G31: =+G30+E31-F31 -> 50.2
D32: ALQUILER | E32: 210 | G32: =+G31+E32-F32 -> 260.2
A33: 42821 | B33: 12446 | C33: MARZO | D33: ALQUILER | F33: 60 | G33: =+G32+E33-F33 -> 200.2
A34: 42828 | B34: 12472 | C34: MARZO | D34: ALQUILER | F34: 100 | G34: =+G33+E34-F34 -> 100.2
A35: 42831 | B35: 12488 | C35: MARZO | D35: ALQUILER | F35: 50 | G35: =+G34+E35-F35 -> 50.2
A36: 42844 | B36: 12556 | C36: MARZO | D36: LUZ | F36: 48.2 | G36: =+G35+E36-F36 -> 2
A37: 42844 | B37: 12556 | C37: MARZO | D37: AGUA | F37: 2 | G37: =+G36+E37-F37 -> -1.4210855e-14
A38: 42855 | B38: POR COBRAR | C38: ABRIL | D38: LUZ | E38: 49.6 | G38: =+G37+E38-F38 -> 49.6
D39: AGUA | E39: 2 | G39: =+G38+E39-F39 -> 51.6
D40: ALQUILER | E40: 210 | G40: =+G39+E40-F40 -> 261.6
A41: 42844 | B41: 12556 | C41: ABRIL | D41: ALQUILER | F41: 60 | G41: =+G40+E41-F41 -> 201.6
A42: 42858 | B42: 12606 | C42: ABRIL | D42: ALQUILER | F42: 150 | G42: =+G41+E42-F42 -> 51.6
A43: 42877 | B43: 12703 | C43: ABRIL | D43: LUZ | F43: 49.6 | G43: =+G42+E43-F43 -> 2
...

Sheet MUJICA SANDRA 
B3: MUJICA PALOMINO SANDRA
A5: FECHA | B5: DOCUMENTO | C5: PERIODO | D5: CONCEPTO | E5: POR COBRAR | F5: PAGADO | G5: SALDO POR COBRAR
A6: 42736 | B6: SALDO AL 2016 | G6: 674.2
A7: 42795 | B7: 12309 | C7: A CUENTA DEL 2016 | F7: 370 | G7: =+G6+E7-F7 -> 304.2
A8: 42797 | B8: 12328 | C8: A CUENTA DEL 2016 | F8: 4.2 | G8: =+G7+E8-F8 -> 300
A9: 42766 | B9: 12173 | C9: A CUENTA DEL 2016 | F9: 300 | G9: =+G8+E9-F9 -> 0
A10: 42766 | B10: POR COBRAR | C10: ENERO | D10: LUZ | E10: 34.5 | G10: =+G9+E10-F10 -> 34.5
D11: AGUA | E11: 2.8 | G11: =+G10+E11-F11 -> 37.3
D12: ALQUILER | E12: 300 | G12: =+G11+E12-F12 -> 337.3
A13: 42795 | B13: 12309 | C13: ENERO | D13: ALQUILER | F13: 300 | G13: =+G12+E13-F13 -> 37.3
A14: 42797 | B14: 12328 | C14: ENERO | D14: LUZ | F14: 34.5 | G14: =+G13+E14-F14 -> 2.8
D15: AGUA | F15: 2.8 | G15: =+G14+E15-F15 -> 1.1546319e-14
A16: 42794 | B16: POR COBRAR | C16: FEBRERO | D16: LUZ | E16: 28.5 | G16: =+G15+E16-F16 -> 28.5
D17: AGUA | E17: 2 | G17: =+G16+E17-F17 -> 30.5
D18: ALQUILER | E18: 300 | G18: =+G17+E18-F18 -> 330.5
A19: 42800 | B19: 12334 | C19: FEBRERO | D19: ALQUILER | F19: 20 | G19: =+G18+E19-F19 -> 310.5
A20: 42800 | B20: 12349 | C20: FEBRERO | D20: ALQUILER | F20: 20 | G20: =+G19+E20-F20 -> 290.5
A21: 42802 | B21: 12366 | C21: FEBRERO | D21: ALQUILER | F21: 20 | G21: =+G20+E21-F21 -> 270.5
A22: 42804 | B22: 12375 | C22: FEBRERO | D22: ALQUILER | F22: 20 | G22: =+G21+E22-F22 -> 250.5
A23: 42808 | B23: 12400 | C23: FEBRERO | D23: ALQUILER | F23: 20 | G23: =+G22+E23-F23 -> 230.5
A24: 42831 | B24: 12492 | C24: FEBRERO | D24: ALQUILER | F24: 200 | G24: =+G23+E24-F24 -> 30.5
A25: 42831 | B25: 12493 | C25: FEBRERO | D25: LUZ | F25: 20 | G25: =+G24+E25-F25 -> 10.5
A26: 42927 | B26: 12986 | C26: FEBRERO | D26: LUZ | F26: 8.5 | G26: =+G25+E26-F26 -> 2
A27: 42927 | B27: 12986 | C27: FEBRERO | D27: AGUA | F27: 2 | G27: =+G26+E27-F27 -> 0
A28: 42825 | B28: POR COBRAR | C28: MARZO | D28: LUZ | E28: 26.9 | G28: =+G27+E28-F28 -> 26.9
D29: AGUA | E29: 2 | G29: =+G28+E29-F29 -> 28.9
D30: ALQUILER | E30: 300 | G30: =+G29+E30-F30 -> 328.9
A31: 42859 | B31: 12628 | C31: MARZO | D31: ALQUILER | F31: 250 | G31: =+G30+E31-F31 -> 78.9
A32: 42885 | B32: 12726 | C32: MARZO | D32: ALQUILER | F32: 50 | G32: =+G31+E32-F32 -> 28.9
A33: 42927 | B33: 12986 | C33: MARZO | D33: LUZ | F33: 26.9 | G33: =+G32+E33-F33 -> 2
A34: 42927 | B34: 12986 | C34: MARZO | D34: AGUA | F34: 2 | G34: =+G33+E34-F34 -> -2.1316282e-14
A35: 42855 | B35: POR COBRAR | C35: ABRIL | D35: LUZ | E35: 28.1 | G35: =+G34+E35-F35 -> 28.1
D36: AGUA | E36: 2 | G36: =+G35+E36-F36 -> 30.1
D37: ALQUILER | E37: 300 | G37: =+G36+E37-F37 -> 330.1
A38: 42885 | B38: 12726 | C38: ABRIL | D38: ALQUILER | F38: 50 | G38: =+G37+E38-F38 -> 280.1
A39: 42898 | B39: 12820 | C39: ABRIL | D39: ALQUILER | F39: 180 | G39: =+G38+E39-F39 -> 100.1
A40: 42916 | B40: 12908 | C40: ABRIL | D40: ALQUILER | F40: 70 | G40: =+G39+E40-F40 -> 30.1
A41: 42927 | B41: 12986 | C41: ABRIL | D41: LUZ | F41: 28.1 | G41: =+G40+E41-F41 -> 2
A42: 42927 | B42: 12986 | C42: ABRIL | D42: AGUA | F42: 2 | G42: =+G41+E42-F42 -> -3.5527137e-14
A43: 42886 | B43: POR COBRAR | C43: MAYO | D43: LUZ | E43: 32.8 | G43: =+G42+E43-F43 -> 32.8
...

Sheet OBREGON FERNANDO
B2: FERNANDO MARTIN OBREGON CASTILLO
A4: FECHA | B4: DOCUMENTO | C4: PERIODO | D4: CONCEPTO | E4: POR COBRAR | F4: PAGADO | G4: SALDO POR COBRAR
A6: 44926 | B6: POR COBRAR | C6: NOVIEMBRE | D6: GARANTIA | E6: 350 | G6: =G5+E6-F6 -> 350
D7: ALQUILER | E7: 350 | G7: =G6+E7-F7 -> 700
A8: 44865 | B8: EB01-1405 | C8: DICIEMBRE | D8: GARANTIA | F8: 350 | G8: =G7+E8-F8 -> 350
