Workbook
Name _Hlk159238530: 'CCENCHO DAVID'!$J$633

Sheet AIRE HECTOR
B3: AIRE MALPARTIDA HECTOR
A5: FECHA | B5: DOCUMENTO | C5: PERIODO | D5: CONCEPTO | E5: POR COBRAR | F5: PAGADO | G5: SALDO POR COBRAR
A6: 42736 | B6: SALDO AL 2016 | G6: 66.7
A7: 42766 | B7: 12184 | C7: A CUENTA 2016 | F7: 66.7 | G7: =+G6+E7-F7 -> 0
A8: 42766 | B8: POR COBRAR | C8: ENERO | D8: LUZ | E8: 66.8 | G8: =+G7+E8-F8 -> 66.8
D9: AGUA | E9: 2.8 | G9: =+G8+E9-F9 -> 69.6
D10: ALQUILER | E10: 450 | G10: =+G9+E10-F10 -> 519.6
A11: 42766 | B11: 12184 | C11: ENERO | D11: ALQUILER | F11: 450 | G11: =+G10+E11-F11 -> 69.6
A12: 42796 | B12: 12321 | C12: ENERO | D12: LUZ | F12: 66.8 | G12: =+G11+E12-F12 -> 2.8
A13: 42796 | B13: 12321 | C13: ENERO | D13: AGUA | F13: 2.8 | G13: =+G12+E13-F13 -> 2.5757174e-14
A14: 42794 | B14: POR COBRAR | C14: FEBRERO | D14: LUZ | E14: 94.8 | G14: =+G13+E14-F14 -> 94.8
D15: AGUA | E15: 2 | G15: =+G14+E15-F15 -> 96.8
D16: ALQUILER | E16: 450 | G16: =+G15+E16-F16 -> 546.8
A17: 42796 | B17: 12320 | C17: FEBRERO | D17: ALQUILER | F17: 450 | G17: =+G16+E17-F17 -> 96.8
A18: 42832 | B18: 12498 | C18: FEBRERO | D18: LUZ | F18: 94.8 | G18: =+G17+E18-F18 -> 2
A19: 42832 | B19: 12498 | C19: FEBRERO | D19: AGUA | F19: 2 | G19: =+G18+E19-F19 -> 7.1054274e-14
A20: 42825 | B20: POR COBRAR | C20: MARZO | D20: LUZ | E20: 69.5 | G20: =+G19+E20-F20 -> 69.5
D21: AGUA | E21: 2 | G21: =+G20+E21-F21 -> 71.5
D22: ALQUILER | E22: 450 | G22: =+G21+E22-F22 -> 521.5
A23: 42832 | B23: 12499 | C23: MARZO | D23: ALQUILER | F23: 450 | G23: =+G22+E23-F23 -> 71.5
A24: 42886 | B24: 12753 | C24: MARZO | D24: LUZ | F24: 69.5 | G24: =+G23+E24-F24 -> 2
A25: 42886 | B25: 12753 | C25: MARZO | D25: AGUA | F25: 2 | G25: =+G24+E25-F25 -> 1.1368684e-13
A26: 42855 | B26: POR COBRAR | C26: ABRIL | D26: LUZ | E26: 43.1 | G26: =+G25+E26-F26 -> 43.1
D27: AGUA | E27: 2 | G27: =+G26+E27-F27 -> 45.1
D28: ALQUILER | E28: 450 | G28: =+G27+E28-F28 -> 495.1
A29: 42886 | B29: 12753 | C29: ABRIL | D29: ALQUILER | F29: 450 | G29: =+G28+E29-F29 -> 45.1
A30: 42886 | B30: 12753 | C30: ABRIL | D30: LUZ | F30: 43.1 | G30: =+G29+E30-F30 -> 2
A31: 42886 | B31: 12753 | C31: ABRIL | D31: AGUA | F31: 2 | G31: =+G30+E31-F31 -> 1.3500312e-13
A32: 42886 | B32: POR COBRAR | C32: MAYO | D32: LUZ | E32: 66.5 | G32: =+G31+E32-F32 -> 66.5
D33: AGUA | E33: 2 | G33: =+G32+E33-F33 -> 68.5
D34: ALQUILER | E34: 450 | G34: =+G33+E34-F34 -> 518.5
A35: 42930 | B35: 13015 | C35: MAYO | D35: ALQUILER | F35: 450 | G35: =+G34+E35-F35 -> 68.5
A36: 42930 | B36: 13015 | C36: MAYO | D36: LUZ | F36: 66.5 | G36: =+G35+E36-F36 -> 2
A37: 42930 | B37: 13015 | C37: MAYO | D37: AGUA | F37: 2 | G37: =+G36+E37-F37 -> 1.1368684e-13
A38: 42916 | B38: POR COBRAR | C38: JUNIO | D38: LUZ | E38: 64.9 | G38: =+G37+E38-F38 -> 64.9
D39: AGUA | E39: 2 | G39: =+G38+E39-F39 -> 66.9
D40: ALQUILER | E40: 450 | G40: =+G39+E40-F40 -> 516.9
A41: 42930 | B41: 13015 | C41: JUNIO | D41: ALQUILER | F41: 450 | G41: =+G40+E41-F41 -> 66.9
A42: 42956 | B42: 13251 | C42: JUNIO | D42: LUZ | F42: 64.9 | G42: =+G41+E42-F42 -> 2
A43: 42956 | B43: 13251 | C43: JUNIO | D43: AGUA | F43: 2 | G43: =+G42+E43-F43 -> 8.5265128e-14
...

Sheet ALARCON MARTHA
B3: ALARCON ESPINOZA MARTHA
A5: FECHA | B5: DOCUMENTO | C5: PERIODO | D5: CONCEPTO | E5: POR COBRAR | F5: PAGADO | G5: SALDO POR COBRAR
A6: 42736 | B6: SALDO AL 2016 | G6: 283.1
A7: 42751 | B7: 12095 | C7: CANCELACION DEL 2016 | F7: 283.1 | G7: =+G6+E7-F7 -> 0
A8: 42766 | B8: POR COBRAR | C8: ENERO | D8: LUZ | E8: 13.5 | G8: =+G7+E8-F8 -> 13.5
D9: AGUA | E9: 2.8 | G9: =+G8+E9-F9 -> 16.3
D10: ALQUILER | E10: 500 | G10: =+G9+E10-F10 -> 516.3
A11: 42766 | B11: 12180 | C11: ENERO | D11: ALQUILER | F11: 250 | G11: =+G10+E11-F11 -> 266.3
A12: 42783 | B12: 12272 | C12: ENERO | D12: ALQUILER | F12: 250 | G12: =+G11+E12-F12 -> 16.3
A13: 42832 | B13: 12500 | C13: ENERO | D13: LUZ | F13: 13.5 | G13: =+G12+E13-F13 -> 2.8
A14: 42832 | B14: 12500 | C14: ENERO | D14: AGUA | F14: 2.8 | G14: =+G13+E14-F14 -> -4.5297099e-14
A15: 42794 | B15: POR COBRAR | C15: FEBRERO | D15: LUZ | E15: 13 | G15: =+G14+E15-F15 -> 13
D16: AGUA | E16: 2 | G16: =+G15+E16-F16 -> 15
D17: ALQUILER | E17: 500 | G17: =+G16+E17-F17 -> 515
A18: 42796 | B18: 12318 | C18: FEBRERO | D18: ALQUILER | F18: 500 | G18: =+G17+E18-F18 -> 15
A19: 42832 | B19: 12500 | C19: FEBRERO | D19: LUZ | F19: 13 | G19: =+G18+E19-F19 -> 2
A20: 42832 | B20: 12500 | C20: FEBRERO | D20: AGUA | F20: 2 | G20: =+G19+E20-F20 -> 0
A21: 42825 | B21: POR COBRAR | C21: MARZO | D21: LUZ | E21: 12 | G21: =+G20+E21-F21 -> 12
D22: AGUA | E22: 2 | G22: =+G21+E22-F22 -> 14
D23: ALQUILER | E23: 500 | G23: =+G22+E23-F23 -> 514
A24: 42831 | B24: 12485 | C24: MARZO | D24: ALQUILER | F24: 500 | G24: =+G23+E24-F24 -> 14
A25: 42847 | B25: 12568 | C25: MARZO | D25: LUZ | F25: 12 | G25: =+G24+E25-F25 -> 2
A26: 42847 | B26: 12568 | C26: MARZO | D26: AGUA | F26: 2 | G26: =+G25+E26-F26 -> 0
A27: 42855 | B27: POR COBRAR | C27: ABRIL | D27: LUZ | E27: 13 | G27: =+G26+E27-F27 -> 13
D28: AGUA | E28: 2 | G28: =+G27+E28-F28 -> 15
D29: ALQUILER | E29: 500 | G29: =+G28+E29-F29 -> 515
A30: 42840 | B30: 12539 | C30: ABRIL | D30: ALQUILER | F30: 500 | G30: =+G29+E30-F30 -> 15
A31: 42887 | B31: 12761 | C31: ABRIL | D31: LUZ | F31: 13 | G31: =+G30+E31-F31 -> 2
A32: 42887 | B32: 12761 | C32: ABRIL | D32: AGUA | F32: 2 | G32: =+G31+E32-F32 -> 0
A33: 42886 | B33: POR COBRAR | C33: MAYO | D33: LUZ | E33: 13 | G33: =+G32+E33-F33 -> 13
D34: AGUA | E34: 2 | G34: =+G33+E34-F34 -> 15
D35: ALQUILER | E35: 500 | G35: =+G34+E35-F35 -> 515
A36: 42870 | B36: 12683 | C36: MAYO | D36: ALQUILER | F36: 500 | G36: =+G35+E36-F36 -> 15
A37: 42947 | B37: 13064 | C37: MAYO | D37: LUZ | F37: 13 | G37: =+G36+E37-F37 -> 2
A38: 42947 | B38: 13064 | C38: MAYO | D38: AGUA | F38: 2 | G38: =+G37+E38-F38 -> 0
A39: 42916 | B39: POR COBRAR | C39: JUNIO | D39: LUZ | E39: 12.5 | G39: =+G38+E39-F39 -> 12.5
D40: AGUA | E40: 2 | G40: =+G39+E40-F40 -> 14.5
D41: ALQUILER | E41: 500 | G41: =+G40+E41-F41 -> 514.5
A42: 42902 | B42: 12837 | C42: JUNIO | D42: ALQUILER | F42: 500 | G42: =+G41+E42-F42 -> 14.5
A43: 42947 | B43: 13064 | C43: JUNIO | D43: LUZ | F43: 12.5 | G43: =+G42+E43-F43 -> 2
...

Sheet ALVARO GUSTAVO
B2: ALVARO HUAMANI GUSTAVO
A4: FECHA | B4: DOCUMENTO | C4: PERIODO | D4: CONCEPTO | E4: POR COBRAR | F4: PAGADO | G4: SALDO POR COBRAR
A6: 44804 | B6: POR COBRAR | C6: AGOSTO | D6: ALQUILER | E6: 300 | G6: =G5+E6-F6 -> 300
G7: =G6+E7-F7 -> 300
A8: 45142 | B8: EB01-1112 | C8: AGOSTO | D8: ALQUILER | F8: 300 | G8: =G7+E8-F8 -> 0
G9: =G8+E9-F9 -> 0
D10: LUZ | E10: 21.6 | G10: =G9+E10-F10 -> 21.6
D11: AGUA | E11: 7 | G11: =G10+E11-F11 -> 28.6
A12: 44956 | B12: RII 1360 | C12: AGOSTO | D12: LUZ | F12: 20 | G12: =G11+E12-F12 -> 8.6
A13: 45033 | B13: RII 1507 | C13: AGOSTO | D13: LUZ | F13: 1.6 | G13: =G12+E13-F13 -> 7
A14: 45033 | B14: RII 1507 | C14: AGOSTO | D14: AGUA | F14: 7 | G14: =G13+E14-F14 -> 0
A15: 44834 | B15: POR COBRAR | C15: SETIEMBRE | D15: ALQUILER | E15: 300 | G15: =G14+E15-F15 -> 300
D16: LUZ | E16: 25.5 | G16: =G15+E16-F16 -> 325.5
D17: AGUA | E17: 8.2 | G17: =G16+E17-F17 -> 333.7
A18: 44838 | B18: EB01-1327 | C18: SETIEMBRE | D18: ALQUILER | F18: 300 | G18: =G17+E18-F18 -> 33.7
A19: 45033 | B19: RII 1507 | C19: SETIEMBRE | D19: LUZ | F19: 25.5 | G19: =G18+E19-F19 -> 8.2
A20: 45033 | B20: RII 1507 | C20: SETIEMBRE | D20: AGUA | F20: 8.2 | G20: =G19+E20-F20 -> 0
A21: 44834 | B21: POR COBRAR | C21: OCTUBRE | D21: ALQUILER | E21: 300 | G21: =G20+E21-F21 -> 300
D22: LUZ | E22: 25.4 | G22: =G21+E22-F22 -> 325.4
D23: AGUA | E23: 4.9 | G23: =G22+E23-F23 -> 330.3
A24: 44895 | B24: EB01-1499 | C24: OCTUBRE | D24: ALQUILER | F24: 300 | G24: =G23+E24-F24 -> 30.3
A25: 45033 | B25: RII 1507 | C25: OCTUBRE | D25: LUZ | F25: 25.4 | G25: =G24+E25-F25 -> 4.9
A26: 45033 | B26: RII 1507 | C26: OCTUBRE | D26: AGUA | F26: 4.9 | G26: =G25+E26-F26 -> -4.4408921e-14
A27: 44834 | B27: POR COBRAR | C27: NOVIEMBRE | D27: LUZ | E27: 28.4 | G27: =G26+E27-F27 -> 28.4
D28: AGUA | E28: 6.3 | G28: =G27+E28-F28 -> 34.7
D29: ALQUILER | E29: 300 | G29: =G28+E29-F29 -> 334.7
A30: 44922 | B30: EB01-1589 | C30: NOVIEMBRE | D30: ALQUILER | F30: 300 | G30: =G29+E30-F30 -> 34.7
A31: 45033 | B31: RII 1507 | C31: NOVIEMBRE | D31: LUZ | F31: 28.4 | G31: =G30+E31-F31 -> 6.3
A32: 45033 | B32: RII 1507 | C32: NOVIEMBRE | D32: AGUA | F32: 6.3 | G32: =G31+E32-F32 -> -6.6613381e-14
A33: 44926 | B33: POR COBRAR | C33: DICIEMBRE | D33: LUZ | E33: 32.5 | G33: =G32+E33-F33 -> 32.5
D34: AGUA | E34: 5.7 | G34: =G33+E34-F34 -> 38.2
D35: ALQUILER | E35: 300 | G35: =G34+E35-F35 -> 338.2
A36: 44956 | B36: EB01-1701 | C36: DICIEMBRE | D36: ALQUILER | F36: 300 | G36: =G35+E36-F36 -> 38.2
A37: 45033 | B37: RII 1507 | C37: DICIEMBRE | D37: LUZ | F37: 32.5 | G37: =G36+E37-F37 -> 5.7
A38: 45033 | B38: RII 1507 | C38: DICIEMBRE | D38: AGUA | F38: 5.7 | G38: =G37+E38-F38 -> -6.8389738e-14
A39: 44926 | B39: POR COBRAR | C39: ENERO | D39: LUZ | E39: 35.5 | G39: =G38+E39-F39 -> 35.5
D40: AGUA | E40: 4.8 | G40: =G39+E40-F40 -> 40.3
D41: ALQUILER | E41: 300 | G41: =G40+E41-F41 -> 340.3
A42: 44985 | B42: EB01-1812 | C42: ENERO | D42: ALQUILER | F42: 300 | G42: =G41+E42-F42 -> 40.3
A43: 45033 | B43: RII 1507 | C43: ENERO | D43: LUZ | F43: 35.5 | G43: =G42+E43-F43 -> 4.8
...

Sheet ALVAREZ EDGAR
B3: ALVAREZ CHIARA EDGAR SALVADOR
A5: FECHA | B5: DOCUMENTO | C5: PERIODO | D5: CONCEPTO | E5: POR COBRAR | F5: PAGADO | G5: SALDO POR COBRAR
A6: 42736 | B6: SALDO AL 2016 | G6: 766.5
A7: 42767 | B7: 12192 | C7: A CUENTA DEL 2016 | F7: 16.5 | G7: =+G6+E7-F7 -> 750
A8: 42859 | B8: 12623 | C8: A CUENTA DEL 2016 | F8: 80 | G8: =+G7+E8-F8 -> 670
A9: 42898 | B9: 12815 | C9: A CUENTA DEL 2016 | F9: 110 | G9: =+G8+E9-F9 -> 560
A10: 42916 | B10: 12897 | C10: A CUENTA DEL 2016 | F10: 70 | G10: =+G9+E10-F10 -> 490
A11: 42947 | B11: 13076 | C11: A CUENTA DEL 2016 | F11: 200 | G11: =+G10+E11-F11 -> 290
A12: 42979 | B12: 13361 | C12: A CUENTA DEL 2016 | F12: 170 | G12: =+G11+E12-F12 -> 120
A13: 43008 | B13: 13559 | C13: A CUENTA DEL 2016 | F13: 90 | G13: =+G12+E13-F13 -> 30
A14: 43039 | B14: 13730 | C14: A CUENTA DEL 2016 | F14: 30 | G14: =+G13+E14-F14 -> 0
A15: 42766 | B15: POR COBRAR | C15: ENERO | D15: LUZ | E15: 13.5 | G15: =+G14+E15-F15 -> 13.5
D16: AGUA | E16: 2.8 | G16: =+G15+E16-F16 -> 16.3
D17: ALQUILER | E17: 300 | G17: =+G16+E17-F17 -> 316.3
A18: 42767 | B18: 12192 | C18: ENERO | D18: ALQUILER | F18: 300 | G18: =+G17+E18-F18 -> 16.3
A19: 42797 | B19: 12324 | C19: ENERO | D19: LUZ | F19: 13.5 | G19: =+G18+E19-F19 -> 2.8
A20: 42797 | B20: 12324 | C20: ENERO | D20: AGUA | F20: 2.8 | G20: =+G19+E20-F20 -> 1.1546319e-14
A21: 42794 | B21: POR COBRAR | C21: FEBRERO | D21: LUZ | E21: 21.8 | G21: =+G20+E21-F21 -> 21.8
D22: AGUA | E22: 2 | G22: =+G21+E22-F22 -> 23.8
D23: ALQUILER | E23: 300 | G23: =+G22+E23-F23 -> 323.8
A24: 42797 | B24: 12324 | C24: FEBRERO | D24: ALQUILER | F24: 300 | G24: =+G23+E24-F24 -> 23.8
A25: 42828 | B25: 12462 | C25: FEBRERO | D25: LUZ | F25: 21.8 | G25: =+G24+E25-F25 -> 2
A26: 42828 | B26: 12462 | C26: FEBRERO | D26: AGUA | F26: 2 | G26: =+G25+E26-F26 -> 1.0658141e-14
A27: 42825 | B27: POR COBRAR | C27: MARZO | D27: LUZ | E27: 20.5 | G27: =+G26+E27-F27 -> 20.5
D28: AGUA | E28: 2 | G28: =+G27+E28-F28 -> 22.5
D29: ALQUILER | E29: 300 | G29: =+G28+E29-F29 -> 322.5
A30: 42828 | B30: 12462 | C30: MARZO | D30: ALQUILER | F30: 300 | G30: =+G29+E30-F30 -> 22.5
A31: 42857 | B31: 12583 | C31: MARZO | D31: LUZ | F31: 20.5 | G31: =+G30+E31-F31 -> 2
A32: 42857 | B32: 12583 | C32: MARZO | D32: AGUA | F32: 2 | G32: =+G31+E32-F32 -> 0
A33: 42855 | B33: POR COBRAR | C33: ABRIL | D33: LUZ | E33: 21.6 | G33: =+G32+E33-F33 -> 21.6
D34: AGUA | E34: 2 | G34: =+G33+E34-F34 -> 23.6
D35: ALQUILER | E35: 300 | G35: =+G34+E35-F35 -> 323.6
A36: 42857 | B36: 12583 | C36: ABRIL | D36: ALQUILER | F36: 300 | G36: =+G35+E36-F36 -> 23.6
A37: 42887 | B37: 12758 | C37: ABRIL | D37: LUZ | F37: 21.6 | G37: =+G36+E37-F37 -> 2
A38: 42887 | B38: 12758 | C38: ABRIL | D38: AGUA | F38: 2 | G38: =+G37+E38-F38 -> 2.1316282e-14
A39: 42886 | B39: POR COBRAR | C39: MAYO | D39: LUZ | E39: 20.9 | G39: =+G38+E39-F39 -> 20.9
D40: AGUA | E40: 2 | G40: =+G39+E40-F40 -> 22.9
D41: ALQUILER | E41: 300 | G41: =+G40+E41-F41 -> 322.9
A42: 42887 | B42: 12758 | C42: MAYO | D42: ALQUILER | F42: 300 | G42: =+G41+E42-F42 -> 22.9
A43: 42919 | B43: 12933 | C43: MAYO | D43: LUZ | F43: 20.9 | G43: =+G42+E43-F43 -> 2
...

Sheet ALVAREZ FLORENCIA
A2: ALVAREZ BERRIO FLORENCIA | I2: DNI | J2: 8877133 | K2: 10 DE CADA MES
A3: FECHA | B3: DOCUMENTO | C3: PERIODO | D3: CONCEPTO | E3: POR COBRAR | F3: PAGADO | G3: SALDO POR COBRAR
A5: 46053 | B5: POR COBRAR | C5: ENERO | D5: LUZ | E5: 14.3 | G5: =+G4+E5-F5 -> 14.3
D6: AGUA | E6: 3 | G6: =+G5+E6-F6 -> 17.3
D7: ALQUILER | E7: 700 | G7: =+G6+E7-F7 -> 717.3
D8: GARANTIA | E8: 1000 | G8: =+G7+E8-F8 -> 1717.3
D9: MULTA X CAPACITACION | E9: 28.3 | G9: =+G8+E9-F9 -> 1745.6
A10: 46032 | B10: RII 3183 | C10: ENERO | D10: GARANTIA | F10: 1000 | G10: =+G9+E10-F10 -> 745.6
A11: 46032 | B11: EB01-6648 | C11: ENERO | D11: ALQUILER | F11: 700 | G11: =+G10+E11-F11 -> 45.6 | I11: ALVAREZ BERRIO FLORENCIA
A12: 46090 | B12: RII 3291 | C12: ENERO | D12: LUZ | F12: 14.3 | G12: =+G11+E12-F12 -> 31.3 | I12: 2026 | J12: ENERO | K12: MULTA X CAPACITACION
A13: 46090 | B13: RII 3291 | C13: ENERO | D13: AGUA | F13: 3 | G13: =+G12+E13-F13 -> 28.3 | J13: FEBRERO | K13: LUZ | L13: 20.2
A14: 46081 | B14: POR COBRAR | C14: FEBRERO | D14: LUZ | E14: 20.2 | G14: =+G13+E14-F14 -> 48.5 | K14: AGUA | L14: 6
D15: AGUA | E15: 6 | G15: =+G14+E15-F15 -> 54.5 | J15: MARZO | K15: LUZ | L15: 19.7
D16: ALQUILER | E16: 700 | G16: =+G15+E16-F16 -> 754.5 | K16: AGUA | L16: 6
A17: 46091 | B17: EB01-7000 | C17: FEBRERO | D17: ALQUILER | F17: 600 | G17: =+G16+E17-F17 -> 154.5 | K17: 100 | L17: =SUM(L12:L16) -> 51.9 | M17: =K17-L17 -> 48.1
A18: 46104 | B18: EB01-7061 | C18: FEBRERO | D18: ALQUILER | F18: 100 | G18: =+G17+E18-F18 -> 54.5
A19: 46140 | B19: RII 3374 | C19: FEBRERO | D19: LUZ | F19: 20.2 | G19: =+G18+E19-F19 -> 34.3
A20: 46140 | B20: RII 3374 | C20: FEBRERO | D20: AGUA | F20: 6 | G20: =+G19+E20-F20 -> 28.3
A21: 46112 | B21: POR COBRAR | C21: MARZO | D21: LUZ | E21: 19.7 | G21: =+G20+E21-F21 -> 48
D22: AGUA | E22: 6 | G22: =+G21+E22-F22 -> 54
D23: ALQUILER | E23: 700 | G23: =+G22+E23-F23 -> 754
A24: 46128 | B24: EB01-7211 | C24: MARZO | D24: ALQUILER | F24: 700 | G24: =+G23+E24-F24 -> 54
A25: 46140 | B25: RII 3374 | C25: MARZO | D25: LUZ | F25: 19.7 | G25: =+G24+E25-F25 -> 34.3
A26: 46140 | B26: RII 3374 | C26: MARZO | D26: AGUA | F26: 6 | G26: =+G25+E26-F26 -> 28.3
A27: 46142 | B27: POR COBRAR | C27: ABRIL | D27: LUZ | G27: =+G26+E27-F27 -> 28.3
D28: AGUA | G28: =+G27+E28-F28 -> 28.3
D29: ALQUILER | E29: 700 | G29: =+G28+E29-F29 -> 728.3
G30: =+G29+E30-F30 -> 728.3
G31: =+G30+E31-F31 -> 728.3
G32: =+G31+E32-F32 -> 728.3
G33: =+G32+E33-F33 -> 728.3
G34: =+G33+E34-F34 -> 728.3
G35: =+G34+E35-F35 -> 728.3
G36: =+G35+E36-F36 -> 728.3
G37: =+G36+E37-F37 -> 728.3
G38: =+G37+E38-F38 -> 728.3
G39: =+G38+E39-F39 -> 728.3
G40: =+G39+E40-F40 -> 728.3
G41: =+G40+E41-F41 -> 728.3
... G107: =+G106+E107-F107 -> 728.3

Sheet ANCHAYA ABEL
B2: ABEL ANCHAYA HUAMAN
A4: FECHA | B4: DOCUMENTO | C4: PERIODO | D4: CONCEPTO | E4: POR COBRAR | F4: PAGADO | G4: SALDO POR COBRAR
A6: 44681 | B6: POR COBRAR | C6: ABRIL | D6: ALQUILER | E6: 700 | G6: =G5+E6-F6 -> 700
D7: GARANTIA | E7: 700 | G7: =G6+E7-F7 -> 1400
A8: 44663 | B8: EB01-690 | C8: MARZO | D8: ALQUILER | F8: 700 | G8: =G7+E8-F8 -> 700
A9: 44663 | B9: EB01-689 | C9: MARZO | D9: GARANTIA | F9: 700 | G9: =G8+E9-F9 -> 0
D10: LUZ | E10: 51.7 | G10: =G9+E10-F10 -> 51.7
D11: AGUA | E11: 2.8 | G11: =G10+E11-F11 -> 54.5
A12: 44764 | B12: RII 1131 | C12: MARZO | D12: LUZ | F12: 51.7 | G12: =G11+E12-F12 -> 2.8
A13: 44764 | B13: RII 1131 | C13: MARZO | D13: AGUA | F13: 2.8 | G13: =G12+E13-F13 -> 0
A14: 44712 | B14: POR COBRAR | C14: MAYO | D14: LUZ | E14: 49.4 | G14: =G13+E14-F14 -> 49.4
D15: AGUA | E15: 9.1 | G15: =G14+E15-F15 -> 58.5
D16: ALQUILER | E16: 700 | G16: =G15+E16-F16 -> 758.5
D17: FUMIGACION | E17: 6 | G17: =G16+E17-F17 -> 764.5
A18: 44697 | B18: EB01-812 | C18: MAYO | D18: ALQUILER | F18: 700 | G18: =G17+E18-F18 -> 64.5
A19: 44764 | B19: RII 1131 | C19: MAYO | D19: LUZ | F19: 49.4 | G19: =G18+E19-F19 -> 15.1
A20: 44764 | B20: RII 1131 | C20: MAYO | D20: AGUA | F20: 9.1 | G20: =G19+E20-F20 -> 6
A21: 45119 | B21: RII 1665 | C21: MAYO | D21: FUMIGACION | F21: 6 | G21: =G20+E21-F21 -> 0
A22: 44742 | B22: POR COBRAR | C22: JUNIO | D22: LUZ | E22: 47.9 | G22: =G21+E22-F22 -> 47.9
D23: AGUA | E23: 6.9 | G23: =G22+E23-F23 -> 54.8
D24: ALQUILER | E24: 700 | G24: =G23+E24-F24 -> 754.8
A25: 44730 | B25: EB01-926 | C25: JUNIO | D25: ALQUILER | F25: 700 | G25: =G24+E25-F25 -> 54.8
A26: 44898 | B26: RII 1305 | C26: JUNIO | D26: LUZ | F26: 47.9 | G26: =G25+E26-F26 -> 6.9
A27: 44898 | B27: RII 1305 | C27: JUNIO | D27: AGUA | F27: 6.9 | G27: =G26+E27-F27 -> -4.4408921e-14
A28: 44773 | B28: POR COBRAR | C28: JULIO | D28: LUZ | E28: 47.6 | G28: =G27+E28-F28 -> 47.6
D29: AGUA | E29: 9.7 | G29: =G28+E29-F29 -> 57.3
D30: ALQUILER | E30: 700 | G30: =G29+E30-F30 -> 757.3
A31: 44767 | B31: EB01-1052 | C31: JULIO | D31: ALQUILER | F31: 700 | G31: =G30+E31-F31 -> 57.3
A32: 44958 | B32: RII 1381 | C32: JULIO | D32: LUZ | F32: 47.6 | G32: =G31+E32-F32 -> 9.7
A33: 44958 | B33: RII 1381 | C33: JULIO | D33: AGUA | F33: 9.7 | G33: =G32+E33-F33 -> -4.6185278e-14
A34: 44804 | B34: POR COBRAR | C34: AGOSTO | D34: LUZ | E34: 47.9 | G34: =G33+E34-F34 -> 47.9
D35: AGUA | E35: 7 | G35: =G34+E35-F35 -> 54.9
D36: ALQUILER | E36: 700 | G36: =G35+E36-F36 -> 754.9
D37: TALONARIO SANTA ROSA | E37: 10 | G37: =G36+E37-F37 -> 764.9
A38: 44804 | B38: EB01-1182 | C38: AGOSTO | D38: ALQUILER | F38: 180 | G38: =G37+E38-F38 -> 584.9
A39: 44958 | B39: RII 1381 | C39: AGOSTO | D39: LUZ | F39: 47.9 | G39: =G38+E39-F39 -> 537
A40: 44958 | B40: RII 1381 | C40: AGOSTO | D40: AGUA | F40: 7 | G40: =G39+E40-F40 -> 530
A41: 45119 | B41: RII 1666 | C41: AGOSTO | D41: TALONARIO SANTA ROSA | F41: 10 | G41: =G40+E41-F41 -> 520
A42: 44039 | B42: EB01-2428 | C42: AGOSTO | D42: ALQUILER | F42: 500 | G42: =G41+E42-F42 -> 20
A43: 45153 | B43: EB01-2533 | C43: AGOSTO | D43: ALQUILER | F43: 19.999 | G43: =G42+E43-F43 -> 0.001
...

Sheet ARMESTAR JUANA 
B3: ARMESTAR GODOS JUANA JACKELYNE
A5: FECHA | B5: DOCUMENTO | C5: PERIODO | D5: CONCEPTO | E5: POR COBRAR | F5: PAGADO | G5: SALDO POR COBRAR
G6: =+E6-F6 -> 0
A7: 43285 | B7: POR COBRAR | C7: JULIO | D7: LUZ | E7: 52.6 | G7: =+G6+E7-F7 -> 52.6
D8: AGUA | E8: 5 | G8: =+G7+E8-F8 -> 57.6
D9: ALQUILER | E9: 300 | G9: =+G8+E9-F9 -> 357.6
D10: GARANTIA | E10: 300 | G10: =+G9+E10-F10 -> 657.6
A11: 43285 | B11: 14807 | C11: JULIO | D11: ALQUILER | F11: 300 | G11: =+G10+E11-F11 -> 357.6
A12: 43285 | B12: 14807 | C12: JULIO | D12: GARANTIA | F12: 300 | G12: =+G11+E12-F12 -> 57.6
A13: 43404 | B13: 15428 | C13: JULIO | D13: LUZ | F13: 52.6 | G13: =+G12+E13-F13 -> 5
A14: 43404 | B14: 15428 | C14: JULIO | D14: AGUA | F14: 5 | G14: =+G13+E14-F14 -> 2.1316282e-14
A15: 43343 | B15: POR COBRAR | C15: AGOSTO | D15: LUZ | E15: 67.5 | G15: =+G14+E15-F15 -> 67.5
D16: AGUA | E16: 5 | G16: =+G15+E16-F16 -> 72.5
D17: ALQUILER | E17: 300 | G17: =+G16+E17-F17 -> 372.5
A18: 43314 | B18: 14996 | C18: AGOSTO | D18: ALQUILER | F18: 105 | G18: =+G17+E18-F18 -> 267.5
A19: 43344 | B19: 15114 | C19: AGOSTO | D19: ALQUILER | F19: 130 | G19: =+G18+E19-F19 -> 137.5
A20: 43374 | B20: 15292 | C20: AGOSTO | D20: LUZ | F20: 67.5 | G20: =+G19+E20-F20 -> 70
A21: 43374 | B21: 15292 | C21: AGOSTO | D21: AGUA | F21: 5 | G21: =+G20+E21-F21 -> 65
A22: 43374 | B22: 15292 | C22: AGOSTO | D22: ALQUILER | F22: 65 | G22: =+G21+E22-F22 -> 0
A23: 43373 | B23: POR COBRAR | C23: SETIEMBRE | D23: LUZ | E23: 53.5 | G23: =+G22+E23-F23 -> 53.5
D24: AGUA | E24: 5 | G24: =+G23+E24-F24 -> 58.5
D25: ALQUILER | E25: 300 | G25: =+G24+E25-F25 -> 358.5
A26: 43374 | B26: 15292 | C26: SETIEMBRE | D26: ALQUILER | F26: 72.5 | G26: =+G25+E26-F26 -> 286
A27: 43404 | B27: 15428 | C27: SETIEMBRE | D27: ALQUILER | F27: 152.4 | G27: =+G26+E27-F27 -> 133.6
A28: 43434 | B28: 15528 | C28: SETIEMBRE | D28: ALQUILER | F28: 75.1 | G28: =+G27+E28-F28 -> 58.5
A29: 43434 | B29: 15528 | C29: SETIEMBRE | D29: LUZ | F29: 53.5 | G29: =+G28+E29-F29 -> 5
A30: 43434 | B30: 15528 | C30: SETIEMBRE | D30: AGUA | F30: 5 | G30: =+G29+E30-F30 -> 0
A31: 43404 | B31: POR COBRAR | C31: OCTUBRE | D31: LUZ | E31: 54 | G31: =+G30+E31-F31 -> 54
D32: AGUA | E32: 6 | G32: =+G31+E32-F32 -> 60
D33: ALQUILER | E33: 300 | G33: =+G32+E33-F33 -> 360
A34: 43434 | B34: 15528 | C34: OCTUBRE | D34: ALQUILER | F34: 36.4 | G34: =+G33+E34-F34 -> 323.6
A35: 43830 | B35: 15708 | C35: OCTUBRE | D35: ALQUILER | F35: 150 | G35: =+G34+E35-F35 -> 173.6
A36: 43496 | B36: 15865 | C36: OCTUBRE | D36: LUZ | F36: 54 | G36: =+G35+E36-F36 -> 119.6
A37: 43496 | B37: 15865 | C37: OCTUBRE | D37: AGUA | F37: 6 | G37: =+G36+E37-F37 -> 113.6
A38: 43496 | B38: 15865 | C38: OCTUBRE | D38: ALQUILER | F38: 113.6 | G38: =+G37+E38-F38 -> 0
A39: 43434 | B39: POR COBRAR | C39: NOVIEMBRE | D39: LUZ | E39: 55.4 | G39: =+G38+E39-F39 -> 55.4
D40: AGUA | E40: 6 | G40: =+G39+E40-F40 -> 61.4
D41: ALQUILER | E41: 300 | G41: =+G40+E41-F41 -> 361.4
A42: 43496 | B42: 15865 | C42: NOVIEMBRE | D42: ALQUILER | F42: 106.4 | G42: =+G41+E42-F42 -> 255
A43: 43524 | B43: 15981 | C43: NOVIEMBRE | D43: ALQUILER | F43: 193.9 | G43: =+G42+E43-F43 -> 61.1
...

Sheet AYALA MARLENE
B3: AYALA HUASHUAYO MARLENE
A5: FECHA | B5: DOCUMENTO | C5: PERIODO | D5: CONCEPTO | E5: POR COBRAR | F5: PAGADO | G5: SALDO POR COBRAR
A6: 42736 | B6: SALDO AL 2016 | G6: 75.4
A7: 42766 | B7: 12182 | C7: A CUENTA 2016 | F7: 75.4 | G7: =+G6+E7-F7 -> 0
A8: 42766 | B8: POR COBRAR | C8: ENERO | D8: LUZ | E8: 74.5 | G8: =+G7+E8-F8 -> 74.5
D9: AGUA | E9: 2.8 | G9: =+G8+E9-F9 -> 77.3
D10: ALQUILER | E10: 780 | G10: =+G9+E10-F10 -> 857.3
A11: 42766 | B11: 12182 | C11: ENERO | D11: ALQUILER | F11: 780 | G11: =+G10+E11-F11 -> 77.3
A12: 42819 | B12: 12441 | C12: ENERO | D12: LUZ | F12: 74.5 | G12: =+G11+E12-F12 -> 2.8
A13: 42819 | B13: 12441 | C13: ENERO | D13: AGUA | F13: 2.8 | G13: =+G12+E13-F13 -> -4.5297099e-14
A14: 42794 | B14: POR COBRAR | C14: FEBRERO | D14: LUZ | E14: 71.3 | G14: =+G13+E14-F14 -> 71.3
D15: AGUA | E15: 2 | G15: =+G14+E15-F15 -> 73.3
D16: ALQUILER | E16: 780 | G16: =+G15+E16-F16 -> 853.3
A17: 42819 | B17: 12441 | C17: FEBRERO | D17: LUZ | F17: 71.3 | G17: =+G16+E17-F17 -> 782
A18: 42819 | B18: 12441 | C18: FEBRERO | D18: AGUA | F18: 2 | G18: =+G17+E18-F18 -> 780
A19: 42819 | B19: 12442 | C19: FEBRERO | D19: ALQUILER | F19: 780 | G19: =+G18+E19-F19 -> 0
A20: 42825 | B20: POR COBRAR | C20: MARZO | D20: LUZ | E20: 67.7 | G20: =+G19+E20-F20 -> 67.7
D21: AGUA | E21: 2 | G21: =+G20+E21-F21 -> 69.7
D22: ALQUILER | E22: 780 | G22: =+G21+E22-F22 -> 849.7
A23: 42832 | B23: 12514 | C23: MARZO | D23: ALQUILER | F23: 780 | G23: =+G22+E23-F23 -> 69.7
A24: 42884 | B24: 12723 | C24: MARZO | D24: LUZ | F24: 67.7 | G24: =+G23+E24-F24 -> 2
A25: 42884 | B25: 12723 | C25: MARZO | D25: AGUA | F25: 2 | G25: =+G24+E25-F25 -> 4.2632564e-14
A26: 42855 | B26: POR COBRAR | C26: ABRIL | D26: LUZ | E26: 70.1 | G26: =+G25+E26-F26 -> 70.1
D27: AGUA | E27: 2 | G27: =+G26+E27-F27 -> 72.1
D28: ALQUILER | E28: 780 | G28: =+G27+E28-F28 -> 852.1
A29: 42884 | B29: 12723 | C29: ABRIL | D29: LUZ | F29: 70.1 | G29: =+G28+E29-F29 -> 782
A30: 42884 | B30: 12723 | C30: ABRIL | D30: AGUA | F30: 2 | G30: =+G29+E30-F30 -> 780
A31: 42872 | B31: 12687 | C31: ABRIL | D31: ALQUILER | F31: 780 | G31: =+G30+E31-F31 -> 0
A32: 42886 | B32: POR COBRAR | C32: MAYO | D32: LUZ | E32: 58.7 | G32: =+G31+E32-F32 -> 58.7
D33: AGUA | E33: 2 | G33: =+G32+E33-F33 -> 60.7
D34: ALQUILER | E34: 780 | G34: =+G33+E34-F34 -> 840.7
A35: 42905 | B35: 12852 | C35: MAYO | D35: ALQUILER | F35: 780 | G35: =+G34+E35-F35 -> 60.7
A36: 42905 | B36: 12853 | C36: MAYO | D36: LUZ | F36: 58.7 | G36: =+G35+E36-F36 -> 2
A37: 42905 | B37: 12853 | C37: MAYO | D37: AGUA | F37: 2 | G37: =+G36+E37-F37 -> 4.2632564e-14
A38: 42916 | B38: POR COBRAR | C38: JUNIO | D38: LUZ | E38: 57 | G38: =+G37+E38-F38 -> 57
D39: AGUA | E39: 2 | G39: =+G38+E39-F39 -> 59
D40: ALQUILER | E40: 780 | G40: =+G39+E40-F40 -> 839
A41: 42930 | B41: 13014 | C41: JUNIO | D41: ALQUILER | F41: 780 | G41: =+G40+E41-F41 -> 59
A42: 42961 | B42: 13265 | C42: JUNIO | D42: LUZ | F42: 57 | G42: =+G41+E42-F42 -> 2
A43: 42961 | B43: 13265 | C43: JUNIO | D43: AGUA | F43: 2 | G43: =+G42+E43-F43 -> 0
...

Sheet ARREDONDO GLADYS
B3: ARREDONDO GARCIA GLADYS
A5: FECHA | B5: DOCUMENTO | C5: PERIODO | D5: CONCEPTO | E5: POR COBRAR | F5: PAGADO | G5: SALDO POR COBRAR
A6: 42736 | B6: SALDO AL 2016 | G6: 363.1
A7: 42765 | B7: 12171 | C7: A CUENTA DEL 2016 | F7: 300 | G7: =+G6+E7-F7 -> 63.1
A8: 42767 | B8: 12200 | C8: A CUENTA DEL 2016 | F8: 43.1 | G8: =+G7+E8-F8 -> 20
A9: 43985 | B9: B001-0001371 | C9: A CUENTA DEL 2016 | F9: 20 | G9: =+G8+E9-F9 -> 0
A10: 42766 | B10: POR COBRAR | C10: ENERO | D10: LUZ | E10: 13.5 | G10: =+G9+E10-F10 -> 13.5
D11: AGUA | E11: 2.8 | G11: =+G10+E11-F11 -> 16.3
D12: ALQUILER | E12: 210 | G12: =+G11+E12-F12 -> 226.3
A13: 42859 | B13: 12622 | C13: ENERO | D13: ALQUILER | F13: 180 | G13: =+G12+E13-F13 -> 46.3
A14: 42898 | B14: 12816 | C14: ENERO | D14: ALQUILER | F14: 30 | G14: =+G13+E14-F14 -> 16.3
A15: 43013 | B15: 13607 | C15: ENERO | D15: LUZ | F15: 13.5 | G15: =+G14+E15-F15 -> 2.8
A16: 43013 | B16: 13607 | C16: ENERO | D16: AGUA | F16: 2.8 | G16: =+G15+E16-F16 -> 1.1546319e-14
A17: 42794 | B17: POR COBRAR | C17: FEBRERO | D17: LUZ | E17: 13 | G17: =+G16+E17-F17 -> 13
D18: AGUA | E18: 2 | G18: =+G17+E18-F18 -> 15
D19: ALQUILER | E19: 210 | G19: =+G18+E19-F19 -> 225
A20: 42898 | B20: 12816 | C20: FEBRERO | D20: ALQUILER | F20: 210 | G20: =+G19+E20-F20 -> 15
A21: 43013 | B21: 13607 | C21: FEBRERO | D21: LUZ | F21: 13 | G21: =+G20+E21-F21 -> 2
A22: 43013 | B22: 13607 | C22: FEBRERO | D22: LUZ | F22: 2 | G22: =+G21+E22-F22 -> 0
A23: 42825 | B23: POR COBRAR | C23: MARZO | D23: LUZ | E23: 12 | G23: =+G22+E23-F23 -> 12
D24: AGUA | E24: 2 | G24: =+G23+E24-F24 -> 14
D25: ALQUILER | E25: 210 | G25: =+G24+E25-F25 -> 224
A26: 42898 | B26: 12816 | C26: MARZO | D26: ALQUILER | F26: 30 | G26: =+G25+E26-F26 -> 194
A27: 42916 | B27: 12899 | C27: MARZO | D27: ALQUILER | F27: 180 | G27: =+G26+E27-F27 -> 14
A28: 43013 | B28: 13607 | C28: MARZO | D28: LUZ | F28: 12 | G28: =+G27+E28-F28 -> 2
A29: 43013 | B29: 13607 | C29: MARZO | D29: AGUA | F29: 2 | G29: =+G28+E29-F29 -> 0
A30: 42855 | B30: POR COBRAR | C30: ABRIL | D30: LUZ | E30: 13 | G30: =+G29+E30-F30 -> 13
D31: AGUA | E31: 2 | G31: =+G30+E31-F31 -> 15
D32: ALQUILER | E32: 210 | G32: =+G31+E32-F32 -> 225
A33: 42916 | B33: 12899 | C33: ABRIL | D33: ALQUILER | F33: 210 | G33: =+G32+E33-F33 -> 15
A34: 43013 | B34: 13607 | C34: ABRIL | D34: LUZ | F34: 4.8 | G34: =+G33+E34-F34 -> 10.2
A35: 43008 | B35: 13558 | C35: ABRIL | D35: LUZ | F35: 8.2 | G35: =+G34+E35-F35 -> 2
A36: 43008 | B36: 13558 | C36: ABRIL | D36: AGUA | F36: 2 | G36: =+G35+E36-F36 -> 0
A37: 42886 | B37: POR COBRAR | C37: MAYO | D37: LUZ | E37: 13 | G37: =+G36+E37-F37 -> 13
D38: AGUA | E38: 2 | G38: =+G37+E38-F38 -> 15
D39: ALQUILER | E39: 210 | G39: =+G38+E39-F39 -> 225
A40: 42916 | B40: 12899 | C40: MAYO | D40: ALQUILER | F40: 15 | G40: =+G39+E40-F40 -> 210
A41: 42947 | B41: 13077 | C41: MAYO | D41: ALQUILER | F41: 195 | G41: =+G40+E41-F41 -> 15
A42: 43008 | B42: 13558 | C42: MAYO | D42: LUZ | F42: 13 | G42: =+G41+E42-F42 -> 2
A43: 43008 | B43: 13558 | C43: MAYO | D43: AGUA | F43: 2 | G43: =+G42+E43-F43 -> 0
...

Sheet AVILA ROSA
B3: AVILA CHAVEZ ROSA
A5: FECHA | B5: DOCUMENTO | C5: PERIODO | D5: CONCEPTO | E5: POR COBRAR | F5: PAGADO
G6: 0
A7: 43196 | B7: POR COBRAR | C7: ABRIL | D7: LUZ | G7: =+G6+E7-F7 -> 0
D8: AGUA | G8: =+G7+E8-F8 -> 0
D9: ALQUILER | E9: 210 | G9: =+G8+E9-F9 -> 210
G10: =+G9+E10-F10 -> 210
D11: GUARDIANIA | E11: 60 | G11: =+G10+E11-F11 -> 270
A12: 43196 | B12: 14445 | C12: ABRIL | D12: ALQUILER | F12: 210 | G12: =+G11+E12-F12 -> 60
G13: =+G12+E13-F13 -> 60
A14: 43283 | B14: 14868 | C14: ABRIL | D14: GUARDIANIA | F14: 60 | G14: =+G13+E14-F14 -> 0
A15: 43250 | B15: POR COBRAR | C15: MAYO | D15: ALQUILER | E15: 210 | G15: =+G14+E15-F15 -> 210
D16: GUARDIANIA | E16: 60 | G16: =+G15+E16-F16 -> 270
A17: 43222 | B17: 14547 | C17: MAYO | D17: ALQUILER | F17: 210 | G17: =+G16+E17-F17 -> 60
A18: 43222 | B18: 14547 | C18: MAYO | D18: GUARDIANIA | F18: 60 | G18: =+G17+E18-F18 -> 0
A19: 43281 | B19: POR COBRAR | C19: JUNIO | D19: ALQUILER | E19: 210 | G19: =+G18+E19-F19 -> 210
D20: GUARDIANIA | E20: 60 | G20: =+G19+E20-F20 -> 270
A21: 43251 | B21: 14702 | C21: JUNIO | D21: ALQUILER | F21: 210 | G21: =+G20+E21-F21 -> 60
A22: 43251 | B22: 14702 | C22: JUNIO | D22: GUARDIANIA | F22: 60 | G22: =+G21+E22-F22 -> 0
A23: 43312 | B23: POR COBRAR | C23: JULIO | D23: ALQUILER | E23: 210 | G23: =+G22+E23-F23 -> 210
D24: GUARDIANIA | E24: 60 | G24: =+G23+E24-F24 -> 270
A25: 43283 | B25: 14868 | C25: JULIO | D25: ALQUILER | F25: 210 | G25: =+G24+E25-F25 -> 60
A26: 43283 | B26: 14868 | C26: JULIO | D26: GUARDIANIA | F26: 60 | G26: =+G25+E26-F26 -> 0
A27: 43343 | B27: POR COBRAR | C27: AGOSTO | D27: ALQUILER | E27: 210 | G27: =+G26+E27-F27 -> 210
D28: GUARDIANIA | E28: 60 | G28: =+G27+E28-F28 -> 270
A29: 43314 | B29: 14902 | C29: AGOSTO | D29: ALQUILER | F29: 210 | G29: =+G28+E29-F29 -> 60
A30: 43314 | B30: 14902 | C30: AGOSTO | D30: GUARDIANIA | F30: 60 | G30: =+G29+E30-F30 -> 0
A31: 43373 | B31: POR COBRAR | C31: SEPTIEMBRE | D31: ALQUILER | E31: 210 | G31: =+G30+E31-F31 -> 210
D32: GUARDIANIA | E32: 60 | G32: =+G31+E32-F32 -> 270
A33: 43346 | B33: 15137 | C33: SEPTIEMBRE | D33: ALQUILER | F33: 210 | G33: =+G32+E33-F33 -> 60
A34: 43346 | B34: 15137 | C34: SEPTIEMBRE | D34: GUARDIANIA | F34: 60 | G34: =+G33+E34-F34 -> 0
A35: 43404 | B35: POR COBRAR | C35: OCTUBRE | D35: ALQUILER | E35: 210 | G35: =+G34+E35-F35 -> 210
D36: GUARDIANIA | E36: 60 | G36: =+G35+E36-F36 -> 270
A37: 43374 | B37: 15251 | C37: OCTUBRE | D37: ALQUILER | F37: 210 | G37: =+G36+E37-F37 -> 60
A38: 43374 | B38: 15251 | C38: OCTUBRE | D38: GUARDIANIA | F38: 60 | G38: =+G37+E38-F38 -> 0
A39: 43434 | B39: POR COBRAR | C39: NOVIEMBRE | D39: ALQUILER | E39: 210 | G39: =+G38+E39-F39 -> 210
D40: GUARDIANIA | E40: 60 | G40: =+G39+E40-F40 -> 270
A41: 43404 | B41: 15386 | C41: NOVIEMBRE | D41: ALQUILER | F41: 210 | G41: =+G40+E41-F41 -> 60
A42: 43404 | B42: 15386 | C42: NOVIEMBRE | D42: GUARDIANIA | F42: 60 | G42: =+G41+E42-F42 -> 0
A43: 43465 | B43: POR COBRAR | C43: DICIEMBRE | D43: ALQUILER | E43: 210 | G43: =+G42+E43-F43 -> 210
...

Sheet AYALA HILARY
B2: AYALA ARIAS HILARY ESPERANZA | I2: COMENZO EN MARZO 2024 | J2: DNI | K2: 70543729
A4: FECHA | B4: DOCUMENTO | C4: PERIODO | D4: CONCEPTO | E4: POR COBRAR | F4: PAGADO | G4: SALDO POR COBRAR
A6: 45382 | B6: POR COBRAR | C6: MARZO | D6: LUZ | E6: 20.6 | G6: =G5+E6-F6 -> 20.6
D7: AGUA | E7: 5 | G7: =G6+E7-F7 -> 25.6
D8: ALQUILER | E8: 350 | G8: =G7+E8-F8 -> 375.6
D9: GARANTIA | E9: 350 | G9: =G8+E9-F9 -> 725.6
A10: 45344 | B10: EB01-3339 | C10: MARZO | D10: GARANTIA | F10: 350 | G10: =G9+E10-F10 -> 375.6
A11: 45387 | B11: EB01-3525 | C11: MARZO | D11: ALQUILER | F11: 350 | G11: =G10+E11-F11 -> 25.6
A12: 45448 | B12: RII 2224 | C12: MARZO | D12: LUZ | F12: 20.6 | G12: =G11+E12-F12 -> 5
A13: 45448 | B13: RII 2224 | C13: MARZO | D13: AGUA | F13: 5 | G13: =G12+E13-F13 -> 2.1316282e-14
A14: 45412 | B14: POR COBRAR | C14: ABRIL | D14: LUZ | E14: 20.5 | G14: =G13+E14-F14 -> 20.5
D15: AGUA | E15: 5 | G15: =G14+E15-F15 -> 25.5
D16: ALQUILER | E16: 350 | G16: =G15+E16-F16 -> 375.5
A17: 45447 | B17: EB01-3786 | C17: ABRIL | D17: ALQUILER | F17: 350 | G17: =G16+E17-F17 -> 25.5
A18: 45448 | B18: RII 2224 | C18: ABRIL | D18: LUZ | F18: 20.5 | G18: =G17+E18-F18 -> 5
A19: 45448 | B19: RII 2224 | C19: ABRIL | D19: AGUA | F19: 5 | G19: =G18+E19-F19 -> 0
A20: 45443 | B20: POR COBRAR | C20: MAYO | D20: LUZ | E20: 18.6 | G20: =G19+E20-F20 -> 18.6
D21: AGUA | E21: 5 | G21: =G20+E21-F21 -> 23.6
D22: ALQUILER | E22: 350 | G22: =G21+E22-F22 -> 373.6
A23: 45475 | B23: EB01-3906 | C23: MAYO | D23: ALQUILER | F23: 350 | G23: =G22+E23-F23 -> 23.6
A24: 45476 | B24: RII 2271 | C24: MAYO | D24: LUZ | F24: 18.6 | G24: =G23+E24-F24 -> 5
A25: 45476 | B25: RII 2271 | C25: MAYO | D25: AGUA | F25: 5 | G25: =G24+E25-F25 -> 2.1316282e-14
A26: 45473 | B26: POR COBRAR | C26: JUNIO | D26: LUZ | E26: 18.1 | G26: =G25+E26-F26 -> 18.1
D27: AGUA | E27: 7 | G27: =G26+E27-F27 -> 25.1
D28: ALQUILER | E28: 350 | G28: =G27+E28-F28 -> 375.1
A29: 45488 | B29: EB01-3964 | C29: JUNIO | D29: ALQUILER | F29: 350 | G29: =G28+E29-F29 -> 25.1
A30: 45499 | B30: RII 2314 | C30: JUNIO | D30: LUZ | F30: 18.1 | G30: =G29+E30-F30 -> 7
A31: 45499 | B31: RII 2314 | C31: JUNIO | D31: AGUA | F31: 7 | G31: =G30+E31-F31 -> 2.1316282e-14
A32: 45504 | B32: POR COBRAR | C32: JULIO | D32: LUZ | E32: 17.8 | G32: =G31+E32-F32 -> 17.8
D33: AGUA | E33: 7 | G33: =G32+E33-F33 -> 24.8
D34: ALQUILER | E34: 350 | G34: =G33+E34-F34 -> 374.8
A35: 45511 | B35: EB01-4072 | C35: JULIO | D35: ALQUILER | F35: 350 | G35: =G34+E35-F35 -> 24.8
A36: 45546 | B36: RII 2401 | C36: JULIO | D36: LUZ | F36: 17.8 | G36: =G35+E36-F36 -> 7
A37: 45546 | B37: RII 2401 | C37: JULIO | D37: AGUA | F37: 7 | G37: =G36+E37-F37 -> 1.0658141e-14
A38: 45535 | B38: POR COBRAR | C38: AGOSTO | D38: LUZ | E38: 17.8 | G38: =G37+E38-F38 -> 17.8
D39: AGUA | E39: 7 | G39: =G38+E39-F39 -> 24.8
D40: ALQUILER | E40: 350 | G40: =G39+E40-F40 -> 374.8
A41: 45546 | B41: EB01-4224 | C41: AGOSTO | D41: ALQUILER | F41: 350 | G41: =G40+E41-F41 -> 24.8
A42: 45735 | B42: RII 2729 | C42: AGOSTO | D42: LUZ | F42: 17.8 | G42: =G41+E42-F42 -> 7
A43: 45735 | B43: RII 2729 | C43: AGOSTO | D43: AGUA | F43: 7 | G43: =G42+E43-F43 -> 1.0658141e-14
...

Sheet AZURZA DAYSI
B2: DAYSI ELIZABETH AZURZA TRIBIÑOS | I2: DNI | J2: 47384400
A4: FECHA | B4: DOCUMENTO | C4: PERIODO | D4: CONCEPTO | E4: POR COBRAR | F4: PAGADO | G4: SALDO POR COBRAR
A5: 42736 | B5: SALDO AL 2016 | G5: 113.1
A6: 42737 | B6: 11992 | C6: ACUENTA DEL 2016 | F6: 42 | G6: =+G5+E6-F6 -> 71.1
A7: 42739 | B7: 12015 | C7: ACUENTA DEL 2016 | F7: 18 | G7: =+G6+E7-F7 -> 53.1
A8: 42748 | B8: 12073 | C8: CANCELACION DEL 2016 | F8: 53.1 | G8: =+G7+E8-F8 -> 0
A9: 42766 | B9: POR COBRAR | C9: ENERO | D9: LUZ | E9: 13.5 | G9: =+G8+E9-F9 -> 13.5
D10: AGUA | E10: 2.7 | G10: =+G9+E10-F10 -> 16.2
D11: ALQUILER | E11: 210 | G11: =+G10+E11-F11 -> 226.2
A12: 42766 | B12: 12177 | C12: ENERO | D12: ALQUILER | F12: 60 | G12: =+G11+E12-F12 -> 166.2
A13: 42760 | B13: 12143 | C13: ENERO | D13: ALQUILER | F13: 14 | G13: =+G12+E13-F13 -> 152.2
A14: 42769 | B14: 12208 | C14: ENERO | D14: ALQUILER | F14: 42 | G14: =+G13+E14-F14 -> 110.2
A15: 42776 | B15: 12247 | C15: ENERO | D15: ALQUILER | F15: 28 | G15: =+G14+E15-F15 -> 82.2
A16: 42780 | B16: 12258 | C16: ENERO | D16: ALQUILER | F16: 28 | G16: =+G15+E16-F16 -> 54.2
A17: 42781 | B17: 12262 | C17: ENERO | D17: ALQUILER | F17: 28 | G17: =+G16+E17-F17 -> 26.2
A18: 42782 | B18: 12266 | C18: ENERO | D18: ALQUILER | F18: 10 | G18: =+G17+E18-F18 -> 16.2
A19: 43314 | B19: 14989 | C19: ENERO | D19: LUZ | F19: 13.5 | G19: =+G18+E19-F19 -> 2.7
A20: 43314 | B20: 14989 | C20: ENERO | D20: AGUA | F20: 2.7 | G20: =+G19+E20-F20 -> -1.1546319e-14
A21: 42794 | B21: POR COBRAR | C21: FEBRERO | D21: LUZ | E21: 13 | G21: =+G20+E21-F21 -> 13
D22: AGUA | E22: 2 | G22: =+G21+E22-F22 -> 15
D23: ALQUILER | E23: 210 | G23: =+G22+E23-F23 -> 225
A24: 42786 | B24: 12280 | C24: FEBRERO | D24: ALQUILER | F24: 28 | G24: =+G23+E24-F24 -> 197
A25: 42790 | B25: 12292 | C25: FEBRERO | D25: ALQUILER | F25: 28 | G25: =+G24+E25-F25 -> 169
A26: 42782 | B26: 12266 | C26: FEBRERO | D26: ALQUILER | F26: 18 | G26: =+G25+E26-F26 -> 151
A27: 42817 | B27: 12427 | C27: FEBRERO | D27: ALQUILER | F27: 28 | G27: =+G26+E27-F27 -> 123
A28: 42821 | B28: 12448 | C28: FEBRERO | D28: ALQUILER | F28: 42 | G28: =+G27+E28-F28 -> 81
A29: 42824 | B29: 12455 | C29: FEBRERO | D29: ALQUILER | F29: 28 | G29: =+G28+E29-F29 -> 53
A30: 42857 | B30: 12581 | C30: FEBRERO | D30: ALQUILER | F30: 7 | G30: =+G29+E30-F30 -> 46
A31: 42858 | B31: 12599 | C31: FEBRERO | D31: ALQUILER | F31: 7 | G31: =+G30+E31-F31 -> 39
A32: 42859 | B32: 12620 | C32: FEBRERO | D32: ALQUILER | F32: 7 | G32: =+G31+E32-F32 -> 32
A33: 42860 | B33: 12636 | C33: FEBRERO | D33: ALQUILER | F33: 7 | G33: =+G32+E33-F33 -> 25
A34: 42861 | B34: 12645 | C34: FEBRERO | D34: ALQUILER | F34: 7 | G34: =+G33+E34-F34 -> 18
A35: 42863 | B35: 12652 | C35: FEBRERO | D35: ALQUILER | F35: 3 | G35: =+G34+E35-F35 -> 15
... A37: 43314 | B37: 14989 | C37: FEBRERO | D37: AGUA | F37: 2 | G37: =+G36+E37-F37 -> 0
A38: 42825 | B38: POR COBRAR | C38: MARZO | D38: LUZ | E38: 12 | G38: =+G37+E38-F38 -> 12
D39: AGUA | E39: 2 | G39: =+G38+E39-F39 -> 14
D40: ALQUILER | E40: 210 | G40: =+G39+E40-F40 -> 224
A41: 42863 | B41: 12652 | C41: MARZO | D41: ALQUILER | F41: 11 | G41: =+G40+E41-F41 -> 213
A42: 42870 | B42: 12679 | C42: MARZO | D42: ALQUILER | F42: 21 | G42: =+G41+E42-F42 -> 192
A43: 42884 | B43: 12717 | C43: MARZO | D43: ALQUILER | F43: 28 | G43: =+G42+E43-F43 -> 164
...

Sheet BENITES ERIKA
E1: SILVIA AZURZA
B3: ERIKA BENITES TRIBIÑOS
A5: FECHA | B5: DOCUMENTO | C5: PERIODO | D5: CONCEPTO | E5: POR COBRAR | F5: PAGADO | G5: SALDO POR COBRAR
A6: 42736 | B6: SALDO AL 2016 | G6: 53.1
A7: 42744 | B7: 12050 | C7: ACUENTA DEL 2016 | F7: 46.2 | G7: =+G6+E7-F7 -> 6.9
A8: 42748 | B8: 12074 | C8: CANCELACION DEL 2016 | F8: 6.9 | G8: =+G7+E8-F8 -> 0
A9: 42766 | B9: POR COBRAR | C9: ENERO | D9: LUZ | E9: 13.5 | G9: =+G8+E9-F9 -> 13.5
D10: AGUA | E10: 2.8 | G10: =+G9+E10-F10 -> 16.3
D11: ALQUILER | E11: 210 | G11: =+G10+E11-F11 -> 226.3
A12: 42744 | B12: 12048 | C12: ENERO | D12: ALQUILER | F12: 42 | G12: =+G11+E12-F12 -> 184.3
A13: 42748 | B13: 12075 | C13: ENERO | D13: ALQUILER | F13: 42 | G13: =+G12+E13-F13 -> 142.3
A14: 42751 | B14: 12089 | C14: ENERO | D14: ALQUILER | F14: 28 | G14: =+G13+E14-F14 -> 114.3
A15: 42753 | B15: 12112 | C15: ENERO | D15: ALQUILER | F15: 28 | G15: =+G14+E15-F15 -> 86.3
A16: 42755 | B16: 12126 | C16: ENERO | D16: ALQUILER | F16: 28 | G16: =+G15+E16-F16 -> 58.3
A17: 42760 | B17: 12142 | C17: ENERO | D17: ALQUILER | F17: 42 | G17: =+G16+E17-F17 -> 16.3
A18: 42993 | B18: 13465 | C18: ENERO | D18: LUZ | F18: 10 | G18: =+G17+E18-F18 -> 6.3
A19: 43167 | B19: 14342 | C19: ENERO | D19: LUZ | F19: 3.5 | G19: =+G18+E19-F19 -> 2.8
A20: 43167 | B20: 14342 | C20: ENERO | D20: AGUA | F20: 2 | G20: =+G19+E20-F20 -> 0.8
A21: 43179 | B21: 14369 | C21: ENERO | D21: AGUA | F21: 0.8 | G21: =+G20+E21-F21 -> 1.1324275e-14
A22: 42794 | B22: POR COBRAR | C22: FEBRERO | D22: LUZ | E22: 13 | G22: =+G21+E22-F22 -> 13
D23: AGUA | E23: 2 | G23: =+G22+E23-F23 -> 15
D24: ALQUILER | E24: 210 | G24: =+G23+E24-F24 -> 225
A25: 43201 | B25: 14456 | C25: FEBRERO | D25: AGUA | F25: 1.3 | G25: =+G24+E25-F25 -> 223.7
A26: 42801 | B26: 12354 | C26: FEBRERO | D26: ALQUILER | F26: 42 | G26: =+G25+E26-F26 -> 181.7
A27: 42776 | B27: 12371 | C27: FEBRERO | D27: ALQUILER | F27: 28 | G27: =+G26+E27-F27 -> 153.7
A28: 42809 | B28: 12404 | C28: FEBRERO | D28: ALQUILER | F28: 42 | G28: =+G27+E28-F28 -> 111.7
A29: 42815 | B29: 12418 | C29: FEBRERO | D29: ALQUILER | F29: 42 | G29: =+G28+E29-F29 -> 69.7
A30: 42857 | B30: 12580 | C30: FEBRERO | D30: ALQUILER | F30: 7 | G30: =+G29+E30-F30 -> 62.7
A31: 42858 | B31: 12598 | C31: FEBRERO | D31: ALQUILER | F31: 7 | G31: =+G30+E31-F31 -> 55.7
A32: 42859 | B32: 12619 | C32: FEBRERO | D32: ALQUILER | F32: 7 | G32: =+G31+E32-F32 -> 48.7
A33: 42860 | B33: 12637 | C33: FEBRERO | D33: ALQUILER | F33: 7 | G33: =+G32+E33-F33 -> 41.7
A34: 42861 | B34: 12646 | C34: FEBRERO | D34: ALQUILER | F34: 7 | G34: =+G33+E34-F34 -> 34.7
A35: 42863 | B35: 12651 | C35: FEBRERO | D35: ALQUILER | F35: 14 | G35: =+G34+E35-F35 -> 20.7
A36: 42864 | B36: 12667 | C36: FEBRERO | D36: ALQUILER | F36: 7 | G36: =+G35+E36-F36 -> 13.7
... A39: 43179 | B39: 14369 | C39: FEBRERO | D39: AGUA | F39: 0.7 | G39: =+G38+E39-F39 -> -1.1324275e-14
A40: 42825 | B40: POR COBRAR | C40: MARZO | D40: LUZ | E40: 12 | G40: =+G39+E40-F40 -> 12
D41: AGUA | E41: 2 | G41: =+G40+E41-F41 -> 14
D42: ALQUILER | E42: 210 | G42: =+G41+E42-F42 -> 224
A43: 43201 | B43: 14456 | C43: MARZO | D43: AGUA | F43: 2 | G43: =+G42+E43-F43 -> 222
A44: 43201 | B44: 14456 | C44: MARZO | D44: LUZ | F44: 7.7 | G44: =+G43+E44-F44 -> 214.3
...

Sheet BELLIDO ZENAIDA
B3: BELLIDO DE LA TORRE DE CHUQUITAIPE ZENAIDA
A5: FECHA | B5: DOCUMENTO | C5: PERIODO | D5: CONCEPTO | E5: POR COBRAR | F5: PAGADO | G5: SALDO POR COBRAR
A6: 42736 | B6: SALDO AL 2016 | G6: 475.3
A7: 42737 | B7: 11997 | C7: ACUENTA DEL 2016 | F7: 450 | G7: =+G6+E7-F7 -> 25.3
A8: 42754 | B8: 12121 | C8: CANCELACION DEL 2016 | F8: 25.3 | G8: =+G7+E8-F8 -> 0
A9: 42766 | B9: POR COBRAR | C9: ENERO | D9: LUZ | E9: 22.8 | G9: =+G8+E9-F9 -> 22.8
D10: AGUA | E10: 2.8 | G10: =+G9+E10-F10 -> 25.6
D11: ALQUILER | E11: 450 | G11: =+G10+E11-F11 -> 475.6
A12: 42773 | B12: 12223 | C12: ENERO | D12: ALQUILER | F12: 450 | G12: =+G11+E12-F12 -> 25.6
A13: 42797 | B13: 12322 | C13: ENERO | D13: LUZ | F13: 22.8 | G13: =+G12+E13-F13 -> 2.8
A14: 42797 | B14: 12322 | C14: ENERO | D14: AGUA | F14: 2.8 | G14: =+G13+E14-F14 -> 2.220446e-14
A15: 42794 | B15: POR COBRAR | C15: FEBRERO | D15: LUZ | E15: 21.8 | G15: =+G14+E15-F15 -> 21.8
D16: AGUA | E16: 2 | G16: =+G15+E16-F16 -> 23.8
D17: ALQUILER | E17: 450 | G17: =+G16+E17-F17 -> 473.8
A18: 42797 | B18: 12322 | C18: FEBRERO | D18: ALQUILER | F18: 450 | G18: =+G17+E18-F18 -> 23.8
A19: 42829 | B19: 12476 | C19: FEBRERO | D19: LUZ | F19: 21.8 | G19: =+G18+E19-F19 -> 2
A20: 42829 | B20: 12476 | C20: FEBRERO | D20: AGUA | F20: 2 | G20: =+G19+E20-F20 -> 1.0658141e-14
A21: 42825 | B21: POR COBRAR | C21: MARZO | D21: LUZ | E21: 20.5 | G21: =+G20+E21-F21 -> 20.5
D22: AGUA | E22: 2 | G22: =+G21+E22-F22 -> 22.5
D23: ALQUILER | E23: 450 | G23: =+G22+E23-F23 -> 472.5
A24: 42829 | B24: 12476 | C24: MARZO | D24: ALQUILER | F24: 450 | G24: =+G23+E24-F24 -> 22.5
A25: 42857 | B25: 12582 | C25: MARZO | D25: LUZ | F25: 20.5 | G25: =+G24+E25-F25 -> 2
A26: 42857 | B26: 12582 | C26: MARZO | D26: AGUA | F26: 2 | G26: =+G25+E26-F26 -> 0
A27: 42855 | B27: POR COBRAR | C27: ABRIL | D27: LUZ | E27: 21.6 | G27: =+G26+E27-F27 -> 21.6
D28: AGUA | E28: 2 | G28: =+G27+E28-F28 -> 23.6
D29: ALQUILER | E29: 450 | G29: =+G28+E29-F29 -> 473.6
A30: 42857 | B30: 12582 | C30: ABRIL | D30: ALQUILER | F30: 450 | G30: =+G29+E30-F30 -> 23.6
A31: 42888 | B31: 12771 | C31: ABRIL | D31: LUZ | F31: 21.6 | G31: =+G30+E31-F31 -> 2
A32: 42888 | B32: 12771 | C32: ABRIL | D32: AGUA | F32: 2 | G32: =+G31+E32-F32 -> 2.1316282e-14
A33: 42886 | B33: POR COBRAR | C33: MAYO | D33: LUZ | E33: 20.9 | G33: =+G32+E33-F33 -> 20.9
D34: AGUA | E34: 2 | G34: =+G33+E34-F34 -> 22.9
D35: ALQUILER | E35: 450 | G35: =+G34+E35-F35 -> 472.9
A36: 42888 | B36: 12770 | C36: MAYO | D36: ALQUILER | F36: 450 | G36: =+G35+E36-F36 -> 22.9
A37: 42919 | B37: 12934 | C37: MAYO | D37: LUZ | F37: 20.9 | G37: =+G36+E37-F37 -> 2
A38: 42919 | B38: 12934 | C38: MAYO | D38: AGUA | F38: 2 | G38: =+G37+E38-F38 -> 3.5527137e-14
A39: 42916 | B39: POR COBRAR | C39: JUNIO | D39: LUZ | E39: 20.3 | G39: =+G38+E39-F39 -> 20.3
D40: AGUA | E40: 2 | G40: =+G39+E40-F40 -> 22.3
D41: ALQUILER | E41: 450 | G41: =+G40+E41-F41 -> 472.3
A42: 42919 | B42: 12934 | C42: JUNIO | D42: ALQUILER | F42: 450 | G42: =+G41+E42-F42 -> 22.3
A43: 42954 | B43: 13238 | C43: JUNIO | D43: LUZ | F43: 20.3 | G43: =+G42+E43-F43 -> 2
...

Sheet BURGA ELMER
A2: BURGA CARRASCO ELMER
A5: FECHA | B5: DOCUMENTO | C5: PERIODO | D5: CONCEPTO | E5: POR COBRAR | F5: PAGADO | G5: SALDO POR COBRAR
G6: 0
A7: 43697 | B7: POR COBRAR | C7: AGOSTO | D7: LUZ | G7: =+G6+E7-F7 -> 0
D8: AGUA | G8: =+G7+E8-F8 -> 0
D9: GARANTIA | E9: 210 | G9: =+G8+E9-F9 -> 210 | I9: TRASPASO AL SR. BURGA CARRASCO ELMER
D10: ALQUILER | E10: 84 | G10: =+G9+E10-F10 -> 294
A11: 43691 | B11: B001-0000537 | C11: AGOSTO | D11: GARANTIA | F11: 210 | G11: =+G10+E11-F11 -> 84
A12: 43999 | B12: B001-0001410 | C12: AGOSTO | D12: ALQUILER | F12: 84 | G12: =+G11+E12-F12 -> 0
A13: 43738 | B13: POR COBRAR | C13: SETIEMBRE | D13: LUZ | E13: 7.7 | G13: =+G12+E13-F13 -> 7.7
D14: AGUA | E14: 6.6 | G14: =+G13+E14-F14 -> 14.3
D15: ALQUILER | E15: 210 | G15: =+G14+E15-F15 -> 224.3
A16: 43738 | B16: B001-0000696 | C16: SETIEMBRE | D16: ALQUILER | F16: 199 | G16: =+G15+E16-F16 -> 25.3
A17: 43894 | B17: B001-0001247 | C17: SETIEMBRE | D17: LUZ | F17: 7.7 | G17: =+G16+E17-F17 -> 17.6
A18: 43894 | B18: B001-0001247 | C18: SETIEMBRE | D18: AGUA | F18: 6.6 | G18: =+G17+E18-F18 -> 11
A19: 43999 | B19: B001-0001410 | C19: SETIEMBRE | D19: ALQUILER | F19: 11 | G19: =+G18+E19-F19 -> 0
A20: 43769 | B20: POR COBRAR | C20: OCTUBRE | D20: LUZ | E20: 7.8 | G20: =+G19+E20-F20 -> 7.8
D21: AGUA | E21: 6.3 | G21: =+G20+E21-F21 -> 14.1
D22: ALQUILER | E22: 210 | G22: =+G21+E22-F22 -> 224.1
A23: 43769 | B23: B001-0000780 | C23: OCTUBRE | D23: ALQUILER | F23: 210 | G23: =+G22+E23-F23 -> 14.1
A24: 43894 | B24: B001-0001247 | C24: OCTUBRE | D24: LUZ | F24: 7.8 | G24: =+G23+E24-F24 -> 6.3
A25: 43894 | B25: B001-0001247 | C25: OCTUBRE | D25: AGUA | F25: 6.3 | G25: =+G24+E25-F25 -> 0
A26: 43799 | B26: POR COBRAR | C26: NOVIEMBRE | D26: LUZ | E26: 8.7 | G26: =+G25+E26-F26 -> 8.7
D27: AGUA | E27: 6.6 | G27: =+G26+E27-F27 -> 15.3
D28: ALQUILER | E28: 210 | G28: =+G27+E28-F28 -> 225.3
A29: 43799 | B29: B001-0000898 | C29: NOVIEMBRE | D29: ALQUILER | F29: 171 | G29: =+G28+E29-F29 -> 54.3
A30: 43999 | B30: B001-0001410 | C30: NOVIEMBRE | D30: ALQUILER | F30: 39 | G30: =+G29+E30-F30 -> 15.3
A31: 43894 | B31: B001-0001247 | C31: NOVIEMBRE | D31: LUZ | F31: 8.7 | G31: =+G30+E31-F31 -> 6.6
A32: 43894 | B32: B001-0001247 | C32: NOVIEMBRE | D32: AGUA | F32: 6.6 | G32: =+G31+E32-F32 -> 1.2434498e-14
A33: 43830 | B33: POR COBRAR | C33: DICIEMBRE | D33: LUZ | E33: 9.1 | G33: =+G32+E33-F33 -> 9.1
D34: AGUA | E34: 6.6 | G34: =+G33+E34-F34 -> 15.7
D35: ALQUILER | E35: 210 | G35: =+G34+E35-F35 -> 225.7
A36: 43830 | B36: B001-0001012 | C36: DICIEMBRE | D36: ALQUILER | F36: 210 | G36: =+G35+E36-F36 -> 15.7
A37: 43894 | B37: B001-0001247 | C37: DICIEMBRE | D37: LUZ | F37: 9.1 | G37: =+G36+E37-F37 -> 6.6
A38: 43894 | B38: B001-0001247 | C38: DICIEMBRE | D38: AGUA | F38: 6.6 | G38: =+G37+E38-F38 -> 1.7763568e-14
A39: 43861 | B39: POR COBRAR | C39: ENERO | D39: LUZ | E39: 11.6 | G39: =+G38+E39-F39 -> 11.6
D40: AGUA | E40: 6.3 | G40: =+G39+E40-F40 -> 17.9
D41: ALQUILER | E41: 210 | G41: =+G40+E41-F41 -> 227.9
A42: 43861 | B42: B001-0001132 | C42: ENERO | D42: ALQUILER | F42: 210 | G42: =+G41+E42-F42 -> 17.9
A43: 43999 | B43: B001-0001410 | C43: ENERO | D43: LUZ | F43: 11.6 | G43: =+G42+E43-F43 -> 6.3
...

Sheet BUSTAMANTE GRACIELA
B3: BUSTAMANTE CHILON GRACIELA
A5: FECHA | B5: DOCUMENTO | C5: PERIODO | D5: CONCEPTO | E5: POR COBRAR | F5: PAGADO | G5: SALDO POR COBRAR
A6: 42736 | B6: SALDO AL 2016 | G6: 116.6
A7: 42802 | B7: 12360 | C7: ACUENTA DEL 2016 | F7: 30 | G7: =+G6+E7-F7 -> 86.6
A8: 42773 | B8: 12224 | C8: ACUENTA DEL 2016 | F8: 30 | G8: =+G7+E8-F8 -> 56.6
A9: 42753 | B9: 12111 | C9: ACUENTA DEL 2016 | F9: 56.6 | G9: =+G8+E9-F9 -> 0
A10: 42766 | B10: POR COBRAR | C10: ENERO | D10: LUZ | E10: 13.5 | G10: =+G9+E10-F10 -> 13.5
D11: AGUA | E11: 21 | G11: =+G10+E11-F11 -> 34.5
D12: ALQUILER | E12: 300 | G12: =+G11+E12-F12 -> 334.5
A13: 42802 | B13: 12360 | C13: ENERO | D13: LUZ | F13: 13.5 | G13: =+G12+E13-F13 -> 321
A14: 42802 | B14: 12360 | C14: ENERO | D14: AGUA | F14: 21 | G14: =+G13+E14-F14 -> 300
A15: 42802 | B15: 12360 | C15: ENERO | D15: ALQUILER | F15: 300 | G15: =+G14+E15-F15 -> 0
A16: 42794 | B16: POR COBRAR | C16: FEBRERO | D16: LUZ | E16: 13 | G16: =+G15+E16-F16 -> 13
D17: AGUA | E17: 15 | G17: =+G16+E17-F17 -> 28
D18: ALQUILER | E18: 300 | G18: =+G17+E18-F18 -> 328
A19: 42802 | B19: 12361 | C19: FEBRERO | D19: ALQUILER | F19: 150 | G19: =+G18+E19-F19 -> 178
A20: 42808 | B20: 12397 | C20: FEBRERO | F20: 150 | G20: =+G19+E20-F20 -> 28
A21: 42845 | B21: 12563 | C21: FEBRERO | D21: LUZ | F21: 13 | G21: =+G20+E21-F21 -> 15
A22: 42845 | B22: 12563 | C22: FEBRERO | D22: AGUA | F22: 15 | G22: =+G21+E22-F22 -> 0
A23: 42825 | B23: POR COBRAR | C23: MARZO | D23: LUZ | E23: 13 | G23: =+G22+E23-F23 -> 13
D24: AGUA | E24: 15 | G24: =+G23+E24-F24 -> 28
D25: ALQUILER | E25: 300 | G25: =+G24+E25-F25 -> 328
A26: 42845 | B26: 12563 | C26: MARZO | D26: ALQUILER | F26: 300 | G26: =+G25+E26-F26 -> 28
A27: 42920 | B27: 12950 | C27: MARZO | D27: LUZ | F27: 13 | G27: =+G26+E27-F27 -> 15
A28: 42920 | B28: 12950 | C28: MARZO | D28: AGUA | F28: 15 | G28: =+G27+E28-F28 -> 0
A29: 42855 | B29: POR COBRAR | C29: ABRIL | D29: LUZ | E29: 13 | G29: =+G28+E29-F29 -> 13
D30: AGUA | E30: 15 | G30: =+G29+E30-F30 -> 28
D31: ALQUILER | E31: 300 | G31: =+G30+E31-F31 -> 328
A32: 42867 | B32: 12676 | C32: ABRIL | D32: ALQUILER | F32: 300 | G32: =+G31+E32-F32 -> 28
A33: 42920 | B33: 12950 | C33: ABRIL | D33: LUZ | F33: 13 | G33: =+G32+E33-F33 -> 15
A34: 42920 | B34: 12950 | C34: ABRIL | D34: AGUA | F34: 15 | G34: =+G33+E34-F34 -> 0
A35: 42886 | B35: POR COBRAR | C35: MAYO | D35: LUZ | E35: 13 | G35: =+G34+E35-F35 -> 13
D36: AGUA | E36: 14.7 | G36: =+G35+E36-F36 -> 27.7
D37: ALQUILER | E37: 300 | G37: =+G36+E37-F37 -> 327.7
A38: 42920 | B38: 12949 | C38: MAYO | D38: ALQUILER | F38: 300 | G38: =+G37+E38-F38 -> 27.7
A39: 43122 | B39: 14117 | C39: MAYO | D39: LUZ | F39: 13 | G39: =+G38+E39-F39 -> 14.7
A40: 43122 | B40: 14117 | C40: MAYO | D40: AGUA | F40: 14.7 | G40: =+G39+E40-F40 -> 0
A41: 42916 | B41: POR COBRAR | C41: JUNIO | D41: LUZ | E41: 12.5 | G41: =+G40+E41-F41 -> 12.5
D42: AGUA | E42: 14.7 | G42: =+G41+E42-F42 -> 27.2
D43: ALQUILER | E43: 300 | G43: =+G42+E43-F43 -> 327.2
...

Sheet CAHUANA ALEX
B3: CAHUANA PUCURIMAY ALEX
A5: FECHA | B5: DOCUMENTO | C5: PERIODO | D5: CONCEPTO | E5: POR COBRAR | F5: PAGADO | G5: SALDO POR COBRAR
G6: 0
A7: 44469 | B7: POR COBRAR | C7: SEPTIEMBRE | D7: LUZ | E7: 10.5 | G7: =+G6+E7-F7 -> 10.5
D8: AGUA | E8: 8.1 | G8: =+G7+E8-F8 -> 18.6
D9: GARANTIA | E9: 300 | G9: =+G8+E9-F9 -> 318.6
D10: ALQUILER | E10: 300 | G10: =+G9+E10-F10 -> 618.6
A11: 44445 | B11: EB01-12 | C11: SEPTIEMBRE | D11: GARANTIA | F11: 300 | G11: =+G10+E11-F11 -> 318.6
A12: 44445 | B12: EB01-12 | C12: SEPTIEMBRE | D12: ALQUILER | F12: 300 | G12: =+G11+E12-F12 -> 18.6
A13: 44523 | B13: RII 764 | C13: SEPTIEMBRE | D13: LUZ | F13: 10.5 | G13: =+G12+E13-F13 -> 8.1
A14: 44523 | B14: RII 764 | C14: SEPTIEMBRE | D14: AGUA | F14: 8.1 | G14: =+G13+E14-F14 -> 2.3092639e-14
A15: 44500 | B15: POR COBRAR | C15: OCTUBRE | D15: LUZ | E15: 10.9 | G15: =+G14+E15-F15 -> 10.9
D16: AGUA | E16: 19.1 | G16: =+G15+E16-F16 -> 30
D17: ALQUILER | E17: 300 | G17: =+G16+E17-F17 -> 330
A18: 44523 | B18: EB01-157 | C18: OCTUBRE | D18: ALQUILER | F18: 300 | G18: =+G17+E18-F18 -> 30
A19: 44557 | B19: RII 000874 | C19: OCTUBRE | D19: LUZ | F19: 10.9 | G19: =+G18+E19-F19 -> 19.1
A20: 44557 | B20: RII 000874 | C20: OCTUBRE | D20: AGUA | F20: 19.1 | G20: =+G19+E20-F20 -> 0
A21: 44530 | B21: POR COBRAR | C21: NOVIEMBRE | D21: LUZ | E21: 11.6 | G21: =+G20+E21-F21 -> 11.6
D22: AGUA | E22: 47.1 | G22: =+G21+E22-F22 -> 58.7 | J22: 10.9
D23: ALQUILER | E23: 300 | G23: =+G22+E23-F23 -> 358.7 | J23: 19.1
A24: 44555 | B24: EB01-301 | C24: NOVIEMBRE | D24: ALQUILER | F24: 300 | G24: =+G23+E24-F24 -> 58.7
A25: 44557 | B25: RII 000874 | C25: NOVIEMBRE | D25: LUZ | F25: 11.6 | G25: =+G24+E25-F25 -> 47.1 | J25: 11.6
A26: 44557 | B26: RII 000874 | C26: NOVIEMBRE | D26: AGUA | F26: 47.1 | G26: =+G25+E26-F26 -> 0 | J26: 47.1
A27: 44561 | B27: POR COBRAR | C27: DICIEMBRE | D27: LUZ | E27: 22 | G27: =+G26+E27-F27 -> 22
D28: AGUA | E28: 37.8 | G28: =+G27+E28-F28 -> 59.8
D29: ALQUILER | E29: 300 | G29: =+G28+E29-F29 -> 359.8
A30: 44614 | B30: EB01-502 | C30: DICIEMBRE | D30: ALQUILER | F30: 300 | G30: =+G29+E30-F30 -> 59.8
A31: 44614 | B31: RII 000933 | C31: DICIEMBRE | D31: LUZ | F31: 22 | G31: =+G30+E31-F31 -> 37.8
A32: 44614 | B32: RII 000933 | C32: DICIEMBRE | D32: AGUA | F32: 37.8 | G32: =+G31+E32-F32 -> 0
A33: 44592 | B33: POR COBRAR | C33: ENERO | D33: LUZ | E33: 42.7 | G33: =+G32+E33-F33 -> 42.7
D34: AGUA | E34: 30.4 | G34: =+G33+E34-F34 -> 73.1
D35: ALQUILER | E35: 300 | G35: =+G34+E35-F35 -> 373.1
A36: 44614 | B36: EB01-502 | C36: ENERO | D36: ALQUILER | F36: 300 | G36: =+G35+E36-F36 -> 73.1
A37: 44662 | B37: RII 000999 | C37: ENERO | D37: LUZ | F37: 42.7 | G37: =+G36+E37-F37 -> 30.4
A38: 44662 | B38: RII 000999 | C38: ENERO | D38: AGUA | F38: 30.4 | G38: =+G37+E38-F38 -> 0
A39: 44620 | B39: POR COBRAR | C39: FEBRERO | D39: LUZ | E39: 42 | G39: =+G38+E39-F39 -> 42
D40: AGUA | E40: 24.9 | G40: =+G39+E40-F40 -> 66.9
D41: ALQUILER | E41: 300 | G41: =+G40+E41-F41 -> 366.9
A42: 44614 | B42: EB01-502 | C42: FEBRERO | D42: ALQUILER | F42: 300 | G42: =+G41+E42-F42 -> 66.9
A43: 44662 | B43: RII 000999 | C43: FEBRERO | D43: LUZ | F43: 42 | G43: =+G42+E43-F43 -> 24.9
...

Sheet ATO MARIA
D1: MARIA VALERIA ATO ARREDONDO | I1: DNI 76276709
A3: FECHA | B3: DOCUMENTO | C3: PERIODO | D3: CONCEPTO | E3: POR COBRAR | F3: PAGADO | G3: SALDO POR COBRAR
G4: =+E4-F4 -> 0
A5: 45260 | B5: POR COBRAR | C5: NOVIEMBRE | D5: ALQUILER | E5: 1200 | G5: =G4+E5-F5 -> 1200
D6: GARANTIA | G6: =G5+E6-F6 -> 1200
G7: =G6+E7-F7 -> 1200
A8: 45252 | B8: EB01-2921 | C8: NOVIEMBRE | D8: ALQUILER | F8: 1200 | G8: =G7+E8-F8 -> 0
A9: 45291 | B9: POR COBRAR | C9: DICIEMBRE | D9: LUZ | E9: 30.6 | G9: =G8+E9-F9 -> 30.6
D10: AGUA | E10: 5 | G10: =G9+E10-F10 -> 35.6
D11: ALQUILER | E11: 1200 | G11: =G10+E11-F11 -> 1235.6
A12: 45289 | B12: EB01-3087 | C12: DICIEMBRE | D12: ALQUILER | F12: 1200 | G12: =G11+E12-F12 -> 35.6
A13: 45316 | B13: RII 2003 | C13: DICIEMBRE | D13: LUZ | F13: 30.6 | G13: =G12+E13-F13 -> 5
A14: 45316 | B14: RII 2003 | C14: DICIEMBRE | D14: AGUA | F14: 5 | G14: =G13+E14-F14 -> -9.2370556e-14
A15: 45322 | B15: POR COBRAR | C15: ENERO | D15: LUZ | E15: 34.2 | G15: =G14+E15-F15 -> 34.2
D16: AGUA | E16: 8.8 | G16: =G15+E16-F16 -> 43
D17: ALQUILER | E17: 1200 | G17: =G16+E17-F17 -> 1243
A18: 45328 | B18: EB01-3300 | C18: ENERO | D18: ALQUILER | F18: 1200 | G18: =G17+E18-F18 -> 43
A19: 45358 | B19: RII 2082 | C19: ENERO | D19: LUZ | F19: 34.2 | G19: =G18+E19-F19 -> 8.8
A20: 45358 | B20: RII 2082 | C20: ENERO | D20: AGUA | F20: 8.8 | G20: =G19+E20-F20 -> 0
A21: 45351 | B21: POR COBRAR | C21: FEBRERO | D21: LUZ | E21: 35.5 | G21: =G20+E21-F21 -> 35.5
D22: AGUA | E22: 5 | G22: =G21+E22-F22 -> 40.5
D23: ALQUILER | E23: 1200 | G23: =G22+E23-F23 -> 1240.5
A24: 45354 | B24: EB01-3447 | C24: FEBRERO | D24: ALQUILER | F24: 1200 | G24: =G23+E24-F24 -> 40.5 | H24: =+F24 -> 1200 | I24: LEON DIANA
A25: 45414 | B25: RII 2162 | C25: FEBRERO | D25: LUZ | F25: 35.5 | G25: =G24+E25-F25 -> 5
A26: 45414 | B26: RII 2162 | C26: FEBRERO | D26: AGUA | F26: 5 | G26: =G25+E26-F26 -> 0
A27: 45382 | B27: POR COBRAR | C27: MARZO | D27: LUZ | E27: 34.3 | G27: =G26+E27-F27 -> 34.3
D28: AGUA | E28: 5 | G28: =G27+E28-F28 -> 39.3
D29: ALQUILER | E29: 1200 | G29: =G28+E29-F29 -> 1239.3
A30: 45393 | B30: EB01-3554 | C30: MARZO | D30: ALQUILER | F30: 1200 | G30: =G29+E30-F30 -> 39.3
A31: 45414 | B31: RII 2162 | C31: MARZO | D31: LUZ | F31: 34.3 | G31: =G30+E31-F31 -> 5
A32: 45414 | B32: RII 2162 | C32: MARZO | D32: AGUA | F32: 5 | G32: =G31+E32-F32 -> -4.2632564e-14
A33: 45412 | B33: POR COBRAR | C33: ABRIL | D33: LUZ | E33: 34.1 | G33: =G32+E33-F33 -> 34.1
D34: AGUA | E34: 5 | G34: =G33+E34-F34 -> 39.1
D35: ALQUILER | E35: 1200 | G35: =G34+E35-F35 -> 1239.1
A36: 45430 | B36: EB01-3698 | C36: ABRIL | D36: ALQUILER | F36: 1200 | G36: =G35+E36-F36 -> 39.1
A37: 45526 | B37: RII 2361 | C37: ABRIL | D37: LUZ | F37: 34.1 | G37: =G36+E37-F37 -> 5
A38: 45526 | B38: RII 2361 | C38: ABRIL | D38: AGUA | F38: 5 | G38: =G37+E38-F38 -> -9.2370556e-14
A39: 45443 | B39: POR COBRAR | C39: MAYO | D39: LUZ | E39: 31.1 | G39: =G38+E39-F39 -> 31.1
D40: AGUA | E40: 5 | G40: =G39+E40-F40 -> 36.1
D41: ALQUILER | E41: 1200 | G41: =G40+E41-F41 -> 1236.1
...

Sheet CLAROS SANTOS
A2: CLAROS TORRES JESUS SANTOS
I3: RUC | J3: 10104498146
A4: FECHA | B4: DOCUMENTO | C4: PERIODO | D4: CONCEPTO | E4: POR COBRAR | F4: PAGADO | G4: SALDO POR COBRAR
G5: 0
A6: 31/06/2025 | B6: POR COBRAR | C6: JUNIO | D6: ALQUILER | E6: 700 | G6: =+G5+E6-F6 -> 700
D7: GARANTIA | E7: 1000 | G7: =+G6+E7-F7 -> 1700
D8: LUZ | E8: 14.3 | G8: =+G7+E8-F8 -> 1714.3
D9: AGUA | E9: 4 | G9: =+G8+E9-F9 -> 1718.3
A10: 45807 | B10: RII 2845 | C10: ABRIL | D10: GARANTIA | F10: 1000 | G10: =+G9+E10-F10 -> 718.3
A11: 45810 | B11: EB01-5583 | C11: ABRIL | D11: ALQUILER | F11: 500 | G11: =+G10+E11-F11 -> 218.3 | H11: =+F11 -> 500 | I11: PARQUEO | K11: JUNIO | L11: LUZ | M11: 14.3
A12: 45810 | B12: EB01-5583 | C12: ABRIL | D12: ALQUILER | F12: 200 | G12: =+G11+E12-F12 -> 18.3 | H12: =+F12 -> 200 | I12: PARQUEO | L12: AGUA | M12: 4
A13: 45939 | B13: RII 3027 | C13: JUNIO | D13: LUZ | F13: 14.3 | G13: =+G12+E13-F13 -> 4
A14: 45939 | B14: RII 3027 | C14: JUNIO | D14: AGUA | F14: 4 | G14: =+G13+E14-F14 -> -4.6185278e-14
A15: 45868 | B15: POR COBRAR | C15: JULIO | D15: LUZ | E15: 18.8 | G15: =+G14+E15-F15 -> 18.8 | K15: JULIO | L15: LUZ | M15: 18.8
D16: AGUA | E16: 4 | G16: =+G15+E16-F16 -> 22.8 | L16: AGUA | M16: 4
D17: ALQUILER | E17: 700 | G17: =+G16+E17-F17 -> 722.8 | L17: ALQUILER | M17: 300 | N17: =SUM(M11:M16) -> 41.1
A18: 45868 | B18: E001-217 | C18: JULIO | D18: ALQUILER | F18: 400 | G18: =+G17+E18-F18 -> 322.8 | M18: =SUM(M11:M17) -> 341.1
A19: 45902 | B19: E001-228 | C19: JULIO | D19: ALQUILER | F19: 160 | G19: =+G18+E19-F19 -> 162.8
A20: 45939 | B20: RII 3027 | C20: JULIO | D20: LUZ | F20: 18.8 | G20: =+G19+E20-F20 -> 144
A21: 45939 | B21: RII 3027 | C21: JULIO | D21: AGUA | F21: 4 | G21: =+G20+E21-F21 -> 140
A22: 45946 | B22: E001-242 | C22: JULIO | D22: ALQUILER | F22: 140 | G22: =+G21+E22-F22 -> 0
A23: 45899 | B23: POR COBRAR | C23: AGOSTO | D23: LUZ | E23: 7 | G23: =+G22+E23-F23 -> 7 | K23: CLAROS SANTOS
D24: AGUA | E24: 6 | G24: =+G23+E24-F24 -> 13 | J24: 2025 | K24: SETIEMBRE | L24: ALQUILER | M24: 140
D25: ALQUILER | E25: 700 | G25: =+G24+E25-F25 -> 713 | K25: OCTUBRE | L25: ALQUILER | M25: 700
A26: 45918 | B26: E001-232 | C26: AGOSTO | D26: ALQUILER | F26: 500 | G26: =+G25+E26-F26 -> 213 | K26: NOVIEMBRE | L26: ALQUILER | M26: 700
A27: 45939 | B27: RII 3027 | C27: AGOSTO | D27: LUZ | F27: 7 | G27: =+G26+E27-F27 -> 206 | M27: =SUM(M24:M26) -> 1540
A28: 45939 | B28: RII 3027 | C28: AGOSTO | D28: AGUA | F28: 6 | G28: =+G27+E28-F28 -> 200
A29: 45946 | B29: E001-242 | C29: AGOSTO | D29: ALQUILER | F29: 160 | G29: =+G28+E29-F29 -> 40
A30: 45946 | B30: E001-243 | C30: AGOSTO | D30: ALQUILER | F30: 40 | G30: =+G29+E30-F30 -> 0
A31: 31/09/2025 | B31: POR COBRAR | C31: SETIEMBRE | D31: LUZ | E31: 25 | G31: =+G30+E31-F31 -> 25 | H31: =SUM(H5:H26) -> 700 | I31: TOTALES
D32: AGUA | E32: 4 | G32: =+G31+E32-F32 -> 29
D33: ALQUILER | E33: 700 | G33: =+G32+E33-F33 -> 729 | K33: OCTUBRE | L33: LUZ | M33: 33.7
A34: 45946 | B34: E001-243 | C34: SETIEMBRE | D34: ALQUILER | F34: 60 | G34: =+G33+E34-F34 -> 669 | L34: AGUA | M34: 6
A35: 45952 | B35: RII 3044 | C35: SETIEMBRE | D35: LUZ | F35: 25 | G35: =+G34+E35-F35 -> 644 | M35: =SUM(M33:M34) -> 39.7
A36: 45952 | B36: RII 3044 | C36: SETIEMBRE | D36: AGUA | F36: 4 | G36: =+G35+E36-F36 -> 640
A37: 45966 | B37: E001-252 | C37: SETIEMBRE | D37: ALQUILER | F37: 500 | G37: =+G36+E37-F37 -> 140
A38: 45994 | B38: E001-267 | C38: SETIEMBRE | D38: ALQUILER | F38: 140 | G38: =+G37+E38-F38 -> 0 | K38: CLAROS SANTOS
A39: 45961 | B39: POR COBRAR | C39: OCTUBRE | D39: LUZ | E39: 33.7 | G39: =+G38+E39-F39 -> 33.7 | J39: 2025 | K39: NOVIEMBRE | L39: LUZ | M39: 24.4
D40: AGUA | E40: 6 | G40: =+G39+E40-F40 -> 39.7 | L40: AGUA | M40: 5
D41: ALQUILER | E41: 700 | G41: =+G40+E41-F41 -> 739.7 | L41: ALQUILER | M41: 500
...

Sheet CALLIROS FIORELLA
A1: CALLIRGOS GONZALES FIORELLA JAZMIN
