Workbook

Sheet 01-02-2026
A1: INGRESOS DEL DIA 01-02-2026
A3: INQUILINO | B3: COMPROBANTE | C3: DETALLE | D3: LUZ | E3: AGUA | F3: ALQUILER | G3: ESPACIO | H3: PARQUEO | I3: TICKET | J3: TOTAL
J4: =SUM(D4:I4) -> 0
J5: =SUM(D5:I5) -> 0
J6: =SUM(D6:I6) -> 0
J7: =SUM(D7:I7) -> 0
J8: =SUM(D8:I8) -> 0
J9: =SUM(D9:I9) -> 0
J10: =SUM(D10:I10) -> 0
J11: =SUM(D11:I11) -> 0
J12: =SUM(D12:I12) -> 0
J13: =SUM(D13:I13) -> 0
J14: =SUM(D14:I14) -> 0
J15: =SUM(D15:I15) -> 0
... J21: =SUM(D21:I21) -> 0
A22: TOTAL | D22: =SUM(D4:D21) -> 0 | E22: =SUM(E4:E21) -> 0 | F22: =SUM(F4:F21) -> 0 | G22: =SUM(G4:G21) -> 0 | H22: =SUM(H4:H21) -> 0 | I22: =SUM(I4:I21) -> 0 | J22: =SUM(J4:J21) -> 0
A24: BBVA
A25: INQUILINOS | B25: COMPROBANTE | C25: DETALLE | D25: LUZ | E25: AGUA | F25: ALQUILER | G25: ESPACIO | H25: DEPOSITO | I25: TICKET | J25: TOTAL
J26: =SUM(D26:I26) -> 0
J27: =SUM(D27:I27) -> 0
J28: =SUM(D28:I28) -> 0
J29: =SUM(D29:I29) -> 0 | L29: TOTAL QR | M29: =J30+J38 -> 0
A30: TOTAL | J30: =SUM(J26:J29) -> 0
A32: BBVA
A33: SOCIOS | B33: RECIBO DE SERVICIO | C33: DETALLE | D33: LUZ | E33: AGUA | F33: G. ADM | G33: P. SOCIAL | H33: DEPOSITO | I33: P.S X FALLECIMIENTO | J33: TOTAL
J34: =SUM(D34:I34) -> 0
J35: =SUM(D35:I35) -> 0
J36: =SUM(D36:I36) -> 0
J37: =SUM(D37:I37) -> 0
A38: TOTAL | J38: =SUM(J34:J37) -> 0
A42: SOCIO | B42: RECIBO DE SERVICIO | C42: DETALLE | D42: LUZ | E42: AGUA | F42: G. ADM | G42: P. SOCIAL | H42: P.S X FALLECIMIENTO | I42: DEPOSITO | J42: TOTAL
J43: =SUM(D43:I43) -> 0
J44: =SUM(D44:I44) -> 0
J45: =SUM(D45:I45) -> 0
J46: =SUM(D46:I46) -> 0
J47: =SUM(D47:I47) -> 0
J48: =SUM(D48:I48) -> 0
J49: =SUM(D49:I49) -> 0
J50: =SUM(D50:I50) -> 0
J51: =SUM(D51:I51) -> 0
...

Sheet 02-02-2026
A1: INGRESOS DEL DIA 02-02-2026
A3: INQUILINO | B3: COMPROBANTE | C3: DETALLE | D3: LUZ | E3: AGUA | F3: ALQUILER | G3: LOCAL 2DO PISO | H3: PARQUEO | I3: TICKET | J3: TOTAL
A4: PAÑITOS HUMEDOS | B4: TK 50748 | C4: 46054 | I4: 6 | J4: =SUM(D4:I4) -> 6
A5: JULIA | B5: TK 50749 | C5: 46054 | I5: 6 | J5: =SUM(D5:I5) -> 6
A6: JOSE | B6: TK 50750 | C6: 46054 | I6: 10 | J6: =SUM(D6:I6) -> 10
A7: JOSE | B7: TK 50751 | C7: 46054 | I7: 10 | J7: =SUM(D7:I7) -> 10
A8: ANATOLIA | B8: TK 50752 | C8: 46054 | I8: 10 | J8: =SUM(D8:I8) -> 10
A9: DESARMADORES | B9: TK 50753 | C9: 46054 | I9: 6 | J9: =SUM(D9:I9) -> 6
A10: ALFONSO GONZALO HUAMANI JUAREZ | B10: EB01-6779 | C10: 46054 | G10: 550 | J10: =SUM(D10:I10) -> 550
A11: LA ROSA MARGARITA | B11: EB01-6780 | C11: 46023 | F11: 800 | J11: =SUM(D11:I11) -> 800
A12: VIOLETA RETAMOZO | B12: EB01-6781 | C12: 46113 | G12: 100 | J12: =SUM(D12:I12) -> 100
A13: ZANABRIA LILIA | B13: EB01-6782 | C13: 46023 | F13: 350 | J13: =SUM(D13:I13) -> 350
A14: MAYHUASCA DORIS | B14: EB01-6783 | C14: 46023 | F14: 80 | J14: =SUM(D14:I14) -> 80
A15: CHOQUEHUANCA DERSE | B15: EB01-6784 | C15: 46023 | F15: 350 | J15: =SUM(D15:I15) -> 350
A16: PEÑA ASHLEY | B16: EB01-6785 | C16: 46054 | F16: 1000 | J16: =SUM(D16:I16) -> 1000
A17: ANCHAYA ABEL | B17: EB01-6786 | C17: 45962 | F17: 50 | J17: =SUM(D17:I17) -> 50
A18: PARQUEO | B18: EB01-6787 | C18: 46054 | H18: 56 | J18: =SUM(D18:I18) -> 56
A19: PRUDENCIO TUEROS | B19: EB01-6788 | C19: 46023 | F19: 500 | J19: =SUM(D19:I19) -> 500
A20: PARQUEO | B20: EB01-6790 | C20: 46054 | H20: 55.9 | J20: =SUM(D20:I20) -> 55.9
A21: CHOQUEHUANCA DERSE | B21: RII 3227 | C21: 45992 | D21: 7.7 | E21: 5 | J21: =SUM(D21:I21) -> 12.7
A22: PEÑA ASHLEY | B22: RII 3228 | C22: 45992 | D22: 30.9 | E22: 5 | J22: =SUM(D22:I22) -> 35.9
J23: =SUM(D23:I23) -> 0
J24: =SUM(D24:I24) -> 0
J25: =SUM(D25:I25) -> 0
J26: =SUM(D26:I26) -> 0
J27: =SUM(D27:I27) -> 0
A28: TOTAL | D28: =SUM(D4:D27) -> 38.6 | E28: =SUM(E4:E27) -> 10 | F28: =SUM(F4:F27) -> 3130 | G28: =SUM(G4:G27) -> 650 | H28: =SUM(H4:H27) -> 111.9 | I28: =SUM(I4:I27) -> 48 | J28: =SUM(J4:J27) -> 3988.5
A30: BBVA
A31: INQUILINOS | B31: COMPROBANTE | C31: DETALLE | D31: LUZ | E31: AGUA | F31: ALQUILER | G31: ESPACIO | H31: DEPOSITO | I31: TICKET | J31: TOTAL
A32: ADMINISTRADORA DE SERVICIOS FUNERARIOS SAC | B32: E001-310 | C32: 46054 | G32: 30 | J32: =SUM(D32:I32) -> 30
J33: =SUM(D33:I33) -> 0
J34: =SUM(D34:I34) -> 0
J35: =SUM(D35:I35) -> 0 | L35: TOTAL QR | M35: =J36+J44 -> 1197.6
A36: TOTAL | J36: =SUM(J32:J35) -> 30
A38: BBVA
A39: SOCIOS | B39: RECIBO DE SERVICIO | C39: DETALLE | D39: LUZ | E39: AGUA | F39: G. ADM | G39: P. SOCIAL | H39: DEPOSITO | I39: P.S X FALLECIMIENTO | J39: TOTAL
A40: QUISPE MIGUEL | B40: RI 32446 | C40: 45992 | D40: 618.6 | E40: 14 | J40: =SUM(D40:I40) -> 632.6
A41: NICHO ESTEPHANY | B41: RI 32447 | C41: 45992 | D41: 391.4 | E41: 78.6 | F41: 60 | G41: 5 | J41: =SUM(D41:I41) -> 535
J42: =SUM(D42:I42) -> 0
J43: =SUM(D43:I43) -> 0
...

Sheet 03-02-2026
A1: INGRESOS DEL DIA 03-02-2026
A3: INQUILINO | B3: COMPROBANTE | C3: DETALLE | D3: LUZ | E3: AGUA | F3: ALQUILER | G3: ESPACIO | H3: PARQUEO | I3: TICKET | J3: TOTAL
A4: JOSE | B4: TK 50754 | C4: 46054 | I4: 10 | J4: =SUM(D4:I4) -> 10
A5: FACILTERR S.A.C. | B5: E001-311 | C5: 46054 | G5: 200 | J5: =SUM(D5:I5) -> 200
A6: ESPARTA JULIO | B6: EB01-6792 | C6: 46023 | F6: 350 | J6: =SUM(D6:I6) -> 350
A7: QUISPE MARISOL | B7: EB01-6794 | C7: 45992 | F7: 10 | J7: =SUM(D7:I7) -> 10
B8: EB01-6795 | C8: 46023 | F8: 70 | J8: =SUM(D8:I8) -> 70
A9: PARQUEO | B9: EB01-6797 | C9: 46054 | H9: 61 | J9: =SUM(D9:I9) -> 61
J10: =SUM(D10:I10) -> 0
J11: =SUM(D11:I11) -> 0
A12: ESPARTA JULIO | B12: RII 3230 | C12: 45992 | D12: 44 | E12: 5 | J12: =SUM(D12:I12) -> 49
A13: QUISPE MARISOL | B13: RII 3231 | C13: 45992 | D13: 10 | E13: 5 | J13: =SUM(D13:I13) -> 15
J14: =SUM(D14:I14) -> 0
J15: =SUM(D15:I15) -> 0
J16: =SUM(D16:I16) -> 0
J17: =SUM(D17:I17) -> 0
J18: =SUM(D18:I18) -> 0
J19: =SUM(D19:I19) -> 0
J20: =SUM(D20:I20) -> 0
J21: =SUM(D21:I21) -> 0
A22: TOTAL | D22: =SUM(D4:D21) -> 54 | E22: =SUM(E4:E21) -> 10 | F22: =SUM(F4:F21) -> 430 | G22: =SUM(G4:G21) -> 200 | H22: =SUM(H4:H21) -> 61 | I22: =SUM(I4:I21) -> 10 | J22: =SUM(J4:J21) -> 765
A24: BBVA
A25: INQUILINOS | B25: COMPROBANTE | C25: DETALLE | D25: LUZ | E25: AGUA | F25: ALQUILER | G25: ESPACIO | H25: DEPOSITO | I25: TICKET | J25: TOTAL
A26: HERRERA ROMINA | B26: EB01-6791 | C26: 46023 | F26: 600 | J26: =SUM(D26:I26) -> 600
B27: RII 3229 | C27: 45992 | D27: 31.4 | E27: 5.3 | J27: =SUM(D27:I27) -> 36.7
C28: 46023 | D28: 1.3 | J28: =SUM(D28:I28) -> 1.3
A29: WALTER DAVID MOTA DAMAS | B29: EB01-6793 | C29: 46054 | G29: 30 | J29: =SUM(D29:I29) -> 30
J30: =SUM(D30:I30) -> 0 | L30: TOTAL QR | M30: =J31+J39 -> 668
A31: TOTAL | J31: =SUM(J26:J30) -> 668
A33: BBVA
A34: SOCIOS | B34: RECIBO DE SERVICIO | C34: DETALLE | D34: LUZ | E34: AGUA | F34: G. ADM | G34: P. SOCIAL | H34: DEPOSITO | I34: P.S X FALLECIMIENTO | J34: TOTAL
J35: =SUM(D35:I35) -> 0
J36: =SUM(D36:I36) -> 0
J37: =SUM(D37:I37) -> 0
J38: =SUM(D38:I38) -> 0
A39: TOTAL | J39: =SUM(J35:J38) -> 0
A43: SOCIO | B43: RECIBO DE SERVICIO | C43: DETALLE | D43: LUZ | E43: AGUA | F43: G. ADM | G43: P. SOCIAL | H43: P.S X FALLECIMIENTO | I43: DEPOSITO | J43: TOTAL
A44: YRUPAILLA ISIDRO | B44: RI 32450 | C44: 45992 | F44: 60 | G44: 5 | J44: =SUM(D44:I44) -> 65
C45: 46023 | F45: 60 | G45: 5 | H45: 10 | J45: =SUM(D45:I45) -> 75
A46: MELO MARINA | B46: RI 32451 | C46: 45992 | D46: 621.9 | E46: 24.6 | J46: =SUM(D46:I46) -> 646.5
...

Sheet 04-02-2026
A1: INGRESOS DEL DIA 04-02-2026
A3: INQUILINO | B3: COMPROBANTE | C3: DETALLE | D3: LUZ | E3: AGUA | F3: ALQUILER | G3: ESPACIO | H3: PARQUEO | I3: TICKET | J3: TOTAL
A4: JOSE | B4: TK 50755 | C4: 46054 | I4: 10 | J4: =SUM(D4:I4) -> 10
A5: CERVANTES CARLOS | B5: EB01-6798 | C5: 46023 | F5: 500 | J5: =SUM(D5:I5) -> 500
A6: ANCHAYA ABEL | B6: EB01-6801 | C6: 45962 | F6: 50 | J6: =SUM(D6:I6) -> 50
A7: AZURZA DAYSI | B7: EB01-6803 | C7: 46023 | F7: 200 | J7: =SUM(D7:I7) -> 200
A8: BENITES ERIKA | B8: EB01-6805 | C8: 46023 | F8: 100 | J8: =SUM(D8:I8) -> 100
A9: CCENCHO DAVID | B9: EB01-6807 | C9: 46023 | F9: 500 | J9: =SUM(D9:I9) -> 500
A10: CONDORI LIDIA | B10: EB01-6808 | C10: 45992 | F10: 200 | J10: =SUM(D10:I10) -> 200
A11: FLORES DOMINICA | B11: EB01-6811 | C11: 45992 | F11: 100 | J11: =SUM(D11:I11) -> 100
A12: PARQUEO | B12: EB01-6814 | C12: 46054 | H12: 61.5 | J12: =SUM(D12:I12) -> 61.5
J13: =SUM(D13:I13) -> 0
J14: =SUM(D14:I14) -> 0
A15: CERVANTES CARLOS | B15: RII 3232 | C15: 45992 | D15: 10 | E15: 5 | J15: =SUM(D15:I15) -> 15
A16: SATALAYA SEGUNDO | B16: RII 3235 | C16: 45992 | D16: 0.2 | J16: =SUM(D16:I16) -> 0.2
A17: CCENCHO DAVID | B17: RII 3237 | C17: 45992 | D17: 10 | E17: 5 | J17: =SUM(D17:I17) -> 15
A18: DAVILA YESENIA | B18: RII 3238 | C18: 45992 | D18: 10 | E18: 5 | J18: =SUM(D18:I18) -> 15
A19: CONDORI LIDIA | B19: RII 3239 | C19: 45962 | D19: 8.6 | E19: 5 | J19: =SUM(D19:I19) -> 13.6
C20: 45992 | D20: 8.2 | E20: 5 | J20: =SUM(D20:I20) -> 13.2
A21: FLORES DOMINICA | B21: RII 3240 | C21: 45992 | D21: 8.6 | E21: 5 | J21: =SUM(D21:I21) -> 13.6
A22: GOMEZ MARIBEL | B22: RII 3241 | C22: 45931 | D22: 7.2 | E22: 10 | J22: =SUM(D22:I22) -> 17.2
C23: 45962 | D23: 7.3 | E23: 15 | J23: =SUM(D23:I23) -> 22.3
C24: 45992 | D24: 7 | E24: 3.5 | J24: =SUM(D24:I24) -> 10.5
J25: =SUM(D25:I25) -> 0
J26: =SUM(D26:I26) -> 0
A27: TOTAL | D27: =SUM(D4:D26) -> 77.1 | E27: =SUM(E4:E26) -> 58.5 | F27: =SUM(F4:F26) -> 1650 | G27: =SUM(G4:G26) -> 0 | H27: =SUM(H4:H26) -> 61.5 | I27: =SUM(I4:I26) -> 10 | J27: =SUM(J4:J26) -> 1857.1
A29: BBVA
A30: INQUILINOS | B30: COMPROBANTE | C30: DETALLE | D30: LUZ | E30: AGUA | F30: ALQUILER | G30: ESPACIO | H30: DEPOSITO | I30: TICKET | J30: TOTAL
A31: LOVEMARK PUBLICIDAD PROMOCIONAL S.A.C. | B31: E001-312 | C31: 46054 | G31: 30 | J31: =SUM(D31:I31) -> 30
A32: CLAROS SANTOS | B32: E001-313 | C32: 45992 | F32: 80 | J32: =SUM(D32:I32) -> 80
A33: SATALAYA SEGUNDO | B33: EB01-6799 | C33: 45931 | F33: 330 | J33: =SUM(D33:I33) -> 330
C34: 45962 | F34: 70 | J34: =SUM(D34:I34) -> 70
A35: ANCHAYA ABEL | B35: EB01-6800 | C35: 45962 | F35: 50 | J35: =SUM(D35:I35) -> 50
A36: HERNANDEZ LILIBETH | B36: EB01-6802 | C36: 45992 | F36: 200 | J36: =SUM(D36:I36) -> 200
A37: BENITES ERIKA | B37: EB01-6804 | C37: 46023 | F37: 100 | J37: =SUM(D37:I37) -> 100
A38: DAVILA YESENIA | B38: EB01-6806 | C38: 46023 | F38: 500 | J38: =SUM(D38:I38) -> 500
A39: MALLMA LISBETH | B39: EB01-6809 | C39: 45992 | F39: 300 | J39: =SUM(D39:I39) -> 300
A40: MUJICA SANDRA | B40: EB01-6810 | C40: 45992 | F40: 150 | J40: =SUM(D40:I40) -> 150
A41: ENCARNACION GLADYS | B41: EB01-6812 | C41: 46023 | F41: 500 | J41: =SUM(D41:I41) -> 500
A42: HERNANDEZ LILIBETH | B42: RII 3233 | C42: 45992 | D42: 30 | E42: 5 | J42: =SUM(D42:I42) -> 35
...

Sheet 05-02-2026
A1: INGRESOS DEL DIA 05-02-2026
A3: INQUILINO | B3: COMPROBANTE | C3: DETALLE | D3: LUZ | E3: AGUA | F3: ALQUILER | G3: ESPACIO | H3: PARQUEO | I3: TICKET | J3: TOTAL
A4: JOSE | B4: TK 50756 | C4: 46054 | I4: 10 | J4: =SUM(D4:I4) -> 10
A5: GOMEZ MARIBEL | B5: EB01-6815 | C5: 46023 | F5: 600 | J5: =SUM(D5:I5) -> 600
A6: YUPANQUI SAYDA | B6: EB01-6816 | C6: 46023 | F6: 350 | J6: =SUM(D6:I6) -> 350
A7: PARQUEO | B7: EB01-6818 | C7: 46054 | H7: 51 | J7: =SUM(D7:I7) -> 51
A8: CLAROS SANTOS | B8: E001-314 | C8: 46023 | F8: 150 | J8: =SUM(D8:I8) -> 150
J9: =SUM(D9:I9) -> 0
J10: =SUM(D10:I10) -> 0
A11: YAURIMUCHA URSULA | B11: RII 3243 | C11: 45992 | D11: 10 | E11: 5 | J11: =SUM(D11:I11) -> 15
J12: =SUM(D12:I12) -> 0
J13: =SUM(D13:I13) -> 0
J14: =SUM(D14:I14) -> 0
J15: =SUM(D15:I15) -> 0
J16: =SUM(D16:I16) -> 0
J17: =SUM(D17:I17) -> 0
J18: =SUM(D18:I18) -> 0
J19: =SUM(D19:I19) -> 0
J20: =SUM(D20:I20) -> 0
J21: =SUM(D21:I21) -> 0
J22: =SUM(D22:I22) -> 0
A23: TOTAL | D23: =SUM(D4:D22) -> 10 | E23: =SUM(E4:E22) -> 5 | F23: =SUM(F4:F22) -> 1100 | G23: =SUM(G4:G22) -> 0 | H23: =SUM(H4:H22) -> 51 | I23: =SUM(I4:I22) -> 10 | J23: =SUM(J4:J22) -> 1176
A25: BBVA
A26: INQUILINOS | B26: COMPROBANTE | C26: DETALLE | D26: LUZ | E26: AGUA | F26: ALQUILER | G26: TALONARIO SANTA ROSA | H26: DEPOSITO | I26: TICKET | J26: TOTAL
A27: GOMEZ MARIBEL | B27: RII 3244 | C27: 45870 | G27: 15 | J27: =SUM(D27:I27) -> 15
C28: 45992 | E28: 21.1 | J28: =SUM(D28:I28) -> 21.1
J29: =SUM(D29:I29) -> 0
J30: =SUM(D30:I30) -> 0 | L30: TOTAL QR | M30: =J31+J39 -> 36.1
A31: TOTAL | J31: =SUM(J27:J30) -> 36.1
A33: BBVA
A34: SOCIOS | B34: RECIBO DE SERVICIO | C34: DETALLE | D34: LUZ | E34: AGUA | F34: G. ADM | G34: P. SOCIAL | H34: DEPOSITO | I34: P.S X FALLECIMIENTO | J34: TOTAL
J35: =SUM(D35:I35) -> 0
J36: =SUM(D36:I36) -> 0
J37: =SUM(D37:I37) -> 0
J38: =SUM(D38:I38) -> 0
A39: TOTAL | J39: =SUM(J35:J38) -> 0
A43: SOCIO | B43: RECIBO DE SERVICIO | C43: DETALLE | D43: LUZ | E43: AGUA | F43: G. ADM | G43: P. SOCIAL | H43: P.S X FALLECIMIENTO | I43: DEPOSITO | J43: TOTAL
A44: AYALA ELISEO | B44: RI 32470 | C44: 45992 | D44: 21.1 | E44: 6 | J44: =SUM(D44:I44) -> 27.1
C45: 46023 | F45: 60 | G45: 5 | I45: 150 | J45: =SUM(D45:I45) -> 215
A46: AYALA NORMA | B46: RI 32471 | C46: 45992 | D46: 21.1 | E46: 6 | J46: =SUM(D46:I46) -> 27.1
...

Sheet 06-02-2026
A1: INGRESOS DEL DIA 06-02-2026
A3: INQUILINO | B3: COMPROBANTE | C3: DETALLE | D3: LUZ | E3: AGUA | F3: ALQUILER | G3: ESPACIO | H3: PARQUEO | I3: TICKET | J3: TOTAL
A4: JOSE | B4: TK 50757 | C4: 46054 | I4: 10 | J4: =SUM(D4:I4) -> 10
A5: CERRON OBDULIA | B5: EB01-6819 | C5: 46023 | F5: 450 | J5: =SUM(D5:I5) -> 450
A6: SANCHEZ DIANA | B6: EB01-6820 | C6: 46023 | F6: 850 | J6: =SUM(D6:I6) -> 850
A7: WALTER DAVID MOTA DAMAS | B7: EB01-6821 | C7: 46054 | G7: 30 | J7: =SUM(D7:I7) -> 30
A8: LOPEZ HAYDEE | B8: EB01-6822 | C8: 46023 | F8: 500 | J8: =SUM(D8:I8) -> 500
A9: PARQUEO | B9: EB01-6824 | C9: 46054 | H9: 75 | J9: =SUM(D9:I9) -> 75
J10: =SUM(D10:I10) -> 0
J11: =SUM(D11:I11) -> 0
J12: =SUM(D12:I12) -> 0
A13: SANCHEZ DIANA | B13: RII 3245 | C13: 45992 | D13: 15.5 | E13: 5 | J13: =SUM(D13:I13) -> 20.5
A14: LOPEZ HAYDEE | B14: RII 3246 | C14: 45992 | D14: 10 | E14: 5 | J14: =SUM(D14:I14) -> 15
J15: =SUM(D15:I15) -> 0
J16: =SUM(D16:I16) -> 0
J17: =SUM(D17:I17) -> 0
J18: =SUM(D18:I18) -> 0
J19: =SUM(D19:I19) -> 0
J20: =SUM(D20:I20) -> 0
J21: =SUM(D21:I21) -> 0
J22: =SUM(D22:I22) -> 0
A23: TOTAL | D23: =SUM(D4:D22) -> 25.5 | E23: =SUM(E4:E22) -> 10 | F23: =SUM(F4:F22) -> 1800 | G23: =SUM(G4:G22) -> 30 | H23: =SUM(H4:H22) -> 75 | I23: =SUM(I4:I22) -> 10 | J23: =SUM(J4:J22) -> 1950.5
A25: BBVA
A26: INQUILINOS | B26: COMPROBANTE | C26: DETALLE | D26: LUZ | E26: AGUA | F26: ALQUILER | G26: ESPACIO | H26: DEPOSITO | I26: TICKET | J26: TOTAL
J27: =SUM(D27:I27) -> 0
J28: =SUM(D28:I28) -> 0
J29: =SUM(D29:I29) -> 0
J30: =SUM(D30:I30) -> 0 | L30: TOTAL QR | M30: =J31+J39 -> 84.6
A31: TOTAL | J31: =SUM(J27:J30) -> 0
A33: BBVA
A34: SOCIOS | B34: RECIBO DE SERVICIO | C34: DETALLE | D34: LUZ | E34: AGUA | F34: G. ADM | G34: P. SOCIAL | H34: DEPOSITO | I34: P.S X FALLECIMIENTO | J34: TOTAL
A35: CUSI SONIA | B35: RI 32479 | C35: 45962 | D35: 27.9 | E35: 6 | J35: =SUM(D35:I35) -> 33.9
C36: 45992 | D36: 17.7 | E36: 6 | F36: 22 | G36: 5 | J36: =SUM(D36:I36) -> 50.7
J37: =SUM(D37:I37) -> 0
J38: =SUM(D38:I38) -> 0
A39: TOTAL | J39: =SUM(J35:J38) -> 84.6
A43: SOCIO | B43: RECIBO DE SERVICIO | C43: DETALLE | D43: LUZ | E43: AGUA | F43: G. ADM | G43: P. SOCIAL | H43: P.S X FALLECIMIENTO | I43: DEPOSITO | J43: TOTAL
A44: HEREDIA MARIA | B44: RI 32473 | C44: 45992 | D44: 8.3 | E44: 6 | J44: =SUM(D44:I44) -> 14.3
A45: AGUIRRE WILFREDO | B45: RI 32474 | C45: 45992 | D45: 32.1 | E45: 6 | J45: =SUM(D45:I45) -> 38.1
C46: 46023 | I46: 200 | J46: =SUM(D46:I46) -> 200
...

Sheet 07-02-2026
A1: INGRESOS DEL DIA 07-02-2026
A3: INQUILINO | B3: COMPROBANTE | C3: DETALLE | D3: LUZ | E3: AGUA | F3: ALQUILER | G3: LOCAL 2DO PISO | H3: PARQUEO | I3: TICKET | J3: TOTAL
A4: FERREYRA TANIA | B4: E001-315 | C4: 46054 | F4: 350 | J4: =SUM(D4:I4) -> 350
A5: ANATOLIA CHIPANA DE VARGAS | B5: EB01-6825 | C5: 46054 | F5: 140 | J5: =SUM(D5:I5) -> 140
A6: AURORA ISABEL NEYRA CONTRERAS | B6: EB01-6826 | C6: 46054 | G6: 500 | J6: =SUM(D6:I6) -> 500
A7: ROSA | B7: TK 50758 | C7: 46054 | I7: 6 | J7: =SUM(D7:I7) -> 6
A8: JOSE | B8: TK 50759 | C8: 46054 | I8: 10 | J8: =SUM(D8:I8) -> 10
J9: =SUM(D9:I9) -> 0
J10: =SUM(D10:I10) -> 0
J11: =SUM(D11:I11) -> 0
J12: =SUM(D12:I12) -> 0
J13: =SUM(D13:I13) -> 0
J14: =SUM(D14:I14) -> 0
J15: =SUM(D15:I15) -> 0
J16: =SUM(D16:I16) -> 0
J17: =SUM(D17:I17) -> 0
J18: =SUM(D18:I18) -> 0
J19: =SUM(D19:I19) -> 0
J20: =SUM(D20:I20) -> 0
... J22: =SUM(D22:I22) -> 0
A23: TOTAL | D23: =SUM(D4:D22) -> 0 | E23: =SUM(E4:E22) -> 0 | F23: =SUM(F4:F22) -> 490 | G23: =SUM(G4:G22) -> 500 | H23: =SUM(H4:H22) -> 0 | I23: =SUM(I4:I22) -> 16 | J23: =SUM(J4:J22) -> 1006
A25: BBVA
A26: INQUILINOS | B26: COMPROBANTE | C26: DETALLE | D26: LUZ | E26: AGUA | F26: ALQUILER | G26: ESPACIO | H26: DEPOSITO | I26: TICKET | J26: TOTAL
A27: PIZARRO ROMANI RAQUEL SONIA | B27: E001-316 | C27: 46060 | G27: 30 | J27: =SUM(D27:I27) -> 30
J28: =SUM(D28:I28) -> 0
J29: =SUM(D29:I29) -> 0
J30: =SUM(D30:I30) -> 0 | L30: TOTAL QR | M30: =J31+J39 -> 30
A31: TOTAL | J31: =SUM(J27:J30) -> 30
A33: BBVA
A34: SOCIOS | B34: RECIBO DE SERVICIO | C34: DETALLE | D34: LUZ | E34: AGUA | F34: G. ADM | G34: P. SOCIAL | H34: DEPOSITO | I34: P.S X FALLECIMIENTO | J34: TOTAL
J35: =SUM(D35:I35) -> 0
J36: =SUM(D36:I36) -> 0
J37: =SUM(D37:I37) -> 0
J38: =SUM(D38:I38) -> 0
A39: TOTAL | J39: =SUM(J35:J38) -> 0
A43: SOCIO | B43: RECIBO DE SERVICIO | C43: DETALLE | D43: LUZ | E43: AGUA | F43: G. ADM | G43: P. SOCIAL | H43: P.S X FALLECIMIENTO | I43: DEPOSITO | J43: TOTAL
A44: CABALLERO GLADYS | B44: RI 32480 | C44: 46023 | F44: 60 | G44: 5 | J44: =SUM(D44:I44) -> 65
B45: RI 32481 | C45: 46054 | F45: 60 | G45: 5 | J45: =SUM(D45:I45) -> 65
J46: =SUM(D46:I46) -> 0
J47: =SUM(D47:I47) -> 0
...

Sheet 08-02-2026
A1: INGRESOS DEL DIA 08-02-2026
A3: INQUILINO | B3: COMPROBANTE | C3: DETALLE | D3: LUZ | E3: AGUA | F3: ALQUILER | G3: ESPACIO | H3: PARQUEO | I3: TICKET | J3: TOTAL
A4: JOSE | B4: TK 50760 | C4: 46054 | I4: 10 | J4: =SUM(D4:I4) -> 10
A5: JOSE DESARMADORES | B5: TK 50761 | C5: 46054 | I5: 10 | J5: =SUM(D5:I5) -> 10
J6: =SUM(D6:I6) -> 0
J7: =SUM(D7:I7) -> 0
J8: =SUM(D8:I8) -> 0
J9: =SUM(D9:I9) -> 0
J10: =SUM(D10:I10) -> 0
J11: =SUM(D11:I11) -> 0
J12: =SUM(D12:I12) -> 0
J13: =SUM(D13:I13) -> 0
J14: =SUM(D14:I14) -> 0
J15: =SUM(D15:I15) -> 0
J16: =SUM(D16:I16) -> 0
J17: =SUM(D17:I17) -> 0
... J21: =SUM(D21:I21) -> 0
A22: TOTAL | D22: =SUM(D4:D21) -> 0 | E22: =SUM(E4:E21) -> 0 | F22: =SUM(F4:F21) -> 0 | G22: =SUM(G4:G21) -> 0 | H22: =SUM(H4:H21) -> 0 | I22: =SUM(I4:I21) -> 20 | J22: =SUM(J4:J21) -> 20
A24: BBVA
A25: INQUILINOS | B25: COMPROBANTE | C25: DETALLE | D25: LUZ | E25: AGUA | F25: ALQUILER | G25: ESPACIO | H25: DEPOSITO | I25: TICKET | J25: TOTAL
J26: =SUM(D26:I26) -> 0
J27: =SUM(D27:I27) -> 0
J28: =SUM(D28:I28) -> 0
J29: =SUM(D29:I29) -> 0 | L29: TOTAL QR | M29: =J30+J38 -> 0
A30: TOTAL | J30: =SUM(J26:J29) -> 0
A32: BBVA
A33: SOCIOS | B33: RECIBO DE SERVICIO | C33: DETALLE | D33: LUZ | E33: AGUA | F33: G. ADM | G33: P. SOCIAL | H33: DEPOSITO | I33: P.S X FALLECIMIENTO | J33: TOTAL
J34: =SUM(D34:I34) -> 0
J35: =SUM(D35:I35) -> 0
J36: =SUM(D36:I36) -> 0
J37: =SUM(D37:I37) -> 0
A38: TOTAL | J38: =SUM(J34:J37) -> 0
A42: SOCIO | B42: RECIBO DE SERVICIO | C42: DETALLE | D42: LUZ | E42: AGUA | F42: G. ADM | G42: P. SOCIAL | H42: P.S X FALLECIMIENTO | I42: DEPOSITO | J42: TOTAL
J43: =SUM(D43:I43) -> 0
J44: =SUM(D44:I44) -> 0
J45: =SUM(D45:I45) -> 0
J46: =SUM(D46:I46) -> 0
J47: =SUM(D47:I47) -> 0
J48: =SUM(D48:I48) -> 0
J49: =SUM(D49:I49) -> 0
...

Sheet 09-02-2026
A1: INGRESOS DEL DIA 09-02-2026
A3: INQUILINO | B3: COMPROBANTE | C3: DETALLE | D3: LUZ | E3: AGUA | F3: ALQUILER | G3: ESPACIO | H3: PARQUEO | I3: TICKET | J3: TOTAL
A4: JOSE | B4: TK 50762 | C4: 46054 | I4: 10 | J4: =SUM(D4:I4) -> 10
A5: VASQUEZ MARGARITA | B5: EB01-6829 | C5: 46054 | G5: 100 | J5: =SUM(D5:I5) -> 100
A6: PARQUEO | B6: EB01-6831 | C6: 46054 | H6: 56 | J6: =SUM(D6:I6) -> 56
A7: PARQUEO | B7: EB01-6833 | C7: 46054 | H7: 54 | J7: =SUM(D7:I7) -> 54
J8: =SUM(D8:I8) -> 0
J9: =SUM(D9:I9) -> 0
J10: =SUM(D10:I10) -> 0
J11: =SUM(D11:I11) -> 0
J12: =SUM(D12:I12) -> 0
J13: =SUM(D13:I13) -> 0
J14: =SUM(D14:I14) -> 0
J15: =SUM(D15:I15) -> 0
J16: =SUM(D16:I16) -> 0
J17: =SUM(D17:I17) -> 0
J18: =SUM(D18:I18) -> 0
J19: =SUM(D19:I19) -> 0
... J22: =SUM(D22:I22) -> 0
A23: TOTAL | D23: =SUM(D4:D22) -> 0 | E23: =SUM(E4:E22) -> 0 | F23: =SUM(F4:F22) -> 0 | G23: =SUM(G4:G22) -> 100 | H23: =SUM(H4:H22) -> 110 | I23: =SUM(I4:I22) -> 10 | J23: =SUM(J4:J22) -> 220
A25: BBVA
A26: INQUILINOS | B26: COMPROBANTE | C26: DETALLE | D26: LUZ | E26: AGUA | F26: ALQUILER | G26: ESPACIO | H26: DEPOSITO | I26: TICKET | J26: TOTAL
A27: MARIBEL GOMEZ MITMA | B27: EB01-6830 | C27: 46054 | G27: 60 | J27: =SUM(D27:I27) -> 60
J28: =SUM(D28:I28) -> 0
J29: =SUM(D29:I29) -> 0
J30: =SUM(D30:I30) -> 0 | L30: TOTAL QR | M30: =J31+J39 -> 60
A31: TOTAL | J31: =SUM(J27:J30) -> 60
A33: BBVA
A34: SOCIOS | B34: RECIBO DE SERVICIO | C34: DETALLE | D34: LUZ | E34: AGUA | F34: G. ADM | G34: P. SOCIAL | H34: DEPOSITO | I34: P.S X FALLECIMIENTO | J34: TOTAL
J35: =SUM(D35:I35) -> 0
J36: =SUM(D36:I36) -> 0
J37: =SUM(D37:I37) -> 0
J38: =SUM(D38:I38) -> 0
A39: TOTAL | J39: =SUM(J35:J38) -> 0
A43: SOCIO | B43: RECIBO DE SERVICIO | C43: DETALLE | D43: LUZ | E43: AGUA | F43: G. ADM | G43: P. SOCIAL | H43: P.S X FALLECIMIENTO | I43: MULTA X CAPACITACION | J43: TOTAL
A44: MAYHUASCA CLUDY | B44: RI 32482 | C44: 45992 | D44: 330.9 | E44: 28 | J44: =SUM(D44:I44) -> 358.9
C45: 45658 | H45: 10 | J45: =SUM(D45:I45) -> 10
A46: URETA EMILIA | B46: RI 32483 | C46: 45992 | D46: 89.9 | E46: 23.4 | J46: =SUM(D46:I46) -> 113.3
A47: ESTRADA OSCAR | B47: RI 32484 | C47: 45992 | D47: 19.2 | E47: 91.7 | J47: =SUM(D47:I47) -> 110.9
C48: 45658 | F48: 56 | G48: 5 | H48: 10 | I48: 28.3 | J48: =SUM(D48:I48) -> 99.3
...

Sheet 10-02-2026
A1: INGRESOS DEL DIA 10-02-2026
A3: INQUILINO | B3: COMPROBANTE | C3: DETALLE | D3: LUZ | E3: AGUA | F3: ALQUILER | G3: ESPACIO | H3: PARQUEO | I3: TICKET | J3: TOTAL
A4: JOSE | B4: TK 50763 | C4: 46054 | I4: 10 | J4: =SUM(D4:I4) -> 10
A5: MOTA DAVID | B5: EB01-6834 | C5: 46054 | G5: 30 | J5: =SUM(D5:I5) -> 30
A6: CHAMBI SIMONA | B6: EB01-6835 | C6: 46023 | F6: 500 | J6: =SUM(D6:I6) -> 500
A7: BURGA ELMER | B7: EB01-6836 | C7: 46023 | F7: 500 | J7: =SUM(D7:I7) -> 500
A8: QUISPE PATRICIA | B8: EB01-6837 | C8: 46023 | F8: 300 | J8: =SUM(D8:I8) -> 300
A9: CARRASCO MERY | B9: EB01-6840 | C9: 46023 | F9: 220 | J9: =SUM(D9:I9) -> 220
A10: PRADO MILAGROS | B10: EB01-6842 | C10: 46023 | F10: 600 | J10: =SUM(D10:I10) -> 600
A11: PARQUEO | B11: EB01-6844 | C11: 46054 | H11: 68 | J11: =SUM(D11:I11) -> 68
J12: =SUM(D12:I12) -> 0
A13: CHAMBI SIMONA | B13: RII 3247 | C13: 45992 | D13: 10 | E13: 5 | J13: =SUM(D13:I13) -> 15
A14: QUISPE PATRICIA | B14: RII 3248 | C14: 45992 | D14: 10 | E14: 5 | J14: =SUM(D14:I14) -> 15
A15: BUSTAMANTE GRACIELA | B15: RII 3249 | C15: 45992 | D15: 6.5 | E15: 5 | J15: =SUM(D15:I15) -> 11.5
J16: =SUM(D16:I16) -> 0
J17: =SUM(D17:I17) -> 0
J18: =SUM(D18:I18) -> 0
J19: =SUM(D19:I19) -> 0
J20: =SUM(D20:I20) -> 0
J21: =SUM(D21:I21) -> 0
J22: =SUM(D22:I22) -> 0
J23: =SUM(D23:I23) -> 0
A24: TOTAL | D24: =SUM(D4:D23) -> 26.5 | E24: =SUM(E4:E23) -> 15 | F24: =SUM(F4:F23) -> 2120 | G24: =SUM(G4:G23) -> 30 | H24: =SUM(H4:H23) -> 68 | I24: =SUM(I4:I23) -> 10 | J24: =SUM(J4:J23) -> 2269.5
A26: BBVA
A27: INQUILINOS | B27: COMPROBANTE | C27: DETALLE | D27: LUZ | E27: AGUA | F27: ALQUILER | G27: ESPACIO | H27: DEPOSITO | I27: TICKET | J27: TOTAL
A28: QUISPE PATRICIA | B28: EB01-6838 | C28: 46023 | F28: 400 | J28: =SUM(D28:I28) -> 400
A29: BUSTAMANTE GRACIELA | B29: EB01-6839 | C29: 46023 | F29: 500 | J29: =SUM(D29:I29) -> 500
A30: CARRASCO MERY | B30: EB01-6841 | C30: 46023 | F30: 100 | J30: =SUM(D30:I30) -> 100
J31: =SUM(D31:I31) -> 0 | L31: TOTAL QR | M31: =J32+J44 -> 1467.2
A32: TOTAL | J32: =SUM(J28:J31) -> 1000
A34: BBVA
A35: SOCIOS | B35: RECIBO DE SERVICIO | C35: DETALLE | D35: LUZ | E35: AGUA | F35: G. ADM | G35: P. SOCIAL | H35: DEPOSITO | I35: P.S X FALLECIMIENTO | J35: TOTAL
A36: BRAVO ANA | B36: RI 32487 | C36: 45992 | D36: 109.7 | E36: 6 | J36: =SUM(D36:I36) -> 115.7
A37: SANCHEZ LUCIA | B37: RI 32488 | C37: 45962 | D37: 25 | E37: 6 | F37: 60 | G37: 5 | J37: =SUM(D37:I37) -> 96
C38: 45992 | D38: 25.3 | E38: 6 | F38: 60 | G38: 5 | J38: =SUM(D38:I38) -> 96.3
A39: MAYHUASCA ULISES | B39: RI 32489 | C39: 45962 | D39: 38.6 | E39: 6 | J39: =SUM(D39:I39) -> 44.6
C40: 45992 | D40: 33.6 | E40: 6 | J40: =SUM(D40:I40) -> 39.6
C41: 46023 | F41: 60 | G41: 5 | I41: 10 | J41: =SUM(D41:I41) -> 75
J42: =SUM(D42:I42) -> 0
J43: =SUM(D43:I43) -> 0
...

Sheet 11-02-2026
A1: INGRESOS DEL DIA 11-02-2026
A3: INQUILINO | B3: COMPROBANTE | C3: DETALLE | D3: LUZ | E3: AGUA | F3: ALQUILER | G3: FUMIGACION | H3: PARQUEO | I3: DEPOSITO | J3: TOTAL
A4: QUISPE MARISOL | B4: EB01-6845 | C4: 46023 | F4: 100 | J4: =SUM(D4:I4) -> 100
A5: ANCHAYA ABEL | B5: EB01-6846 | C5: 45962 | F5: 50 | J5: =SUM(D5:I5) -> 50
C6: 45992 | F6: 50 | J6: =SUM(D6:I6) -> 50
A7: SALAZAR MARIA | B7: EB01-6849 | C7: 45962 | F7: 100 | J7: =SUM(D7:I7) -> 100
A8: ARREDONDO GLADYS | B8: EB01-6850 | C8: 46023 | F8: 90 | J8: =SUM(D8:I8) -> 90
A9: PARQUEO | B9: EB01-6852 | C9: 46054 | F9: 72 | J9: =SUM(D9:I9) -> 72
J10: =SUM(D10:I10) -> 0
J11: =SUM(D11:I11) -> 0
J12: =SUM(D12:I12) -> 0
J13: =SUM(D13:I13) -> 0
J14: =SUM(D14:I14) -> 0
J15: =SUM(D15:I15) -> 0
J16: =SUM(D16:I16) -> 0
J17: =SUM(D17:I17) -> 0
A18: CLAROS SANTOS JESUS | B18: E001-317 | C18: 46023 | F18: 100 | J18: =SUM(D18:I18) -> 100
A19: ANCHAYA ABEL | B19: RII 3250 | C19: 45931 | G19: 5 | J19: =SUM(D19:I19) -> 5
A20: SALDAÑA JESSICA | B20: RII 3220 | C20: 46023 | I20: 200 | J20: =SUM(D20:I20) -> 200
J21: =SUM(D21:I21) -> 0
J22: =SUM(D22:I22) -> 0
J23: =SUM(D23:I23) -> 0
J24: =SUM(D24:I24) -> 0
A25: TOTAL | D25: =SUM(D4:D24) -> 0 | E25: =SUM(E4:E24) -> 0 | F25: =SUM(F4:F24) -> 562 | G25: =SUM(G4:G24) -> 5 | H25: =SUM(H4:H24) -> 0 | I25: =SUM(I4:I24) -> 200 | J25: =SUM(J4:J24) -> 767
A27: BBVA
A28: INQUILINOS | B28: COMPROBANTE | C28: DETALLE | D28: LUZ | E28: AGUA | F28: ALQUILER | G28: ESPACIO | H28: DEPOSITO | I28: TICKET | J28: TOTAL
A29: MALLMA LISBETH | B29: RII 3251 | C29: 45962 | D29: 18.4 | E29: 5 | J29: =SUM(D29:I29) -> 23.4
C30: 45992 | D30: 46.1 | E30: 5 | J30: =SUM(D30:I30) -> 51.1
B31: EB01-6847 | C31: 45962 | F31: 19.3 | J31: =SUM(D31:I31) -> 19.3
C32: 45992 | F32: 56.2 | J32: =SUM(D32:I32) -> 56.2
A33: SANDRA MUJICA | B33: EB01-6848 | C33: 45992 | F33: 150 | J33: =SUM(D33:I33) -> 150
A34: ACCO VICTOR | B34: RII 3253 | C34: 45992 | H34: 150 | J34: =SUM(D34:I34) -> 150
C35: 45992 | H35: 150 | J35: =SUM(D35:I35) -> 150
C36: 46023 | H36: 150 | J36: =SUM(D36:I36) -> 150
C37: 46023 | H37: 150 | J37: =SUM(D37:I37) -> 150
J38: =SUM(D38:I38) -> 0
J39: =SUM(D39:I39) -> 0 | L39: TOTAL QR | M39: =J40+J52 -> 1718.4
A40: TOTAL | J40: =SUM(J29:J39) -> 900
A42: BBVA
A43: SOCIOS | B43: RECIBO DE SERVICIO | C43: DETALLE | D43: LUZ | E43: AGUA | F43: G. ADM | G43: P. SOCIAL | H43: DEPOSITO | I43: P.S X FALLECIMIENTO | J43: TOTAL
...

Sheet 12-02-2026
A1: INGRESOS DEL DIA 12-02-2026
A3: INQUILINO | B3: COMPROBANTE | C3: DETALLE | D3: LUZ | E3: AGUA | F3: ALQUILER | G3: ESPACIO | H3: PARQUEO | I3: TICKET | J3: TOTAL
A4: JOSE | B4: TK 50764 | C4: 46054 | I4: 10 | J4: =SUM(D4:I4) -> 10
A5: CAYO BACILIO | B5: EB01-6853 | C5: 46023 | F5: 300 | J5: =SUM(D5:I5) -> 300
A6: SEGUNDO SATALAYA | B6: EB01-6856 | C6: 45962 | F6: 170 | J6: =SUM(D6:I6) -> 170
A7: COLINA SIRLEY | B7: EB01-6857 | C7: 46023 | F7: 1200 | J7: =SUM(D7:I7) -> 1200
A8: PARQUEO | B8: EB01-6859 | C8: 46054 | H8: 46.5 | J8: =SUM(D8:I8) -> 46.5
J9: =SUM(D9:I9) -> 0
J10: =SUM(D10:I10) -> 0
J11: =SUM(D11:I11) -> 0
J12: =SUM(D12:I12) -> 0
J13: =SUM(D13:I13) -> 0
J14: =SUM(D14:I14) -> 0
J15: =SUM(D15:I15) -> 0
J16: =SUM(D16:I16) -> 0
J17: =SUM(D17:I17) -> 0
J18: =SUM(D18:I18) -> 0
J19: =SUM(D19:I19) -> 0
J20: =SUM(D20:I20) -> 0
J21: =SUM(D21:I21) -> 0
A22: TOTAL | D22: =SUM(D4:D21) -> 0 | E22: =SUM(E4:E21) -> 0 | F22: =SUM(F4:F21) -> 1670 | G22: =SUM(G4:G21) -> 0 | H22: =SUM(H4:H21) -> 46.5 | I22: =SUM(I4:I21) -> 10 | J22: =SUM(J4:J21) -> 1726.5
A24: BBVA
A25: INQUILINOS | B25: COMPROBANTE | C25: DETALLE | D25: LUZ | E25: AGUA | F25: ALQUILER | G25: ESPACIO | H25: DEPOSITO | I25: TICKET | J25: TOTAL
A26: CAMARENA GABRIELA | B26: EB01-6854 | C26: 46054 | F26: 60 | J26: =SUM(D26:I26) -> 60
A27: SEGUNDO SATALAYA | B27: EB01-6855 | C27: 45962 | F27: 30 | J27: =SUM(D27:I27) -> 30
J28: =SUM(D28:I28) -> 0
J29: =SUM(D29:I29) -> 0 | L29: TOTAL QR | M29: =J30+J38 -> 90
A30: TOTAL | J30: =SUM(J26:J29) -> 90
A32: BBVA
A33: SOCIOS | B33: RECIBO DE SERVICIO | C33: DETALLE | D33: LUZ | E33: AGUA | F33: G. ADM | G33: P. SOCIAL | H33: DEPOSITO | I33: P.S X FALLECIMIENTO | J33: TOTAL
J34: =SUM(D34:I34) -> 0
J35: =SUM(D35:I35) -> 0
J36: =SUM(D36:I36) -> 0
J37: =SUM(D37:I37) -> 0
A38: TOTAL | J38: =SUM(J34:J37) -> 0
A42: SOCIO | B42: RECIBO DE SERVICIO | C42: DETALLE | D42: LUZ | E42: AGUA | F42: G. ADM | G42: P. SOCIAL | H42: P.S X FALLECIMIENTO | I42: DEPOSITO | J42: TOTAL
A43: CAMPUZANO VICENTA | B43: RI 32504 | C43: 45962 | D43: 17 | E43: 6 | J43: =SUM(D43:I43) -> 23
C44: 45992 | D44: 14.6 | E44: 6 | J44: =SUM(D44:I44) -> 20.6
J45: =SUM(D45:I45) -> 0
J46: =SUM(D46:I46) -> 0
...

Sheet 13-02-2026
A1: INGRESOS DEL DIA 13-02-2026
A3: INQUILINO | B3: COMPROBANTE | C3: DETALLE | D3: LUZ | E3: AGUA | F3: ALQUILER | G3: ESPACIO | H3: PARQUEO | I3: TICKET | J3: TOTAL
A4: JOSE | B4: TK 50765 | C4: 46054 | I4: 10 | J4: =SUM(D4:I4) -> 10
A5: ARREDONDO GLADYS | B5: RII 3254 | C5: 45901 | D5: 10 | E5: 4 | J5: =SUM(D5:I5) -> 14
C6: 45931 | D6: 10 | E6: 6 | J6: =SUM(D6:I6) -> 16
C7: 45962 | D7: 10 | E7: 5 | J7: =SUM(D7:I7) -> 15
C8: 45992 | D8: 10 | E8: 5 | J8: =SUM(D8:I8) -> 15
A10: FRANCISCO CONTESOR TORRES ASTO | B10: EB01-6860 | C10: 46054 | G10: 30 | J10: =SUM(D10:I10) -> 30
A11: PARQUEO | B11: EB01-6862 | C11: 46054 | H11: 48 | J11: =SUM(D11:I11) -> 48
J12: =SUM(D12:I12) -> 0
J13: =SUM(D13:I13) -> 0
J14: =SUM(D14:I14) -> 0
J15: =SUM(D15:I15) -> 0
J16: =SUM(D16:I16) -> 0
J17: =SUM(D17:I17) -> 0
J18: =SUM(D18:I18) -> 0
J19: =SUM(D19:I19) -> 0
J20: =SUM(D20:I20) -> 0
J21: =SUM(D21:I21) -> 0
J22: =SUM(D22:I22) -> 0
A23: TOTAL | D23: =SUM(D4:D22) -> 40 | E23: =SUM(E4:E22) -> 20 | F23: =SUM(F4:F22) -> 0 | G23: =SUM(G4:G22) -> 30 | H23: =SUM(H4:H22) -> 48 | I23: =SUM(I4:I22) -> 10 | J23: =SUM(J4:J22) -> 148
A25: BBVA
A26: INQUILINOS | B26: COMPROBANTE | C26: DETALLE | D26: LUZ | E26: AGUA | F26: ALQUILER | G26: ESPACIO | H26: DEPOSITO | I26: TICKET | J26: TOTAL
J27: =SUM(D27:I27) -> 0
J28: =SUM(D28:I28) -> 0
J29: =SUM(D29:I29) -> 0
J30: =SUM(D30:I30) -> 0 | L30: TOTAL QR | M30: =J31+J39 -> 0
A31: TOTAL | J31: =SUM(J27:J30) -> 0
A33: BBVA
A34: SOCIOS | B34: RECIBO DE SERVICIO | C34: DETALLE | D34: LUZ | E34: AGUA | F34: G. ADM | G34: P. SOCIAL | H34: DEPOSITO | I34: P.S X FALLECIMIENTO | J34: TOTAL
J35: =SUM(D35:I35) -> 0
J36: =SUM(D36:I36) -> 0
J37: =SUM(D37:I37) -> 0
J38: =SUM(D38:I38) -> 0
A39: TOTAL | J39: =SUM(J35:J38) -> 0
A43: SOCIO | B43: RECIBO DE SERVICIO | C43: DETALLE | D43: LUZ | E43: AGUA | F43: G. ADM | G43: P. SOCIAL | H43: P.S X FALLECIMIENTO | I43: DEPOSITO | J43: TOTAL
A44: SERMEÑO JAVIER | B44: RI 32505 | C44: 45992 | D44: 299.9 | E44: 15 | J44: =SUM(D44:I44) -> 314.9
A45: CASTRO AQUILA | B45: RI 32506 | C45: 45992 | D45: 45 | E45: 15 | J45: =SUM(D45:I45) -> 60
A46: SALAZAR VICTORIA | B46: RI 32507 | C46: 45992 | D46: 14.6 | E46: 6 | J46: =SUM(D46:I46) -> 20.6
B47: RI 32508 | C47: 46023 | F47: 60 | G47: 5 | J47: =SUM(D47:I47) -> 65
...

Sheet 14-02-2026
A1: INGRESOS DEL DIA 14-02-2026
A3: INQUILINO | B3: COMPROBANTE | C3: DETALLE | D3: LUZ | E3: AGUA | F3: ALQUILER | G3: ESPACIO | H3: PARQUEO | I3: TICKET | J3: TOTAL
A4: JOSE | B4: TK 50766 | C4: 46054 | G4: 10 | J4: =SUM(D4:I4) -> 10
A5: CAMILA | B5: TK 50767 | C5: 46054 | G5: 15 | J5: =SUM(D5:I5) -> 15
A6: QUISPE LISBETH | B6: EB01-6863 | C6: 45992 | F6: 300 | J6: =SUM(D6:I6) -> 300
A7: PIZARRO RAQUEL SONIA | B7: EB01-6864 | C7: 46054 | G7: 30 | J7: =SUM(D7:I7) -> 30
A8: PARQUEO | B8: EB01-6867 | C8: 46054 | H8: 63 | J8: =SUM(D8:I8) -> 63
J9: =SUM(D9:I9) -> 0
J10: =SUM(D10:I10) -> 0
J11: =SUM(D11:I11) -> 0
J12: =SUM(D12:I12) -> 0
J13: =SUM(D13:I13) -> 0
J14: =SUM(D14:I14) -> 0
J15: =SUM(D15:I15) -> 0
J16: =SUM(D16:I16) -> 0
J17: =SUM(D17:I17) -> 0
J18: =SUM(D18:I18) -> 0
J19: =SUM(D19:I19) -> 0
J20: =SUM(D20:I20) -> 0
... J22: =SUM(D22:I22) -> 0
A23: TOTAL | D23: =SUM(D4:D22) -> 0 | E23: =SUM(E4:E22) -> 0 | F23: =SUM(F4:F22) -> 300 | G23: =SUM(G4:G22) -> 55 | H23: =SUM(H4:H22) -> 63 | I23: =SUM(I4:I22) -> 0 | J23: =SUM(J4:J22) -> 418
A25: BBVA
A26: INQUILINOS | B26: COMPROBANTE | C26: DETALLE | D26: LUZ | E26: AGUA | F26: ALQUILER | G26: ESPACIO | H26: DEPOSITO | I26: TICKET | J26: TOTAL
J27: =SUM(D27:I27) -> 0
J28: =SUM(D28:I28) -> 0
J29: =SUM(D29:I29) -> 0
J30: =SUM(D30:I30) -> 0 | L30: TOTAL QR | M30: =J31+J39 -> 0
A31: TOTAL | J31: =SUM(J27:J30) -> 0
A33: BBVA
A34: SOCIOS | B34: RECIBO DE SERVICIO | C34: DETALLE | D34: LUZ | E34: AGUA | F34: G. ADM | G34: P. SOCIAL | H34: DEPOSITO | I34: P.S X FALLECIMIENTO | J34: TOTAL
J35: =SUM(D35:I35) -> 0
J36: =SUM(D36:I36) -> 0
J37: =SUM(D37:I37) -> 0
J38: =SUM(D38:I38) -> 0
A39: TOTAL | J39: =SUM(J35:J38) -> 0
A43: SOCIO | B43: RECIBO DE SERVICIO | C43: DETALLE | D43: LUZ | E43: AGUA | F43: G. ADM | G43: P. SOCIAL | H43: P.S X FALLECIMIENTO | I43: DEPOSITO | J43: TOTAL
J44: =SUM(D44:I44) -> 0
J45: =SUM(D45:I45) -> 0
J46: =SUM(D46:I46) -> 0
J47: =SUM(D47:I47) -> 0
...

Sheet 15-02-2026
A1: INGRESOS DEL DIA 15-02-2026
A3: INQUILINO | B3: COMPROBANTE | C3: DETALLE | D3: LUZ | E3: AGUA | F3: ALQUILER | G3: ESPACIO | H3: PARQUEO | I3: TICKET | J3: TOTAL
J4: =SUM(D4:I4) -> 0
J5: =SUM(D5:I5) -> 0
J6: =SUM(D6:I6) -> 0
J7: =SUM(D7:I7) -> 0
J8: =SUM(D8:I8) -> 0
J9: =SUM(D9:I9) -> 0
J10: =SUM(D10:I10) -> 0
J11: =SUM(D11:I11) -> 0
J12: =SUM(D12:I12) -> 0
J13: =SUM(D13:I13) -> 0
J14: =SUM(D14:I14) -> 0
J15: =SUM(D15:I15) -> 0
... J21: =SUM(D21:I21) -> 0
A22: TOTAL | D22: =SUM(D4:D21) -> 0 | E22: =SUM(E4:E21) -> 0 | F22: =SUM(F4:F21) -> 0 | G22: =SUM(G4:G21) -> 0 | H22: =SUM(H4:H21) -> 0 | I22: =SUM(I4:I21) -> 0 | J22: =SUM(J4:J21) -> 0
A24: BBVA
A25: INQUILINOS | B25: COMPROBANTE | C25: DETALLE | D25: LUZ | E25: AGUA | F25: ALQUILER | G25: ESPACIO | H25: DEPOSITO | I25: TICKET | J25: TOTAL
J26: =SUM(D26:I26) -> 0
J27: =SUM(D27:I27) -> 0
J28: =SUM(D28:I28) -> 0
J29: =SUM(D29:I29) -> 0 | L29: TOTAL QR | M29: =J30+J38 -> 0
A30: TOTAL | J30: =SUM(J26:J29) -> 0
A32: BBVA
A33: SOCIOS | B33: RECIBO DE SERVICIO | C33: DETALLE | D33: LUZ | E33: AGUA | F33: G. ADM | G33: P. SOCIAL | H33: DEPOSITO | I33: P.S X FALLECIMIENTO | J33: TOTAL
J34: =SUM(D34:I34) -> 0
J35: =SUM(D35:I35) -> 0
J36: =SUM(D36:I36) -> 0
J37: =SUM(D37:I37) -> 0
A38: TOTAL | J38: =SUM(J34:J37) -> 0
A42: SOCIO | B42: RECIBO DE SERVICIO | C42: DETALLE | D42: LUZ | E42: AGUA | F42: G. ADM | G42: P. SOCIAL | H42: P.S X FALLECIMIENTO | I42: DEPOSITO | J42: TOTAL
J43: =SUM(D43:I43) -> 0
J44: =SUM(D44:I44) -> 0
J45: =SUM(D45:I45) -> 0
J46: =SUM(D46:I46) -> 0
J47: =SUM(D47:I47) -> 0
J48: =SUM(D48:I48) -> 0
J49: =SUM(D49:I49) -> 0
J50: =SUM(D50:I50) -> 0
J51: =SUM(D51:I51) -> 0
...

Sheet 16-02-2026
A1: INGRESOS DEL DIA 16-02-2026
A3: INQUILINO | B3: COMPROBANTE | C3: DETALLE | D3: LUZ | E3: AGUA | F3: ALQUILER | G3: ESPACIO | H3: PARQUEO | I3: MULTA POR CAPACITACION | J3: TOTAL
A4: CAMARENA GABRIELA | B4: EB01-6869 | C4: 46054 | G4: 60 | J4: =SUM(D4:I4) -> 60
A5: QUISPE MARISOL | B5: EB01-6870 | C5: 46023 | F5: 50 | J5: =SUM(D5:I5) -> 50
A6: PARQUEO | B6: EB01-6872 | C6: 46054 | H6: 51.5 | J6: =SUM(D6:I6) -> 51.5
J7: =SUM(D7:I7) -> 0
J8: =SUM(D8:I8) -> 0
J9: =SUM(D9:I9) -> 0
J10: =SUM(D10:I10) -> 0
J11: =SUM(D11:I11) -> 0
J12: =SUM(D12:I12) -> 0
A13: PRADO MILAGROS | B13: RII 3255 | C13: 46023 | I13: 28.3 | J13: =SUM(D13:I13) -> 28.3
J14: =SUM(D14:I14) -> 0
J15: =SUM(D15:I15) -> 0
J16: =SUM(D16:I16) -> 0
J17: =SUM(D17:I17) -> 0
J18: =SUM(D18:I18) -> 0
J19: =SUM(D19:I19) -> 0
J20: =SUM(D20:I20) -> 0
A21: TOTAL | D21: =SUM(D4:D20) -> 0 | E21: =SUM(E4:E20) -> 0 | F21: =SUM(F4:F20) -> 50 | G21: =SUM(G4:G20) -> 60 | H21: =SUM(H4:H20) -> 51.5 | I21: =SUM(I4:I20) -> 28.3 | J21: =SUM(J4:J20) -> 189.8
A23: BBVA
A24: INQUILINOS | B24: COMPROBANTE | C24: DETALLE | D24: LUZ | E24: AGUA | F24: ALQUILER | G24: ESPACIO | H24: DEPOSITO | I24: TICKET | J24: TOTAL
J25: =SUM(D25:I25) -> 0
J26: =SUM(D26:I26) -> 0
J27: =SUM(D27:I27) -> 0
J28: =SUM(D28:I28) -> 0 | L28: TOTAL QR | M28: =J29+J39 -> 510
A29: TOTAL | J29: =SUM(J25:J28) -> 0
A31: BBVA
A32: SOCIOS | B32: RECIBO DE SERVICIO | C32: DETALLE | D32: LUZ | E32: AGUA | F32: G. ADM | G32: P. SOCIAL | H32: DEPOSITO | I32: P.S X FALLECIMIENTO | J32: TOTAL
A33: HALIRE JOSUE | B33: RI 32513 | C33: 45962 | D33: 24.7 | E33: 7 | H33: 200 | J33: =SUM(D33:I33) -> 231.7
C34: 45992 | D34: 25.8 | E34: 6.1 | H34: 200 | J34: =SUM(D34:I34) -> 231.9
C35: 46023 | D35: 28.4 | E35: 8 | I35: 10 | J35: =SUM(D35:I35) -> 46.4
J38: =SUM(D38:I38) -> 0
A39: TOTAL | J39: =SUM(J33:J38) -> 510
A43: SOCIO | B43: RECIBO DE SERVICIO | C43: DETALLE | D43: LUZ | E43: AGUA | F43: G. ADM | G43: P. SOCIAL | H43: P.S X FALLECIMIENTO | I43: DEPOSITO | J43: TOTAL
A44: RIVERA JUANA | B44: RI 32512 | C44: 45962 | D44: 31.3 | E44: 6 | J44: =SUM(D44:I44) -> 37.3
C45: 45992 | D45: 31.8 | E45: 6 | J45: =SUM(D45:I45) -> 37.8
C46: 46054 | D46: 30.9 | E46: 5 | J46: =SUM(D46:I46) -> 35.9
A47: HALIRE JOSUE | B47: RI 32514 | C47: 46023 | E47: 0.1 | J47: =SUM(D47:I47) -> 0.1
A48: CCOYLLO POLANCO DANIEL | B48: RI 32515 | C48: 46023 | D48: 325.6 | E48: 5 | F48: 60 | G48: 5 | J48: =SUM(D48:I48) -> 395.6
...

Sheet 17-02-2026
A1: INGRESOS DEL DIA 17-02-2026
A3: INQUILINO | B3: COMPROBANTE | C3: DETALLE | D3: LUZ | E3: AGUA | F3: ALQUILER | G3: ESPACIO | H3: PARQUEO | I3: TICKET | J3: TOTAL
A4: JOSE DESARMADORES | B4: TK 50768 | C4: 46054 | I4: 10 | J4: =SUM(D4:I4) -> 10
A5: JOSE | B5: TK 50769 | C5: 46054 | I5: 10 | J5: =SUM(D5:I5) -> 10
A6: JOSE | B6: TK 50770 | C6: 46054 | I6: 10 | J6: =SUM(D6:I6) -> 10
A7: PEÑA TERESA | B7: EB01-6873 | C7: 46023 | F7: 600 | J7: =SUM(D7:I7) -> 600
A8: ALARCON MARTHA | B8: EB01-6874 | C8: 46023 | F8: 550 | J8: =SUM(D8:I8) -> 550
A9: PARQUEO | B9: EB01-6876 | C9: 46054 | H9: 45 | J9: =SUM(D9:I9) -> 45
J10: =SUM(D10:I10) -> 0
J11: =SUM(D11:I11) -> 0
J12: =SUM(D12:I12) -> 0
J13: =SUM(D13:I13) -> 0
A14: PEÑA TERESA | B14: RII 3256 | C14: 45931 | E14: 6 | J14: =SUM(D14:I14) -> 6
C15: 45962 | D15: 10 | E15: 5 | J15: =SUM(D15:I15) -> 15
C16: 45992 | D16: 10 | E16: 5 | J16: =SUM(D16:I16) -> 15
C17: 46023 | D17: 15 | E17: 3 | J17: =SUM(D17:I17) -> 18
A18: ALARCON MARTHA | B18: RII 3257 | C18: 46023 | D18: 36 | E18: 15 | J18: =SUM(D18:I18) -> 51
J19: =SUM(D19:I19) -> 0
J20: =SUM(D20:I20) -> 0
J21: =SUM(D21:I21) -> 0
A22: TOTAL | D22: =SUM(D4:D21) -> 71 | E22: =SUM(E4:E21) -> 34 | F22: =SUM(F4:F21) -> 1150 | G22: =SUM(G4:G21) -> 0 | H22: =SUM(H4:H21) -> 45 | I22: =SUM(I4:I21) -> 30 | J22: =SUM(J4:J21) -> 1330
A24: BBVA
A25: INQUILINOS | B25: COMPROBANTE | C25: DETALLE | D25: LUZ | E25: AGUA | F25: ALQUILER | G25: ESPACIO | H25: DEPOSITO | I25: TICKET | J25: TOTAL
J26: =SUM(D26:I26) -> 0
J27: =SUM(D27:I27) -> 0
J28: =SUM(D28:I28) -> 0
J29: =SUM(D29:I29) -> 0 | L29: TOTAL QR | M29: =J30+J40 -> 462.4
A30: TOTAL | J30: =SUM(J26:J29) -> 0
A32: BBVA
A33: SOCIOS | B33: RECIBO DE SERVICIO | C33: DETALLE | D33: LUZ | E33: AGUA | F33: G. ADM | G33: P. SOCIAL | H33: DEPOSITO | I33: P.S X FALLECIMIENTO | J33: TOTAL
A34: GAVILAN NORMA | B34: RI 32521 | C34: 46023 | D34: 25.7 | E34: 108.4 | J34: =SUM(D34:I34) -> 134.1
A35: CALDERON ESTELA | B35: RI 32523 | C35: 45992 | D35: 89.9 | E35: 6 | F35: 60 | G35: 5 | J35: =SUM(D35:I35) -> 160.9
C36: 46023 | D36: 87.4 | E36: 5 | F36: 60 | G36: 5 | I36: 10 | J36: =SUM(D36:I36) -> 167.4
J39: =SUM(D39:I39) -> 0
A40: TOTAL | J40: =SUM(J34:J39) -> 462.4
A44: SOCIO | B44: RECIBO DE SERVICIO | C44: DETALLE | D44: LUZ | E44: AGUA | F44: G. ADM | G44: P. SOCIAL | H44: P.S X FALLECIMIENTO | I44: DEPOSITO | J44: TOTAL
A45: PAREDES FLORES OSCAR | B45: RI 32517 | C45: 45992 | D45: 150.4 | E45: 6 | J45: =SUM(D45:I45) -> 156.4
A46: ROMERO JAVIER | B46: RI 32518 | C46: 45962 | D46: 60.4 | E46: 6 | J46: =SUM(D46:I46) -> 66.4
C47: 45992 | D47: 61.3 | E47: 6 | J47: =SUM(D47:I47) -> 67.3
C48: 46023 | D48: 59.6 | E48: 5 | J48: =SUM(D48:I48) -> 64.6
...

Sheet 18-02-2026
A1: INGRESOS DEL DIA 18-02-2026
A3: INQUILINO | B3: COMPROBANTE | C3: DETALLE | D3: LUZ | E3: AGUA | F3: ALQUILER | G3: ESPACIO | H3: PARQUEO | I3: TICKET | J3: TOTAL
A4: JOSE | B4: TK 50771 | C4: 46054 | I4: 10 | J4: =SUM(D4:I4) -> 10
A5: HERRERA ORFELITA | B5: EB01-6877 | C5: 46023 | F5: 600 | J5: =SUM(D5:I5) -> 600
A6: QUISPE MARISOL | B6: EB01-6878 | C6: 46023 | F6: 100 | J6: =SUM(D6:I6) -> 100
A7: ANCHAYA ABEL | B7: EB01-6880 | C7: 45992 | F7: 150 | J7: =SUM(D7:I7) -> 150
A8: SATALAYA SEGUNDO | B8: EB01-6881 | C8: 45962 | F8: 140 | J8: =SUM(D8:I8) -> 140
A9: MALLMA LISBETH | B9: EB01-6882 | C9: 45992 | F9: 143.8 | J9: =SUM(D9:I9) -> 143.8
C10: 46023 | F10: 6.2 | J10: =SUM(D10:I10) -> 6.2
A11: MUJICA SANDRA | B11: EB01-6883 | C11: 45992 | F11: 32.4 | J11: =SUM(D11:I11) -> 32.4
C12: 46023 | F12: 101 | J12: =SUM(D12:I12) -> 101
A13: AZURZA DAYSI | B13: EB01-6885 | C13: 46023 | F13: 40 | J13: =SUM(D13:I13) -> 40
A14: BENITES ERIKA | B14: EB01-6886 | C14: 46023 | F14: 200 | J14: =SUM(D14:I14) -> 200
A15: ARREDONDO GLADIS | B15: EB01-6887 | C15: 45992 | F15: 100 | J15: =SUM(D15:I15) -> 100
A16: FLORES DOMINICA | B16: EB01-6888 | C16: 46023 | F16: 200 | J16: =SUM(D16:I16) -> 200
A17: CONDORI LIDIA | B17: EB01-6889 | C17: 45992 | F17: 150 | J17: =SUM(D17:I17) -> 150
A18: PARQUEO | B18: EB01-6891 | C18: 46054 | H18: 53 | J18: =SUM(D18:I18) -> 53
J19: =SUM(D19:I19) -> 0
A20: CLAROS SANTOS JESUS | B20: E001-319 | C20: 46023 | F20: 50 | J20: =SUM(D20:I20) -> 50
J21: =SUM(D21:I21) -> 0
J22: =SUM(D22:I22) -> 0
A23: MUJICA SANDRA | B23: RII 3259 | C23: 45992 | D23: 11.6 | E23: 5 | J23: =SUM(D23:I23) -> 16.6
A24: CONDORI LIDIA | B24: RII 3260 | C24: 46023 | D24: 7.6 | E24: 3 | J24: =SUM(D24:I24) -> 10.6
J25: =SUM(D25:I25) -> 0
J26: =SUM(D26:I26) -> 0
J27: =SUM(D27:I27) -> 0
J28: =SUM(D28:I28) -> 0
A29: TOTAL | D29: =SUM(D4:D28) -> 19.2 | E29: =SUM(E4:E28) -> 8 | F29: =SUM(F4:F28) -> 2013.4 | G29: =SUM(G4:G28) -> 0 | H29: =SUM(H4:H28) -> 53 | I29: =SUM(I4:I28) -> 10 | J29: =SUM(J4:J28) -> 2103.6
A31: BBVA
A32: INQUILINOS | B32: COMPROBANTE | C32: DETALLE | D32: LUZ | E32: AGUA | F32: ALQUILER | G32: ESPACIO | H32: DEPOSITO | I32: TICKET | J32: TOTAL
A33: CLAROS SANTOS JESUS | B33: E001-318 | C33: 46023 | F33: 100 | J33: =SUM(D33:I33) -> 100
A34: ASAEL CASTILLO | B34: EB01-6879 | C34: 46023 | F34: 700 | J34: =SUM(D34:I34) -> 700
A35: AZURZA DAYSI | B35: EB01-6884 | C35: 46023 | F35: 160 | J35: =SUM(D35:I35) -> 160
A36: ASAEL CASTILLO | B36: RII 3258 | C36: 45992 | D36: 26.6 | E36: 5 | J36: =SUM(D36:I36) -> 31.6
J37: =SUM(D37:I37) -> 0
J38: =SUM(D38:I38) -> 0 | L38: TOTAL QR | M38: =J39+J50 -> 1592.9
A39: TOTAL | J39: =SUM(J33:J38) -> 991.6
A41: BBVA
A42: SOCIOS | B42: RECIBO DE SERVICIO | C42: DETALLE | D42: LUZ | E42: AGUA | F42: G. ADM | G42: P. SOCIAL | H42: DEPOSITO | I42: P.S X FALLECIMIENTO | J42: TOTAL
A43: ROJAS LIONILA | B43: RI 32527 | C43: 45962 | D43: 68.5 | E43: 6 | J43: =SUM(D43:I43) -> 74.5
...

Sheet 19-02-2026
A1: INGRESOS DEL DIA 19-02-2026
A3: INQUILINO | B3: COMPROBANTE | C3: DETALLE | D3: LUZ | E3: AGUA | F3: ALQUILER | G3: ESPACIO | H3: PARQUEO | I3: TICKET | J3: TOTAL
A4: JOSE | B4: TK 50772 | C4: 46054 | I4: 10 | J4: =SUM(D4:I4) -> 10
A5: AIRE HECTOR | B5: EB01-6892 | C5: 46023 | F5: 300 | J5: =SUM(D5:I5) -> 300
A6: CUNIAS MARIELA | B6: EB01-6893 | C6: 46054 | F6: 50 | J6: =SUM(D6:I6) -> 50
A7: PARQUEO | B7: EB01-6896 | C7: 46054 | H7: 70.3 | J7: =SUM(D7:I7) -> 70.3
J8: =SUM(D8:I8) -> 0
J9: =SUM(D9:I9) -> 0
J10: =SUM(D10:I10) -> 0
A11: AIRE HECTOR | B11: RII 3261 | C11: 45992 | D11: 17 | E11: 12 | J11: =SUM(D11:I11) -> 29
C12: 46023 | D12: 17 | E12: 11 | J12: =SUM(D12:I12) -> 28
A13: CUNIAS MARIELA | B13: RII 3262 | C13: 45901 | D13: 8 | E13: 4 | J13: =SUM(D13:I13) -> 12
C14: 45931 | D14: 6 | E14: 2 | J14: =SUM(D14:I14) -> 8
J15: =SUM(D15:I15) -> 0
J16: =SUM(D16:I16) -> 0
J17: =SUM(D17:I17) -> 0
J18: =SUM(D18:I18) -> 0
J19: =SUM(D19:I19) -> 0
J20: =SUM(D20:I20) -> 0
J21: =SUM(D21:I21) -> 0
A22: TOTAL | D22: =SUM(D4:D21) -> 48 | E22: =SUM(E4:E21) -> 29 | F22: =SUM(F4:F21) -> 350 | G22: =SUM(G4:G21) -> 0 | H22: =SUM(H4:H21) -> 70.3 | I22: =SUM(I4:I21) -> 10 | J22: =SUM(J4:J21) -> 507.3
A24: BBVA
A25: INQUILINOS | B25: COMPROBANTE | C25: DETALLE | D25: LUZ | E25: AGUA | F25: ALQUILER | G25: ESPACIO | H25: DEPOSITO | I25: TICKET | J25: TOTAL
A26: CUNIAS MARIELA | B26: EB01-6894 | C26: 46054 | F26: 450 | J26: =SUM(D26:I26) -> 450
J27: =SUM(D27:I27) -> 0
J28: =SUM(D28:I28) -> 0
J29: =SUM(D29:I29) -> 0 | L29: TOTAL QR | M29: =J30+J38 -> 450
A30: TOTAL | J30: =SUM(J26:J29) -> 450
A32: BBVA
A33: SOCIOS | B33: RECIBO DE SERVICIO | C33: DETALLE | D33: LUZ | E33: AGUA | F33: G. ADM | G33: P. SOCIAL | H33: DEPOSITO | I33: P.S X FALLECIMIENTO | J33: TOTAL
J34: =SUM(D34:I34) -> 0
J35: =SUM(D35:I35) -> 0
J36: =SUM(D36:I36) -> 0
J37: =SUM(D37:I37) -> 0
A38: TOTAL | J38: =SUM(J34:J37) -> 0
A42: SOCIO | B42: RECIBO DE SERVICIO | C42: DETALLE | D42: LUZ | E42: AGUA | F42: G. ADM | G42: P. SOCIAL | H42: P.S X FALLECIMIENTO | I42: DEPOSITO | J42: TOTAL
A43: ANULADO | B43: RI 32538 | J43: =SUM(D43:I43) -> 0
A44: CALLE ALVAREZ MARCO | B44: RI 32539 | C44: 45992 | D44: 10.7 | E44: 6 | J44: =SUM(D44:I44) -> 16.7
B45: RI 32540 | C45: 46023 | D45: 10.7 | E45: 5 | J45: =SUM(D45:I45) -> 15.7
A46: CALLE FIDEL | B46: RI 32541 | C46: 46023 | F46: 60 | G46: 5 | H46: 10 | J46: =SUM(D46:I46) -> 75
...

Sheet 20-02-2026
A1: INGRESOS DEL DIA 20-02-2026
A3: INQUILINO | B3: COMPROBANTE | C3: DETALLE | D3: LUZ | E3: AGUA | F3: ALQUILER | G3: OTROS | H3: PARQUEO | I3: TICKET | J3: TOTAL
A4: JOSE | B4: TK 50773 | C4: 46054 | I4: 10 | J4: =SUM(D4:I4) -> 10
A5: ARREDONDO GLADYS | B5: EB01-6898 | C5: 46023 | F5: 100 | J5: =SUM(D5:I5) -> 100
A6: PARQUEO | B6: EB01-6899 | C6: 46054 | H6: 59 | J6: =SUM(D6:I6) -> 59
A7: PRETEL LUCAS (MAQUINA DE CHICLES) | B7: 10893 | C7: 46054 | G7: 45.2 | J7: =SUM(D7:I7) -> 45.2
J8: =SUM(D8:I8) -> 0
A9: AYALA MARLENE | B9: RI 3263 | C9: 46023 | D9: 117.2 | E9: 3 | J9: =SUM(D9:I9) -> 120.2
J10: =SUM(D10:I10) -> 0
J11: =SUM(D11:I11) -> 0
J12: =SUM(D12:I12) -> 0
J13: =SUM(D13:I13) -> 0
J14: =SUM(D14:I14) -> 0
J15: =SUM(D15:I15) -> 0
J16: =SUM(D16:I16) -> 0
J17: =SUM(D17:I17) -> 0
J18: =SUM(D18:I18) -> 0
J19: =SUM(D19:I19) -> 0
J20: =SUM(D20:I20) -> 0
J21: =SUM(D21:I21) -> 0
A22: TOTAL | D22: =SUM(D4:D21) -> 117.2 | E22: =SUM(E4:E21) -> 3 | F22: =SUM(F4:F21) -> 100 | G22: =SUM(G4:G21) -> 45.2 | H22: =SUM(H4:H21) -> 59 | I22: =SUM(I4:I21) -> 10 | J22: =SUM(J4:J21) -> 334.4
A24: BBVA
A25: INQUILINOS | B25: COMPROBANTE | C25: DETALLE | D25: LUZ | E25: AGUA | F25: ALQUILER | G25: ESPACIO | H25: DEPOSITO | I25: TICKET | J25: TOTAL
A26: SALAZAR MARIA | B26: EB01-6897 | C26: 45962 | F26: 200 | J26: =SUM(D26:I26) -> 200
C27: 45992 | F27: 500 | J27: =SUM(D27:I27) -> 500
C28: 46023 | F28: 500 | J28: =SUM(D28:I28) -> 500
B29: RII 3264 | C29: 46023 | D29: 15.7 | E29: 3 | J29: =SUM(D29:I29) -> 18.7
J30: =SUM(D30:I30) -> 0
J31: =SUM(D31:I31) -> 0 | L31: TOTAL QR | M31: =J32+J40 -> 1294.2
A32: TOTAL | J32: =SUM(J26:J31) -> 1218.7
A34: BBVA
A35: SOCIOS | B35: RECIBO DE SERVICIO | C35: DETALLE | D35: LUZ | E35: AGUA | F35: G. ADM | G35: P. SOCIAL | H35: DEPOSITO | I35: P.S X FALLECIMIENTO | J35: TOTAL
A36: BERNAOLA FLORENCIA | B36: RI 32543 | C36: 45992 | D36: 1.2 | E36: 74.3 | J36: =SUM(D36:I36) -> 75.5
J37: =SUM(D37:I37) -> 0
J38: =SUM(D38:I38) -> 0
J39: =SUM(D39:I39) -> 0
A40: TOTAL | J40: =SUM(J36:J39) -> 75.5
A44: SOCIO | B44: RECIBO DE SERVICIO | C44: DETALLE | D44: LUZ | E44: AGUA | F44: G. ADM | G44: P. SOCIAL | H44: P.S X FALLECIMIENTO | I44: DEPOSITO | J44: TOTAL
A45: CRUZ LUIS | B45: RI 32542 | C45: 46023 | D45: 21.4 | E45: 5 | H45: 10 | J45: =SUM(D45:I45) -> 36.4
A46: CABALLERO GLADYS | B46: RI 32544 | C46: 45992 | D46: 5 | E46: 6 | J46: =SUM(D46:I46) -> 11
...

Sheet 21-02-2026
A1: INGRESOS DEL DIA 21-02-2026
A3: INQUILINO | B3: COMPROBANTE | C3: DETALLE | D3: LUZ | E3: AGUA | F3: ALQUILER | G3: ESPACIO | H3: PARQUEO | I3: TICKET | J3: TOTAL
A4: JOSE | B4: TK 50774 | C4: 46054 | I4: 10 | J4: =SUM(D4:I4) -> 10
A5: ADMINISTRADORA DE SERVICIOS FUNERARIOS SAC | B5: E001-320 | C5: 46054 | G5: 30 | J5: =SUM(D5:I5) -> 30
J6: =SUM(D6:I6) -> 0
A7: PALOMINO ROSA | B7: EB01-6901 | C7: 46054 | F7: 650 | J7: =SUM(D7:I7) -> 650
J8: =SUM(D8:I8) -> 0
J9: =SUM(D9:I9) -> 0
J10: =SUM(D10:I10) -> 0
J11: =SUM(D11:I11) -> 0
A12: PALOMINO ROSA | B12: RII 3265 | C12: 45992 | D12: 20.1 | E12: 5 | J12: =SUM(D12:I12) -> 25.1
C13: 46023 | D13: 19 | E13: 3 | J13: =SUM(D13:I13) -> 22
J14: =SUM(D14:I14) -> 0
J15: =SUM(D15:I15) -> 0
J16: =SUM(D16:I16) -> 0
J17: =SUM(D17:I17) -> 0
J18: =SUM(D18:I18) -> 0
J19: =SUM(D19:I19) -> 0
J20: =SUM(D20:I20) -> 0
J21: =SUM(D21:I21) -> 0
A22: TOTAL | D22: =SUM(D4:D21) -> 39.1 | E22: =SUM(E4:E21) -> 8 | F22: =SUM(F4:F21) -> 650 | G22: =SUM(G4:G21) -> 30 | H22: =SUM(H4:H21) -> 0 | I22: =SUM(I4:I21) -> 10 | J22: =SUM(J4:J21) -> 737.1
A24: BBVA
A25: INQUILINOS | B25: COMPROBANTE | C25: DETALLE | D25: LUZ | E25: AGUA | F25: ALQUILER | G25: ESPACIO | H25: DEPOSITO | I25: TICKET | J25: TOTAL
J26: =SUM(D26:I26) -> 0
J27: =SUM(D27:I27) -> 0
J28: =SUM(D28:I28) -> 0
J29: =SUM(D29:I29) -> 0 | L29: TOTAL QR | M29: =J30+J38 -> 90.9
A30: TOTAL | J30: =SUM(J26:J29) -> 0
A32: BBVA
A33: SOCIOS | B33: RECIBO DE SERVICIO | C33: DETALLE | D33: LUZ | E33: AGUA | F33: G. ADM | G33: P. SOCIAL | H33: DEPOSITO | I33: P.S X FALLECIMIENTO | J33: TOTAL
A34: SANCHEZ JUDITH | B34: RI 32546 | C34: 46023 | D34: 42.3 | E34: 48.6 | J34: =SUM(D34:I34) -> 90.9
J35: =SUM(D35:I35) -> 0
J36: =SUM(D36:I36) -> 0
J37: =SUM(D37:I37) -> 0
A38: TOTAL | J38: =SUM(J34:J37) -> 90.9
A42: SOCIO | B42: RECIBO DE SERVICIO | C42: DETALLE | D42: LUZ | E42: AGUA | F42: G. ADM | G42: P. SOCIAL | H42: P.S X FALLECIMIENTO | I42: MULTA | J42: TOTAL
A43: ESPEJO ROSA | B43: RI 32545 | C43: 45992 | D43: 102.6 | E43: 6 | F43: 60 | G43: 5 | J43: =SUM(D43:I43) -> 173.6
C44: 46023 | D44: 99.7 | E44: 5 | F44: 60 | G44: 5 | I44: 28.3 | J44: =SUM(D44:I44) -> 198
J45: =SUM(D45:I45) -> 0
J46: =SUM(D46:I46) -> 0
...

Sheet 22-02-2026
A1: INGRESOS DEL DIA 22-02-2026
A3: INQUILINO | B3: COMPROBANTE | C3: DETALLE | D3: LUZ | E3: AGUA | F3: ALQUILER | G3: ESPACIO | H3: PARQUEO | I3: TICKET | J3: TOTAL
J4: =SUM(D4:I4) -> 0
J5: =SUM(D5:I5) -> 0
J6: =SUM(D6:I6) -> 0
J7: =SUM(D7:I7) -> 0
J8: =SUM(D8:I8) -> 0
J9: =SUM(D9:I9) -> 0
J10: =SUM(D10:I10) -> 0
J11: =SUM(D11:I11) -> 0
J12: =SUM(D12:I12) -> 0
J13: =SUM(D13:I13) -> 0
J14: =SUM(D14:I14) -> 0
J15: =SUM(D15:I15) -> 0
... J21: =SUM(D21:I21) -> 0
A22: TOTAL | D22: =SUM(D4:D21) -> 0 | E22: =SUM(E4:E21) -> 0 | F22: =SUM(F4:F21) -> 0 | G22: =SUM(G4:G21) -> 0 | H22: =SUM(H4:H21) -> 0 | I22: =SUM(I4:I21) -> 0 | J22: =SUM(J4:J21) -> 0
A24: BBVA
A25: INQUILINOS | B25: COMPROBANTE | C25: DETALLE | D25: LUZ | E25: AGUA | F25: ALQUILER | G25: ESPACIO | H25: DEPOSITO | I25: TICKET | J25: TOTAL
J26: =SUM(D26:I26) -> 0
J27: =SUM(D27:I27) -> 0
J28: =SUM(D28:I28) -> 0
J29: =SUM(D29:I29) -> 0 | L29: TOTAL QR | M29: =J30+J38 -> 0
A30: TOTAL | J30: =SUM(J26:J29) -> 0
A32: BBVA
A33: SOCIOS | B33: RECIBO DE SERVICIO | C33: DETALLE | D33: LUZ | E33: AGUA | F33: G. ADM | G33: P. SOCIAL | H33: DEPOSITO | I33: P.S X FALLECIMIENTO | J33: TOTAL
J34: =SUM(D34:I34) -> 0
J35: =SUM(D35:I35) -> 0
J36: =SUM(D36:I36) -> 0
J37: =SUM(D37:I37) -> 0
A38: TOTAL | J38: =SUM(J34:J37) -> 0
A42: SOCIO | B42: RECIBO DE SERVICIO | C42: DETALLE | D42: LUZ | E42: AGUA | F42: G. ADM | G42: P. SOCIAL | H42: P.S X FALLECIMIENTO | I42: DEPOSITO | J42: TOTAL
J43: =SUM(D43:I43) -> 0
J44: =SUM(D44:I44) -> 0
J45: =SUM(D45:I45) -> 0
J46: =SUM(D46:I46) -> 0
J47: =SUM(D47:I47) -> 0
J48: =SUM(D48:I48) -> 0
J49: =SUM(D49:I49) -> 0
J50: =SUM(D50:I50) -> 0
J51: =SUM(D51:I51) -> 0
...

Sheet 23-02-2026
A1: INGRESOS DEL DIA 23-02-2026
A3: INQUILINO | B3: COMPROBANTE | C3: DETALLE | D3: LUZ | E3: AGUA | F3: ALQUILER | G3: ESPACIO | H3: PARQUEO | I3: LOCAL 2DO PISO | J3: TOTAL
A4: SEVEN DAYS CORPORATION S.A.C. | B4: E001-321 | C4: 46054 | G4: 60 | J4: =SUM(D4:I4) -> 60
A5: PARQUEO | B5: EB01-6905 | C5: 46054 | H5: 67 | J5: =SUM(D5:I5) -> 67
A6: CARLOS ROJAS SILVA | B6: EB01-6907 | C6: 46174 | I6: 200 | J6: =SUM(D6:I6) -> 200
A7: LEON RODRIGUEZ ANGIE | B7: EB01-6908 | C7: 46023 | F7: 850 | J7: =SUM(D7:I7) -> 850
A8: PARQUEO | B8: EB01-6910 | C8: 46054 | H8: 54.7 | J8: =SUM(D8:I8) -> 54.7
J9: =SUM(D9:I9) -> 0
J10: =SUM(D10:I10) -> 0
J11: =SUM(D11:I11) -> 0
J12: =SUM(D12:I12) -> 0
J13: =SUM(D13:I13) -> 0
J14: =SUM(D14:I14) -> 0
A15: LEON RODRIGUEZ ANGIE | B15: RII 3267 | C15: 46023 | D15: 13.3 | E15: 3 | J15: =SUM(D15:I15) -> 16.3
J16: =SUM(D16:I16) -> 0
J17: =SUM(D17:I17) -> 0
J18: =SUM(D18:I18) -> 0
J19: =SUM(D19:I19) -> 0
J20: =SUM(D20:I20) -> 0
J21: =SUM(D21:I21) -> 0
A22: TOTAL | D22: =SUM(D5:D21) -> 13.3 | E22: =SUM(E5:E21) -> 3 | F22: =SUM(F5:F21) -> 850 | G22: =SUM(G4:G21) -> 60 | H22: =SUM(H5:H21) -> 121.7 | I22: =SUM(I5:I21) -> 200 | J22: =SUM(J4:J21) -> 1248
A24: BBVA
A25: INQUILINOS | B25: COMPROBANTE | C25: DETALLE | D25: LUZ | E25: AGUA | F25: ALQUILER | G25: ESPACIO | H25: DEPOSITO | I25: TICKET | J25: TOTAL
A26: DAVID CHOQUEHUANCA HUAMAN | B26: EB01-6906 | C26: 46023 | F26: 180 | J26: =SUM(D26:I26) -> 180
B27: RII 3266 | C27: 45839 | D27: 8.2 | E27: 4 | J27: =SUM(D27:I27) -> 12.2
C28: 45962 | D28: 20.4 | E28: 5 | J28: =SUM(D28:I28) -> 25.4
C29: 45992 | D29: 26.6 | E29: 5 | J29: =SUM(D29:I29) -> 31.6
C30: 46023 | D30: 29 | E30: 3 | J30: =SUM(D30:I30) -> 32
J31: =SUM(D31:I31) -> 0
J32: =SUM(D32:I32) -> 0
J33: =SUM(D33:I33) -> 0 | L33: TOTAL QR | M33: =J34+J42 -> 1347.6
A34: TOTAL | J34: =SUM(J26:J33) -> 281.2
A36: BBVA
A37: SOCIOS | B37: RECIBO DE SERVICIO | C37: DETALLE | D37: LUZ | E37: AGUA | F37: G. ADM | G37: P. SOCIAL | H37: DEPOSITO | I37: P.S X FALLECIMIENTO | J37: TOTAL
A38: PALOMINO EUSEBIO | B38: RI 32552 | C38: 46023 | D38: 31.4 | E38: 36.6 | I38: 10 | J38: =SUM(D38:I38) -> 78
A39: FLORES FLORES IRENE | B39: RI 32554 | C39: 46023 | D39: 504.8 | E39: 97.3 | F39: 60 | G39: 5 | I39: 10 | J39: =SUM(D39:I39) -> 677.1
A40: QUISPE DOROTEA | B40: RI 32558 | C40: 45992 | D40: 305.3 | E40: 6 | J40: =SUM(D40:I40) -> 311.3
J41: =SUM(D41:I41) -> 0
A42: TOTAL | J42: =SUM(J38:J41) -> 1066.4
A46: SOCIO | B46: RECIBO DE SERVICIO | C46: DETALLE | D46: LUZ | E46: AGUA | F46: G. ADM | G46: P. SOCIAL | H46: P.S X FALLECIMIENTO | I46: MULTA | J46: TOTAL
...

Sheet 24-02-2026
A1: INGRESOS DEL DIA 24-02-2026
A3: INQUILINO | B3: COMPROBANTE | C3: DETALLE | D3: LUZ | E3: AGUA | F3: ALQUILER | G3: ESPACIO | H3: PARQUEO | I3: TICKET | J3: TOTAL
A4: JOSE DESARMADORES | B4: TK 50775 | C4: 46054 | I4: 10 | J4: =SUM(D4:I4) -> 10
A5: JOSE | B5: TK 50776 | C5: 46054 | I5: 10 | J5: =SUM(D5:I5) -> 10
A6: PARQUEO | B6: EB01-6912 | C6: 46054 | H6: 55.2 | J6: =SUM(D6:I6) -> 55.2
J7: =SUM(D7:I7) -> 0
J8: =SUM(D8:I8) -> 0
J9: =SUM(D9:I9) -> 0
J10: =SUM(D10:I10) -> 0
J11: =SUM(D11:I11) -> 0
J12: =SUM(D12:I12) -> 0
J13: =SUM(D13:I13) -> 0
J14: =SUM(D14:I14) -> 0
J15: =SUM(D15:I15) -> 0
J16: =SUM(D16:I16) -> 0
J17: =SUM(D17:I17) -> 0
J18: =SUM(D18:I18) -> 0
... J21: =SUM(D21:I21) -> 0
A22: TOTAL | D22: =SUM(D4:D21) -> 0 | E22: =SUM(E4:E21) -> 0 | F22: =SUM(F4:F21) -> 0 | G22: =SUM(G4:G21) -> 0 | H22: =SUM(H4:H21) -> 55.2 | I22: =SUM(I4:I21) -> 20 | J22: =SUM(J4:J21) -> 75.2
A24: BBVA
A25: INQUILINOS | B25: COMPROBANTE | C25: DETALLE | D25: LUZ | E25: AGUA | F25: ALQUILER | G25: ESPACIO | H25: DEPOSITO | I25: TICKET | J25: TOTAL
J26: =SUM(D26:I26) -> 0
J27: =SUM(D27:I27) -> 0
J28: =SUM(D28:I28) -> 0
J29: =SUM(D29:I29) -> 0 | L29: TOTAL QR | M29: =J30+J38 -> 230
A30: TOTAL | J30: =SUM(J26:J29) -> 0
A32: BBVA
A33: SOCIOS | B33: RECIBO DE SERVICIO | C33: DETALLE | D33: LUZ | E33: AGUA | F33: G. ADM | G33: P. SOCIAL | H33: DEPOSITO | I33: P.S X FALLECIMIENTO | J33: TOTAL
A34: ZAPATA ROSANA | B34: RI 32563 | C34: 45992 | D34: 84 | E34: 146 | J34: =SUM(D34:I34) -> 230
J35: =SUM(D35:I35) -> 0
J36: =SUM(D36:I36) -> 0
J37: =SUM(D37:I37) -> 0
A38: TOTAL | J38: =SUM(J34:J37) -> 230
A42: SOCIO | B42: RECIBO DE SERVICIO | C42: DETALLE | D42: LUZ | E42: AGUA | F42: G. ADM | G42: P. SOCIAL | H42: P.S X FALLECIMIENTO | I42: MULTA | J42: TOTAL
A43: DE LA CRUZ JOSE | B43: RI 32561 | C43: 46023 | H43: 10 | J43: =SUM(D43:I43) -> 10
A44: SANCHEZ JUDITH | B44: RI 32562 | C44: 45962 | D44: 53.6 | E44: 11.6 | F44: 60 | G44: 5 | J44: =SUM(D44:I44) -> 130.2
C45: 45992 | D45: 18.5 | E45: 70.1 | F45: 60 | G45: 5 | J45: =SUM(D45:I45) -> 153.6
C46: 46023 | F46: 60 | G46: 5 | H46: 10 | I46: 28.3 | J46: =SUM(D46:I46) -> 103.3
A47: ZAPATA ROSANA | B47: RI 32564 | C47: 45992 | D47: 0.6 | J47: =SUM(D47:I47) -> 0.6
A48: MAYHUASCA CLUDY | B48: RI 32565 | C48: 46023 | D48: 362 | E48: 30 | J48: =SUM(D48:I48) -> 392
...

Sheet 25-02-2026
A1: INGRESOS DEL DIA 25-02-2026
A3: INQUILINO | B3: COMPROBANTE | C3: DETALLE | D3: LUZ | E3: AGUA | F3: ALQUILER | G3: ESPACIO | H3: PARQUEO | I3: TICKET | J3: TOTAL
A4: JOSE | B4: TK 50777 | C4: 46054 | I4: 10 | J4: =SUM(D4:I4) -> 10
A5: LAPAS MARIA | B5: RII 3268 | C5: 45962 | D5: 10 | E5: 5 | J5: =SUM(D5:I5) -> 15
C6: 45992 | D6: 10 | E6: 5 | J6: =SUM(D6:I6) -> 15
C7: 46023 | D7: 15 | E7: 3 | J7: =SUM(D7:I7) -> 18
A8: CLAROS SANTOS JESUS | B8: RII 3269 | C8: 46023 | D8: 21.1 | E8: 3 | J8: =SUM(D8:I8) -> 24.1
A9: CASTRO JANETT | B9: RII 3270 | C9: 46023 | D9: 9 | E9: 3 | J9: =SUM(D9:I9) -> 12
A10: ARREDONDO GLADYS | B10: RII 3271 | C10: 46023 | D10: 15 | E10: 3 | J10: =SUM(D10:I10) -> 18
J11: =SUM(D11:I11) -> 0
J12: =SUM(D12:I12) -> 0
J13: =SUM(D13:I13) -> 0
J14: =SUM(D14:I14) -> 0
A15: HUAMANI MAXIMO | B15: EB01-6913 | C15: 46054 | F15: 400 | J15: =SUM(D15:I15) -> 400
A16: QUISPE MARISOL | B16: EB01-6914 | C16: 46023 | F16: 50 | J16: =SUM(D16:I16) -> 50
A17: ALVAREZ EDGAR | B17: EB01-6915 | C17: 46023 | F17: 300 | J17: =SUM(D17:I17) -> 300
A18: CASTRO JANETT | B18: EB01-6916 | C18: 45992 | F18: 150 | J18: =SUM(D18:I18) -> 150
C19: 46023 | F19: 100 | J19: =SUM(D19:I19) -> 100
A20: ARREDONDO GLADYS | B20: EB01-6917 | C20: 46023 | F20: 100 | J20: =SUM(D20:I20) -> 100
A21: PARQUEO | B21: EB01-6919 | C21: 46054 | H21: 63.5 | J21: =SUM(D21:I21) -> 63.5
J22: =SUM(D22:I22) -> 0
J23: =SUM(D23:I23) -> 0
J24: =SUM(D24:I24) -> 0
J25: =SUM(D25:I25) -> 0
A26: CLAROS SANTOS JESUS | B26: E001-323 | C26: 46023 | F26: 100 | J26: =SUM(D26:I26) -> 100
J27: =SUM(D27:I27) -> 0
J28: =SUM(D28:I28) -> 0
A29: TOTAL | D29: =SUM(D4:D28) -> 80.1 | E29: =SUM(E4:E28) -> 22 | F29: =SUM(F4:F28) -> 1200 | G29: =SUM(G4:G28) -> 0 | H29: =SUM(H4:H28) -> 63.5 | I29: =SUM(I4:I28) -> 10 | J29: =SUM(J4:J28) -> 1375.6
A31: BBVA
A32: INQUILINOS | B32: COMPROBANTE | C32: DETALLE | D32: LUZ | E32: AGUA | F32: ALQUILER | G32: ESPACIO | H32: DEPOSITO | I32: TICKET | J32: TOTAL
A33: VASQUEZ TAFUR SONIA | B33: E001-322 | C33: 46082 | G33: 30 | J33: =SUM(D33:I33) -> 30
J34: =SUM(D34:I34) -> 0
J35: =SUM(D35:I35) -> 0
J36: =SUM(D36:I36) -> 0 | L36: TOTAL QR | M36: =J37+J45 -> 30
A37: TOTAL | J37: =SUM(J33:J36) -> 30
A39: BBVA
A40: SOCIOS | B40: RECIBO DE SERVICIO | C40: DETALLE | D40: LUZ | E40: AGUA | F40: G. ADM | G40: P. SOCIAL | H40: DEPOSITO | I40: P.S X FALLECIMIENTO | J40: TOTAL
J41: =SUM(D41:I41) -> 0
J42: =SUM(D42:I42) -> 0
J43: =SUM(D43:I43) -> 0
...

Sheet 26-02-2026
A1: INGRESOS DEL DIA 26-02-2026
A3: INQUILINO | B3: COMPROBANTE | C3: DETALLE | D3: LUZ | E3: AGUA | F3: ALQUILER | G3: ESPACIO | H3: PARQUEO | I3: TICKET | K3: TOTAL
A4: JOSE | B4: TK 50778 | C4: 46054 | I4: 10 | K4: =SUM(D4:I4) -> 10
A5: PARQUEO | B5: EB01-6920 | C5: 46054 | H5: 62.7 | K5: =SUM(D5:I5) -> 62.7
K6: =SUM(D6:I6) -> 0
K7: =SUM(D7:I7) -> 0
K8: =SUM(D8:I8) -> 0
K9: =SUM(D9:I9) -> 0
K10: =SUM(D10:I10) -> 0
K11: =SUM(D11:I11) -> 0
K12: =SUM(D12:I12) -> 0
K13: =SUM(D13:I13) -> 0
